Workbook

Sheet base
A1: Date | B1: PBI | C1: DPBI | D1: EMBI | E1: ITCRM | F1: M1R | G1: M3R | H1: GPN | I1: VITI | J1: PBIBR | K1: RPRIM
A2: 38718 | B2: 532348.21 | C2: 0.078495711 | D2: 394.41518 | E2: 166.81316 | F2: 0.065572691 | G2: 0.024910905 | H2: 0.28693314 | I2: 0.066973169 | J2: 0.0428 | K2: 0.032958003
A3: 38808 | B3: 614076.39 | C3: 0.055715853 | D3: 353.71381 | E3: 166.01966 | F3: 0.074826081 | G3: 0.048520637 | H3: 0.2540691 | I3: 0.067706744 | J3: 0.0228 | K3: 0.031862289
A4: 38899 | B4: 562978.97 | C4: 0.093804903 | D4: 339.04529 | E4: 165.95347 | F4: 0.0729218 | G4: 0.06474531 | H4: 0.28130623 | I4: 0.018443079 | J4: 0.0449 | K4: 0.031968251
A5: 38991 | B5: 572794.05 | C5: 0.096770404 | D5: 281.70526 | E5: 163.55665 | F5: 0.082156516 | G5: 0.092447249 | H5: 0.30014681 | I5: 0.0287149 | J5: 0.048 | K5: 0.032215474
A6: 39083 | B6: 576846.89 | C6: 0.083589411 | D6: 210.27944 | E6: 163.25902 | F6: 0.10364673 | G6: 0.1266018 | H6: 0.3354463 | I6: 0.068186259 | J6: 0.052 | K6: 0.031042814
A7: 39173 | B7: 674620.56 | C7: 0.098593874 | D7: 268.38567 | E7: 161.94288 | F7: 0.10878117 | G7: 0.11396594 | H7: 0.34084552 | I7: 0.026535251 | J7: 0.0654 | K7: 0.031321511
A8: 39264 | B8: 610425.69 | C8: 0.084277977 | D8: 415.12806 | E8: 157.56189 | F8: 0.095031538 | G8: 0.089343321 | H8: 0.44092854 | I8: 0.0081467198 | J8: 0.0587 | K8: 0.031924431
A9: 39356 | B9: 625876.87 | C9: 0.092673486 | D9: 386.90139 | E9: 158.87919 | F9: 0.03479478 | G9: 0.037973687 | H9: 0.36017815 | I9: 0.13455358 | J9: 0.0664 | K9: 0.028543076
A10: 39448 | B10: 616720.36 | C10: 0.069123146 | D10: 482.23843 | E10: 159.2879 | F10: 0.0060995986 | G10: 0.0057682917 | H10: 0.34656181 | I10: 0.22926803 | J10: 0.0616 | K10: 0.025607989
A11: 39539 | B11: 711405.5 | C11: 0.054526855 | D11: 556.6532 | E11: 152.77005 | F11: -0.032825593 | G11: -0.041444326 | H11: 0.39823908 | I11: 0.14032077 | J11: 0.0634 | K11: 0.023277094
A12: 39630 | B12: 647087.96 | C12: 0.060060161 | D12: 696.82717 | E12: 142.65217 | F12: -0.01260622 | G12: -0.031056134 | H12: 0.30597299 | I12: 0.16267284 | J12: 0.0698 | K12: 0.02323516
A13: 39722 | B13: 613490.82 | C13: -0.019789909 | D13: 1696.5902 | E13: 128.29873 | F13: 0.0082101847 | G13: -0.043350325 | H13: 0.35000525 | I13: -0.019042212 | J13: 0.0102 | K13: 0.020534122
... A79: 45748 | B79: 775964.8 | C79: 0.063041514 | D79: 723.84615 | E79: 84.109103 | F79: 0.28204721 | G79: 0.16935724 | H79: 0.39 | I79: 0.066773455 | J79: 0.0222 | K79: 0.011355804

Sheet base_mensual
A1: Date | B1: DPBI_desest | C1: prod_autos | D1: expo_autos | E1: vtas_concesionarios | F1: vtas_autos_livianos | G1: despacho_cem | H1: ISAC_desest | I1: hierro_primario | J1: acero_crudo | K1: lamin_tot_no_planos | L1: reca_derech_comex | M1: reca_iva | N1: reca_gananc | O1: reca_derech_comex_real | P1: reca_iva_real | Q1: reca_gananc_real | R1: merval_px | S1: merval_avg | T1: merval_px_real | U1: merval_avg_real | V1: IBG INDEX | W1: IBG INDEX real | X1: M1 | Y1: M1 real | Z1: M2 | AA1: M2 real | AB1: badlar_TNA | AC1: faena_aves | AD1: vta_usados | AE1: ipi_desest | AF1: bcnd | AG1: bcd | AH1: bui | AI1: bk | AJ1: alim_beb | AK1: cigarrillos | AL1: insum_text | AM1: pasta_papel | AN1: combustible | AO1: quim_plast | AP1: min_no_met | AQ1: metalicas | AR1: metalmec | AS1: automov | AT1: ICC | AU1: IL | AV1: salario | AW1: molienda_soja | AX1: inflacion | AY1: EMBI | AZ1: ICG | BA1: IGA_OJF | BB1: EMAE
A2: 41305 | B2: -0.0013364764 | C2: 44061 | D2: 24195 | E2: 58070 | F2: 13509 | G2: 913823 | H2: 179.86247 | I2: 401.24497 | J2: 398.02701 | K2: 191.69618 | L2: 4744.5808 | M2: 19127.968 | N2: 12506.848 | O2: =+L2/$AX2/100 -> 0.47144086 | P2: =+M2/$AX2/100 -> 1.9006328 | Q2: =+N2/$AX2/100 -> 1.2427313 | R2: 3462.42 | S2: 3174.4283 | T2: =+R2/$AX2/100 -> 0.34404014 | U2: =+S2/$AX2/100 -> 0.31542411 | V2: 197267.7 | W2: =+V2/AX2/100 -> 19.601322 | X2: =+'[1]Agregados MesTrim'!B208 -> 409601.9 | Y2: =+X2/$AX2/100 -> 40.699712 | Z2: 539862 | AA2: =+Z2/$AX2/100 -> 53.642886 | AB2: 0.15139881 | AC2: 63266 | AD2: 153852 | AE2: 160.4271 | AF2: 147.38627 | AG2: 91.557057 | AH2: 150.24596 | AI2: 223.23467 | AJ2: 157.96979 | AK2: 110.13955 | AL2: 65.735296 | AM2: 153.93588 | AN2: 108.44158 | AO2: 201.21629 | AP2: 179.80005 | AQ2: 162.15783 | AR2: 86.904814 | AS2: 148.60577 | AT2: 46.856686 | AU2: 137.03399 | AV2: =+VLOOKUP(A2,'[2]Salario Real'!$A$5:$C$292,2) -> 128.03594 | AW2: 1708802 | AX2: 100.64 | AY2: 1101.696 | AZ2: 1.7623828 | BA2: 167.18324 | BB2: 136.51707
A3: 41333 | B3: -0.0013364764 | C3: 52911 | D3: 24646 | E3: 67696 | F3: 15605 | G3: 839605 | H3: 184.56116 | I3: 324.94676 | J3: 388.5379 | K3: 173.73251 | L3: 4486.7342 | M3: 18234.774 | N3: 12755.386 | O3: =+L3/$AX3/100 -> 0.44383705 | P3: =+M3/$AX3/100 -> 1.8038216 | Q3: =+N3/$AX3/100 -> 1.2617892 | R3: 3048.55 | S3: 3258.7965 | T3: =+R3/$AX3/100 -> 0.30156889 | U3: =+S3/$AX3/100 -> 0.32236691 | V3: 182443 | W3: =+V3/AX3/100 -> 18.04764 | X3: =+'[1]Agregados MesTrim'!B209 -> 403844.41 | Y3: =+X3/$AX3/100 -> 39.949126 | Z3: 541450 | AA3: =+Z3/AX3/100 -> 53.561357 | AB3: 0.14764706 | AC3: 54703 | AD3: 123646 | AE3: 161.81948 | AF3: 130.83791 | AG3: 125.10045 | AH3: 136.40118 | AI3: 319.07921 | AJ3: 138.91591 | AK3: 102.40887 | AL3: 81.317636 | AM3: 150.26781 | AN3: 98.350307 | AO3: 171.37856 | AP3: 160.87098 | AQ3: 155.4077 | AR3: 130.23903 | AS3: 186.46689 | AT3: 47.61668 | AU3: 140.0485 | AV3: =+VLOOKUP(A3,'[2]Salario Real'!$A$5:$C$292,2) -> 125.88604 | AW3: 1212383 | AX3: 101.08967 | AY3: 1286.804 | AZ3: 1.8314094 | BA3: 168.59632 | BB3: 132.79532
A4: 41362 | B4: -0.0013364764 | C4: 79031 | D4: 41591 | E4: 77185 | F4: 19197 | G4: 939405 | H4: 187.0393 | I4: 306.23802 | J4: 443.30658 | K4: 236.04005 | L4: 5647.9986 | M4: 18358.205 | N4: 11688.338 | O4: =+L4/$AX4/100 -> 0.552318 | P4: =+M4/$AX4/100 -> 1.7952496 | Q4: =+N4/$AX4/100 -> 1.143003 | R4: 3380.78 | S4: 3369.091 | T4: =+R4/$AX4/100 -> 0.3306066 | U4: =+S4/$AX4/100 -> 0.32946353 | V4: 198283.3 | W4: =+V4/AX4/100 -> 19.390131 | X4: =+'[1]Agregados MesTrim'!B210 -> 406819.11 | Y4: =+X4/$AX4/100 -> 39.782856 | Z4: 556047 | AA4: =+Z4/AX4/100 -> 54.375857 | AB4: 0.14851974 | AC4: 61557 | AD4: 142916 | AE4: 164.75222 | AF4: 143.01413 | AG4: 194.4071 | AH4: 167.8354 | AI4: 425.3219 | AJ4: 150.84513 | AK4: 115.45441 | AL4: 98.646554 | AM4: 157.9072 | AN4: 114.64863 | AO4: 221.49405 | AP4: 184.22149 | AQ4: 208.23387 | AR4: 195.12844 | AS4: 277.66047 | AT4: 46.908466 | AU4: 140.99069 | AV4: =+VLOOKUP(A4,'[2]Salario Real'!$A$5:$C$292,2) -> 124.46944 | AW4: 1721068 | AX4: 102.25991 | AY4: 1307.326 | AZ4: 1.913988 | BA4: 174.11857 | BB4: 149.40395
A5: 41394 | B5: 0.0070491739 | C5: 75496 | D5: 40864 | E5: 85533 | F5: 21185 | G5: 975601 | H5: 190.02608 | I5: 289.82868 | J5: 395.86102 | K5: 210.16233 | L5: 10660.667 | M5: 18509.156 | N5: 11045.605 | O5: =+L5/$AX5/100 -> 1.0426175 | P5: =+M5/$AX5/100 -> 1.8102028 | Q5: =+N5/$AX5/100 -> 1.0802646 | R5: 3845.94 | S5: 3494.9573 | T5: =+R5/$AX5/100 -> 0.37613447 | U5: =+S5/$AX5/100 -> 0.34180822 | V5: 228743.2 | W5: =+V5/AX5/100 -> 22.371177 | X5: =+'[1]Agregados MesTrim'!B211 -> 417888.6 | Y5: =+X5/$AX5/100 -> 40.869673 | Z5: 558223 | AA5: =+Z5/AX5/100 -> 54.594433 | AB5: 0.1513125 | AC5: 62207 | AD5: 151692 | AE5: 167.37289 | AF5: 146.46637 | AG5: 195.33292 | AH5: 155.14709 | AI5: 436.00151 | AJ5: 158.97659 | AK5: 102.43898 | AL5: 98.61643 | AM5: 148.70781 | AN5: 96.292441 | AO5: 202.4246 | AP5: 192.0641 | AQ5: 196.41319 | AR5: 205.12374 | AS5: 265.01225 | AT5: 44.055088 | AU5: 141.47396 | AV5: =+VLOOKUP(A5,'[2]Salario Real'!$A$5:$C$292,2) -> 124.48312 | AW5: 3587628 | AX5: 102.24907 | AY5: 1210.234 | AZ5: 1.7586069 | BA5: 170.91693 | BB5: 155.9416
A6: 41425 | B6: 0.0070491739 | C6: 79590 | D6: 49594 | E6: 85646 | F6: 21827 | G6: 1016258 | H6: 196.56929 | I6: 348.35881 | J6: 423.81265 | K6: 201.8714 | L6: 7368.6601 | M6: 20322.85 | N6: 21101.714 | O6: =+L6/$AX6/100 -> 0.704203 | P6: =+M6/$AX6/100 -> 1.9422001 | Q6: =+N6/$AX6/100 -> 2.0166339 | R6: 3489.43 | S6: 3686.0196 | T6: =+R6/$AX6/100 -> 0.33347543 | U6: =+S6/$AX6/100 -> 0.35226296 | V6: 203767.4 | W6: =+V6/AX6/100 -> 19.473502 | X6: =+'[1]Agregados MesTrim'!B212 -> 425667.09 | Y6: =+X6/$AX6/100 -> 40.679857 | Z6: 563482 | AA6: =+Z6/AX6/100 -> 53.850457 | AB6: 0.15798295 | AC6: 65927 | AD6: 166001 | AE6: 169.3936 | AF6: 153.31702 | AG6: 199.29813 | AH6: 164.10242 | AI6: 454.97336 | AJ6: 167.83618 | AK6: 102.21951 | AL6: 104.76187 | AM6: 153.7167 | AN6: 101.20239 | AO6: 217.22422 | AP6: 198.31914 | AQ6: 205.49227 | AR6: 206.17397 | AS6: 279.9881 | AT6: 41.648998 | AU6: 142.40954 | AV6: =+VLOOKUP(A6,'[2]Salario Real'!$A$5:$C$292,2) -> 128.12976 | AW6: 3933147 | AX6: 104.63829 | AY6: 1167.336 | AZ6: 1.4201471 | BA6: 171.79096 | BB6: 167.97348
A7: 41453 | B7: 0.0070491739 | C7: 63461 | D7: 42621 | E7: 88541 | F7: 21906 | G7: 931774 | H7: 189.85581 | I7: 326.51453 | J7: 458.57168 | K7: 204.76066 | L7: 5816.7771 | M7: 19729.981 | N7: 21914.388 | O7: =+L7/$AX7/100 -> 0.54594382 | P7: =+M7/$AX7/100 -> 1.851792 | Q7: =+N7/$AX7/100 -> 2.0568134 | R7: 2976.27 | S7: 3198.431 | T7: =+R7/$AX7/100 -> 0.27934305 | U7: =+S7/$AX7/100 -> 0.30019436 | V7: 175063.6 | W7: =+V7/AX7/100 -> 16.430902 | X7: =+'[1]Agregados MesTrim'!B213 -> 438076.83 | Y7: =+X7/$AX7/100 -> 41.11647 | Z7: 600987 | AA7: =+Z7/AX7/100 -> 56.40669 | AB7: 0.16572917 | AC7: 56424 | AD7: 136903 | AE7: 163.37278 | AF7: 151.47161 | AG7: 172.29816 | AH7: 148.62867 | AI7: 397.15421 | AJ7: 166.36302 | AK7: 99.064048 | AL7: 95.505915 | AM7: 153.22901 | AN7: 106.15101 | AO7: 176.79112 | AP7: 186.73022 | AQ7: 186.39997 | AR7: 188.73816 | AS7: 223.61105 | AT7: 44.491737 | AU7: 139.03479 | AV7: =+VLOOKUP(A7,'[2]Salario Real'!$A$5:$C$292,2) -> 128.54141 | AW7: 3925104 | AX7: 106.54534 | AY7: 1198.724 | AZ7: 1.7441265 | BA7: 169.5184 | BB7: 156.27186
A8: 41486 | B8: 0.0064292807 | C8: 71895 | D8: 39289 | E8: 81425 | F8: 18087 | G8: 1015717 | H8: 187.8489 | I8: 315.33109 | J8: 444.54429 | K8: 208.78051 | L8: 7879.662 | M8: 21561.773 | N8: 15648.793 | O8: =+L8/$AX8/100 -> 0.73322129 | P8: =+M8/$AX8/100 -> 2.0063743 | Q8: =+N8/$AX8/100 -> 1.4561574 | R8: 3357.86 | S8: 3276.0052 | T8: =+R8/$AX8/100 -> 0.31245686 | U8: =+S8/$AX8/100 -> 0.30484007 | V8: 194992.1 | W8: =+V8/AX8/100 -> 18.144479 | X8: =+'[1]Agregados MesTrim'!B214 -> 451829.23 | Y8: =+X8/$AX8/100 -> 42.043784 | Z8: 607319 | AA8: =+Z8/AX8/100 -> 56.512477 | AB8: 0.17284091 | AC8: 66082 | AD8: 177328 | AE8: 164.39346 | AF8: 163.50211 | AG8: 188.1505 | AH8: 153.64146 | AI8: 422.99684 | AJ8: 180.94619 | AK8: 102.11091 | AL8: 93.673788 | AM8: 156.53156 | AN8: 109.57701 | AO8: 187.53378 | AP8: 197.40782 | AQ8: 197.08288 | AR8: 199.61214 | AS8: 252.53718 | AT8: 47.481728 | AU8: 141.20699 | AV8: =+VLOOKUP(A8,'[2]Salario Real'!$A$5:$C$292,2) -> 128.90478 | AW8: 3641364 | AX8: 107.46636 | AY8: 1111.536 | AZ8: 1.6790159 | BA8: 171.84473 | BB8: 150.731
A9: 41516 | B9: 0.0064292807 | C9: 69922 | D9: 33528 | E9: 88922 | F9: 22581 | G9: 1079794 | H9: 191.56118 | I9: 357.45189 | J9: 488.37987 | K9: 226.49293 | L9: 8857.8651 | M9: 22341.219 | N9: 15661.008 | O9: =+L9/$AX9/100 -> 0.81990531 | P9: =+M9/$AX9/100 -> 2.067957 | Q9: =+N9/$AX9/100 -> 1.4496206 | R9: 3935.89 | S9: 3747.6118 | T9: =+R9/$AX9/100 -> 0.36431545 | U9: =+S9/$AX9/100 -> 0.34688797 | V9: 226987.2 | W9: =+V9/AX9/100 -> 21.010482 | X9: =+'[1]Agregados MesTrim'!B215 -> 456853.67 | Y9: =+X9/$AX9/100 -> 42.287475 | Z9: 609597 | AA9: =+Z9/AX9/100 -> 56.425766 | AB9: 0.17723214 | AC9: 61917 | AD9: 169751 | AE9: 167.7836 | AF9: 164.87063 | AG9: 192.0704 | AH9: 163.25163 | AI9: 441.78654 | AJ9: 180.56235 | AK9: 109.64654 | AL9: 90.283906 | AM9: 153.28829 | AN9: 112.69137 | AO9: 207.34629 | AP9: 207.71125 | AQ9: 205.51433 | AR9: 210.51616 | AS9: 248.70069 | AT9: 50.028309 | AU9: 144.48179 | AV9: =+VLOOKUP(A9,'[2]Salario Real'!$A$5:$C$292,2) -> 128.89675 | AW9: 3678455 | AX9: 108.03522 | AY9: 1169.982 | AZ9: 1.868806 | BA9: 173.36121 | BB9: 148.42145
A10: 41547 | B10: 0.0064292807 | C10: 71928 | D10: 36489 | E10: 85300 | F10: 21851 | G10: 1051925 | H10: 187.60771 | I10: 329.44104 | J10: 460.42824 | K10: 230.88963 | L10: 7230.5075 | M10: 22094.359 | N10: 14077.562 | O10: =+L10/$AX10/100 -> 0.6626273 | P10: =+M10/$AX10/100 -> 2.0247992 | Q10: =+N10/$AX10/100 -> 1.2901137 | R10: 4783.77 | S10: 4531.1524 | T10: =+R10/$AX10/100 -> 0.43840029 | U10: =+S10/$AX10/100 -> 0.41524959 | V10: 258046.2 | W10: =+V10/AX10/100 -> 23.648196 | X10: =+'[1]Agregados MesTrim'!B216 -> 463559.48 | Y10: =+X10/$AX10/100 -> 42.482103 | Z10: 631712 | AA10: =+Z10/AX10/100 -> 57.892149 | AB10: 0.18110119 | AC10: 59071 | AD10: 165247 | AE10: 168.01688 | AF10: 164.8569 | AG10: 195.61071 | AH10: 161.99909 | AI10: 435.46478 | AJ10: 183.70203 | AK10: 98.535006 | AL10: 90.694706 | AM10: 152.77023 | AN10: 113.25152 | AO10: 205.57697 | AP10: 206.05334 | AQ10: 200.45736 | AR10: 211.50804 | AS10: 253.4456 | AT10: 48.647949 | AU10: 144.97905 | AV10: =+VLOOKUP(A10,'[2]Salario Real'!$A$5:$C$292,2) -> 128.6218 | AW10: 3582271 | AX10: 109.11877 | AY10: 1034.507 | AZ10: 1.7716093 | BA10: 174.40758 | BB10: 147.00484
A11: 41578 | B11: -0.0085728871 | C11: 75604 | D11: 42873 | E11: 81358 | F11: 20971 | G11: 1152262 | H11: 185.59018 | I11: 399.78171 | J11: 483.42903 | K11: 235.66319 | L11: 6345.9555 | M11: 23077.258 | N11: 14858.813 | O11: =+L11/$AX11/100 -> 0.57096183 | P11: =+M11/$AX11/100 -> 2.0763199 | Q11: =+N11/$AX11/100 -> 1.3368854 | R11: 5165.09 | S11: 5227.3178 | T11: =+R11/$AX11/100 -> 0.46471634 | U11: =+S11/$AX11/100 -> 0.47031514 | V11: 281415 | W11: =+V11/AX11/100 -> 25.319627 | X11: =+'[1]Agregados MesTrim'!B217 -> 470870.18 | Y11: =+X11/$AX11/100 -> 42.365393 | Z11: 635188 | AA11: =+Z11/AX11/100 -> 57.149487 | AB11: 0.18806818 | AC11: 62966 | AD11: 171497 | AE11: 167.64166 | AF11: 166.23719 | AG11: 204.87517 | AH11: 166.15754 | AI11: 451.23616 | AJ11: 181.6063 | AK11: 112.14847 | AL11: 87.971203 | AM11: 155.93141 | AN11: 111.33118 | AO11: 214.70063 | AP11: 222.12211 | AQ11: 210.90621 | AR11: 220.06888 | AS11: 266.42486 | AT11: 51.85112 | AU11: 147.3121 | AV11: =+VLOOKUP(A11,'[2]Salario Real'!$A$5:$C$292,2) -> 126.0401 | AW11: 2963012 | AX11: 111.145 | AY11: 920.685 | AZ11: 1.9764988 | BA11: 173.55227 | BB11: 148.69396
A12: 41607 | B12: -0.0085728871 | C12: 62186 | D12: 33733 | E12: 75274 | F12: 19735 | G12: 1062265 | H12: 186.85841 | I12: 370.20309 | J12: 417.62409 | K12: 214.68465 | L12: 4946.6552 | M12: 23256.036 | N12: 15271.748 | O12: =+L12/$AX12/100 -> 0.43831173 | P12: =+M12/$AX12/100 -> 2.0606638 | Q12: =+N12/$AX12/100 -> 1.3531944 | R12: 5718.68 | S12: 5437.7114 | T12: =+R12/$AX12/100 -> 0.50671907 | U12: =+S12/$AX12/100 -> 0.48182309 | V12: 287678.9 | W12: =+V12/AX12/100 -> 25.490565 | X12: =+'[1]Agregados MesTrim'!B218 -> 476573.89 | Y12: =+X12/$AX12/100 -> 42.228116 | Z12: 645178 | AA12: =+Z12/AX12/100 -> 57.167738 | AB12: 0.19095395 | AC12: 57917 | AD12: 147503 | AE12: 162.93222 | AF12: 148.67198 | AG12: 146.15261 | AH12: 163.45135 | AI12: 385.55054 | AJ12: 160.21307 | AK12: 108.05527 | AL12: 87.476872 | AM12: 157.77837 | AN12: 108.05876 | AO12: 214.11792 | AP12: 201.9588 | AQ12: 207.24857 | AR12: 152.89372 | AS12: 221.1326 | AT12: 49.885075 | AU12: 146.56115 | AV12: =+VLOOKUP(A12,'[2]Salario Real'!$A$5:$C$292,2) -> 125.30039 | AW12: 2318967 | AX12: 112.85701 | AY12: 775.912 | AZ12: 1.8471888 | BA12: 171.72866 | BB12: 145.6959
A13: 41639 | B13: -0.0085728871 | C13: 44922 | D13: 23872 | E13: 88967 | F13: 23295 | G13: 927744 | H13: 195.44041 | I13: 346.05941 | J13: 383.27763 | K13: 197.72594 | L13: 5029.7242 | M13: 22392.671 | N13: 17068.468 | O13: =+L13/$AX13/100 -> 0.43839068 | P13: =+M13/$AX13/100 -> 1.9517448 | Q13: =+N13/$AX13/100 -> 1.4876874 | R13: 5391.03 | S13: 5334.8486 | T13: =+R13/$AX13/100 -> 0.46988208 | U13: =+S13/$AX13/100 -> 0.46498532 | V13: 265324.6 | W13: =+V13/AX13/100 -> 23.125688 | X13: =+'[1]Agregados MesTrim'!B219 -> 498500.37 | Y13: =+X13/$AX13/100 -> 43.449284 | Z13: 701500 | AA13: =+Z13/AX13/100 -> 61.142728 | AB13: 0.20240132 | AC13: 60426 | AD13: 138927 | AE13: 162.96708 | AF13: 158.75526 | AG13: 122.41946 | AH13: 154.23042 | AI13: 346.92444 | AJ13: 167.90489 | AK13: 126.55488 | AL13: 76.006396 | AM13: 163.88072 | AN13: 112.46484 | AO13: 194.87532 | AP13: 185.43494 | AQ13: 197.03494 | AR13: 145.00251 | AS13: 161.98866 | AT13: 46.148899 | AU13: 144.64783 | AV13: =+VLOOKUP(A13,'[2]Salario Real'!$A$5:$C$292,2) -> 122.54161 | AW13: 1768668 | AX13: 114.73155 | AY13: 807.94 | AZ13: 1.6809168 | BA13: 172.05413 | BB13: 142.57688
A14: 41670 | B14: -0.015388241 | C14: 36156 | D14: 19570 | E14: 46766 | F14: 10357 | G14: 931705 | H14: 188.71428 | I14: 431.75222 | J14: 421.2372 | K14: 187.60111 | L14: 6549.6632 | M14: 27221.455 | N14: 18371.935 | O14: =+L14/$AX14/100 -> 0.56439229 | P14: =+M14/$AX14/100 -> 2.3457053 | Q14: =+N14/$AX14/100 -> 1.5831316 | R14: 6018.65 | S14: 5620.4991 | T14: =+R14/$AX14/100 -> 0.51863425 | U14: =+S14/$AX14/100 -> 0.48432512 | V14: 309834 | W14: =+V14/AX14/100 -> 26.698766 | X14: =+'[1]Agregados MesTrim'!B220 -> 501200.36 | Y14: =+X14/$AX14/100 -> 43.189033 | Z14: 669364 | AA14: =+Z14/AX14/100 -> 57.679895 | AB14: 0.21928977 | AC14: 62476 | AD14: 165000 | AE14: 163.42356 | AF14: 155.43906 | AG14: 77.848692 | AH14: 154.65602 | AI14: 236.12084 | AJ14: 162.41553 | AK14: 130.88667 | AL14: 71.676976 | AM14: 154.95649 | AN14: 110.93636 | AO14: 202.68252 | AP14: 185.6689 | AQ14: 187.7675 | AR14: 84.14835 | AS14: 123.93534 | AT14: 43.671379 | AU14: 141.86604 | AV14: =+VLOOKUP(A14,'[2]Salario Real'!$A$5:$C$292,2) -> 119.01068 | AW14: 1968357 | AX14: 116.04806 | AY14: 1084.941 | AZ14: 1.462484 | BA14: 170.40074 | BB14: 137.9697
... A51: 42794 | B51: 0.0090530868 | C51: 25717 | D51: 12931 | E51: 65274 | F51: 14339 | G51: 805992 | H51: 171.63532 | I51: 219.9 | J51: 305.1 | K51: 123.4 | L51: 5327.6131 | M51: 53121.923 | N51: 35345.859 | O51: =+L51/$AX51/100 -> 0.22828119 | P51: =+M51/$AX51/100 -> 2.2762043 | Q51: =+N51/$AX51/100 -> 1.5145234 | R51: 19117.45 | S51: 19455.244 | T51: =+R51/$AX51/100 -> 0.81915748 | U51: =+S51/$AX51/100 -> 0.83363149 | V51: 835707.9 | W51: =+V51/AX51/100 -> 35.80898 | X51: =+'[1]Agregados MesTrim'!B257 -> 1052367.4 | Y51: =+X51/$AX51/100 -> 45.092553 | Z51: 1457405 | AA51: =+Z51/AX51/100 -> 62.447879 | AB51: 0.200625 | AC51: 53259 | AD51: 115035 | AE51: 152.3922 | AF51: 126.88984 | AG51: 91.711789 | AH51: 134.84441 | AI51: 272.71953 | AJ51: 139.36977 | AK51: 82.969051 | AL51: 86.825857 | AM51: 139.22328 | AN51: 94.029594 | AO51: 176.08947 | AP51: 160.42355 | AQ51: 143.79648 | AR51: 127.97845 | AS51: 89.469202 | AT51: 40.681772 | AU51: 135.71053 | AV51: =+VLOOKUP(A51,'[2]Salario Real'!$A$5:$C$292,2) -> 115.42381 | AW51: 2624252 | AX51: 233.37942 | AY51: 466 | AZ51: 2.3498972 | BA51: 166.57934 | BB51: 132.15852
A52: 42825 | B52: 0.0090530868 | C52: 39675 | D52: 17508 | E52: 68947 | F52: 18401 | G52: =+G51 -> 805992 | H52: 184.13292 | I52: 348.3 | J52: 392.3 | K52: 179.1 | L52: 11663.22 | M52: 53405.706 | N52: 32942.997 | O52: =+L52/$AX52/100 -> 0.48816366 | P52: =+M52/$AX52/100 -> 2.2352938 | Q52: =+N52/$AX52/100 -> 1.3788279 | R52: 20265.32 | S52: 19502.229 | T52: =+R52/$AX52/100 -> 0.84820422 | U52: =+S52/$AX52/100 -> 0.81626506 | V52: 879071.4 | W52: =+V52/AX52/100 -> 36.793501 | X52: =+'[1]Agregados MesTrim'!B258 -> 1091302.5 | Y52: =+X52/$AX52/100 -> 45.676424 | Z52: 1485143 | AA52: =+Z52/AX52/100 -> 62.160605 | AB52: 0.195 | AC52: 65557 | AD52: 151128 | AE52: 150.55261 | AF52: 151.51044 | AG52: 126.30598 | AH52: 159.58267 | AI52: 408.43791 | AJ52: 165.73212 | AK52: 101.45988 | AL52: 102.05897 | AM52: 156.47326 | AN52: 101.66576 | AO52: 213.37715 | AP52: 201.97088 | AQ52: 181.81642 | AR52: 171.44042 | AS52: 144.35283 | AT52: 40.950099 | AU52: 137.48204 | AV52: =+VLOOKUP(A52,'[2]Salario Real'!$A$5:$C$292,2) -> 114.38181 | AW52: 3360400 | AX52: 238.92029 | AY52: 442 | AZ52: 2.3168326 | BA52: 171.95423 | BB52: 152.62096
A53: 42853 | B53: 0.0099059614 | C53: 37730 | D53: 18571 | E53: 68117 | F53: 18860 | G53: 848868 | H53: 181.61309 | I53: 337.7 | J53: 367.4 | K53: 185 | L53: 13838.443 | M53: 60099.747 | N53: 29603.988 | O53: =+L53/$AX53/100 -> 0.56422273 | P53: =+M53/$AX53/100 -> 2.4503944 | Q53: =+N53/$AX53/100 -> 1.2070175 | R53: 21019.91 | S53: 20832.6 | T53: =+R53/$AX53/100 -> 0.85702639 | U53: =+S53/$AX53/100 -> 0.84938938 | V53: 909427.5 | W53: =+V53/AX53/100 -> 37.079291 | X53: =+'[1]Agregados MesTrim'!B259 -> 1099820.5 | Y53: =+X53/$AX53/100 -> 44.842019 | Z53: 1520578 | AA53: =+Z53/AX53/100 -> 61.997196 | AB53: 0.19246528 | AC53: 58046 | AD53: 124348 | AE53: 151.66067 | AF53: 136.91197 | AG53: 114.88342 | AH53: 153.7588 | AI53: 406.26505 | AJ53: 150.77834 | AK53: 88.11183 | AL53: 100.36751 | AM53: 135.31536 | AN53: 101.49276 | AO53: 199.27243 | AP53: 171.62473 | AQ53: 173.71511 | AR53: 158.12702 | AS53: 139.89489 | AT53: 46.19 | AU53: 138.71492 | AV53: =+VLOOKUP(A53,'[2]Salario Real'!$A$5:$C$292,2) -> 115.16642 | AW53: 3998354 | AX53: 245.26561 | AY53: 405 | AZ53: 2.6113299 | BA53: 173.08307 | BB53: 151.94634
A54: 42886 | B54: 0.0099059614 | C54: 45273 | D54: 19956 | E54: 79521 | F54: 19863 | G54: 972913 | H54: 183.01275 | I54: 324.5 | J54: 394.1 | K54: 196.1 | L54: 12150.068 | M54: 59734.884 | N54: 52277.478 | O54: =+L54/$AX54/100 -> 0.4883771 | P54: =+M54/$AX54/100 -> 2.4010688 | Q54: =+N54/$AX54/100 -> 2.1013152 | R54: 22348.61 | S54: 21545.771 | T54: =+R54/$AX54/100 -> 0.89831178 | U54: =+S54/$AX54/100 -> 0.86604134 | V54: 960233.4 | W54: =+V54/AX54/100 -> 38.596986 | X54: =+'[1]Agregados MesTrim'!B260 -> 1105808 | Y54: =+X54/$AX54/100 -> 44.44842 | Z54: 1520280 | AA54: =+Z54/AX54/100 -> 61.108294 | AB54: 0.19633929 | AC54: 62478 | AD54: 143095 | AE54: 153.71749 | AF54: 148.27124 | AG54: 130.48812 | AH54: 160.61992 | AI54: 448.58363 | AJ54: 164.61981 | AK54: 90.735482 | AL54: 101.9789 | AM54: 136.25889 | AN54: 102.17647 | AO54: 218.88616 | AP54: 187.51789 | AQ54: 183.49765 | AR54: 172.2585 | AS54: 168.07424 | AT54: 45.76 | AU54: 139.63233 | AV54: =+VLOOKUP(A54,'[2]Salario Real'!$A$5:$C$292,2) -> 115.79683 | AW54: 4524320 | AX54: 248.78456 | AY54: 408 | AZ54: 2.516899 | BA54: 172.76268 | BB54: 168.38921
A55: 42916 | B55: 0.0099059614 | C55: 45496 | D55: 19701 | E55: 80172 | F55: 23664 | G55: 1010400 | H55: 191.81795 | I55: 263 | J55: 372.2 | K55: 183.7 | L55: 11211.437 | M55: 62109.042 | N55: 62119.573 | O55: =+L55/$AX55/100 -> 0.44533965 | P55: =+M55/$AX55/100 -> 2.4670895 | Q55: =+N55/$AX55/100 -> 2.4675079 | R55: 21912.63 | S55: 21586.409 | T55: =+R55/$AX55/100 -> 0.87041144 | U55: =+S55/$AX55/100 -> 0.85745332 | V55: 945528.2 | W55: =+V55/AX55/100 -> 37.558183 | X55: =+'[1]Agregados MesTrim'!B261 -> 1149047.5 | Y55: =+X55/$AX55/100 -> 45.642358 | Z55: 1635486 | AA55: =+Z55/AX55/100 -> 64.964622 | AB55: 0.19809524 | AC55: 63512 | AD55: 136787 | AE55: 155.77274 | AF55: 148.66409 | AG55: 131.98868 | AH55: 156.08741 | AI55: 446.94986 | AJ55: 165.53565 | AK55: 89.287782 | AL55: 97.768208 | AM55: 141.5611 | AN55: 104.42986 | AO55: 198.30422 | AP55: 195.15704 | AQ55: 170.66976 | AR55: 174.46486 | AS55: 167.09173 | AT55: 42.042889 | AU55: 139.59353 | AV55: =+VLOOKUP(A55,'[2]Salario Real'!$A$5:$C$292,2) -> 116.45817 | AW55: 3865651 | AX55: 251.75025 | AY55: 432 | AZ55: 2.2778038 | BA55: 173.21806 | BB55: 161.03569
A56: 42947 | B56: 0.013434622 | C56: 38169 | D56: 14522 | E56: 72684 | F56: 18304 | G56: 1020379 | H56: 195.87969 | I56: 189.3 | J56: 398.8 | K56: 195.5 | L56: 13865.348 | M56: 64239.983 | N56: 50704.603 | O56: =+L56/$AX56/100 -> 0.54137992 | P56: =+M56/$AX56/100 -> 2.5082844 | Q56: =+N56/$AX56/100 -> 1.9797883 | R56: 21582.4 | S56: 21741.409 | T56: =+R56/$AX56/100 -> 0.84269633 | U56: =+S56/$AX56/100 -> 0.84890492 | V56: 941809 | W56: =+V56/AX56/100 -> 36.773435 | X56: =+'[1]Agregados MesTrim'!B262 -> 1171250 | Y56: =+X56/$AX56/100 -> 45.732082 | Z56: 1652780 | AA56: =+Z56/AX56/100 -> 64.533677 | AB56: 0.20160714 | AC56: 61603 | AD56: 157087 | AE56: 156.05609 | AF56: 157.64197 | AG56: 139.54053 | AH56: 155.74337 | AI56: 395.66906 | AJ56: 179.03569 | AK56: 82.350764 | AL56: 92.621102 | AM56: 154.34181 | AN56: 103.9695 | AO56: 201.35955 | AP56: 199.80435 | AQ56: 182.07831 | AR56: 189.04324 | AS56: 139.79924 | AT56: 42.476402 | AU56: 140.38571 | AV56: =+VLOOKUP(A56,'[2]Salario Real'!$A$5:$C$292,2) -> 119.92417 | AW56: 4305907 | AX56: 256.11124 | AY56: 440 | AZ56: 2.2354476 | BA56: 175.1279 | BB56: 150.30605
A57: 42978 | B57: 0.013434622 | C57: 45262 | D57: 17583 | E57: 76700 | F57: 21305 | G57: 1126090 | H57: 195.6608 | I57: 189.1 | J57: 417.4 | K57: 198.7 | L57: 13873.958 | M57: 69934.068 | N57: 47401.356 | O57: =+L57/$AX57/100 -> 0.53421963 | P57: =+M57/$AX57/100 -> 2.6928257 | Q57: =+N57/$AX57/100 -> 1.825199 | R57: 23588.98 | S57: 22481.799 | T57: =+R57/$AX57/100 -> 0.90829854 | U57: =+S57/$AX57/100 -> 0.8656663 | V57: 989359.1 | W57: =+V57/AX57/100 -> 38.095476 | X57: =+'[1]Agregados MesTrim'!B263 -> 1198208.3 | Y57: =+X57/$AX57/100 -> 46.137259 | Z57: 1664614 | AA57: =+Z57/AX57/100 -> 64.096306 | AB57: 0.20806818 | AC57: 62232 | AD57: 16444 | AE57: 154.4939 | AF57: 167.58374 | AG57: 139.15813 | AH57: 161.16738 | AI57: 436.68218 | AJ57: 188.21051 | AK57: 94.991647 | AL57: 89.600271 | AM57: 148.4885 | AN57: 106.0973 | AO57: 214.36079 | AP57: 216.75345 | AQ57: 186.28445 | AR57: 184.88008 | AS57: 161.73448 | AT57: 47.609829 | AU57: 141.58713 | AV57: =+VLOOKUP(A57,'[2]Salario Real'!$A$5:$C$292,2) -> 119.9558 | AW57: 3729455 | AX57: 259.70514 | AY57: 404 | AZ57: 2.5317971 | BA57: 174.72838 | BB57: 149.25534
A58: 43007 | B58: 0.013434622 | C58: 46961 | D58: 20561 | E58: 76192 | F58: 24844 | G58: 1138062 | H58: 198.91603 | I58: 275.3 | J58: 422.7 | K58: 201.5 | L58: 11692.627 | M58: 68471.049 | N58: 51850.596 | O58: =+L58/$AX58/100 -> 0.44184067 | P58: =+M58/$AX58/100 -> 2.5873822 | Q58: =+N58/$AX58/100 -> 1.959329 | R58: 26078.29 | S58: 24374.788 | T58: =+R58/$AX58/100 -> 0.98544574 | U58: =+S58/$AX58/100 -> 0.92107384 | V58: 1087342 | W58: =+V58/AX58/100 -> 41.088451 | X58: =+'[1]Agregados MesTrim'!B264 -> 1221580.5 | Y58: =+X58/$AX58/100 -> 46.161053 | Z58: 1690577 | AA58: =+Z58/AX58/100 -> 63.883479 | AB58: 0.21327381 | AC58: 55889 | AD58: 160561 | AE58: 156.58298 | AF58: 160.63467 | AG58: 129.68331 | AH58: 166.2161 | AI58: 428.50326 | AJ58: 178.93077 | AK58: 96.244973 | AL58: 87.773156 | AM58: 151.25539 | AN58: 103.05896 | AO58: 222.00536 | AP58: 215.41753 | AQ58: 188.63508 | AR58: 170.08234 | AS58: 162.79894 | AT58: 51.039745 | AU58: 143.70942 | AV58: =+VLOOKUP(A58,'[2]Salario Real'!$A$5:$C$292,2) -> 119.08696 | AW58: 3244205 | AX58: 264.63446 | AY58: 377 | AZ58: 2.8550328 | BA58: 175.42296 | BB58: 146.38656
A59: 43039 | B59: 0.0098511957 | C59: 43854 | D59: 21176 | E59: 74416 | F59: 20694 | G59: 1160045 | H59: 204.0521 | I59: 347 | J59: 447.1 | K59: 217.4 | L59: 10849.68 | M59: 69461.998 | N59: 48788.467 | O59: =+L59/$AX59/100 -> 0.40386988 | P59: =+M59/$AX59/100 -> 2.5856623 | Q59: =+N59/$AX59/100 -> 1.8161081 | R59: 27935.28 | S59: 27106.665 | T59: =+R59/$AX59/100 -> 1.0398664 | U59: =+S59/$AX59/100 -> 1.009022 | V59: 1194787 | W59: =+V59/AX59/100 -> 44.474904 | X59: =+'[1]Agregados MesTrim'!B265 -> 1230285 | Y59: =+X59/$AX59/100 -> 45.796286 | Z59: 1712671 | AA59: =+Z59/AX59/100 -> 63.752684 | AB59: 0.21645833 | AC59: 59397 | AD59: 158961 | AE59: 151.42582 | AF59: 159.71383 | AG59: 123.4805 | AH59: 162.51726 | AI59: 406.4157 | AJ59: 181.28516 | AK59: 83.797543 | AL59: 84.182403 | AM59: 149.52772 | AN59: 93.497766 | AO59: 222.49978 | AP59: 216.50883 | AQ59: 193.75524 | AR59: 162.61014 | AS59: 153.17535 | AT59: 51.107132 | AU59: 146.77866 | AV59: =+VLOOKUP(A59,'[2]Salario Real'!$A$5:$C$292,2) -> 119.38642 | AW59: 3580292 | AX59: 268.64296 | AY59: 363 | AZ59: 2.8276212 | BA59: 176.60649 | BB59: 149.38595
A60: 43069 | B60: 0.0098511957 | C60: 45228 | D60: 19122 | E60: 78631 | F60: 22654 | G60: 1191537 | H60: 208.60828 | I60: 327.2 | J60: 435 | K60: 218.8 | L60: 11323.548 | M60: 74273.736 | N60: 47423.902 | O60: =+L60/$AX60/100 -> 0.41579173 | P60: =+M60/$AX60/100 -> 2.7272728 | Q60: =+N60/$AX60/100 -> 1.7413681 | R60: 26905.26 | S60: 27294.203 | T60: =+R60/$AX60/100 -> 0.98793984 | U60: =+S60/$AX60/100 -> 1.0022215 | V60: 1145938 | W60: =+V60/AX60/100 -> 42.077936 | X60: =+'[1]Agregados MesTrim'!B266 -> 1266812.4 | Y60: =+X60/$AX60/100 -> 46.51635 | Z60: 1759117 | AA60: =+Z60/AX60/100 -> 64.593383 | AB60: 0.2259375 | AC60: 62011 | AD60: 158159 | AE60: 153.35536 | AF60: 154.23404 | AG60: 117.69476 | AH60: 159.76952 | AI60: 382.53231 | AJ60: 170.7649 | AK60: 96.056763 | AL60: 83.087501 | AM60: 129.94968 | AN60: 97.18615 | AO60: 216.07802 | AP60: 223.56724 | AQ60: 193.0293 | AR60: 147.63079 | AS60: 158.14081 | AT60: 51.101856 | AU60: 147.81615 | AV60: =+VLOOKUP(A60,'[2]Salario Real'!$A$5:$C$292,2) -> 119.42754 | AW60: 3352362 | AX60: 272.33703 | AY60: 363 | AZ60: 2.9666981 | BA60: 177.3914 | BB60: 151.92604
A61: 43098 | B61: 0.0098511957 | C61: 33280 | D61: 18202 | E61: 90307 | F61: 27096 | G61: 1011880 | H61: 209.0617 | I61: 333.3 | J61: 380.8 | K61: 188.9 | L61: 9705.6672 | M61: 71938.271 | N61: 53060.636 | O61: =+L61/$AX61/100 -> 0.34551583 | P61: =+M61/$AX61/100 -> 2.5609586 | Q61: =+N61/$AX61/100 -> 1.8889263 | R61: 30065.61 | S61: 27806.317 | T61: =+R61/$AX61/100 -> 1.0703174 | U61: =+S61/$AX61/100 -> 0.98988793 | V61: 1307017 | W61: =+V61/AX61/100 -> 46.529008 | X61: =+'[1]Agregados MesTrim'!B267 -> 1363490.3 | Y61: =+X61/$AX61/100 -> 48.539424 | Z61: 2010302 | AA61: =+Z61/AX61/100 -> 71.565525 | AB61: 0.23273026 | AC61: 57148 | AD61: 157056 | AE61: 156.27025 | AF61: 151.65293 | AG61: 95.896492 | AH61: 153.10595 | AI61: 332.37513 | AJ61: 165.92074 | AK61: 101.44002 | AL61: 71.912952 | AM61: 136.52983 | AN61: 109.66718 | AO61: 197.64129 | AP61: 198.60516 | AQ61: 180.56039 | AR61: 130.79387 | AS61: 116.56987 | AT61: 43.179905 | AU61: 145.83551 | AV61: =+VLOOKUP(A61,'[2]Salario Real'!$A$5:$C$292,2) -> 116.64219 | AW61: 2178912 | AX61: 280.90369 | AY61: 351 | AZ61: 2.3634554 | BA61: 176.78158 | BB61: 146.78338
A62: 43131 | B62: -0.0065221402 | C62: 21858 | D62: 10409 | E62: 64452 | F62: 10588 | G62: 1052361 | H62: 207.51824 | I62: 328.1 | J62: 343.8 | K62: 144.5 | L62: 11856.252 | M62: 84972.326 | N62: 48922.566 | O62: =+L62/$AX62/100 -> 0.41480071 | P62: =+M62/$AX62/100 -> 2.9728266 | Q62: =+N62/$AX62/100 -> 1.7115961 | R62: 34938.64 | S62: 33159.786 | T62: =+R62/$AX62/100 -> 1.222357 | U62: =+S62/$AX62/100 -> 1.1601223 | V62: 1489055 | W62: =+V62/AX62/100 -> 52.095811 | X62: =+'[1]Agregados MesTrim'!B268 -> 1377172.4 | Y62: =+X62/$AX62/100 -> 48.181505 | Z62: 1898479 | AA62: =+Z62/AX62/100 -> 66.419846 | AB62: 0.22965909 | AC62: 58253 | AD62: 164683 | AE62: 154.79795 | AF62: 148.53659 | AG62: 63.403155 | AH62: 155.76606 | AI62: 202.09585 | AJ62: 163.0468 | AK62: 97.470599 | AL62: 68.578666 | AM62: 153.49574 | AN62: 102.92029 | AO62: 204.92121 | AP62: 197.63071 | AQ62: 170.15516 | AR62: 83.838155 | AS62: 75.588437 | AT62: 45.188713 | AU62: 147.63985 | AV62: =+VLOOKUP(A62,'[2]Salario Real'!$A$5:$C$292,2) -> 116.59202 | AW62: 2733098 | AX62: 285.83008 | AY62: 372 | AZ62: 2.278398 | BA62: 175.32512 | BB62: 142.74091
A63: 43159 | B63: -0.0065221402 | C63: 39085 | D63: 19237 | E63: 73733 | F63: 13644 | G63: 931601 | H63: 201.67148 | I63: 329.7 | J63: 417.3 | K63: 203.3 | L63: 12046.789 | M63: 77705.216 | N63: 45419.005 | O63: =+L63/$AX63/100 -> 0.41151219 | P63: =+M63/$AX63/100 -> 2.6543706 | Q63: =+N63/$AX63/100 -> 1.5514901 | R63: 33010.9 | S63: 32140.945 | T63: =+R63/$AX63/100 -> 1.1276355 | U63: =+S63/$AX63/100 -> 1.0979183 | V63: 1427163 | W63: =+V63/AX63/100 -> 48.751161 | X63: =+'[1]Agregados MesTrim'!B269 -> 1355687.5 | Y63: =+X63/$AX63/100 -> 46.309595 | Z63: 1889764.8 | AA63: =+Z63/AX63/100 -> 64.553403 | AB63: 0.2278125 | AC63: 50502 | AD63: 130593 | AE63: 157.26199 | AF63: 134.04978 | AG63: 98.371278 | AH63: 146.15963 | AI63: 302.79158 | AJ63: 147.25558 | AK63: 87.574409 | AL63: 87.019293 | AM63: 147.54861 | AN63: 94.744081 | AO63: 191.3359 | AP63: 181.39719 | AQ63: 184.80162 | AR63: 115.52191 | AS63: 140.85198 | AT63: 43.82262 | AU63: 150.05738 | AV63: =+VLOOKUP(A63,'[2]Salario Real'!$A$5:$C$292,2) -> 114.73756 | AW63: 2379481 | AX63: 292.74441 | AY63: 405 | AZ63: 2.3201058 | BA63: 175.71899 | BB63: 138.81804
A64: 43189 | B64: -0.0065221402 | C64: 49655 | D64: 27702 | E64: 79562 | F64: 18335 | G64: 1097868 | H64: 204.99493 | I64: 370 | J64: 473.9 | K64: 257.5 | L64: 10187.991 | M64: 79964.981 | N64: 48557.391 | O64: =+L64/$AX64/100 -> 0.34005565 | P64: =+M64/$AX64/100 -> 2.6690782 | Q64: =+N64/$AX64/100 -> 1.6207529 | R64: 31114.93 | S64: 32156.855 | T64: =+R64/$AX64/100 -> 1.0385569 | U64: =+S64/$AX64/100 -> 1.0733344 | V64: 1351347 | W64: =+V64/AX64/100 -> 45.10538 | X64: =+'[1]Agregados MesTrim'!B270 -> 1361304.5 | Y64: =+X64/$AX64/100 -> 45.437743 | Z64: 1949574 | AA64: =+Z64/AX64/100 -> 65.073054 | AB64: 0.228125 | AC64: 59944 | AD64: 150670 | AE64: 159.209 | AF64: 150.30399 | AG64: 134.20373 | AH64: 166.97705 | AI64: 399.6435 | AJ64: 165.93095 | AK64: 95.307817 | AL64: 96.804741 | AM64: 159.90362 | AN64: 100.57741 | AO64: 218.17281 | AP64: 210.43108 | AQ64: 206.63328 | AR64: 160.68434 | AS64: 181.40385 | AT64: 43.812939 | AU64: 148.44194 | AV64: =+VLOOKUP(A64,'[2]Salario Real'!$A$5:$C$292,2) -> 113.71614 | AW64: 3049728 | AX64: 299.59774 | AY64: 420 | AZ64: 2.3215669 | BA64: 178.55 | BB64: 155.85732
... A101: 44316 | B101: 0.0068638512 | C101: 29315 | D101: 15848 | E101: 29876 | F101: 8574 | G101: 955508 | H101: 181.1889 | I101: 314.4 | J101: 346.4 | K101: 176.6 | L101: 106669.82 | M101: 250798.33 | N101: 145979.71 | O101: =+L101/$AX101/100 -> 1.0446661 | P101: =+M101/$AX101/100 -> 2.4561822 | Q101: =+N101/$AX101/100 -> 1.4296457 | R101: 49056.1 | S101: 48383.353 | T101: =+R101/$AX101/100 -> 0.48042872 | U101: =+S101/$AX101/100 -> 0.4738402 | V101: 2073069 | W101: =+V101/AX101/100 -> 20.302508 | X101: =+'[1]Agregados MesTrim'!B307 -> 3957188.2 | Y101: =+X101/$AX101/100 -> 38.754546 | Z101: 6277474 | AA101: =+Z101/AX101/100 -> 61.47816 | AB101: 0.34096875 | AC101: 59088 | AD101: 128480 | AE101: 158.9806 | AF101: 150.68999 | AG101: 165.15805 | AH101: 157.41987 | AI101: 269.53554 | AJ101: 168.5643 | AK101: 87.78467 | AL101: 95.653553 | AM101: 138.57402 | AN101: 91.732684 | AO101: 206.08162 | AP101: 189.30722 | AQ101: 157.44682 | AR101: 216.22333 | AS101: 106.85409 | AT101: 35.335178 | AU101: 129.24669 | AV101: =+VLOOKUP(A101,'[2]Salario Real'!$A$5:$C$292,2) -> 96.598955 | AW101: 4212341 | AX101: 1021.0901 | AY101: 1551 | AZ101: 1.73 | BA101: 161.65 | BB101: 147.3
A102: 44347 | B102: 0.0068638512 | C102: 34953 | D102: 19919 | E102: 28025 | F102: 9606 | G102: 884205 | H102: 176.95133 | I102: 300.6 | J102: 391.1 | K102: 178.8 | L102: 117400.51 | M102: 239693.84 | N102: 214548.17 | O102: =+L102/$AX102/100 -> 1.1127792 | P102: =+M102/$AX102/100 -> 2.271935 | Q102: =+N102/$AX102/100 -> 2.033592 | R102: 59268.94 | S102: 54064.218 | T102: =+R102/$AX102/100 -> 0.56177988 | U102: =+S102/$AX102/100 -> 0.512447 | V102: 2478321 | W102: =+V102/AX102/100 -> 23.490734 | X102: =+'[1]Agregados MesTrim'!B308 -> 4089059.8 | Y102: =+X102/$AX102/100 -> 38.758101 | Z102: 6584839 | AA102: =+Z102/AX102/100 -> 62.414312 | AB102: 0.34115132 | AC102: 62144 | AD102: 97226 | AE102: 156.68066 | AF102: 148.23634 | AG102: 140.00003 | AH102: 162.74341 | AI102: 321.10072 | AJ102: 164.83864 | AK102: 89.807631 | AL102: 96.813962 | AM102: 131.3359 | AN102: 98.148088 | AO102: 216.22067 | AP102: 177.52892 | AQ102: 169.84737 | AR102: 181.88189 | AS102: 127.1745 | AT102: 35.43507 | AU102: 128.5993 | AV102: =+VLOOKUP(A102,'[2]Salario Real'!$A$5:$C$292,2) -> 96.773806 | AW102: 4300687 | AX102: 1055.0207 | AY102: 1508 | AZ102: 1.93 | BB102: 151.2
A103: 44377 | B103: 0.0068638512 | C103: 40035 | D103: 22737 | E103: 28187 | F103: 8572 | G103: 970712 | H103: 186.43834 | I103: 244.2 | J103: 400.3 | K103: 190.6 | L103: 118186.46 | M103: 261725.5 | N103: 221256.6 | O103: =+L103/$AX103/100 -> 1.0857608 | P103: =+M103/$AX103/100 -> 2.4044319 | Q103: =+N103/$AX103/100 -> 2.0326504 | R103: 62371.95 | S103: 65582.588 | T103: =+R103/$AX103/100 -> 0.57300152 | U103: =+S103/$AX103/100 -> 0.60249716 | V103: 2602437 | W103: =+V103/AX103/100 -> 23.908189 | X103: =+'[1]Agregados MesTrim'!B309 -> 4222488.4 | Y103: =+X103/$AX103/100 -> 38.791352 | Z103: 7059705 | AA103: =+Z103/AX103/100 -> 64.856425 | AB103: 0.34119048 | AC103: 59469 | AD103: 142190 | AE103: 157.86407 | AF103: 158.59948 | AG103: 138.58135 | AH103: 161.35586 | AI103: 356.61894 | AJ103: 182.49441 | AK103: 74.50574 | AL103: 92.774056 | AM103: 136.67008 | AN103: 92.771058 | AO103: 205.82276 | AP103: 190.41319 | AQ103: 171.02665 | AR103: 177.07119 | AS103: 145.70461 | AT103: 34.637596 | AU103: 127.53777 | AV103: =+VLOOKUP(A103,'[2]Salario Real'!$A$5:$C$292,2) -> 95.447014 | AW103: 4096192 | AX103: 1088.5128 | AY103: 1573 | AZ103: 1.7 | BB103: 149
A104: 44407 | B104: 0.019707112 | C104: 31935 | D104: 23177 | E104: 24369 | F104: 7720 | G104: 1053191 | H104: 188.28619 | I104: 297 | J104: 430.1 | K104: 198.7 | L104: 107235 | M104: 269528.16 | N104: 181315.34 | O104: =+L104/$AX104/100 -> 0.9564853 | P104: =+M104/$AX104/100 -> 2.4040632 | Q104: =+N104/$AX104/100 -> 1.6172467 | R104: 66005.29 | S104: 64273.625 | T104: =+R104/$AX104/100 -> 0.58873584 | U104: =+S104/$AX104/100 -> 0.57329021 | V104: 2743862 | W104: =+V104/AX104/100 -> 24.473946 | X104: =+'[1]Agregados MesTrim'!B310 -> 4442520.1 | Y104: =+X104/$AX104/100 -> 39.62517 | Z104: 7205281 | AA104: =+Z104/AX104/100 -> 64.267685 | AB104: 0.34130952 | AC104: 63351 | AD104: 149250 | AE104: 155.71141 | AF104: 168.23251 | AG104: 135.56595 | AH104: 156.10512 | AI104: 356.41631 | AJ104: 191.72287 | AK104: 85.562581 | AL104: 88.367694 | AM104: 153.79704 | AN104: 93.871048 | AO104: 194.64292 | AP104: 205.98752 | AQ104: 182.15176 | AR104: 188.67962 | AS104: 116.06972 | AT104: 37.861069 | AU104: 128.2787 | AV104: =+VLOOKUP(A104,'[2]Salario Real'!$A$5:$C$292,2) -> 97.451428 | AW104: 3855443 | AX104: 1121.1359 | AY104: 1591 | AZ104: 1.7 | BB104: 142.4
A105: 44439 | B105: 0.019707112 | C105: 38362 | D105: 24937 | E105: 26069 | F105: 9211 | G105: 1096465 | H105: 186.39881 | I105: 315.2 | J105: 423.4 | K105: 203.4 | L105: 115738.8 | M105: 277858.71 | N105: 231332.52 | O105: =+L105/$AX105/100 -> 1.0074659 | P105: =+M105/$AX105/100 -> 2.4186634 | Q105: =+N105/$AX105/100 -> 2.0136691 | R105: 76451.68 | S105: 69119.15 | T105: =+R105/$AX105/100 -> 0.66548527 | U105: =+S105/$AX105/100 -> 0.60165815 | V105: 3183796 | W105: =+V105/AX105/100 -> 27.713836 | X105: =+'[1]Agregados MesTrim'!B311 -> 4607578.7 | Y105: =+X105/$AX105/100 -> 40.107369 | Z105: 7426772 | AA105: =+Z105/AX105/100 -> 64.647466 | AB105: 0.34157738 | AC105: 64656 | AD105: 153390 | AE105: 154.12204 | AF105: 173.55016 | AG105: 136.53537 | AH105: 161.20257 | AI105: 391.33168 | AJ105: 195.65711 | AK105: 95.748854 | AL105: 86.201553 | AM105: 146.19415 | AN105: 97.903324 | AO105: 207.93693 | AP105: 211.58658 | AQ105: 181.83074 | AR105: 184.24896 | AS105: 139.68871 | AT105: 39.76358 | AU105: 128.74761 | AV105: =+VLOOKUP(A105,'[2]Salario Real'!$A$5:$C$292,2) -> 98.28027 | AW105: 3574880 | AX105: 1148.811 | AY105: 1538 | AZ105: 1.85 | BB105: 141
A106: 44469 | B106: 0.019707112 | C106: 43535 | D106: 25230 | E106: 25700 | F106: 10544 | G106: 1120916 | H106: 185.51536 | I106: 333.5 | J106: 432 | K106: 217.4 | L106: 110534.03 | M106: 303774.65 | N106: 205180.12 | O106: =+L106/$AX106/100 -> 0.9292034 | P106: =+M106/$AX106/100 -> 2.553679 | Q106: =+N106/$AX106/100 -> 1.7248449 | R106: 77363.64 | S106: 76501.897 | T106: =+R106/$AX106/100 -> 0.65035679 | U106: =+S106/$AX106/100 -> 0.64311255 | V106: 3235692 | W106: =+V106/AX106/100 -> 27.200817 | X106: =+'[1]Agregados MesTrim'!B312 -> 4707507.7 | Y106: =+X106/$AX106/100 -> 39.573624 | Z106: 7681869 | AA106: =+Z106/AX106/100 -> 64.577567 | AB106: 0.34159091 | AC106: 61422 | AD106: 161220 | AE106: 155.30311 | AF106: 171.6383 | AG106: 120.4068 | AH106: 163.83081 | AI106: 416.39572 | AJ106: 195.99395 | AK106: 85.923141 | AL106: 85.999418 | AM106: 154.07623 | AN106: 95.402466 | AO106: 202.43062 | AP106: 216.79179 | AQ106: 181.27496 | AR106: 157.58304 | AS106: 158.57854 | AT106: 40.519817 | AU106: 130.67055 | AV106: =+VLOOKUP(A106,'[2]Salario Real'!$A$5:$C$292,2) -> 98.330776 | AW106: 3701792 | AX106: 1189.5569 | AY106: 1619 | AZ106: 1.58 | BB106: 141.3
A107: 44498 | B107: 0.02501015 | C107: 41002 | D107: 25938 | E107: 25291 | F107: 9131 | G107: 1151997 | H107: 188.22028 | I107: 311.2 | J107: 447.7 | K107: 216.2 | L107: 127231.08 | M107: 285669.26 | N107: 221846.29 | O107: =+L107/$AX107/100 -> 1.0332356 | P107: =+M107/$AX107/100 -> 2.3199021 | Q107: =+N107/$AX107/100 -> 1.8015998 | R107: 83560.96 | S107: 82054.697 | T107: =+R107/$AX107/100 -> 0.6785933 | U107: =+S107/$AX107/100 -> 0.66636103 | V107: 3505469 | W107: =+V107/AX107/100 -> 28.467693 | X107: =+'[1]Agregados MesTrim'!B313 -> 4998786.8 | Y107: =+X107/$AX107/100 -> 40.594833 | Z107: 8186815 | AA107: =+Z107/AX107/100 -> 66.484609 | AB107: 0.34141447 | AC107: 62800 | AD107: 140850 | AE107: 153.8392 | AF107: 161.55963 | AG107: 115.31269 | AH107: 160.80908 | AI107: 372.48931 | AJ107: 182.26718 | AK107: 88.683286 | AL107: 81.212174 | AM107: 150.15467 | AN107: 100.53027 | AO107: 203.3485 | AP107: 221.65319 | AQ107: 187.73847 | AR107: 147.05016 | AS107: 149.54533 | AT107: 40.210735 | AU107: 131.2516 | AV107: =+VLOOKUP(A107,'[2]Salario Real'!$A$5:$C$292,2) -> 98.514797 | AW107: 3338045 | AX107: 1231.385 | AY107: 1712 | AZ107: 1.52 | BB107: 139.5
A108: 44530 | B108: 0.02501015 | C108: 46490 | D108: 32513 | E108: 27811 | F108: 9054 | G108: 1150124 | H108: 189.90746 | I108: 326.6 | J108: 450.9 | K108: 213.8 | L108: 114451.37 | M108: 312196.21 | N108: 228249.97 | O108: =+L108/$AX108/100 -> 0.90652225 | P108: =+M108/$AX108/100 -> 2.4727777 | Q108: =+N108/$AX108/100 -> 1.8078741 | R108: 79315.79 | S108: 88706.951 | T108: =+R108/$AX108/100 -> 0.62822774 | U108: =+S108/$AX108/100 -> 0.70261127 | V108: 3315874 | W108: =+V108/AX108/100 -> 26.263674 | X108: =+'[1]Agregados MesTrim'!B314 -> 5264643.6 | Y108: =+X108/$AX108/100 -> 41.699076 | Z108: 8617294 | AA108: =+Z108/AX108/100 -> 68.254041 | AB108: 0.34175595 | AC108: 62394 | AD108: 152870 | AE108: 155.84283 | AF108: 161.7627 | AG108: 111.81447 | AH108: 160.09595 | AI108: 380.04418 | AJ108: 177.43102 | AK108: 106.62097 | AL108: 81.41585 | AM108: 163.11661 | AN108: 97.714356 | AO108: 209.88571 | AP108: 218.54469 | AQ108: 186.38266 | AR108: 133.33624 | AS108: 169.41293 | AT108: 39.69146 | AU108: 132.55445 | AV108: =+VLOOKUP(A108,'[2]Salario Real'!$A$5:$C$292,2) -> 100.37935 | AW108: 2920428 | AX108: 1262.5324 | AY108: 1872 | AZ108: 1.45 | BB108: 143.8
A109: 44561 | B109: 0.02501015 | C109: 39849 | D109: 19615 | E109: 32723 | F109: 11367 | G109: 1034552 | H109: 197.92974 | I109: 306.8 | J109: 428.5 | K109: 196.7 | L109: 126241.92 | M109: 349998.42 | N109: 259595.08 | O109: =+L109/$AX109/100 -> 0.96293392 | P109: =+M109/$AX109/100 -> 2.6696786 | Q109: =+N109/$AX109/100 -> 1.9801102 | R109: 83500.11 | S109: 84643.486 | T109: =+R109/$AX109/100 -> 0.63691276 | U109: =+S109/$AX109/100 -> 0.64563407 | V109: 3486253 | W109: =+V109/AX109/100 -> 26.592049 | X109: =+'[1]Agregados MesTrim'!B315 -> 5642222.9 | Y109: =+X109/$AX109/100 -> 43.037114 | Z109: 9442876 | AA109: =+Z109/AX109/100 -> 72.027309 | AB109: 0.342 | AC109: 63084 | AD109: 150740 | AE109: 158.98914 | AF109: 165.71407 | AG109: 104.10821 | AH109: 148.15776 | AI109: 336.43609 | AJ109: 182.97697 | AK109: 104.96053 | AL109: 73.205674 | AM109: 154.06173 | AN109: 103.0255 | AO109: 156.80918 | AP109: 201.71314 | AQ109: 182.27316 | AR109: 127.26263 | AS109: 145.46372 | AT109: 37.765217 | AU109: 133.45912 | AV109: =+VLOOKUP(A109,'[2]Salario Real'!$A$5:$C$292,2) -> 98.05936 | AW109: 2957255 | AX109: 1311.0133 | AY109: 1688 | AZ109: 1.42 | BB109: 147.2
A110: 44592 | B110: 0.018747031 | C110: 18651 | D110: 9298 | E110: 20147 | F110: 4682 | G110: 886157 | H110: 189.73794 | I110: 324.5 | J110: 353.8 | K110: 157.1 | L110: 108988.47 | M110: 359213.57 | N110: 238619.85 | O110: =+L110/$AX110/100 -> 0.80031246 | P110: =+M110/$AX110/100 -> 2.6377386 | Q110: =+N110/$AX110/100 -> 1.7522077 | R110: 90907.52 | S110: 85002.126 | T110: =+R110/$AX110/100 -> 0.66754235 | U110: =+S110/$AX110/100 -> 0.62417849 | V110: 3782133 | W110: =+V110/AX110/100 -> 27.772553 | X110: =+'[1]Agregados MesTrim'!B316 -> 5891023.9 | Y110: =+X110/$AX110/100 -> 43.258335 | Z110: 9149386 | AA110: =+Z110/AX110/100 -> 67.18479 | AB110: 0.36925595 | AC110: 59651 | AD110: 117858 | AE110: 156.84246 | AF110: 144.40611 | AG110: 67.502379 | AH110: 154.85834 | AI110: 207.17726 | AJ110: 159.74263 | AK110: 90.432063 | AL110: 68.309417 | AM110: 150.6471 | AN110: 100.2915 | AO110: 206.04639 | AP110: 177.0513 | AQ110: 161.58917 | AR110: 94.313239 | AS110: 67.992328 | AT110: 40.139919 | AU110: 132.21726 | AV110: =+VLOOKUP(A110,'[2]Salario Real'!$A$5:$C$292,2) -> 98.771442 | AW110: 2517871 | AX110: 1361.824 | AY110: 1756 | AZ110: 1.54 | BB110: 139.6
A111: 44620 | B111: 0.018747031 | C111: 37661 | D111: 20024 | E111: 25432 | F111: 7237 | G111: 948858 | H111: 199.91848 | I111: 259.6 | J111: 318.9 | K111: 163.7 | L111: 146690.23 | M111: 335525.23 | N111: 243350.53 | O111: =+L111/$AX111/100 -> 1.0289168 | P111: =+M111/$AX111/100 -> 2.3534462 | Q111: =+N111/$AX111/100 -> 1.706913 | R111: 87969.87 | S111: 88995.795 | T111: =+R111/$AX111/100 -> 0.6170396 | U111: =+S111/$AX111/100 -> 0.62423565 | V111: 3689707 | W111: =+V111/AX111/100 -> 25.880399 | X111: =+'[1]Agregados MesTrim'!B317 -> 5716607.3 | Y111: =+X111/$AX111/100 -> 40.097513 | Z111: 9205450 | AA111: =+Z111/AX111/100 -> 64.569007 | AB111: 0.38315789 | AC111: 57255 | AD111: 121553 | AE111: 163.22197 | AF111: 142.66329 | AG111: 104.00905 | AH111: 145.22786 | AI111: 317.2459 | AJ111: 157.25322 | AK111: 91.316755 | AL111: 85.8848 | AM111: 147.35581 | AN111: 81.388836 | AO111: 199.36861 | AP111: 184.43045 | AQ111: 145.74092 | AR111: 127.68458 | AS111: 137.38348 | AT111: 39.426281 | AU111: 136.46845 | AV111: =+VLOOKUP(A111,'[2]Salario Real'!$A$5:$C$292,2) -> 97.998989 | AW111: 2643817 | AX111: 1425.6763 | AY111: 1795 | AZ111: 1.49 | BB111: 137.8
A112: 44651 | B112: 0.018747031 | C112: 48746 | D112: 24623 | E112: 33827 | F112: 10307 | G112: 1058689 | H112: 193.61819 | I112: 311.1 | J112: 416.7 | K112: 196.4 | L112: 184412.12 | M112: 384314.16 | N112: 231162.5 | O112: =+L112/$AX112/100 -> 1.211891 | P112: =+M112/$AX112/100 -> 2.5255762 | Q112: =+N112/$AX112/100 -> 1.5191178 | R112: 90959.59 | S112: 89298.58 | T112: =+R112/$AX112/100 -> 0.59775412 | U112: =+S112/$AX112/100 -> 0.58683855 | V112: 3802758 | W112: =+V112/AX112/100 -> 24.990375 | X112: =+'[1]Agregados MesTrim'!B318 -> 5800396.5 | Y112: =+X112/$AX112/100 -> 38.118146 | Z112: 9251632 | AA112: =+Z112/AX112/100 -> 60.79844 | AB112: 0.40541667 | AC112: 64820 | AD112: 140248 | AE112: 162.13443 | AF112: 158.69411 | AG112: 169.84793 | AH112: 163.65352 | AI112: 422.32306 | AJ112: 178.27883 | AK112: 89.769328 | AL112: 96.713022 | AM112: 157.29721 | AN112: 93.837758 | AO112: 210.9409 | AP112: 205.47531 | AQ112: 182.45553 | AR112: 214.53885 | AS112: 177.86583 | AT112: 36.913712 | AU112: 137.17989 | AV112: =+VLOOKUP(A112,'[2]Salario Real'!$A$5:$C$292,2) -> 96.792033 | AW112: 2934752 | AX112: 1521.689 | AY112: 1785 | AZ112: 1.51 | BB112: 153.9
...

Sheet base_desest
A1: =+base_mensual!A1 -> Date | B1: =+base_mensual!B1 -> DPBI_desest | C1: =+base_mensual!AE1 -> ipi_desest | D1: =+base_mensual!H1 -> ISAC_desest | E1: =+[3]Sheet1!B1 -> prod_autos | F1: =+[3]Sheet1!C1 -> expo_autos | G1: =+[3]Sheet1!D1 -> vtas_concesionarios | H1: =+[3]Sheet1!E1 -> vtas_autos_livianos | I1: =+[3]Sheet1!F1 -> despacho_cem | J1: =+[3]Sheet1!G1 -> hierro_primario | K1: =+[3]Sheet1!H1 -> acero_crudo | L1: =+[3]Sheet1!I1 -> lamin_tot_no_planos | ... AW1: =+[3]Sheet1!AT1 -> molienda_soja | AX1: =+base_mensual!AY1 -> EMBI | AY1: =+base_mensual!AZ1 -> ICG | AZ1: =+base_mensual!BB1 -> EMAE
A2: =+base_mensual!A2 -> 41305 | B2: =+base_mensual!B2 -> -0.0013364764 | C2: =+base_mensual!AE2 -> 160.4271 | D2: =+base_mensual!H2 -> 179.86247 | E2: =+[3]Sheet1!B2 -> 70641.686 | F2: =+[3]Sheet1!C2 -> 39691.165 | G2: =+[3]Sheet1!D2 -> 85505.414 | H2: =+[3]Sheet1!E2 -> 21347.436 | I2: =+[3]Sheet1!F2 -> 977817.58 | J2: =+[3]Sheet1!G2 -> 330.29693 | K2: =+[3]Sheet1!H2 -> 422.31402 | L2: =+[3]Sheet1!I2 -> 213.88724 | ... AW2: =+[3]Sheet1!AT2 -> 2776253.9 | AX2: =+base_mensual!AY2 -> 1101.696 | AY2: =+base_mensual!AZ2 -> 1.7623828 | AZ2: =+[3]Sheet1!AX2 -> 148.44706
A3: =+base_mensual!A3 -> 41333 | B3: =+base_mensual!B3 -> -0.0013364764 | C3: =+base_mensual!AE3 -> 161.81948 | D3: =+base_mensual!H3 -> 184.56116 | E3: =+[3]Sheet1!B3 -> 56164.062 | F3: =+[3]Sheet1!C3 -> 34433.007 | G3: =+[3]Sheet1!D3 -> 83940.337 | H3: =+[3]Sheet1!E3 -> 15895.989 | I3: =+[3]Sheet1!F3 -> 995442.99 | J3: =+[3]Sheet1!G3 -> 340.10839 | K3: =+[3]Sheet1!H3 -> 428.95053 | L3: =+[3]Sheet1!I3 -> 215.51813 | ... AW3: =+[3]Sheet1!AT3 -> 2801203.9 | AX3: =+base_mensual!AY3 -> 1286.804 | AY3: =+base_mensual!AZ3 -> 1.8314094 | AZ3: =+[3]Sheet1!AX3 -> 148.40163
A4: =+base_mensual!A4 -> 41362 | B4: =+base_mensual!B4 -> -0.0013364764 | C4: =+base_mensual!AE4 -> 164.75222 | D4: =+base_mensual!H4 -> 187.0393 | E4: =+[3]Sheet1!B4 -> 71963.64 | F4: =+[3]Sheet1!C4 -> 39578.849 | G4: =+[3]Sheet1!D4 -> 86333.678 | H4: =+[3]Sheet1!E4 -> 21332.685 | I4: =+[3]Sheet1!F4 -> 1000141.8 | J4: =+[3]Sheet1!G4 -> 348.24504 | K4: =+[3]Sheet1!H4 -> 431.38031 | L4: =+[3]Sheet1!I4 -> 212.86616 | ... AW4: =+[3]Sheet1!AT4 -> 2803380.8 | AX4: =+base_mensual!AY4 -> 1307.326 | AY4: =+base_mensual!AZ4 -> 1.913988 | AZ4: =+[3]Sheet1!AX4 -> 149.99915
A5: =+base_mensual!A5 -> 41394 | B5: =+base_mensual!B5 -> 0.0070491739 | C5: =+base_mensual!AE5 -> 167.37289 | D5: =+base_mensual!H5 -> 190.02608 | E5: =+[3]Sheet1!B5 -> 69812.508 | F5: =+[3]Sheet1!C5 -> 38173.386 | G5: =+[3]Sheet1!D5 -> 87195.287 | H5: =+[3]Sheet1!E5 -> 22144.299 | I5: =+[3]Sheet1!F5 -> 1001152.4 | J5: =+[3]Sheet1!G5 -> 350.03215 | K5: =+[3]Sheet1!H5 -> 436.74425 | L5: =+[3]Sheet1!I5 -> 216.87278 | ... AW5: =+[3]Sheet1!AT5 -> 2715192.7 | AX5: =+base_mensual!AY5 -> 1210.234 | AY5: =+base_mensual!AZ5 -> 1.7586069 | AZ5: =+[3]Sheet1!AX5 -> 148.40264
A6: =+base_mensual!A6 -> 41425 | B6: =+base_mensual!B6 -> 0.0070491739 | C6: =+base_mensual!AE6 -> 169.3936 | D6: =+base_mensual!H6 -> 196.56929 | E6: =+[3]Sheet1!B6 -> 85485.563 | F6: =+[3]Sheet1!C6 -> 42163.64 | G6: =+[3]Sheet1!D6 -> 84085.955 | H6: =+[3]Sheet1!E6 -> 21228.463 | I6: =+[3]Sheet1!F6 -> 1003162.6 | J6: =+[3]Sheet1!G6 -> 341.00723 | K6: =+[3]Sheet1!H6 -> 436.12142 | L6: =+[3]Sheet1!I6 -> 217.31041 | ... AW6: =+[3]Sheet1!AT6 -> 2810830.8 | AX6: =+base_mensual!AY6 -> 1167.336 | AY6: =+base_mensual!AZ6 -> 1.4201471 | AZ6: =+[3]Sheet1!AX6 -> 148.27883
A7: =+base_mensual!A7 -> 41453 | B7: =+base_mensual!B7 -> 0.0070491739 | C7: =+base_mensual!AE7 -> 163.37278 | D7: =+base_mensual!H7 -> 189.85581 | E7: =+[3]Sheet1!B7 -> 66326.862 | F7: =+[3]Sheet1!C7 -> 36346.343 | G7: =+[3]Sheet1!D7 -> 80603.859 | H7: =+[3]Sheet1!E7 -> 20109.691 | I7: =+[3]Sheet1!F7 -> 993174.89 | J7: =+[3]Sheet1!G7 -> 345.34083 | K7: =+[3]Sheet1!H7 -> 426.47144 | L7: =+[3]Sheet1!I7 -> 213.42423 | ... AW7: =+[3]Sheet1!AT7 -> 2742201.6 | AX7: =+base_mensual!AY7 -> 1198.724 | AY7: =+base_mensual!AZ7 -> 1.7441265 | AZ7: =+[3]Sheet1!AX7 -> 148.24497
A8: =+base_mensual!A8 -> 41486 | B8: =+base_mensual!B8 -> 0.0064292807 | C8: =+base_mensual!AE8 -> 164.39346 | D8: =+base_mensual!H8 -> 187.8489 | E8: =+[3]Sheet1!B8 -> 66639.026 | F8: =+[3]Sheet1!C8 -> 37831.51 | G8: =+[3]Sheet1!D8 -> 78577.129 | H8: =+[3]Sheet1!E8 -> 19110.929 | I8: =+[3]Sheet1!F8 -> 984851.57 | J8: =+[3]Sheet1!G8 -> 339.59213 | K8: =+[3]Sheet1!H8 -> 432.90855 | L8: =+[3]Sheet1!I8 -> 212.28112 | ... AW8: =+[3]Sheet1!AT8 -> 2831216 | AX8: =+base_mensual!AY8 -> 1111.536 | AY8: =+base_mensual!AZ8 -> 1.6790159 | AZ8: =+[3]Sheet1!AX8 -> 148.60621
A9: =+base_mensual!A9 -> 41516 | B9: =+base_mensual!B9 -> 0.0064292807 | C9: =+base_mensual!AE9 -> 167.7836 | D9: =+base_mensual!H9 -> 191.56118 | E9: =+[3]Sheet1!B9 -> 64189.576 | F9: =+[3]Sheet1!C9 -> 34146.251 | G9: =+[3]Sheet1!D9 -> 76904.34 | H9: =+[3]Sheet1!E9 -> 19200.913 | I9: =+[3]Sheet1!F9 -> 1018452.4 | J9: =+[3]Sheet1!G9 -> 333.63021 | K9: =+[3]Sheet1!H9 -> 427.51491 | L9: =+[3]Sheet1!I9 -> 209.33462 | ... AW9: =+[3]Sheet1!AT9 -> 2947653.4 | AX9: =+base_mensual!AY9 -> 1169.982 | AY9: =+base_mensual!AZ9 -> 1.868806 | AZ9: =+[3]Sheet1!AX9 -> 149.48908
A10: =+base_mensual!A10 -> 41547 | B10: =+base_mensual!B10 -> 0.0064292807 | C10: =+base_mensual!AE10 -> 168.01688 | D10: =+base_mensual!H10 -> 187.60771 | E10: =+[3]Sheet1!B10 -> 62665.73 | F10: =+[3]Sheet1!C10 -> 33433.192 | G10: =+[3]Sheet1!D10 -> 74180.648 | H10: =+[3]Sheet1!E10 -> 18635.99 | I10: =+[3]Sheet1!F10 -> 966955.44 | J10: =+[3]Sheet1!G10 -> 346.24288 | K10: =+[3]Sheet1!H10 -> 431.15273 | L10: =+[3]Sheet1!I10 -> 206.18594 | ... AW10: =+[3]Sheet1!AT10 -> 3032593.9 | AX10: =+base_mensual!AY10 -> 1034.507 | AY10: =+base_mensual!AZ10 -> 1.7716093 | AZ10: =+[3]Sheet1!AX10 -> 148.3382
A11: =+base_mensual!A11 -> 41578 | B11: =+base_mensual!B11 -> -0.0085728871 | C11: =+base_mensual!AE11 -> 167.64166 | D11: =+base_mensual!H11 -> 185.59018 | E11: =+[3]Sheet1!B11 -> 62295.784 | F11: =+[3]Sheet1!C11 -> 33045.254 | G11: =+[3]Sheet1!D11 -> 75460.574 | H11: =+[3]Sheet1!E11 -> 18331.672 | I11: =+[3]Sheet1!F11 -> 980622.01 | J11: =+[3]Sheet1!G11 -> 340.00949 | K11: =+[3]Sheet1!H11 -> 428.68559 | L11: =+[3]Sheet1!I11 -> 205.33936 | ... AW11: =+[3]Sheet1!AT11 -> 2975171 | AX11: =+base_mensual!AY11 -> 920.685 | AY11: =+base_mensual!AZ11 -> 1.9764988 | AZ11: =+[3]Sheet1!AX11 -> 148.60092
A12: =+base_mensual!A12 -> 41607 | B12: =+base_mensual!B12 -> -0.0085728871 | C12: =+base_mensual!AE12 -> 162.93222 | D12: =+base_mensual!H12 -> 186.85841 | E12: =+[3]Sheet1!B12 -> 59031.894 | F12: =+[3]Sheet1!C12 -> 32846.449 | G12: =+[3]Sheet1!D12 -> 70252.111 | H12: =+[3]Sheet1!E12 -> 17566.387 | I12: =+[3]Sheet1!F12 -> 1001153.9 | J12: =+[3]Sheet1!G12 -> 342.27305 | K12: =+[3]Sheet1!H12 -> 438.2954 | L12: =+[3]Sheet1!I12 -> 206.9025 | ... AW12: =+[3]Sheet1!AT12 -> 2825213.6 | AX12: =+base_mensual!AY12 -> 775.912 | AY12: =+base_mensual!AZ12 -> 1.8471888 | AZ12: =+[3]Sheet1!AX12 -> 148.47674
A13: =+base_mensual!A13 -> 41639 | B13: =+base_mensual!B13 -> -0.0085728871 | C13: =+base_mensual!AE13 -> 162.96708 | D13: =+base_mensual!H13 -> 195.44041 | E13: =+[3]Sheet1!B13 -> 56712.823 | F13: =+[3]Sheet1!C13 -> 32401.005 | G13: =+[3]Sheet1!D13 -> 88124.261 | H13: =+[3]Sheet1!E13 -> 25857.31 | I13: =+[3]Sheet1!F13 -> 980342.83 | J13: =+[3]Sheet1!G13 -> 345.03701 | K13: =+[3]Sheet1!H13 -> 433.13567 | L13: =+[3]Sheet1!I13 -> 201.83781 | ... AW13: =+[3]Sheet1!AT13 -> 2859496.4 | AX13: =+base_mensual!AY13 -> 807.94 | AY13: =+base_mensual!AZ13 -> 1.6809168 | AZ13: =+[3]Sheet1!AX13 -> 147.70031
... A151: =+base_mensual!A151 -> 45838 | B151: =+base_mensual!B151 -> -0.00061022349 | C151: =+base_mensual!AE151 -> 145.87769 | D151: =+base_mensual!H151 -> 147.32896 | E151: =+[3]Sheet1!B151 -> 42824.268 | F151: =+[3]Sheet1!C151 -> 25068.842 | G151: =+[3]Sheet1!D151 -> 50975.129 | H151: =+[3]Sheet1!E151 -> 15428.284 | I151: =+[3]Sheet1!F151 -> 812723.03 | J151: =+[3]Sheet1!G151 -> 179.90835 | K151: =+[3]Sheet1!H151 -> 330.97201 | L151: =+[3]Sheet1!I151 -> 132.05656 | ... AW151: =+[3]Sheet1!AT151 -> 3663439.8 | AX151: =+base_mensual!AY151 -> 677 | AY151: =+base_mensual!AZ151 -> 2.34 | AZ151: =+[3]Sheet1!AX151 -> 154.57717
A152: =+base_mensual!A152 -> 45869 | C152: =+base_mensual!AE152 -> 143.87986 | D152: =+base_mensual!H152 -> 144.59337 | E152: =+[3]Sheet1!B152 -> 40286.059 | F152: =+[3]Sheet1!C152 -> 19341.74 | G152: =+[3]Sheet1!D152 -> 54539.803 | H152: =+[3]Sheet1!E152 -> 16447.017 | I152: =+[3]Sheet1!F152 -> 824715.41 | J152: =+[3]Sheet1!G152 -> 202.98358 | K152: =+[3]Sheet1!H152 -> 345.07804 | L152: =+[3]Sheet1!I152 -> 136.60922 | ... AW152: =+[3]Sheet1!AT152 -> 3777410.3 | AX152: =+base_mensual!AY152 -> 734 | AY152: =+base_mensual!AZ152 -> 2.45 | AZ152: =+[3]Sheet1!AX152 -> 152.81092
A153: =+base_mensual!A153 -> 45900 | C153: =+base_mensual!AE153 -> 145.81729 | D153: =+base_mensual!H153 -> 145.3 | E153: =+[3]Sheet1!B153 -> 40559.81 | F153: =+[3]Sheet1!C153 -> 20616.58 | G153: =+[3]Sheet1!D153 -> 54584.332 | H153: =+[3]Sheet1!E153 -> 15695.637 | I153: =+[3]Sheet1!F153 -> 835241.3 | J153: =+[3]Sheet1!G153 -> 190.59233 | K153: =+[3]Sheet1!H153 -> 344.29865 | L153: =+[3]Sheet1!I153 -> 120.31383 | ... AW153: =+[3]Sheet1!AT153 -> 3894329 | AX153: =+base_mensual!AY153 -> 829 | AY153: =+base_mensual!AZ153 -> 2.12 | AZ153: =+[3]Sheet1!AX153 -> 152.47735

Sheet Sheet1

Sheet Sheet2

Sheet NOTAS
C1: 🟦 PC1 – “Ciclo real e inversión productiva agregada”
C2: Variable | D2: Loading
C3: bcd (bienes de capital durables) | D3: 0.396
C4: bui (uso de capacidad instalada) | D4: 0.389
C5: ipi_desest (producción industrial) | D5: 0.384
C6: metalmec | D6: 0.355
C7: bk (bienes de capital) | D7: 0.326
C8: ligadas a actividad industrial, inversión y utilización de capacidad.
C10: 🟨 PC2 – “Confianza del consumidor y divergencia industria–servicios”
C11: Variable | D11: Loading
C12: ICC (confianza del consumidor) | D12: 0.716
C13: reca_iva_real | D13: -0.359
C14: metalmec | D14: 0.341
C15: acero_crudo | D15: -0.29
C16: bk | D16: -0.257 | G16: =12*3 -> 36
C17: Alta correlación positiva con ICC, negativa con bienes de capital y recaudación real. | G17: =+G16/12 -> 3
C19: 🟩 PC3 – “Construcción doméstica vs sector exportador”
C20: Variable | D20: Loading
C21: ISAC_desest (construcción) | D21: 0.68
C22: expo_autos (exportaciones de autos) | D22: -0.598
C23: acero_crudo | D23: 0.18
C24: Dualidad entre el sector de construcción (doméstico) y el sector exportador (autos).
C26: Factor | D26: Tipo | E26: Variables dominantes | F26: Interpretación
C27: F1 (PC1) | D27: Real / inversión | E27: bcd, bk, bui, ipi, metalmec | F27: Ciclo real agregado e inversión productiva
C28: F2 (PC2) | D28: Expectativas / consumo | E28: ICC, reca_iva_real, bk | F28: Sentimiento y consumo interno
C29: F3 (PC3) | D29: Sectorial / externo | E29: ISAC, expo_autos | F29: Contraste entre sectores internos y externos

Sheet FUENTES
A1: fuentes
A3: Ganancias | B3: https://www.argentina.gob.ar/economia/ingresospublicos/pormes
A5: Despecho Cemento | B5: https://www.afcp.org.ar/copia-de-despacho-de-cemento-y-cons
A6: autos | B6: https://adefa.org.ar/es/estadisticas-mensuales
A7: faena aves | B7: https://www.magyp.gob.ar/sitio/areas/aves/estadistica/carne/index.php
A8: vta usados | B8: https://cca.org.ar/estadisticas-2024/
A9: ICC | B9: https://www.utdt.edu/ver_contenido.php?id_contenido=8513&id_item_menu=16458
A10: IL | B10: https://www.utdt.edu/ver_contenido.php?id_contenido=13306&id_item_menu=16461
A11: ISAC SD
A12: Hierro primario | B12: https://www.acero.org.ar/wp-content/uploads/2025/09/Produccion-Siderurgica-Argentina-1960-2025-.pdf
A13: Acero Crudo | B13: https://www.acero.org.ar/wp-content/uploads/2025/09/Produccion-Siderurgica-Argentina-1960-2025-.pdf
A14: Der COMEX | B14: https://www.arca.gob.ar/institucional/documentos/ARCA-Recaudacion-082025.pdf
