Workbook

Sheet close
A1: Dates | B1: BBAS3 BZ EQUITY | C1: BBDC3 BZ EQUITY | D1: BEEF3 BZ EQUITY | E1: BRAP4 BZ EQUITY | F1: BRKM5 BZ EQUITY | G1: CMIG4 BZ EQUITY | H1: COGN3 BZ EQUITY | I1: CSAN3 BZ EQUITY | J1: CSNA3 BZ EQUITY | K1: CURY3 BZ EQUITY | L1: CYRE3 BZ EQUITY | M1: DIRR3 BZ EQUITY | N1: EMBJ3 BZ EQUITY | O1: EQTL3 BZ EQUITY | P1: FLRY3 BZ EQUITY | Q1: GOAU4 BZ EQUITY | R1: HAPV3 BZ EQUITY | S1: HYPE3 BZ EQUITY | T1: ITUB4 BZ EQUITY | U1: MBRF3 BZ EQUITY | V1: MOTV3 BZ EQUITY | W1: PETR3 BZ EQUITY | X1: PETR4 BZ EQUITY | Y1: POMO4 BZ EQUITY | Z1: PSSA3 BZ EQUITY | AA1: RADL3 BZ EQUITY | AB1: SANB11 BZ EQUITY | AC1: SBSP3 BZ EQUITY | AD1: SLCE3 BZ EQUITY | AE1: TAEE11 BZ EQUITY | AF1: TOTS3 BZ EQUITY | AG1: USIM5 BZ EQUITY | AH1: VALE3 BZ EQUITY | AI1: VIVT3 BZ EQUITY | AJ1: VBBR3 BZ EQUITY | AK1: IBOV Index
A2: Date | B2: =+TRIM(LEFT(B1,5)) -> BBAS3 | C2: =+TRIM(LEFT(C1,5)) -> BBDC3 | D2: =+TRIM(LEFT(D1,5)) -> BEEF3 | E2: =+TRIM(LEFT(E1,5)) -> BRAP4 | F2: =+TRIM(LEFT(F1,5)) -> BRKM5 | G2: =+TRIM(LEFT(G1,5)) -> CMIG4 | H2: =+TRIM(LEFT(H1,5)) -> COGN3 | I2: =+TRIM(LEFT(I1,5)) -> CSAN3 | ... AA2: =+TRIM(LEFT(AA1,5)) -> RADL3 | AB2: =+TRIM(LEFT(AB1,6)) -> SANB11 | AC2: =+TRIM(LEFT(AC1,5)) -> SBSP3 | AD2: =+TRIM(LEFT(AD1,5)) -> SLCE3 | AE2: =+TRIM(LEFT(AE1,6)) -> TAEE11 | AF2: =+TRIM(LEFT(AF1,5)) -> TOTS3 | AG2: =+TRIM(LEFT(AG1,5)) -> USIM5 | AH2: =+TRIM(LEFT(AH1,5)) -> VALE3 | AI2: =+TRIM(LEFT(AI1,5)) -> VIVT3 | AJ2: =+TRIM(LEFT(AJ1,5)) -> VBBR3 | AK2: =+TRIM(LEFT(AK1,5)) -> IBOV
A3: =_xll.BDH(B$1,"TOT_RETURN_INDEX_GROSS_DVDS","2017-12-28","","Dir=V","Per=D","Days=T","Dts=S","cols=2;rows=2098") -> 43097 | B3: 15.91 | C3: =_xll.BDH(C$1,"TOT_RETURN_INDEX_GROSS_DVDS","2017-12-28","","Dir=V","Per=D","Days=T","Dts=H","cols=1;rows=2098") -> 18.248 | D3: =_xll.BDH(D$1,"TOT_RETURN_INDEX_GROSS_DVDS","2017-12-28","","Dir=V","Per=D","Days=T","Dts=H","cols=1;rows=2098") -> 9.381 | E3: =_xll.BDH(E$1,"TOT_RETURN_INDEX_GROSS_DVDS","2017-12-28","","Dir=V","Per=D","Days=T","Dts=H","cols=1;rows=2098") -> 11.759 | F3: =_xll.BDH(F$1,"TOT_RETURN_INDEX_GROSS_DVDS","2017-12-28","","Dir=V","Per=D","Days=T","Dts=H","cols=1;rows=2098") -> 42.87 | G3: =_xll.BDH(G$1,"TOT_RETURN_INDEX_GROSS_DVDS","2017-12-28","","Dir=V","Per=D","Days=T","Dts=H","cols=1;rows=2098") -> 3.502 | H3: =_xll.BDH(H$1,"TOT_RETURN_INDEX_GROSS_DVDS","2017-12-28","","Dir=V","Per=D","Days=T","Dts=H","cols=1;rows=2098") -> 16.727 | I3: =_xll.BDH(I$1,"TOT_RETURN_INDEX_GROSS_DVDS","2017-12-28","","Dir=V","Per=D","Days=T","Dts=H","cols=1;rows=2098") -> 10.375 | J3: =_xll.BDH(J$1,"TOT_RETURN_INDEX_GROSS_DVDS","2017-12-28","","Dir=V","Per=D","Days=T","Dts=H","cols=1;rows=2098") -> 8.38 | L3: =_xll.BDH(L$1,"TOT_RETURN_INDEX_GROSS_DVDS","2017-12-28","","Dir=V","Per=D","Days=T","Dts=H","cols=1;rows=2098") -> 11.058 | M3: =_xll.BDH(M$1,"TOT_RETURN_INDEX_GROSS_DVDS","2017-12-28","","Dir=V","Per=D","Days=T","Dts=H","cols=1;rows=2098") -> 1.883 | N3: =_xll.BDH(N$1,"TOT_RETURN_INDEX_GROSS_DVDS","2017-12-28","","Dir=V","Per=D","Days=T","Dts=H","cols=1;rows=2098") -> 20 | O3: =_xll.BDH(O$1,"TOT_RETURN_INDEX_GROSS_DVDS","2017-12-28","","Dir=V","Per=D","Days=T","Dts=H","cols=1;rows=2098") -> 13.025 | P3: =_xll.BDH(P$1,"TOT_RETURN_INDEX_GROSS_DVDS","2017-12-28","","Dir=V","Per=D","Days=T","Dts=H","cols=1;rows=2098") -> 27.922 | Q3: =_xll.BDH(Q$1,"TOT_RETURN_INDEX_GROSS_DVDS","2017-12-28","","Dir=V","Per=D","Days=T","Dts=H","cols=1;rows=2098") -> 4.343 | S3: =_xll.BDH(S$1,"TOT_RETURN_INDEX_GROSS_DVDS","2017-12-28","","Dir=V","Per=D","Days=T","Dts=H","cols=1;rows=2098") -> 35.633 | T3: =_xll.BDH(T$1,"TOT_RETURN_INDEX_GROSS_DVDS","2017-12-28","","Dir=V","Per=D","Days=T","Dts=H","cols=1;rows=2098") -> 20.66 | U3: =_xll.BDH(U$1,"TOT_RETURN_INDEX_GROSS_DVDS","2017-12-28","","Dir=V","Per=D","Days=T","Dts=H","cols=1;rows=2098") -> 7.278 | V3: =_xll.BDH(V$1,"TOT_RETURN_INDEX_GROSS_DVDS","2017-12-28","","Dir=V","Per=D","Days=T","Dts=H","cols=1;rows=2098") -> 16.15 | W3: =_xll.BDH(W$1,"TOT_RETURN_INDEX_GROSS_DVDS","2017-12-28","","Dir=V","Per=D","Days=T","Dts=H","cols=1;rows=2098") -> 16.91 | X3: =_xll.BDH(X$1,"TOT_RETURN_INDEX_GROSS_DVDS","2017-12-28","","Dir=V","Per=D","Days=T","Dts=H","cols=1;rows=2098") -> 16.1 | Y3: =_xll.BDH(Y$1,"TOT_RETURN_INDEX_GROSS_DVDS","2017-12-28","","Dir=V","Per=D","Days=T","Dts=H","cols=1;rows=2098") -> 3.007 | Z3: =_xll.BDH(Z$1,"TOT_RETURN_INDEX_GROSS_DVDS","2017-12-28","","Dir=V","Per=D","Days=T","Dts=H","cols=1;rows=2098") -> 18.165 | ... AK3: =_xll.BDH(AK$1,"TOT_RETURN_INDEX_GROSS_DVDS","2017-12-28","","Dir=V","Per=D","Days=T","Dts=H","cols=1;rows=2098") -> 76402.08
A4: 43102 | B4: 16.465 | C4: 18.373 | D4: 9.592 | E4: 12.127 | F4: 43.86 | G4: 3.548 | H4: 16.673 | I4: 10.638 | J4: 8.68 | L4: 11.142 | M4: 1.947 | N4: 20.52 | O4: 13.039 | P4: 28.007 | Q4: 4.538 | S4: 36.495 | T4: 21.298 | U4: 7.259 | V4: 16.56 | W4: 17.33 | X4: 16.55 | Y4: 2.97 | Z4: 18.2 | AA4: 17.053 | AB4: 31.702 | AC4: 6.71 | AD4: 5.078 | AE4: 21.46 | AF4: 10.05 | AG4: 9.6 | AH4: 41.72 | AI4: 20.7 | AJ4: 16.086 | AK4: 77891.04
A5: 43103 | B5: 16.675 | C5: 18.451 | D5: 9.522 | E5: 12.242 | F5: 43.49 | G5: 3.517 | H5: 16.818 | I5: 10.638 | J5: 9 | L5: 11.192 | M5: 1.89 | N5: 21.3 | O5: 13.065 | P5: 27.461 | Q5: 4.523 | S5: 35.926 | T5: 21.443 | U5: 7.179 | V5: 16.44 | W5: 17.55 | X5: 16.7 | Y5: 3.053 | Z5: 18.53 | AA5: 16.631 | AB5: 31.44 | AC5: 6.59 | AD5: 5.122 | AE5: 21.49 | AF5: 10.263 | AG5: 9.92 | AH5: 41.47 | AI5: 20.1 | AJ5: 16.152 | AK5: 77995.16
A6: 43104 | B6: 16.835 | C6: 18.787 | D6: 9.487 | E6: 12.59 | F6: 44.15 | G6: 3.476 | H6: 17.045 | I6: 10.613 | J6: 9.28 | L6: 11.284 | M6: 1.91 | N6: 21.8 | O6: 12.918 | P6: 26.912 | Q6: 4.688 | S6: 36.19 | T6: 21.89 | U6: 7.179 | V6: 16.5 | W6: 17.7 | X6: 16.73 | Y6: 3.143 | Z6: 18.545 | AA6: 16.759 | AB6: 31.818 | AC6: 6.462 | AD6: 5.102 | AE6: 21.15 | AF6: 10.2 | AG6: 10.48 | AH6: 41.64 | AI6: 20.32 | AJ6: 16.058 | AK6: 78647.42
A7: 43105 | B7: 16.835 | C7: 18.793 | D7: 9.592 | E7: 12.893 | F7: 45.22 | G7: 3.481 | H7: 17.009 | I7: 10.723 | J7: 9.49 | L7: 11.459 | M7: 1.913 | N7: 20.65 | O7: 13.045 | P7: 27.3 | Q7: 4.703 | S7: 36.525 | T7: 21.953 | U7: 7.239 | V7: 16.57 | W7: 17.84 | X7: 16.83 | Y7: 3.105 | Z7: 18.905 | AA7: 17.053 | AB7: 32.157 | AC7: 6.535 | AD7: 5.197 | AE7: 21.25 | AF7: 10.42 | AG7: 10.03 | AH7: 42.29 | AI7: 20.37 | AJ7: 16.338 | AK7: 79071.47
A8: 43108 | B8: 16.875 | C8: 18.793 | D8: 9.266 | E8: 13.118 | F8: 45.3 | G8: 3.492 | H8: 16.255 | I8: 10.63 | J8: 9.95 | L8: 11.518 | M8: 1.903 | N8: 20.7 | O8: 13.216 | P8: 26.59 | Q8: 4.763 | S8: 36.149 | T8: 21.88 | U8: 7.109 | V8: 16.34 | W8: 18.12 | X8: 17.03 | Y8: 3.045 | Z8: 18.81 | AA8: 16.836 | AB8: 32.702 | AC8: 6.669 | AD8: 5.17 | AE8: 21.15 | AF8: 10.413 | AG8: 10.14 | AH8: 43.23 | AI8: 20.585 | AJ8: 16.245 | AK8: 79378.53
A9: 43109 | B9: 16.715 | C9: 18.65 | D9: 9.249 | E9: 12.97 | F9: 45.4 | G9: 3.42 | H9: 16.455 | I9: 10.338 | J9: 10.22 | L9: 11.468 | M9: 1.917 | N9: 20.23 | O9: 13.216 | P9: 25.822 | Q9: 4.755 | S9: 36.342 | T9: 21.642 | U9: 7.02 | V9: 16.35 | W9: 18.12 | X9: 17.03 | Y9: 3.03 | Z9: 18.94 | AA9: 16.601 | AB9: 32.471 | AC9: 6.578 | AD9: 5.172 | AE9: 20.76 | AF9: 10.417 | AG9: 10.25 | AH9: 43.07 | AI9: 20.53 | AJ9: 16.245 | AK9: 78863.54
A10: 43110 | B10: 16.645 | C10: 18.531 | D10: 9.249 | E10: 12.835 | F10: 44.91 | G10: 3.471 | H10: 16.773 | I10: 10.138 | J10: 10.25 | L10: 11.225 | M10: 1.927 | N10: 20.29 | O10: 13.115 | P10: 26.665 | Q10: 4.77 | S10: 36.2 | T10: 21.569 | U10: 7.01 | V10: 15.95 | W10: 17.78 | X10: 16.8 | Y10: 3.037 | Z10: 19.35 | AA10: 16.094 | AB10: 32.41 | AC10: 6.446 | AD10: 5.298 | AE10: 20.48 | AF10: 10.39 | AG10: 10.25 | AH10: 42.47 | AI10: 20.27 | AJ10: 16.105 | AK10: 78200.57
A11: 43111 | B11: 17.025 | C11: 18.793 | D11: 9.249 | E11: 13.224 | F11: 46.21 | G11: 3.543 | H11: 16.164 | I11: 10.24 | J11: 10.85 | L11: 11.669 | M11: 1.93 | N11: 20.5 | O11: 13.192 | P11: 26.125 | Q11: 5.01 | S11: 36.353 | T11: 22.021 | U11: 7.02 | V11: 15.95 | W11: 18.22 | X11: 17.25 | Y11: 3.068 | Z11: 19.745 | AA11: 16.318 | AB11: 32.894 | AC11: 6.532 | AD11: 5.306 | AE11: 20.33 | AF11: 10.377 | AG11: 10.8 | AH11: 43.3 | AI11: 21.085 | AJ11: 16.012 | AK11: 79365.44
A12: 43112 | B12: 17.065 | C12: 18.793 | D12: 9.073 | E12: 13.314 | F12: 46.63 | G12: 3.507 | H12: 15.464 | I12: 10.425 | J12: 10.51 | L12: 11.752 | M12: 1.87 | N12: 20.25 | O12: 13.298 | P12: 25.964 | Q12: 5.138 | S12: 37.053 | T12: 22.001 | U12: 6.841 | V12: 16.06 | W12: 18.36 | X12: 17.3 | Y12: 3.022 | Z12: 20.335 | AA12: 16.308 | AB12: 32.733 | AC12: 6.57 | AD12: 5.289 | AE12: 20.33 | AF12: 10.36 | AG12: 11.02 | AH12: 43.55 | AI12: 20.895 | AJ12: 15.937 | AK12: 79349.12
A13: 43115 | B13: 17.15 | C13: 18.838 | D13: 9.073 | E13: 13.306 | F13: 47.72 | G13: 3.492 | H13: 15.4 | I13: 10.42 | J13: 10.78 | L13: 12.037 | M13: 1.92 | N13: 20.1 | O13: 13.514 | P13: 26.391 | Q13: 5.115 | S13: 36.88 | T13: 22.137 | U13: 6.801 | V13: 16.08 | W13: 18.46 | X13: 17.35 | Y13: 3.06 | Z13: 20.83 | AA13: 16.335 | AB13: 32.672 | AC13: 6.574 | AD13: 5.344 | AE13: 20.55 | AF13: 10.347 | AG13: 11.3 | AH13: 43.47 | AI13: 20.75 | AJ13: 16.404 | AK13: 79752.38
A14: 43116 | B14: 17.3 | C14: 19.152 | D14: 9.055 | E14: 12.979 | F14: 49.27 | G14: 3.502 | H14: 15.236 | I14: 10.19 | J14: 10.48 | L14: 11.945 | M14: 2.093 | N14: 19.93 | O14: 13.363 | P14: 26.239 | Q14: 5.003 | S14: 36.911 | T14: 22.341 | U14: 6.672 | V14: 15.97 | W14: 18.79 | X14: 17.65 | Y14: 3.037 | Z14: 21.44 | AA14: 16.069 | AB14: 32.612 | AC14: 6.607 | AD14: 5.363 | AE14: 20.43 | AF14: 10.507 | AG14: 10.96 | AH14: 42.3 | AI14: 21.075 | AJ14: 16.413 | AK14: 79831.77
A15: 43117 | B15: 17.71 | C15: 19.738 | D15: 8.888 | E15: 13.237 | F15: 48.86 | G15: 3.446 | H15: 15.673 | I15: 10.5 | J15: 10.9 | L15: 12.045 | M15: 2.077 | N15: 19.9 | O15: 13.51 | P15: 26.391 | Q15: 5.19 | S15: 36.921 | T15: 22.71 | U15: 6.811 | V15: 16.04 | W15: 19.47 | X15: 18.36 | Y15: 3.053 | Z15: 20.725 | AA15: 16.316 | AB15: 32.964 | AC15: 6.96 | AD15: 5.361 | AE15: 20.5 | AF15: 10.46 | AG15: 11.15 | AH15: 43.15 | AI15: 21.21 | AJ15: 16.572 | AK15: 81189.16
... A79: 43213 | B79: 18.613 | C79: 20.156 | D79: 7.126 | E79: 14.678 | F79: 47.34 | G79: 4.282 | H79: 13.004 | I79: 9.45 | J79: 9.13 | L79: 11.208 | M79: 2.053 | N79: 23.723 | O79: 13.713 | P79: 25.861 | Q79: 5.993 | S79: 32.389 | T79: 25.858 | U79: 8.134 | V79: 12.318 | W79: 24.35 | X79: 22.48 | Y79: 3.03 | Z79: 22.671 | AA79: 12.753 | AB79: 39.642 | AC79: 6.739 | AD79: 7.684 | AE79: 20.97 | AF79: 10.662 | AG79: 10.99 | AH79: 48.042 | AI79: 22.597 | AJ79: 21.832 | AK79: 85602.5
A80: 43214 | B80: 18.432 | C80: 20.012 | D80: 7.311 | E80: 15.005 | F80: 47 | G80: 4.19 | H80: 13.269 | I80: 9.888 | J80: 9.13 | L80: 11.342 | M80: 2.027 | N80: 23.555 | O80: 13.594 | P80: 25.619 | Q80: 5.97 | R80: =_xll.BDH(R$1,"TOT_RETURN_INDEX_GROSS_DVDS","2017-12-28","","Dir=V","Per=D","Days=T","Dts=H","cols=1;rows=2021") -> 70.5 | S80: 32.675 | T80: 25.731 | U80: 8.034 | V80: 12.114 | W80: 24.27 | X80: 22.4 | Y80: 2.992 | Z80: 22.145 | AA80: 12.866 | AB80: 39.702 | AC80: 6.735 | AD80: 7.524 | AE80: 20.99 | AF80: 10.662 | AG80: 10.75 | AH80: 48.861 | AI80: 22.525 | AJ80: 21.4 | AK80: 85469.08
A81: 43215 | B81: 18.673 | C81: 20.319 | D81: 7.284 | E81: 14.723 | F81: 45.23 | G81: 4.165 | H81: 12.821 | I81: 9.838 | J81: 9.14 | L81: 11.275 | M81: 2 | N81: 23.193 | O81: 13.697 | P81: 25.813 | Q81: 5.925 | R81: 86.55 | S81: 33.482 | T81: 25.579 | U81: 7.825 | V81: 11.83 | W81: 23.5 | X81: 21.73 | Y81: 2.992 | Z81: 22.481 | AA81: 12.927 | AB81: 38.489 | AC81: 6.817 | AD81: 7.642 | AE81: 21.16 | AF81: 10.582 | AG81: 10.89 | AH81: 48.497 | AI81: 21.81 | AJ81: 21.006 | AK81: 85044.39
A82: 43216 | B82: 18.82 | C82: 20.357 | D82: 7.179 | E82: 15.038 | F82: 45.45 | G82: 4.246 | H82: 12.537 | I82: 10.08 | J82: 9.22 | L82: 11.292 | M82: 2.01 | N82: 23.274 | O82: 13.987 | P82: 26.336 | Q82: 6.045 | R82: 83.52 | S82: 32.144 | T82: 26.173 | U82: 7.955 | V82: 12.023 | W82: 24.45 | X82: 22.63 | Y82: 3.045 | Z82: 22.446 | AA82: 13.227 | AB82: 38.438 | AC82: 6.9 | AD82: 7.82 | AE82: 20.92 | AF82: 10.685 | AG82: 11.058 | AH82: 49.255 | AI82: 22.504 | AJ82: 21.581 | AK82: 86383.2
A83: 43217 | B83: 18.82 | C83: 20.407 | D83: 7.223 | E83: 14.927 | F83: 45.99 | G83: 4.307 | H83: 12.994 | I83: 10.075 | J83: 8.9 | L83: 11.501 | M83: 2.02 | N83: 22.671 | O83: 14.13 | P83: 25.726 | Q83: 5.97 | R83: 84 | S83: 32.307 | T83: 26.122 | U83: 7.935 | V83: 12.185 | W83: 24.52 | X83: 22.71 | Y83: 3.045 | Z83: 22.521 | AA83: 13.131 | AB83: 38.641 | AC83: 6.923 | AD83: 7.952 | AE83: 21.3 | AF83: 10.699 | AG83: 10.766 | AH83: 48.901 | AI83: 22.674 | AJ83: 22.157 | AK83: 86444.66
A84: 43220 | B84: 18.492 | C84: 20.012 | D84: 7.223 | E84: 15.085 | F84: 45.65 | G84: 4.312 | H84: 12.821 | I84: 9.945 | J84: 8.78 | L84: 11.627 | M84: 2.03 | N84: 22.229 | O84: 14.359 | P84: 25.29 | Q84: 5.865 | R84: 82.95 | S84: 32.164 | T84: 25.873 | U84: 7.875 | V84: 12.155 | W84: 24.63 | X84: 22.97 | Y84: 3.091 | Z84: 22.641 | AA84: 12.995 | AB84: 38.529 | AC84: 7.018 | AD84: 8.213 | AE84: 21.29 | AF84: 10.679 | AG84: 10.947 | AH84: 49.225 | AI84: 22.658 | AJ84: 22.421 | AK84: 86115.5
A85: 43222 | B85: 18.149 | C85: 19.692 | D85: 7.047 | E85: 15.026 | F85: 45.576 | G85: 4.195 | H85: 12.445 | I85: 9.93 | J85: 8.91 | L85: 11.25 | M85: 1.973 | N85: 22.129 | O85: 14.329 | P85: 24.97 | Q85: 5.798 | R85: 81.93 | S85: 31.654 | T85: 24.709 | U85: 7.756 | V85: 12.053 | W85: 24.57 | X85: 22.6 | Y85: 3.083 | Z85: 23.878 | AA85: 12.469 | AB85: 37.306 | AC85: 6.887 | AD85: 7.795 | AE85: 21.23 | AF85: 10.395 | AG85: 10.877 | AH85: 49.265 | AI85: 22.782 | AJ85: 22.557 | AK85: 84547.09
A86: 43223 | B86: 17.635 | C86: 19.458 | D86: 6.809 | E86: 15.145 | F86: 44.397 | G86: 4.152 | H86: 12.125 | I86: 9.65 | J86: 8.58 | L86: 11.125 | M86: 1.96 | N86: 22.209 | O86: 14.036 | P86: 24.776 | Q86: 5.76 | R86: 82.47 | S86: 31.276 | T86: 24.222 | U86: 7.547 | V86: 11.82 | W86: 24.31 | X86: 22.45 | Y86: 3.068 | Z86: 23.357 | AA86: 12.352 | AB86: 36.558 | AC86: 6.787 | AD86: 8.172 | AE86: 21.012 | AF86: 10.392 | AG86: 10.636 | AH86: 49.65 | AI86: 21.903 | AJ86: 21.844 | AK86: 83288.14
A87: 43224 | B87: 17.6 | C87: 19.389 | D87: 6.818 | E87: 15.361 | F87: 45.617 | G87: 4.282 | H87: 12.153 | I87: 9.469 | J87: 8.7 | L87: 11.116 | M87: 1.95 | N87: 22.069 | O87: 13.867 | P87: 25.755 | Q87: 5.85 | R87: 80.25 | S87: 31.143 | T87: 23.938 | U87: 7.915 | V87: 11.982 | W87: 23.89 | X87: 22.27 | Y87: 3.106 | Z87: 22.601 | AA87: 11.903 | AB87: 36.71 | AC87: 6.757 | AD87: 7.977 | AE87: 20.655 | AF87: 10.395 | AG87: 11.027 | AH87: 50.267 | AI87: 21.862 | AJ87: 21.356 | AK87: 83118.03
A88: 43227 | B88: 17.58 | C88: 19.144 | D88: 7.003 | E88: 14.589 | F88: 45.378 | G88: 4.271 | H88: 12.116 | I88: 9.405 | J88: 8.47 | L88: 11.242 | M88: 2.067 | N88: 22.109 | O88: 13.798 | P88: 25.445 | Q88: 5.655 | R88: 81 | S88: 31 | T88: 23.974 | U88: 7.686 | V88: 11.809 | W88: 24.74 | X88: 22.65 | Y88: 3.007 | Z88: 22.836 | AA88: 11.593 | AB88: 36.396 | AC88: 6.473 | AD88: 7.919 | AE88: 20.972 | AF88: 9.985 | AG88: 10.806 | AH88: 49.801 | AI88: 21.533 | AJ88: 21.288 | AK88: 82714.42
A89: 43228 | B89: 18.059 | C89: 19.194 | D89: 6.87 | E89: 13.779 | F89: 45.524 | G89: 4.25 | H89: 12.217 | I89: 9.511 | J89: 8.47 | L89: 11.243 | M89: 2.06 | N89: 22.38 | O89: 13.768 | P89: 25.668 | Q89: 5.595 | R89: 81 | S89: 30.786 | T89: 24.05 | U89: 7.617 | V89: 11.911 | W89: 24.74 | X89: 22.91 | Y89: 3.447 | Z89: 23.392 | AA89: 11.774 | AB89: 36.012 | AC89: 6.543 | AD89: 8.335 | AE89: 20.757 | AF89: 10.168 | AG89: 10.897 | AH89: 49.751 | AI89: 21.785 | AJ89: 20.468 | AK89: 82956.05
A90: 43229 | B90: 18.82 | C90: 19.219 | D90: 6.923 | E90: 13.821 | F90: 46.139 | G90: 4.228 | H90: 11.759 | I90: 9.755 | J90: 8.7 | L90: 11.304 | M90: 2.093 | N90: 23.173 | O90: 13.703 | P90: 26.152 | Q90: 5.955 | R90: 80.7 | S90: 30.572 | T90: 24.126 | U90: 8.124 | V90: 11.86 | W90: 27.22 | X90: 24.78 | Y90: 3.242 | Z90: 24.169 | AA90: 11.94 | AB90: 36.083 | AC90: 6.531 | AD90: 8.509 | AE90: 20.552 | AF90: 10.178 | AG90: 11.128 | AH90: 50.823 | AI90: 21.995 | AJ90: 20.8 | AK90: 84265.49
A91: 43230 | B91: 18.129 | C91: 19.696 | D91: 6.562 | E91: 14.309 | F91: 48.257 | G91: 4.304 | H91: 12.034 | I91: 9.678 | J91: 8.99 | L91: 11.556 | M91: 2.05 | N91: 22.561 | O91: 13.723 | P91: 26.307 | Q91: 6.09 | R91: 81.6 | S91: 30.868 | T91: 24.785 | U91: 8.024 | V91: 12.135 | W91: 28.84 | X91: 25.75 | Y91: 3.197 | Z91: 24.695 | AA91: 12.734 | AB91: 37.508 | AC91: 6.134 | AD91: 8.818 | AE91: 21.053 | AF91: 10.545 | AG91: 11.178 | AH91: 51.986 | AI91: 21.98 | AJ91: 20.819 | AK91: 85861.2
A92: 43231 | B92: 18.044 | C92: 19.269 | D92: 6.342 | E92: 14.389 | F92: 47.266 | G92: 4.293 | H92: 10.203 | I92: 10.061 | J92: 9.28 | L92: 10.929 | M92: 2.09 | N92: 22.45 | O92: 13.138 | P92: 25.716 | Q92: 6 | R92: 82.8 | S92: 30.347 | T92: 24.39 | U92: 7.845 | V92: 12.307 | W92: 28.95 | X92: 25.44 | Y92: 3.287 | Z92: 24.294 | AA92: 13.15 | AB92: 36.912 | AC92: 5.765 | AD92: 8.656 | AE92: 20.859 | AF92: 10.188 | AG92: 11.068 | AH92: 53.23 | AI92: 21.949 | AJ92: 20.702 | AK92: 85220.23
... A675: 44091 | B675: 18.209 | C675: 17.445 | D675: 11.592 | E675: 20.594 | F675: 24.259 | G675: 6.707 | H675: 5.5 | I675: 20.321 | J675: 17.895 | L675: 23.166 | M675: 5.799 | N675: 7.011 | O675: 24.131 | P675: 31.027 | Q675: 7.595 | R675: 196.014 | S675: 34.581 | T675: 20.626 | U675: 16.446 | V675: 16.134 | W675: 23.28 | X675: 23.843 | Y675: 2.394 | Z675: 30.126 | AA675: 21.939 | AB675: 31.795 | AC675: 10.038 | AD675: 10.803 | AE675: 37.192 | AF675: 29.016 | AG675: 11.79 | AH675: 66.26 | AI675: 29.291 | AJ675: 25.309 | AK675: 100097.8
A676: 44092 | B676: 17.75 | C676: 17.135 | D676: 11.574 | E676: 20.58 | F676: 23.39 | G676: 6.529 | H676: 5.271 | I676: 19.902 | J676: 17.542 | K676: =_xll.BDH(K$1,"TOT_RETURN_INDEX_GROSS_DVDS","2017-12-28","","Dir=V","Per=D","Days=T","Dts=H","cols=1;rows=1425") -> 9.35 | L676: 22.568 | M676: 5.633 | N676: 6.719 | O676: 23.562 | P676: 30.817 | Q676: 7.453 | R676: 191.975 | S676: 33.388 | T676: 20.113 | U676: 16.337 | V676: 15.736 | W676: 22.762 | X676: 23.305 | Y676: 2.353 | Z676: 29.538 | AA676: 22.222 | AB676: 30.979 | AC676: 10.033 | AD676: 11.079 | AE676: 36.659 | AF676: 28.944 | AG676: 11.295 | AH676: 65.812 | AI676: 29.039 | AJ676: 24.43 | AK676: 98289.71
A677: 44095 | B677: 17.49 | C677: 16.834 | D677: 11.354 | E677: 20.003 | F677: 23.734 | G677: 6.412 | H677: 5.3 | I677: 19.716 | J677: 17.36 | K677: 9.46 | L677: 22.362 | M677: 5.474 | N677: 6.397 | O677: 23.635 | P677: 30.722 | Q677: 7.342 | R677: 192.495 | S677: 33.542 | T677: 19.938 | U677: 16.436 | V677: 15.179 | W677: 22.077 | X677: 22.498 | Y677: 2.248 | Z677: 28.998 | AA677: 21.997 | AB677: 30.934 | AC677: 9.968 | AD677: 10.933 | AE677: 36.815 | AF677: 28.699 | AG677: 11.233 | AH677: 64.04 | AI677: 28.798 | AJ677: 24.202 | AK677: 96990.72
A678: 44096 | B678: 17.456 | C678: 17.007 | D678: 11.151 | E678: 20.12 | F678: 24.28 | G678: 6.529 | H678: 5.405 | I678: 19.343 | J678: 17.948 | K678: 9.67 | L678: 23.068 | M678: 5.518 | N678: 6.216 | O678: 23.366 | P678: 30.428 | Q678: 7.358 | R678: 192.342 | S678: 34.161 | T678: 20.113 | U678: 16.198 | V678: 15.474 | W678: 22.067 | X678: 22.39 | Y678: 2.24 | Z678: 29.145 | AA678: 22.237 | AB678: 31.149 | AC678: 10.209 | AD678: 10.858 | AE678: 36.815 | AF678: 29.047 | AG678: 11.089 | AH678: 64.272 | AI678: 28.792 | AJ678: 24.373 | AK678: 97293.54
A679: 44097 | B679: 17.093 | C679: 16.56 | D679: 10.861 | E679: 20.138 | F679: 22.779 | G679: 6.393 | H679: 5.252 | I679: 18.534 | J679: 17.232 | K679: 9.64 | L679: 22.431 | M679: 5.395 | N679: 6.075 | O679: 22.88 | P679: 29.314 | Q679: 7.334 | R679: 191.669 | S679: 32.846 | T679: 19.573 | U679: 15.541 | V679: 15.508 | W679: 21.527 | X679: 21.776 | Y679: 2.167 | Z679: 28.933 | AA679: 21.968 | AB679: 30.265 | AC679: 10.097 | AD679: 10.703 | AE679: 36.659 | AF679: 27.727 | AG679: 10.831 | AH679: 65.706 | AI679: 28.305 | AJ679: 23.803 | AK679: 95734.82
A680: 44098 | B680: 17.229 | C680: 16.824 | D680: 10.693 | E680: 20.364 | F680: 22.543 | G680: 6.621 | H680: 5.243 | I680: 18.676 | J680: 16.921 | K680: 10 | L680: 22.96 | M680: 5.478 | N680: 6.216 | O680: 23.221 | P680: 29.272 | Q680: 7.326 | R680: 191.853 | S680: 33.995 | T680: 20.052 | U680: 15.581 | V680: 15.679 | W680: 21.683 | X680: 21.959 | Y680: 2.2 | Z680: 28.933 | AA680: 22.516 | AB680: 31.092 | AC680: 10.188 | AD680: 10.695 | AE680: 37.036 | AF680: 28.617 | AG680: 10.718 | AH680: 65.217 | AI680: 28.36 | AJ680: 24.077 | AK680: 97012.07
A681: 44099 | B681: 17.161 | C681: 16.788 | D681: 10.526 | E681: 20.526 | F681: 22.286 | G681: 6.473 | H681: 5.319 | I681: 18.356 | J681: 17.018 | K681: 10.39 | L681: 23.136 | M681: 5.45 | N681: 6.156 | O681: 23.376 | P681: 28.715 | Q681: 7.287 | R681: 192.434 | S681: 33.852 | T681: 19.947 | U681: 15.651 | V681: 15.599 | W681: 21.454 | X681: 21.669 | Y681: 2.183 | Z681: 28.886 | AA681: 22.209 | AB681: 30.821 | AC681: 10.211 | AD681: 10.565 | AE681: 36.776 | AF681: 28.955 | AG681: 10.584 | AH681: 65.873 | AI681: 28.181 | AJ681: 23.837 | AK681: 96999.38
A682: 44102 | B682: 17.28 | C682: 16.633 | D682: 9.997 | E682: 20.125 | F682: 21.256 | G682: 6.313 | H682: 5.08 | I682: 17.822 | J682: 16.836 | K682: 10.29 | L682: 22.136 | M682: 5.288 | N682: 6.397 | O682: 22.549 | P682: 27.601 | Q682: 7.247 | R682: 185.06 | S682: 32.416 | T682: 19.938 | U682: 14.985 | V682: 14.883 | W682: 20.936 | X682: 21.131 | Y682: 2.143 | Z682: 28.487 | AA682: 21.313 | AB682: 31.466 | AC682: 9.871 | AD682: 10.44 | AE682: 36.308 | AF682: 27.952 | AG682: 10.45 | AH682: 65.351 | AI682: 27.503 | AJ682: 23.118 | AK682: 94666.37
A683: 44103 | B683: 16.856 | C683: 16.331 | D683: 9.883 | E683: 19.94 | F683: 21.492 | G683: 6.27 | H683: 4.966 | I683: 17.701 | J683: 16.387 | K683: 10.22 | L683: 21.96 | M683: 5.232 | N683: 6.136 | O683: 22.352 | P683: 27.979 | Q683: 7.153 | R683: 185.366 | S683: 32.316 | T683: 19.503 | U683: 14.915 | V683: 14.417 | W683: 20.344 | X683: 20.786 | Y683: 2.094 | Z683: 28.199 | AA683: 21.129 | AB683: 30.696 | AC683: 9.919 | AD683: 10.536 | AE683: 36.386 | AF683: 27.86 | AG683: 10.151 | AH683: 64.872 | AI683: 27.479 | AJ683: 22.912 | AK683: 93580.35
A684: 44104 | B684: 16.776 | C684: 16.45 | D684: 10.341 | E684: 20.233 | F684: 22.296 | G684: 6.251 | H684: 4.937 | I684: 18.365 | J684: 17.649 | K684: 10.8 | L684: 22.783 | M684: 5.371 | N684: 6.277 | O684: 21.907 | P684: 27.832 | Q684: 7.421 | R684: 190.139 | S684: 32.946 | T684: 19.59 | U684: 15.164 | V684: 14.406 | W684: 20.51 | X684: 21.109 | Y684: 2.167 | Z684: 28.346 | AA684: 22.565 | AB684: 31.682 | AC684: 9.892 | AD684: 10.657 | AE684: 36.334 | AF684: 27.717 | AG684: 10.337 | AH684: 65.717 | AI684: 27.423 | AJ684: 23.003 | AK684: 94603.38
A685: 44105 | B685: 16.873 | C685: 16.478 | D685: 10.174 | E685: 20.215 | F685: 22.865 | G685: 6.356 | H685: 5.262 | I685: 18.902 | J685: 17.692 | K685: 11.1 | L685: 23.823 | M685: 5.708 | N685: 6.508 | O685: 22.187 | P685: 27.969 | Q685: 7.39 | R685: 192.771 | S685: 33.476 | T685: 19.621 | U685: 15.114 | V685: 14.565 | W685: 20.697 | X685: 21.367 | Y685: 2.167 | Z685: 28.957 | AA685: 23.211 | AB685: 31.614 | AC685: 9.953 | AD685: 11.016 | AE685: 36.542 | AF685: 28.136 | AG685: 10.378 | AH685: 65.439 | AI685: 27.355 | AJ685: 23.974 | AK685: 95478.52
...

Sheet volume
A1: Dates | B1: BBAS3 BZ EQUITY | C1: BBDC3 BZ EQUITY | D1: BEEF3 BZ EQUITY | E1: BRAP4 BZ EQUITY | F1: BRKM5 BZ EQUITY | G1: CMIG4 BZ EQUITY | H1: COGN3 BZ EQUITY | I1: CSAN3 BZ EQUITY | J1: CSNA3 BZ EQUITY | K1: CURY3 BZ EQUITY | L1: CYRE3 BZ EQUITY | M1: DIRR3 BZ EQUITY | N1: EMBJ3 BZ EQUITY | O1: EQTL3 BZ EQUITY | P1: FLRY3 BZ EQUITY | Q1: GOAU4 BZ EQUITY | R1: HAPV3 BZ EQUITY | S1: HYPE3 BZ EQUITY | T1: ITUB4 BZ EQUITY | U1: MBRF3 BZ EQUITY | V1: MOTV3 BZ EQUITY | W1: PETR3 BZ EQUITY | X1: PETR4 BZ EQUITY | Y1: POMO4 BZ EQUITY | Z1: PSSA3 BZ EQUITY | AA1: RADL3 BZ EQUITY | AB1: SANB11 BZ EQUITY | AC1: SBSP3 BZ EQUITY | AD1: SLCE3 BZ EQUITY | AE1: TAEE11 BZ EQUITY | AF1: TOTS3 BZ EQUITY | AG1: USIM5 BZ EQUITY | AH1: VALE3 BZ EQUITY | AI1: VIVT3 BZ EQUITY | AJ1: VBBR3 BZ EQUITY
A2: Date | B2: =+close!B2 -> BBAS3 | C2: =+close!C2 -> BBDC3 | D2: =+close!D2 -> BEEF3 | E2: =+close!E2 -> BRAP4 | F2: =+close!F2 -> BRKM5 | G2: =+close!G2 -> CMIG4 | H2: =+close!H2 -> COGN3 | I2: =+close!I2 -> CSAN3 | ... AJ2: =+close!AJ2 -> VBBR3
A3: =_xll.BDH(B$1,"TURNOVER","2017-12-28","","Dir=V","Per=D","Days=T","Dts=S","cols=2;rows=2098") -> 43097 | B3: 195932200 | C3: =_xll.BDH(C$1,"TURNOVER","2017-12-28","","Dir=V","Per=D","Days=T","Dts=H","cols=1;rows=2098") -> 35401050 | D3: =_xll.BDH(D$1,"TURNOVER","2017-12-28","","Dir=V","Per=D","Days=T","Dts=H","cols=1;rows=2098") -> 7822328 | E3: =_xll.BDH(E$1,"TURNOVER","2017-12-28","","Dir=V","Per=D","Days=T","Dts=H","cols=1;rows=2098") -> 56231490 | F3: =_xll.BDH(F$1,"TURNOVER","2017-12-28","","Dir=V","Per=D","Days=T","Dts=H","cols=1;rows=2098") -> 77637130 | G3: =_xll.BDH(G$1,"TURNOVER","2017-12-28","","Dir=V","Per=D","Days=T","Dts=H","cols=1;rows=2098") -> 41042800 | H3: =_xll.BDH(H$1,"TURNOVER","2017-12-28","","Dir=V","Per=D","Days=T","Dts=H","cols=1;rows=2098") -> 77127550 | I3: =_xll.BDH(I$1,"TURNOVER","2017-12-28","","Dir=V","Per=D","Days=T","Dts=H","cols=1;rows=2098") -> 38933560 | J3: =_xll.BDH(J$1,"TURNOVER","2017-12-28","","Dir=V","Per=D","Days=T","Dts=H","cols=1;rows=2098") -> 47712400 | K3: =_xll.BDH(K$1,"TURNOVER","2017-12-28","","Dir=V","Per=D","Days=T","Dts=H","cols=1;rows=1424") -> 159974800 | L3: =_xll.BDH(L$1,"TURNOVER","2017-12-28","","Dir=V","Per=D","Days=T","Dts=H","cols=1;rows=2098") -> 13650800 | M3: =_xll.BDH(M$1,"TURNOVER","2017-12-28","","Dir=V","Per=D","Days=T","Dts=H","cols=1;rows=2098") -> 4688892 | N3: =_xll.BDH(N$1,"TURNOVER","2017-12-28","","Dir=V","Per=D","Days=T","Dts=H","cols=1;rows=2098") -> 111473200 | O3: =_xll.BDH(O$1,"TURNOVER","2017-12-28","","Dir=V","Per=D","Days=T","Dts=H","cols=1;rows=2098") -> 50548450 | P3: =_xll.BDH(P$1,"TURNOVER","2017-12-28","","Dir=V","Per=D","Days=T","Dts=H","cols=1;rows=2098") -> 180639100 | Q3: =_xll.BDH(Q$1,"TURNOVER","2017-12-28","","Dir=V","Per=D","Days=T","Dts=H","cols=1;rows=2098") -> 32196640 | R3: =_xll.BDH(R$1,"TURNOVER","2017-12-28","","Dir=V","Per=D","Days=T","Dts=H","cols=1;rows=2020") -> 1164267000 | S3: =_xll.BDH(S$1,"TURNOVER","2017-12-28","","Dir=V","Per=D","Days=T","Dts=H","cols=1;rows=2098") -> 60086800 | T3: =_xll.BDH(T$1,"TURNOVER","2017-12-28","","Dir=V","Per=D","Days=T","Dts=H","cols=1;rows=2098") -> 453145400 | U3: =_xll.BDH(U$1,"TURNOVER","2017-12-28","","Dir=V","Per=D","Days=T","Dts=H","cols=1;rows=2098") -> 10342230 | V3: =_xll.BDH(V$1,"TURNOVER","2017-12-28","","Dir=V","Per=D","Days=T","Dts=H","cols=1;rows=2098") -> 62994480 | W3: =_xll.BDH(W$1,"TURNOVER","2017-12-28","","Dir=V","Per=D","Days=T","Dts=H","cols=1;rows=2098") -> 80454650 | X3: =_xll.BDH(X$1,"TURNOVER","2017-12-28","","Dir=V","Per=D","Days=T","Dts=H","cols=1;rows=2098") -> 305803800 | Y3: =_xll.BDH(Y$1,"TURNOVER","2017-12-28","","Dir=V","Per=D","Days=T","Dts=H","cols=1;rows=2098") -> 6091041 | Z3: =_xll.BDH(Z$1,"TURNOVER","2017-12-28","","Dir=V","Per=D","Days=T","Dts=H","cols=1;rows=2098") -> 12430250 | ... AJ3: =_xll.BDH(AJ$1,"TURNOVER","2017-12-28","","Dir=V","Per=D","Days=T","Dts=H","cols=1;rows=2098") -> 31245060
A4: 43102 | B4: 300320800 | C4: 44103100 | D4: 3452437 | E4: 40472630 | F4: 82708900 | G4: 51232160 | H4: 98871260 | I4: 36823410 | J4: 81837020 | K4: 24121840 | L4: 24379120 | M4: 3139003 | N4: 78517640 | O4: 38507980 | P4: 63819050 | Q4: 118403200 | R4: 167820100 | S4: 41799900 | T4: 483649100 | U4: 7669110 | V4: 92938190 | W4: 77288990 | X4: 549628200 | Y4: 12095870 | Z4: 7945419 | AA4: 80270310 | AB4: 40901990 | AC4: 28019650 | AD4: 6973658 | AE4: 13607540 | AF4: 9456282 | AG4: 131496400 | AH4: 584490600 | AI4: 263733 | AJ4: 63660800
A5: 43103 | B5: 271479800 | C5: 21050220 | D5: 3975214 | E5: 88635900 | F5: 56282110 | G5: 54710270 | H5: 201111600 | I5: 67228580 | J5: 103686700 | K5: 25432890 | L5: 25446740 | M5: 3659631 | N5: 200106900 | O5: 38774620 | P5: 44892460 | Q5: 113842000 | R5: 78962990 | S5: 63416350 | T5: 654269500 | U5: 7715542 | V5: 107443900 | W5: 170801800 | X5: 927610000 | Y5: 21227670 | Z5: 8607404 | AA5: 100492700 | AB5: 41091600 | AC5: 25645860 | AD5: 14661750 | AE5: 21463990 | AF5: 8036368 | AG5: 155001200 | AH5: 530011900 | AI5: 1214244 | AJ5: 125293800
A6: 43104 | B6: 325419100 | C6: 39043440 | D6: 7063808 | E6: 160300200 | F6: 70626240 | G6: 52964610 | H6: 230132300 | I6: 61764520 | J6: 140421800 | K6: 11596250 | L6: 31023110 | M6: 2749529 | N6: 144425500 | O6: 100887500 | P6: 52969650 | Q6: 159030400 | R6: 30753360 | S6: 66400530 | T6: 696661800 | U6: 13377310 | V6: 92045600 | W6: 121231100 | X6: 624099800 | Y6: 16983560 | Z6: 10187170 | AA6: 105970500 | AB6: 45555610 | AC6: 25126080 | AD6: 17189940 | AE6: 34012470 | AF6: 9375011 | AG6: 340284100 | AH6: 774747900 | AI6: 851991 | AJ6: 25121880
A7: 43105 | B7: 177069400 | C7: 26982440 | D7: 4395332 | E7: 74943200 | F7: 75961300 | G7: 35017850 | H7: 60994870 | I7: 65646210 | J7: 157528300 | K7: 8841126 | L7: 73202800 | M7: 1632100 | N7: 189696200 | O7: 62724140 | P7: 40760520 | Q7: 88595630 | R7: 35159010 | S7: 37758610 | T7: 472439100 | U7: 5545909 | V7: 71300100 | W7: 82678800 | X7: 452007600 | Y7: 12035620 | Z7: 14477160 | AA7: 86345020 | AB7: 177500500 | AC7: 23138310 | AD7: 12478890 | AE7: 13735380 | AF7: 133077600 | AG7: 292219600 | AH7: 638897200 | AI7: 179092 | AJ7: 56186360
A8: 43108 | B8: 172545600 | C8: 48250180 | D8: 10869180 | E8: 47431710 | F8: 67002100 | G8: 28747550 | H8: 129180800 | I8: 37550310 | J8: 152752300 | K8: 17003830 | L8: 35208100 | M8: 4421778 | N8: 99527940 | O8: 65227890 | P8: 43711640 | Q8: 73766130 | R8: 64161490 | S8: 63740770 | T8: 381831100 | U8: 9887093 | V8: 63800720 | W8: 85654630 | X8: 480575900 | Y8: 14604790 | Z8: 10934460 | AA8: 48299690 | AB8: 61187900 | AC8: 22094400 | AD8: 9439021 | AE8: 40897730 | AF8: 7211777 | AG8: 196620000 | AH8: 624702200 | AI8: 278591 | AJ8: 59054780
A9: 43109 | B9: 195449100 | C9: 37847690 | D9: 6883322 | E9: 68002510 | F9: 71163360 | G9: 57579320 | H9: 310265200 | I9: 39605960 | J9: 152334800 | K9: 25527580 | L9: 39098500 | M9: 2788895 | N9: 104875700 | O9: 78063870 | P9: 43140800 | Q9: 137825300 | R9: 50928220 | S9: 73101370 | T9: 637615000 | U9: 9050189 | V9: 145504000 | W9: 119204400 | X9: 598574700 | Y9: 8135826 | Z9: 11725150 | AA9: 65051060 | AB9: 38040390 | AC9: 27376280 | AD9: 10272070 | AE9: 43565180 | AF9: 15558500 | AG9: 199398800 | AH9: 692636000 | AI9: 550438 | AJ9: 53424540
A10: 43110 | B10: 169259400 | C10: 15052970 | D10: 6308889 | E10: 24421100 | F10: 49863940 | G10: 90744850 | H10: 233834000 | I10: 56900420 | J10: 137529700 | K10: 18317430 | L10: 29304450 | M10: 4628177 | N10: 68746910 | O10: 74897010 | P10: 41583760 | Q10: 126082400 | R10: 30217480 | S10: 30706780 | T10: 402886900 | U10: 4908928 | V10: 63906800 | W10: 84624260 | X10: 483078000 | Y10: 8662445 | Z10: 24103250 | AA10: 94770500 | AB10: 23788000 | AC10: 15410700 | AD10: 17495760 | AE10: 30284430 | AF10: 4943788 | AG10: 112564400 | AH10: 517775600 | AI10: 389461 | AJ10: 95720190
A11: 43111 | B11: 327374200 | C11: 59252150 | D11: 4421235 | E11: 28404350 | F11: 68911070 | G11: 58350390 | H11: 446629400 | I11: 52932680 | J11: 157682400 | K11: 23932420 | L11: 64977420 | M11: 2034554 | N11: 69578100 | O11: 45429770 | P11: 42609320 | Q11: 162670200 | R11: 25624160 | S11: 54835800 | T11: 466672300 | U11: 7196091 | V11: 86060160 | W11: 182166900 | X11: 648199400 | Y11: 10441150 | Z11: 20470950 | AA11: 80303660 | AB11: 25711530 | AC11: 24260230 | AD11: 11291220 | AE11: 23420990 | AF11: 3982980 | AG11: 255653700 | AH11: 439432600 | AI11: 108484 | AJ11: 18486040
A12: 43112 | B12: 259491800 | C12: 32012390 | D12: 4674069 | E12: 38482470 | F12: 53498240 | G12: 53915950 | H12: 207217400 | I12: 36545510 | J12: 240214700 | K12: 12160020 | L12: 45408890 | M12: 4070945 | N12: 55539560 | O12: 56785500 | P12: 28114300 | Q12: 253830100 | R12: 26853890 | S12: 67861100 | T12: 309610900 | U12: 9505647 | V12: 47283500 | W12: 100729900 | X12: 792052900 | Y12: 8344002 | Z12: 29053040 | AA12: 68415970 | AB12: 36241420 | AC12: 20383650 | AD12: 12763340 | AE12: 20857670 | AF12: 10085630 | AG12: 375715700 | AH12: 652035300 | AI12: 241204 | AJ12: 44527440
A13: 43115 | B13: 179991200 | C13: 38122290 | D13: 4565731 | E13: 17702450 | F13: 49612610 | G13: 40092180 | H13: 171556400 | I13: 14158890 | J13: 95129590 | K13: 16323760 | L13: 37156740 | M13: 1567480 | N13: 20919170 | O13: 29985010 | P13: 29958880 | Q13: 156646800 | R13: 32178480 | S13: 15803750 | T13: 331411600 | U13: 6243135 | V13: 33503320 | W13: 42641370 | X13: 501946600 | Y13: 8180541 | Z13: 12671040 | AA13: 48273440 | AB13: 11419050 | AC13: 8039887 | AD13: 9153503 | AE13: 11933250 | AF13: 5969947 | AG13: 170535800 | AH13: 315487000 | AI13: 145622 | AJ13: 10580930
A14: 43116 | B14: 214882800 | C14: 38221180 | D14: 5860836 | E14: 73861540 | F14: 152067100 | G14: 50902370 | H14: 114262500 | I14: 56098070 | J14: 117617600 | K14: 11870140 | L14: 42310890 | M14: 9747234 | N14: 71030140 | O14: 50500810 | P14: 35164190 | Q14: 136112800 | R14: 48714890 | S14: 46827560 | T14: 402925500 | U14: 7073232 | V14: 48741100 | W14: 134991800 | X14: 1035475000 | Y14: 7921784 | Z14: 36305300 | AA14: 75703020 | AB14: 28865480 | AC14: 24325280 | AD14: 15602580 | AE14: 15858080 | AF14: 14929260 | AG14: 215993900 | AH14: 858879600 | AI14: 380288 | AJ14: 85047370
A15: 43117 | B15: 424601600 | C15: 39337160 | D15: 7184097 | E15: 35800860 | F15: 77820130 | G15: 80500390 | H15: 134332400 | I15: 35252660 | J15: 162857100 | K15: 7300970 | L15: 47487130 | M15: 6273212 | N15: 70837820 | O15: 53483300 | P15: 32348740 | Q15: 152605800 | R15: 29019460 | S15: 31575580 | T15: 447340300 | U15: 5578694 | V15: 33471390 | W15: 125377200 | X15: 1057469000 | Y15: 3453705 | Z15: 42951310 | AA15: 79406720 | AB15: 30559060 | AC15: 87409200 | AD15: 10407750 | AE15: 25701050 | AF15: 7196731 | AG15: 203883000 | AH15: 707946000 | AI15: 484582 | AJ15: 62018320
... A1426: 45194 | B1426: 424465900 | C1426: 63219130 | D1426: 63915750 | E1426: 69376350 | F1426: 88750650 | G1426: 159101600 | H1426: 46924370 | I1426: 88208040 | J1426: 79190430 | K1426: 58400300 | L1426: 145600600 | M1426: 73107330 | N1426: 109488500 | O1426: 164635500 | P1426: 54119780 | Q1426: 66983330 | R1426: 517295100 | S1426: 111609100 | T1426: 382971900 | U1426: 85399690 | V1426: 98258250 | W1426: 146620900 | X1426: 913559700 | Y1426: 19999800 | Z1426: 43853420 | AA1426: 175252100 | AB1426: 37725960 | AC1426: 79678970 | AD1426: 39708910 | AE1426: 68005660 | AF1426: 88081550 | AG1426: 67724090 | AH1426: 2305017000 | AI1426: 75061090 | AJ1426: 98803040
A1427: 45195 | B1427: 541400300 | C1427: 84967260 | D1427: 67065230 | E1427: 55241590 | F1427: 55284330 | G1427: 130419900 | H1427: 69197830 | I1427: 105156100 | J1427: 77675210 | L1427: 129017400 | M1427: 73147160 | N1427: 110120900 | O1427: 258060400 | P1427: 66205860 | Q1427: 58430460 | R1427: 531844100 | S1427: 236047600 | T1427: 648909200 | U1427: 49233430 | V1427: 328473900 | W1427: 467958000 | X1427: 2047340000 | Y1427: 37264370 | Z1427: 38296690 | AA1427: 205852000 | AB1427: 44110620 | AC1427: 175102200 | AD1427: 63042460 | AE1427: 63476290 | AF1427: 96443980 | AG1427: 80464800 | AH1427: 1588331000 | AI1427: 89624250 | AJ1427: 167644900
A1428: 45196 | B1428: 508213700 | C1428: 102888100 | D1428: 93928310 | E1428: 39475800 | F1428: 50483000 | G1428: 87052240 | H1428: 78695540 | I1428: 139391700 | J1428: 64692850 | L1428: 151644700 | M1428: 55925600 | N1428: 106972500 | O1428: 297860100 | P1428: 83487550 | Q1428: 96901280 | R1428: 322708800 | S1428: 108710900 | T1428: 611658500 | U1428: 83850560 | V1428: 188445100 | W1428: 580775200 | X1428: 1835761000 | Y1428: 19203680 | Z1428: 43883990 | AA1428: 236958500 | AB1428: 34328910 | AC1428: 246937300 | AD1428: 51790860 | AE1428: 92360140 | AF1428: 126670200 | AG1428: 61435700 | AH1428: 1124159000 | AI1428: 105858300 | AJ1428: 157044600
A1429: 45197 | B1429: 563904100 | C1429: 95563730 | D1429: 60060910 | E1429: 28290860 | F1429: 63887080 | G1429: 77723980 | H1429: 65308810 | I1429: 142101000 | J1429: 51805470 | L1429: 192796600 | M1429: 74117090 | N1429: 72933710 | O1429: 263070800 | P1429: 39614620 | Q1429: 68512800 | R1429: 235160000 | S1429: 96032860 | T1429: 775778800 | U1429: 39227820 | V1429: 191674900 | W1429: 322504300 | X1429: 1057230000 | Y1429: 25791930 | Z1429: 35234200 | AA1429: 197133000 | AB1429: 31048690 | AC1429: 138631200 | AD1429: 47639790 | AE1429: 68675100 | AF1429: 80947660 | AG1429: 72689340 | AH1429: 1736066000 | AI1429: 132407100 | AJ1429: 135341200
A1430: 45198 | B1430: 257802100 | C1430: 69987180 | D1430: 75273260 | E1430: 83913060 | F1430: 55529730 | G1430: 90077220 | H1430: 64937590 | I1430: 139929600 | J1430: 47980400 | L1430: 159859200 | M1430: 77640610 | N1430: 81841480 | O1430: 148265200 | P1430: 31858980 | Q1430: 91955700 | R1430: 165066300 | S1430: 90367520 | T1430: 478838300 | U1430: 65613030 | V1430: 155531700 | W1430: 386591600 | X1430: 1387560000 | Y1430: 19700450 | Z1430: 26045010 | AA1430: 272941500 | AB1430: 22598930 | AC1430: 249586300 | AD1430: 35155120 | AE1430: 47818980 | AF1430: 109340900 | AG1430: 54230880 | AH1430: 1281960000 | AI1430: 141343600 | AJ1430: 96724890
A1431: 45201 | B1431: 222873300 | C1431: 55464550 | D1431: 62775900 | E1431: 23215020 | F1431: 42163850 | G1431: 75194160 | H1431: 64975040 | I1431: 99039020 | J1431: 48377060 | L1431: 63055000 | M1431: 29148920 | N1431: 45018030 | O1431: 112404900 | P1431: 99614260 | Q1431: 43949220 | R1431: 277571700 | S1431: 91069300 | T1431: 339326800 | U1431: 57996120 | V1431: 146196900 | W1431: 309855800 | X1431: 1177274000 | Y1431: 18091760 | Z1431: 24430250 | AA1431: 92965090 | AB1431: 49590620 | AC1431: 210127300 | AD1431: 38006300 | AE1431: 35938020 | AF1431: 78101500 | AG1431: 50495950 | AH1431: 748389200 | AI1431: 150892700 | AJ1431: 66034380
A1432: 45202 | B1432: 300192800 | C1432: 75282430 | D1432: 44720880 | E1432: 35425500 | F1432: 54139400 | G1432: 76622950 | H1432: 49966140 | I1432: 80780770 | J1432: 67734580 | L1432: 100097900 | M1432: 56563180 | N1432: 89026600 | O1432: 528797900 | P1432: 158269500 | Q1432: 62080320 | R1432: 226317800 | S1432: 133601400 | T1432: 571053000 | U1432: 73130540 | V1432: 107832200 | W1432: 364561600 | X1432: 1288060000 | Y1432: 20887600 | Z1432: 30007480 | AA1432: 133843900 | AB1432: 55225480 | AC1432: 193415300 | AD1432: 33180730 | AE1432: 87722050 | AF1432: 62866530 | AG1432: 54080670 | AH1432: 1015392000 | AI1432: 97362900 | AJ1432: 229569200
A1433: 45203 | B1433: 382363800 | C1433: 69720100 | D1433: 39172140 | E1433: 37219170 | F1433: 43302330 | G1433: 90433530 | H1433: 49168580 | I1433: 107368100 | J1433: 74559980 | L1433: 134309700 | M1433: 27803560 | N1433: 77439100 | O1433: 186816700 | P1433: 56641550 | Q1433: 52749620 | R1433: 213400700 | S1433: 110293300 | T1433: 643916900 | U1433: 69583700 | V1433: 59983230 | W1433: 746272300 | X1433: 2918953000 | Y1433: 25512610 | Z1433: 23222400 | AA1433: 106331700 | AB1433: 69539500 | AC1433: 188381000 | AD1433: 32023240 | AE1433: 57345720 | AF1433: 74063300 | AG1433: 47428650 | AH1433: 948324300 | AI1433: 116288300 | AJ1433: 194821500
A1434: 45204 | B1434: 366402800 | C1434: 97760160 | D1434: 60402780 | E1434: 37794820 | F1434: 41817020 | G1434: 62731990 | H1434: 33074140 | I1434: 105698000 | J1434: 58299140 | L1434: 121334900 | M1434: 52856580 | N1434: 63254480 | O1434: 231252400 | P1434: 61817700 | Q1434: 48197640 | R1434: 264924500 | S1434: 61079470 | T1434: 789138500 | U1434: 66214820 | V1434: 40363680 | W1434: 287839200 | X1434: 1151533000 | Y1434: 21310710 | Z1434: 24632200 | AA1434: 117467700 | AB1434: 89846420 | AC1434: 115752100 | AD1434: 76769490 | AE1434: 36271000 | AF1434: 52591530 | AG1434: 57852290 | AH1434: 763262500 | AI1434: 80596100 | AJ1434: 115183500
A1435: 45205 | B1435: 998502500 | C1435: 60960180 | D1435: 60489090 | E1435: 59494770 | F1435: 54638650 | G1435: 83452080 | H1435: 61356610 | I1435: 147009900 | J1435: 51815790 | L1435: 153043500 | M1435: 64512280 | N1435: 80948030 | O1435: 241507100 | P1435: 46432360 | Q1435: 52207040 | R1435: 220256900 | S1435: 55225860 | T1435: 1228405000 | U1435: 51806920 | V1435: 99967000 | W1435: 423781000 | X1435: 1595037000 | Y1435: 29036360 | Z1435: 34284340 | AA1435: 152106100 | AB1435: 81986900 | AC1435: 129985900 | AD1435: 37706860 | AE1435: 60639340 | AF1435: 52220840 | AG1435: 53484740 | AH1435: 1516585000 | AI1435: 100517600 | AJ1435: 138234600
A1436: 45208 | B1436: 478198800 | C1436: 53361960 | D1436: 56683200 | E1436: 42623960 | F1436: 35359820 | G1436: 100122300 | H1436: 44860230 | I1436: 92187620 | J1436: 67420250 | L1436: 85931160 | M1436: 46932710 | N1436: 66869520 | O1436: 162159500 | P1436: 51757920 | Q1436: 56265250 | R1436: 246975300 | S1436: 84851560 | T1436: 402869800 | U1436: 91674810 | V1436: 100908700 | W1436: 435652400 | X1436: 2691056000 | Y1436: 26299340 | Z1436: 22365580 | AA1436: 111885600 | AB1436: 68915550 | AC1436: 95400960 | AD1436: 38540970 | AE1436: 86826360 | AF1436: 89785870 | AG1436: 70226980 | AH1436: 948932800 | AI1436: 107254000 | AJ1436: 116719100
A1437: 45209 | B1437: 479145800 | C1437: 65373280 | D1437: 62035750 | E1437: 32660300 | F1437: 91550370 | G1437: 69724510 | H1437: 51127890 | I1437: 136683100 | J1437: 71873190 | L1437: 125197400 | M1437: 48076780 | N1437: 91715710 | O1437: 247029400 | P1437: 45915650 | Q1437: 60066440 | R1437: 202489100 | S1437: 183528500 | T1437: 681277600 | U1437: 61264740 | V1437: 69089910 | W1437: 349407500 | X1437: 1696557000 | Y1437: 49995350 | Z1437: 25825230 | AA1437: 121384600 | AB1437: 68847220 | AC1437: 145772000 | AD1437: 29909010 | AE1437: 45938160 | AF1437: 53629280 | AG1437: 62875650 | AH1437: 1223337000 | AI1437: 166868300 | AJ1437: 178915900
A1438: 45210 | B1438: 403205200 | C1438: 62052300 | D1438: 75058720 | E1438: 41219650 | F1438: 46813830 | G1438: 106718500 | H1438: 33721560 | I1438: 84555960 | J1438: 83184390 | L1438: 157736400 | M1438: 44882970 | N1438: 63825330 | O1438: 191904800 | P1438: 25568060 | Q1438: 78463100 | R1438: 580972900 | S1438: 99556880 | T1438: 441936700 | U1438: 67679370 | V1438: 77272560 | W1438: 386330800 | X1438: 1451577000 | Y1438: 40352570 | Z1438: 19204140 | AA1438: 91087390 | AB1438: 54432310 | AC1438: 213160000 | AD1438: 42764180 | AE1438: 68943320 | AF1438: 70428910 | AG1438: 64357570 | AH1438: 916635600 | AI1438: 132671100 | AJ1438: 129720000
... A2022: 46066 | B2022: 1537676000 | C2022: 196466300 | D2022: 54535790 | E2022: 63976820 | F2022: 54756120 | G2022: 108073100 | H2022: 120244600 | I2022: 165597900 | J2022: 197405300 | L2022: 115106200 | M2022: 65315420 | N2022: 280795700 | O2022: 260790500 | P2022: 50704570 | Q2022: 216415400 | R2022: 39504860 | S2022: 54904180 | T2022: 1531317000 | U2022: 106238700 | V2022: 219139100 | W2022: 265513500 | X2022: 1011600000 | Y2022: 62011890 | Z2022: 62059320 | AA2022: 276968100 | AB2022: 157432600 | AC2022: 352126100 | AD2022: 35532540 | AE2022: 74714940 | AF2022: 349342200 | AG2022: 175203500 | AH2022: 2493366000 | AI2022: 163779000 | AJ2022: 139553000
A2023: 46071 | B2023: 993674800 | C2023: 156303700 | D2023: 67046280 | E2023: 68420290 | F2023: 29596740 | G2023: 119052700 | H2023: 82054900 | I2023: 159708100 | J2023: 86768930 | L2023: 185333600 | M2023: 112321800 | N2023: 442822700 | O2023: 273071500 | P2023: 31943360 | Q2023: 51075120 | S2023: 54261420 | T2023: 1117289000 | U2023: 139460200 | V2023: 240260900 | W2023: 435717400 | X2023: 1197746000 | Y2023: 56469880 | Z2023: 69141220 | AA2023: 185669600 | AB2023: 75661310 | AC2023: 417631900 | AD2023: 28535510 | AE2023: 50068560 | AF2023: 219450200 | AG2023: 48312300 | AH2023: 1763329000 | AI2023: 143125500 | AJ2023: 264252800
A2024: 46072 | B2024: 864703400 | C2024: 98658600 | D2024: 56805720 | E2024: 99408170 | F2024: 21615600 | G2024: 94116620 | H2024: 146698700 | I2024: 154526800 | J2024: 117181500 | L2024: 104524200 | M2024: 74549410 | N2024: 235275900 | O2024: 379129200 | P2024: 25705940 | Q2024: 71233820 | S2024: 46355660 | T2024: 1553721000 | U2024: 89997340 | V2024: 779994400 | W2024: 473123800 | X2024: 1832746000 | Y2024: 61989700 | Z2024: 60615420 | AA2024: 178118600 | AB2024: 71045650 | AC2024: 414656700 | AD2024: 26693500 | AE2024: 57662430 | AF2024: 178541500 | AG2024: 54380850 | AH2024: 2369906000 | AI2024: 122328300 | AJ2024: 201690400
A2025: 46073 | B2025: 1082868000 | C2025: 101866000 | D2025: 56442810 | E2025: 103486000 | F2025: 25460720 | G2025: 136278100 | H2025: 123171700 | I2025: 239368600 | J2025: 147530300 | L2025: 171017500 | M2025: 71907360 | N2025: 435254800 | O2025: 344091800 | P2025: 45719130 | Q2025: 89927760 | S2025: 77556540 | T2025: 1545796000 | U2025: 511383000 | V2025: 249495700 | W2025: 392582800 | X2025: 1962788000 | Y2025: 46839640 | Z2025: 101186700 | AA2025: 219357100 | AB2025: 224632700 | AC2025: 466348600 | AD2025: 29167570 | AE2025: 98665570 | AF2025: 179283700 | AG2025: 78477650 | AH2025: 3471520000 | AI2025: 203302600 | AJ2025: 180741200
A2026: 46076 | B2026: 1961317000 | C2026: 82113260 | D2026: 66983240 | E2026: 82291830 | F2026: 30294620 | G2026: 192498900 | H2026: 89846520 | I2026: 341272900 | J2026: 151350600 | L2026: 148505600 | M2026: 55057440 | N2026: 355773300 | O2026: 298794500 | P2026: 45809010 | Q2026: 93555100 | S2026: 47425090 | T2026: 1633129000 | U2026: 177777600 | V2026: 317397700 | W2026: 540326000 | X2026: 2130688000 | Y2026: 50609490 | Z2026: 100582300 | AA2026: 129589100 | AB2026: 158894800 | AC2026: 292924300 | AD2026: 30630080 | AE2026: 228936800 | AF2026: 241395700 | AG2026: 69419630 | AH2026: 1850921000 | AI2026: 249260800 | AJ2026: 314248400
A2027: 46077 | B2027: 724388000 | C2027: 92770420 | D2027: 236835600 | E2027: 58172860 | F2027: 31138960 | G2027: 157594400 | H2027: 104746100 | I2027: 260036100 | J2027: 102881700 | L2027: 147748900 | M2027: 81548540 | N2027: 344727600 | O2027: 375693200 | P2027: 37747950 | Q2027: 168763700 | S2027: 74703890 | T2027: 1841010000 | U2027: 1100539000 | V2027: 244701200 | W2027: 457265600 | X2027: 1703501000 | Y2027: 67711990 | Z2027: 104112500 | AA2027: 216090400 | AB2027: 166263400 | AC2027: 514761100 | AD2027: 24550710 | AE2027: 148495000 | AF2027: 312236200 | AG2027: 118158800 | AH2027: 1741537000 | AI2027: 198305500 | AJ2027: 383968200
A2028: 46078 | B2028: 815360000 | C2028: 73330830 | D2028: 105343200 | E2028: 115819200 | F2028: 20566230 | G2028: 159605200 | H2028: 132418100 | I2028: 227305400 | J2028: 75600350 | L2028: 195759000 | M2028: 112920300 | N2028: 259041600 | O2028: 229474000 | P2028: 22705830 | Q2028: 74832820 | S2028: 40193970 | T2028: 1381882000 | U2028: 163478400 | V2028: 152910400 | W2028: 282468500 | X2028: 1028531000 | Y2028: 105688600 | Z2028: 79377720 | AA2028: 169806800 | AB2028: 129838100 | AC2028: 411393400 | AD2028: 29275930 | AE2028: 66775120 | AF2028: 191215300 | AG2028: 87684270 | AH2028: 2573606000 | AI2028: 119919800 | AJ2028: 281077200
A2029: 46079 | B2029: 675701200 | C2029: 117728000 | D2029: 86166190 | E2029: 61518780 | F2029: 20442720 | G2029: 146095300 | H2029: 64258740 | I2029: 204765200 | J2029: 107333600 | L2029: 167938900 | M2029: 99946480 | N2029: 296903300 | O2029: 292942100 | P2029: 55045580 | Q2029: 95286810 | S2029: 49367400 | T2029: 1261277000 | U2029: 177970400 | V2029: 297477500 | W2029: 371173700 | X2029: 1179177000 | Y2029: 203019400 | Z2029: 74861370 | AA2029: 221096400 | AB2029: 129720200 | AC2029: 418864200 | AD2029: 34630380 | AE2029: 64915960 | AF2029: 284373400 | AG2029: 104147600 | AH2029: 2166986000 | AI2029: 172184300 | AJ2029: 235762300
A2030: 46080 | B2030: 551944100 | C2030: 239783600 | D2030: 61138830 | E2030: 61203310 | F2030: 20337350 | G2030: 173617200 | H2030: 77088650 | I2030: 183552600 | J2030: 90112490 | L2030: 160753400 | M2030: 83197020 | N2030: 415903600 | O2030: 310642900 | P2030: 54987980 | Q2030: 96320670 | S2030: 69021130 | T2030: 2093280000 | U2030: 217170800 | V2030: 202885000 | W2030: 569472800 | X2030: 1540621000 | Y2030: 82020290 | Z2030: 125669600 | AA2030: 224512200 | AB2030: 130453600 | AC2030: 694464100 | AD2030: 38220600 | AE2030: 71898460 | AF2030: 284865400 | AG2030: 132213200 | AH2030: 1538463000 | AI2030: 461045100 | AJ2030: 473477300
A2031: 46083 | B2031: 639827100 | C2031: 105873600 | D2031: 73345590 | E2031: 62619500 | F2031: 33505370 | G2031: 136174100 | H2031: 76868980 | I2031: 166894500 | J2031: 93123790 | L2031: 142815000 | M2031: 101423300 | N2031: 379571400 | O2031: 205157200 | P2031: 69261940 | Q2031: 82504520 | S2031: 48244480 | T2031: 2170973000 | U2031: 130831200 | V2031: 416915600 | W2031: 742086400 | X2031: 3434243000 | Y2031: 132626000 | Z2031: 58774070 | AA2031: 193458400 | AB2031: 98790310 | AC2031: 349599100 | AD2031: 40200420 | AE2031: 101710400 | AF2031: 130979000 | AG2031: 69366090 | AH2031: 1228084000 | AI2031: 355430100 | AJ2031: 267721600
A2032: 46084 | B2032: 1602022000 | C2032: 191783400 | D2032: 81958730 | E2032: 123784800 | F2032: 44241360 | G2032: 204430300 | H2032: 118289800 | I2032: 268327000 | J2032: 125249500 | L2032: 241401900 | M2032: 122329800 | N2032: 530548500 | O2032: 434686100 | P2032: 121811600 | Q2032: 155379000 | S2032: 163882800 | T2032: 2399694000 | U2032: 164974000 | V2032: 262875600 | W2032: 1169414000 | X2032: 3871736000 | Y2032: 114699900 | Z2032: 149970900 | AA2032: 308632900 | AB2032: 180490300 | AC2032: 625212900 | AD2032: 35207000 | AE2032: 109659000 | AF2032: 218576300 | AG2032: 92645990 | AH2032: 3029301000 | AI2032: 254838200 | AJ2032: 367620000
A2033: 46085 | B2033: 379395800 | C2033: 92175960 | D2033: 70341920 | E2033: 59209270 | F2033: 70120640 | G2033: 135237700 | H2033: 69374800 | I2033: 162353400 | J2033: 73289540 | L2033: 159520500 | M2033: 158410000 | N2033: 253660000 | O2033: 308505000 | P2033: 44469280 | Q2033: 58585870 | S2033: 46109260 | T2033: 1220662000 | U2033: 175399500 | V2033: 179565900 | W2033: 471466300 | X2033: 2053885000 | Y2033: 93027560 | Z2033: 90727700 | AA2033: 452083200 | AB2033: 90759620 | AC2033: 553538800 | AD2033: 26967900 | AE2033: 59859630 | AF2033: 138416300 | AG2033: 59399660 | AH2033: 1486111000 | AI2033: 164504000 | AJ2033: 168392500
...

Sheet z_vol
B1: log_vol | C1: center | D1: abs_dev | E1: MAD
A2: =+volume!A3 -> 43097 | B2: =+LN(volume!G3) -> 17.530126
A3: =+volume!A4 -> 43102 | B3: =+LN(volume!G4) -> 17.751878
A4: =+volume!A5 -> 43103 | B4: =+LN(volume!G5) -> 17.817562
A5: =+volume!A6 -> 43104 | B5: =+LN(volume!G6) -> 17.785135
A6: =+volume!A7 -> 43105 | B6: =+LN(volume!G7) -> 17.371368
A7: =+volume!A8 -> 43108 | B7: =+LN(volume!G8) -> 17.174063
A8: =+volume!A9 -> 43109 | B8: =+LN(volume!G9) -> 17.868674
A9: =+volume!A10 -> 43110 | B9: =+LN(volume!G10) -> 18.323562
A10: =+volume!A11 -> 43111 | B10: =+LN(volume!G11) -> 17.881977
A11: =+volume!A12 -> 43112 | B11: =+LN(volume!G12) -> 17.802937
A12: =+volume!A13 -> 43115 | B12: =+LN(volume!G13) -> 17.506692
A13: =+volume!A14 -> 43116 | B13: =+LN(volume!G14) -> 17.74542
... A30: =+volume!A31 -> 43140 | B30: =+LN(volume!G31) -> 18.097803
A31: =+volume!A32 -> 43145 | B31: =+LN(volume!G32) -> 18.132908 | C31: =+MEDIAN(B2:B31) -> 18.007725 | D31: =+ABS(B31-C31) -> 0.12518315
A32: =+volume!A33 -> 43146 | B32: =+LN(volume!G33) -> 18.8577 | C32: =+MEDIAN(B3:B32) -> 18.115356 | D32: =+ABS(B32-C32) -> 0.74234448
A33: =+volume!A34 -> 43147 | B33: =+LN(volume!G34) -> 18.570417 | C33: =+MEDIAN(B4:B33) -> 18.156654 | D33: =+ABS(B33-C33) -> 0.41376335
A34: =+volume!A35 -> 43150 | B34: =+LN(volume!G35) -> 17.929267 | C34: =+MEDIAN(B5:B34) -> 18.156654 | D34: =+ABS(B34-C34) -> 0.2273863
A35: =+volume!A36 -> 43151 | B35: =+LN(volume!G36) -> 18.368929 | C35: =+MEDIAN(B6:B35) -> 18.192086 | D35: =+ABS(B35-C35) -> 0.17684306
A36: =+volume!A37 -> 43152 | B36: =+LN(volume!G37) -> 18.590698 | C36: =+MEDIAN(B7:B36) -> 18.208972 | D36: =+ABS(B36-C36) -> 0.38172622
A37: =+volume!A38 -> 43153 | B37: =+LN(volume!G38) -> 18.446595 | C37: =+MEDIAN(B8:B37) -> 18.228399 | D37: =+ABS(B37-C37) -> 0.21819587
A38: =+volume!A39 -> 43154 | B38: =+LN(volume!G39) -> 18.312549 | C38: =+MEDIAN(B9:B38) -> 18.243246 | D38: =+ABS(B38-C38) -> 0.069302817
A39: =+volume!A40 -> 43157 | B39: =+LN(volume!G40) -> 18.49437 | C39: =+MEDIAN(B10:B39) -> 18.243246 | D39: =+ABS(B39-C39) -> 0.25112342
A40: =+volume!A41 -> 43158 | B40: =+LN(volume!G41) -> 18.413975 | C40: =+MEDIAN(B11:B40) -> 18.265875 | D40: =+ABS(B40-C40) -> 0.14810001
A41: =+volume!A42 -> 43159 | B41: =+LN(volume!G42) -> 18.538637 | C41: =+MEDIAN(B12:B41) -> 18.300217 | D41: =+ABS(B41-C41) -> 0.23842032
A42: =+volume!A43 -> 43160 | B42: =+LN(volume!G43) -> 18.190161 | C42: =+MEDIAN(B13:B42) -> 18.300217 | D42: =+ABS(B42-C42) -> 0.1100561
... A59: =+volume!A60 -> 43185 | B59: =+LN(volume!G60) -> 17.6472 | C59: =+MEDIAN(B30:B59) -> 18.296309 | D59: =+ABS(B59-C59) -> 0.64910917
A60: =+volume!A61 -> 43186 | B60: =+LN(volume!G61) -> 18.121673 | C60: =+MEDIAN(B31:B60) -> 18.296309 | D60: =+ABS(B60-C60) -> 0.17463569 | E60: =+MEDIAN(D31:D60) -> 0.25812405 | F60: =0.6745*(B60-C60)/E60 -> -0.45633785
A61: =+volume!A62 -> 43187 | B61: =+LN(volume!G62) -> 18.337191 | C61: =+MEDIAN(B32:B61) -> 18.32487 | D61: =+ABS(B61-C61) -> 0.012321012 | E61: =+MEDIAN(D32:D61) -> 0.25812405 | F61: =0.6745*(B61-C61)/E61 -> 0.032195848
A62: =+volume!A63 -> 43188 | B62: =+LN(volume!G63) -> 18.16211 | C62: =+MEDIAN(B33:B62) -> 18.296309 | D62: =+ABS(B62-C62) -> 0.13419862 | E62: =+MEDIAN(D33:D62) -> 0.24477187 | F62: =0.6745*(B62-C62)/E62 -> -0.36980135
A63: =+volume!A64 -> 43192 | B63: =+LN(volume!G64) -> 18.487348 | C63: =+MEDIAN(B34:B63) -> 18.296309 | D63: =+ABS(B63-C63) -> 0.19103938 | E63: =+MEDIAN(D34:D63) -> 0.23290331 | F63: =0.6745*(B63-C63)/E63 -> 0.55325989
A64: =+volume!A65 -> 43193 | B64: =+LN(volume!G65) -> 17.665838 | C64: =+MEDIAN(B35:B64) -> 18.296309 | D64: =+ABS(B64-C64) -> 0.63047115 | E64: =+MEDIAN(D35:D64) -> 0.24477187 | F64: =0.6745*(B64-C64)/E64 -> -1.7373434
A65: =+volume!A66 -> 43194 | B65: =+LN(volume!G66) -> 17.857885 | C65: =+MEDIAN(B36:B65) -> 18.264916 | D65: =+ABS(B65-C65) -> 0.40703068 | E65: =+MEDIAN(D36:D65) -> 0.25812405 | F65: =0.6745*(B65-C65)/E65 -> -1.0636056
A66: =+volume!A67 -> 43195 | B66: =+LN(volume!G67) -> 17.546693 | C66: =+MEDIAN(B37:B66) -> 18.229583 | D66: =+ABS(B66-C66) -> 0.68288994 | E66: =+MEDIAN(D37:D66) -> 0.25812405 | F66: =0.6745*(B66-C66)/E66 -> -1.7844492
A67: =+volume!A68 -> 43196 | B67: =+LN(volume!G68) -> 17.787972 | C67: =+MEDIAN(B38:B67) -> 18.199781 | D67: =+ABS(B67-C67) -> 0.41180954 | E67: =+MEDIAN(D38:D67) -> 0.26542115 | F67: =0.6745*(B67-C67)/E67 -> -1.0465087
A68: =+volume!A69 -> 43199 | B68: =+LN(volume!G69) -> 18.057754 | C68: =+MEDIAN(B39:B68) -> 18.176135 | D68: =+ABS(B68-C68) -> 0.11838145 | E68: =+MEDIAN(D39:D68) -> 0.26542115 | F68: =0.6745*(B68-C68)/E68 -> -0.3008362
A69: =+volume!A70 -> 43200 | B69: =+LN(volume!G70) -> 18.082964 | C69: =+MEDIAN(B40:B69) -> 18.141892 | D69: =+ABS(B69-C69) -> 0.058928044 | E69: =+MEDIAN(D40:D69) -> 0.26542115 | F69: =0.6745*(B69-C69)/E69 -> -0.14975056
A70: =+volume!A71 -> 43201 | B70: =+LN(volume!G71) -> 17.521013 | C70: =+MEDIAN(B41:B70) -> 18.102318 | D70: =+ABS(B70-C70) -> 0.58130535 | E70: =+MEDIAN(D41:D70) -> 0.28083688 | F70: =0.6745*(B70-C70)/E70 -> -1.3961502
A71: =+volume!A72 -> 43202 | B71: =+LN(volume!G72) -> 17.819108 | C71: =+MEDIAN(B42:B71) -> 18.070359 | D71: =+ABS(B71-C71) -> 0.25125116 | E71: =+MEDIAN(D42:D71) -> 0.28083688 | F71: =0.6745*(B71-C71)/E71 -> -0.60344251
... A2099: =+volume!A2100 -> 46184 | B2099: =+LN(volume!G2100) -> 18.016056 | C2099: =+MEDIAN(B2070:B2099) -> 18.848501 | D2099: =+ABS(B2099-C2099) -> 0.83244507 | E2099: =+MEDIAN(D2070:D2099) -> 0.3397419 | F2099: =0.6745*(B2099-C2099)/E2099 -> -1.6526787

Sheet Sheet3
A1: =+close!A2 -> Date | B1: =+close!B2 -> BBAS3 | D1: std_short | E1: std_long
A2: =+close!A3 -> 43097 | B2: =+close!B3 -> 15.91
A3: =+close!A4 -> 43102 | B3: =+close!B4 -> 16.465 | C3: =+B3/B2-1 -> 0.034883721
A4: =+close!A5 -> 43103 | B4: =+close!B5 -> 16.675 | C4: =+B4/B3-1 -> 0.012754327
A5: =+close!A6 -> 43104 | B5: =+close!B6 -> 16.835 | C5: =+B5/B4-1 -> 0.0095952024
A6: =+close!A7 -> 43105 | B6: =+close!B7 -> 16.835 | C6: =+B6/B5-1 -> 0
A7: =+close!A8 -> 43108 | B7: =+close!B8 -> 16.875 | C7: =+B7/B6-1 -> 0.0023760024 | D7: =+_xlfn.STDEV.P(C3:C7) -> 0.012382306
A8: =+close!A9 -> 43109 | B8: =+close!B9 -> 16.715 | C8: =+B8/B7-1 -> -0.0094814815 | D8: =+_xlfn.STDEV.P(C4:C8) -> 0.0077949784
A9: =+close!A10 -> 43110 | B9: =+close!B10 -> 16.645 | C9: =+B9/B8-1 -> -0.0041878552 | D9: =+_xlfn.STDEV.P(C5:C9) -> 0.0063964551
A10: =+close!A11 -> 43111 | B10: =+close!B11 -> 17.025 | C10: =+B10/B9-1 -> 0.022829679 | D10: =+_xlfn.STDEV.P(C6:C10) -> 0.011024144
A11: =+close!A12 -> 43112 | B11: =+close!B12 -> 17.065 | C11: =+B11/B10-1 -> 0.002349486 | D11: =+_xlfn.STDEV.P(C7:C11) -> 0.010965702
A12: =+close!A13 -> 43115 | B12: =+close!B13 -> 17.15 | C12: =+B12/B11-1 -> 0.0049809552 | D12: =+_xlfn.STDEV.P(C8:C12) -> 0.010996105
A13: =+close!A14 -> 43116 | B13: =+close!B14 -> 17.3 | C13: =+B13/B12-1 -> 0.0087463557 | D13: =+_xlfn.STDEV.P(C9:C13) -> 0.0089942712
A14: =+close!A15 -> 43117 | B14: =+close!B15 -> 17.71 | C14: =+B14/B13-1 -> 0.023699422 | D14: =+_xlfn.STDEV.P(C10:C14) -> 0.0090087278
A15: =+close!A16 -> 43118 | B15: =+close!B16 -> 17.59 | C15: =+B15/B14-1 -> -0.0067758329 | D15: =+_xlfn.STDEV.P(C11:C15) -> 0.0099659235
A16: =+close!A17 -> 43119 | B16: =+close!B17 -> 17.475 | C16: =+B16/B15-1 -> -0.0065378056 | D16: =+_xlfn.STDEV.P(C12:C16) -> 0.011272425
A17: =+close!A18 -> 43122 | B17: =+close!B18 -> 17.535 | C17: =+B17/B16-1 -> 0.0034334764 | D17: =+_xlfn.STDEV.P(C13:C17) -> 0.011285065
A18: =+close!A19 -> 43123 | B18: =+close!B19 -> 17.6 | C18: =+B18/B17-1 -> 0.003706872 | D18: =+_xlfn.STDEV.P(C14:C18) -> 0.011085252
... A2099: =+close!A2100 -> 46184 | B2099: =+close!B2100 -> 34.216 | C2099: =+B2099/B2098-1 -> 0.0078944268 | D2099: =+_xlfn.STDEV.P(C2095:C2099) -> 0.0086405175
