Workbook

Sheet Resumen
A1: MODELO DE PBI — PBI BR, EMBI, M1R
A2: Muestra comun 2007Q1-2026Q1 (n=77) en los tres modelos.
A4: Metrica | B4: BASE (EMBI en nivel) | C4: NUEVO (D4log) | D4: NUEVO + dummies COVID
A5: n | B5: =Modelo_Base!B96 -> 77 | C5: =Modelo_Nuevo!B95 -> 77 | D5: =Modelo_COVID!B97 -> 77
A6: k (parametros) | B6: =Modelo_Base!B97 -> 5 | C6: =Modelo_Nuevo!B96 -> 4 | D6: =Modelo_COVID!B98 -> 6
A7: R2 | B7: =Modelo_Base!B98 -> 0.66165713 | C7: =Modelo_Nuevo!B97 -> 0.73307957 | D7: =Modelo_COVID!B99 -> 0.75960653
A8: R2 ajustado | B8: =Modelo_Base!B99 -> 0.64286031 | C8: =Modelo_Nuevo!B98 -> 0.72211024 | D8: =Modelo_COVID!B100 -> 0.74267741
A9: SSR | B9: =Modelo_Base!B100 -> 0.095000423 | C9: =Modelo_Nuevo!B99 -> 0.074946323 | D9: =Modelo_COVID!B101 -> 0.067498042
A10: AIC | B10: =Modelo_Base!B102 -> -287.20478 | C10: =Modelo_Nuevo!B101 -> -307.46218 | D10: =Modelo_COVID!B103 -> -311.52205
A11: BIC | B11: =Modelo_Base!B103 -> -275.48575 | C11: =Modelo_Nuevo!B102 -> -298.08696 | D11: =Modelo_COVID!B104 -> -297.45922
A12: Durbin-Watson | B12: =Modelo_Base!B105 -> 0.63378658 | C12: =Modelo_Nuevo!B104 -> 0.75726826 | D12: =Modelo_COVID!B106 -> 0.90246402
A13: Breusch-Pagan p | B13: =Diagnosticos!E19 -> 0.0049901339 | C13: =Diagnosticos!E20 -> 0.020126596 | D13: =Diagnosticos!E21 -> 0.2609386
A15: Restriccion implicita del modelo base
A16: H0: beta_EMBI(t) + beta_EMBI(t-6) = 0
A17: F | B17: =Modelo_Base!B113 -> 0.40013046 | C17: No rechazar implica que los dos terminos de EMBI en nivel son, de hecho, una diferencia.
A18: p-valor | B18: =Modelo_Base!B114 -> 0.52902569
A20: Test F de las dummies COVID (H0: ambas = 0)
A21: F | B21: =Modelo_COVID!B189 -> 3.9173575 | C21: Caso limite: el BIC prefiere NO poner dummies, el AIC prefiere ponerlas. El argumento a favor es que sin ellas el coeficiente de M1R queda sesgado a la baja y persiste heterocedasticidad.
A22: p-valor | B22: =Modelo_COVID!B190 -> 0.024333247
A24: Coeficientes del modelo con dummies, errores HAC (Newey-West, L=4)
A25: Regresor | B25: Coef. | C25: se HAC | D25: t HAC | E25: p HAC
A26: =Modelo_COVID!A175 -> const | B26: =Modelo_COVID!B175 -> 0.00021985685 | C26: =Modelo_COVID!C175 -> 0.0074836232 | D26: =Modelo_COVID!D175 -> 0.029378397 | E26: =Modelo_COVID!E175 -> 0.97664523
A27: =Modelo_COVID!A176 -> PBI BR (t) | B27: =Modelo_COVID!B176 -> 0.8985969 | C27: =Modelo_COVID!C176 -> 0.19728512 | D27: =Modelo_COVID!D176 -> 4.5548134 | E27: =Modelo_COVID!E176 -> 2.1229437e-05
A28: =Modelo_COVID!A177 -> D4lnEMBI (t-2) | B28: =Modelo_COVID!B177 -> -0.045785174 | C28: =Modelo_COVID!C177 -> 0.0089357708 | D28: =Modelo_COVID!D177 -> -5.1238079 | E28: =Modelo_COVID!E177 -> 2.4736762e-06
A29: =Modelo_COVID!A178 -> M1R (t) | B29: =Modelo_COVID!B178 -> 0.10860046 | C29: =Modelo_COVID!C178 -> 0.036487995 | D29: =Modelo_COVID!D178 -> 2.976334 | E29: =Modelo_COVID!E178 -> 0.0039864433
A30: =Modelo_COVID!A179 -> D_2020Q2 | B30: =Modelo_COVID!B179 -> -0.079176941 | C30: =Modelo_COVID!C179 -> 0.031880776 | D30: =Modelo_COVID!D179 -> -2.4835325 | E30: =Modelo_COVID!E179 -> 0.015371532
A31: =Modelo_COVID!A180 -> D_2021Q2 | B31: =Modelo_COVID!B180 -> 0.070138162 | C31: =Modelo_COVID!C180 -> 0.022534011 | D31: =Modelo_COVID!D180 -> 3.1125467 | E31: =Modelo_COVID!E180 -> 0.0026725825
A33: COMO USAR ESTE ARCHIVO
A34: 1. Editable solo lo azul de la hoja Datos (EMBI, PBI BR, M1R, PBI). Todo lo demas es formula.
A35: 2. Para agregar un trimestre: extender las filas de Datos y de cada hoja de modelo, y recalcular.
A36: 3. Las regresiones usan INDEX(LINEST(...)) para devolver escalares, sin formulas matriciales.
A37: 4. AIC y BIC siguen la convencion de statsmodels: -2logL + 2k y -2logL + ln(n)k.
A38: 5. Cita los errores HAC, no los de LINEST.

Sheet Datos
A1: DATOS Y TRANSFORMACIONES
A2: Azul = dato original (editable). Negro = formula. Trimestral 2005Q1-2026Q1.
A3: PBI, PBI de Brasil y M1R ya vienen como variacion interanual (I(0)). EMBI viene en NIVEL (I(1)): se le aplica D4log(.), el mismo filtro que tiene la dependiente, para balancear la regresion.
A4: Periodo | B4: EMBI (pb) | C4: PBI BR | D4: M1R | E4: PBI (dep.) | G4: ln(EMBI) | H4: D4 ln EMBI
A5: 2005Q1 | C5: 0.0419 | D5: 0.16600162 | E5: 0.072187868 | G5: =IF(ISNUMBER(B5),LN(B5),"")
A6: 2005Q2 | C6: 0.0447 | D6: 0.17034803 | E6: 0.13077981 | G6: =IF(ISNUMBER(B6),LN(B6),"")
A7: 2005Q3 | B7: 413.72934 | C7: 0.0211 | D7: 0.095469669 | E7: 0.069719779 | G7: =IF(ISNUMBER(B7),LN(B7),"") -> 6.025212
A8: 2005Q4 | B8: 423.41625 | C8: 0.0215 | D8: 0.10753949 | E8: 0.077828945 | G8: =IF(ISNUMBER(B8),LN(B8),"") -> 6.0483557
A9: 2006Q1 | B9: 394.41518 | C9: 0.0428 | D9: 0.065572691 | E9: 0.078495711 | G9: =IF(ISNUMBER(B9),LN(B9),"") -> 5.9774041 | H9: =IF(AND(ISNUMBER(G9),ISNUMBER(G5)),G9-G5,"")
A10: 2006Q2 | B10: 353.71381 | C10: 0.0228 | D10: 0.074826081 | E10: 0.055715853 | G10: =IF(ISNUMBER(B10),LN(B10),"") -> 5.8684881 | H10: =IF(AND(ISNUMBER(G10),ISNUMBER(G6)),G10-G6,"")
A11: 2006Q3 | B11: 339.04529 | C11: 0.0449 | D11: 0.0729218 | E11: 0.093804903 | G11: =IF(ISNUMBER(B11),LN(B11),"") -> 5.8261337 | H11: =IF(AND(ISNUMBER(G11),ISNUMBER(G7)),G11-G7,"") -> -0.19907832
A12: 2006Q4 | B12: 281.70526 | C12: 0.048 | D12: 0.082156516 | E12: 0.096770404 | G12: =IF(ISNUMBER(B12),LN(B12),"") -> 5.6408613 | H12: =IF(AND(ISNUMBER(G12),ISNUMBER(G8)),G12-G8,"") -> -0.40749439
A13: 2007Q1 | B13: 210.27944 | C13: 0.052 | D13: 0.10364673 | E13: 0.083589411 | G13: =IF(ISNUMBER(B13),LN(B13),"") -> 5.3484373 | H13: =IF(AND(ISNUMBER(G13),ISNUMBER(G9)),G13-G9,"") -> -0.62896681
A14: 2007Q2 | B14: 268.38567 | C14: 0.0654 | D14: 0.10878117 | E14: 0.098593874 | G14: =IF(ISNUMBER(B14),LN(B14),"") -> 5.592425 | H14: =IF(AND(ISNUMBER(G14),ISNUMBER(G10)),G14-G10,"") -> -0.27606314
A15: 2007Q3 | B15: 415.12806 | C15: 0.0587 | D15: 0.095031538 | E15: 0.084277977 | G15: =IF(ISNUMBER(B15),LN(B15),"") -> 6.0285871 | H15: =IF(AND(ISNUMBER(G15),ISNUMBER(G11)),G15-G11,"") -> 0.20245337
A16: 2007Q4 | B16: 386.90139 | C16: 0.0664 | D16: 0.03479478 | E16: 0.092673486 | G16: =IF(ISNUMBER(B16),LN(B16),"") -> 5.9581698 | H16: =IF(AND(ISNUMBER(G16),ISNUMBER(G12)),G16-G12,"") -> 0.31730851
A17: 2008Q1 | B17: 482.23843 | C17: 0.0616 | D17: 0.0060995986 | E17: 0.069123146 | G17: =IF(ISNUMBER(B17),LN(B17),"") -> 6.1784387 | H17: =IF(AND(ISNUMBER(G17),ISNUMBER(G13)),G17-G13,"") -> 0.83000136
A18: 2008Q2 | B18: 556.6532 | C18: 0.0634 | D18: -0.032825593 | E18: 0.054526855 | G18: =IF(ISNUMBER(B18),LN(B18),"") -> 6.3219424 | H18: =IF(AND(ISNUMBER(G18),ISNUMBER(G14)),G18-G14,"") -> 0.72951743
A19: 2008Q3 | B19: 696.82717 | C19: 0.0698 | D19: -0.01260622 | E19: 0.060060161 | G19: =IF(ISNUMBER(B19),LN(B19),"") -> 6.5465374 | H19: =IF(AND(ISNUMBER(G19),ISNUMBER(G15)),G19-G15,"") -> 0.51795036
A20: 2008Q4 | B20: 1696.5902 | C20: 0.0102 | D20: 0.0082101847 | E20: -0.019789909 | G20: =IF(ISNUMBER(B20),LN(B20),"") -> 7.4363758 | H20: =IF(AND(ISNUMBER(G20),ISNUMBER(G16)),G20-G16,"") -> 1.4782059
... A89: 2026Q1 | B89: 536.22222 | C89: 0.0182 | D89: -0.030260826 | E89: 0.024694045 | G89: =IF(ISNUMBER(B89),LN(B89),"") -> 6.2845487 | H89: =IF(AND(ISNUMBER(G89),ISNUMBER(G85)),G89-G85,"") -> -0.24419616
B91: EMBI 2005Q1-Q2 venia codificado como 0 en el origen: es un faltante, no un dato.

Sheet Modelo_Base
A1: MODELO BASE — PBI ~ PBI BR(t) + EMBI(t) + M1R(t) + EMBI(t-6)
A2: EMBI entra en NIVEL en los dos terminos: regresion no balanceada (I(1) contra I(0)). Muestra comun 2007Q1-2026Q1 (n=77).
A5: Periodo | B5: y = PBI | C5: PBI BR (t) | D5: EMBI (t) | E5: M1R (t) | F5: EMBI (t-6) | G5: const=1 | H5: residuo e | I5: e^2 | L5: R: PBI BR(t) | M5: R: EMBI(t)-EMBI(t-6) | N5: R: M1R(t)
A6: =Datos!A13 -> 2007Q1 | B6: =Datos!E13 -> 0.083589411 | C6: =Datos!C13 -> 0.052 | D6: =Datos!B13 -> 210.27944 | E6: =Datos!D13 -> 0.10364673 | F6: =Datos!B7 -> 413.72934 | G6: 1 | H6: =B6-($B$89+$B$90*C6+$B$91*D6+$B$92*E6+$B$93*F6) -> 0.014180359 | I6: =H6^2 -> 0.00020108259 | L6: =C6 -> 0.052 | M6: =D6-F6 -> -203.44991 | N6: =E6 -> 0.10364673
A7: =Datos!A14 -> 2007Q2 | B7: =Datos!E14 -> 0.098593874 | C7: =Datos!C14 -> 0.0654 | D7: =Datos!B14 -> 268.38567 | E7: =Datos!D14 -> 0.10878117 | F7: =Datos!B8 -> 423.41625 | G7: 1 | H7: =B7-($B$89+$B$90*C7+$B$91*D7+$B$92*E7+$B$93*F7) -> 0.015792798 | I7: =H7^2 -> 0.00024941246 | L7: =C7 -> 0.0654 | M7: =D7-F7 -> -155.03058 | N7: =E7 -> 0.10878117
A8: =Datos!A15 -> 2007Q3 | B8: =Datos!E15 -> 0.084277977 | C8: =Datos!C15 -> 0.0587 | D8: =Datos!B15 -> 415.12806 | E8: =Datos!D15 -> 0.095031538 | F8: =Datos!B9 -> 394.41518 | G8: 1 | H8: =B8-($B$89+$B$90*C8+$B$91*D8+$B$92*E8+$B$93*F8) -> 0.014975325 | I8: =H8^2 -> 0.00022426035 | L8: =C8 -> 0.0587 | M8: =D8-F8 -> 20.712886 | N8: =E8 -> 0.095031538
A9: =Datos!A16 -> 2007Q4 | B9: =Datos!E16 -> 0.092673486 | C9: =Datos!C16 -> 0.0664 | D9: =Datos!B16 -> 386.90139 | E9: =Datos!D16 -> 0.03479478 | F9: =Datos!B10 -> 353.71381 | G9: 1 | H9: =B9-($B$89+$B$90*C9+$B$91*D9+$B$92*E9+$B$93*F9) -> 0.02036821 | I9: =H9^2 -> 0.00041486399 | L9: =C9 -> 0.0664 | M9: =D9-F9 -> 33.187578 | N9: =E9 -> 0.03479478
A10: =Datos!A17 -> 2008Q1 | B10: =Datos!E17 -> 0.069123146 | C10: =Datos!C17 -> 0.0616 | D10: =Datos!B17 -> 482.23843 | E10: =Datos!D17 -> 0.0060995986 | F10: =Datos!B11 -> 339.04529 | G10: 1 | H10: =B10-($B$89+$B$90*C10+$B$91*D10+$B$92*E10+$B$93*F10) -> 0.0076469608 | I10: =H10^2 -> 5.847601e-05 | L10: =C10 -> 0.0616 | M10: =D10-F10 -> 143.19314 | N10: =E10 -> 0.0060995986
A11: =Datos!A18 -> 2008Q2 | B11: =Datos!E18 -> 0.054526855 | C11: =Datos!C18 -> 0.0634 | D11: =Datos!B18 -> 556.6532 | E11: =Datos!D18 -> -0.032825593 | F11: =Datos!B12 -> 281.70526 | G11: 1 | H11: =B11-($B$89+$B$90*C11+$B$91*D11+$B$92*E11+$B$93*F11) -> -0.001924534 | I11: =H11^2 -> 3.7038311e-06 | L11: =C11 -> 0.0634 | M11: =D11-F11 -> 274.94795 | N11: =E11 -> -0.032825593
A12: =Datos!A19 -> 2008Q3 | B12: =Datos!E19 -> 0.060060161 | C12: =Datos!C19 -> 0.0698 | D12: =Datos!B19 -> 696.82717 | E12: =Datos!D19 -> -0.01260622 | F12: =Datos!B13 -> 210.27944 | G12: 1 | H12: =B12-($B$89+$B$90*C12+$B$91*D12+$B$92*E12+$B$93*F12) -> 0.00095623987 | I12: =H12^2 -> 9.143947e-07 | L12: =C12 -> 0.0698 | M12: =D12-F12 -> 486.54774 | N12: =E12 -> -0.01260622
A13: =Datos!A20 -> 2008Q4 | B13: =Datos!E20 -> -0.019789909 | C13: =Datos!C20 -> 0.0102 | D13: =Datos!B20 -> 1696.5902 | E13: =Datos!D20 -> 0.0082101847 | F13: =Datos!B14 -> 268.38567 | G13: 1 | H13: =B13-($B$89+$B$90*C13+$B$91*D13+$B$92*E13+$B$93*F13) -> 0.011986646 | I13: =H13^2 -> 0.00014367969 | L13: =C13 -> 0.0102 | M13: =D13-F13 -> 1428.2046 | N13: =E13 -> 0.0082101847
A14: =Datos!A21 -> 2009Q1 | B14: =Datos!E21 -> -0.061887551 | C14: =Datos!C21 -> -0.0242 | D14: =Datos!B21 -> 1700.0604 | E14: =Datos!D21 -> -0.029228652 | F14: =Datos!B15 -> 415.12806 | G14: 1 | H14: =B14-($B$89+$B$90*C14+$B$91*D14+$B$92*E14+$B$93*F14) -> 0.0066024794 | I14: =H14^2 -> 4.3592734e-05 | L14: =C14 -> -0.0242 | M14: =D14-F14 -> 1284.9323 | N14: =E14 -> -0.029228652
A15: =Datos!A22 -> 2009Q2 | B15: =Datos!E22 -> -0.11274547 | C15: =Datos!C22 -> -0.022 | D15: =Datos!B22 -> 1455.6592 | E15: =Datos!D22 -> -0.073032733 | F15: =Datos!B16 -> 386.90139 | G15: 1 | H15: =B15-($B$89+$B$90*C15+$B$91*D15+$B$92*E15+$B$93*F15) -> -0.049490702 | I15: =H15^2 -> 0.0024493296 | L15: =C15 -> -0.022 | M15: =D15-F15 -> 1068.7578 | N15: =E15 -> -0.073032733
A16: =Datos!A23 -> 2009Q3 | B16: =Datos!E23 -> -0.0565118 | C16: =Datos!C23 -> -0.0116 | D16: =Datos!B23 -> 921.66961 | E16: =Datos!D23 -> -0.04586153 | F16: =Datos!B17 -> 482.23843 | G16: 1 | H16: =B16-($B$89+$B$90*C16+$B$91*D16+$B$92*E16+$B$93*F16) -> -0.025103065 | I16: =H16^2 -> 0.00063016386 | L16: =C16 -> -0.0116 | M16: =D16-F16 -> 439.43118 | N16: =E16 -> -0.04586153
A17: =Datos!A24 -> 2009Q4 | B17: =Datos!E24 -> 0.0028199823 | C17: =Datos!C24 -> 0.0533 | D17: =Datos!B24 -> 717.92377 | E17: =Datos!D24 -> -0.051628665 | F17: =Datos!B18 -> 556.6532 | G17: 1 | H17: =B17-($B$89+$B$90*C17+$B$91*D17+$B$92*E17+$B$93*F17) -> -0.04319535 | I17: =H17^2 -> 0.0018658383 | L17: =C17 -> 0.0533 | M17: =D17-F17 -> 161.27057 | N17: =E17 -> -0.051628665
... A82: =Datos!A89 -> 2026Q1 | B82: =Datos!E89 -> 0.024694045 | C82: =Datos!C89 -> 0.0182 | D82: =Datos!B89 -> 536.22222 | E82: =Datos!D89 -> -0.030260826 | F82: =Datos!B83 -> 1484.5455 | G82: 1 | H82: =B82-($B$89+$B$90*C82+$B$91*D82+$B$92*E82+$B$93*F82) -> -0.013895261 | I82: =H82^2 -> 0.00019307827 | L82: =C82 -> 0.0182 | M82: =D82-F82 -> -948.32323 | N82: =E82 -> -0.030260826
A87: A. ESTIMACION OLS (LINEST devuelve los coeficientes en orden inverso; se extraen con INDEX)
A88: Regresor | B88: Coef. | C88: Error est. | D88: t | E88: p-valor | G88: gl resid. | H88: =INDEX(LINEST($B$6:$B$82,$C$6:$F$82,TRUE(),TRUE()),4,2) -> 72
A89: const | B89: =INDEX(LINEST($B$6:$B$82,$C$6:$F$82,TRUE(),TRUE()),1,5) -> 0.00046745153 | C89: =INDEX(LINEST($B$6:$B$82,$C$6:$F$82,TRUE(),TRUE()),2,5) -> 0.0092901089 | D89: =B89/C89 -> 0.050317121 | E89: =TDIST(ABS(D89),$H$88,2) -> 0.96000901
A90: PBI BR (t) | B90: =INDEX(LINEST($B$6:$B$82,$C$6:$F$82,TRUE(),TRUE()),1,4) -> 1.0781853 | C90: =INDEX(LINEST($B$6:$B$82,$C$6:$F$82,TRUE(),TRUE()),2,4) -> 0.12415468 | D90: =B90/C90 -> 8.6842098 | E90: =TDIST(ABS(D90),$H$88,2) -> 8.0962874e-13
A91: EMBI (t) | B91: =INDEX(LINEST($B$6:$B$82,$C$6:$F$82,TRUE(),TRUE()),1,3) -> -2.9850252e-05 | C91: =INDEX(LINEST($B$6:$B$82,$C$6:$F$82,TRUE(),TRUE()),2,3) -> 7.081004e-06 | D91: =B91/C91 -> -4.2155395 | E91: =TDIST(ABS(D91),$H$88,2) -> 7.1345168e-05
A92: M1R (t) | B92: =INDEX(LINEST($B$6:$B$82,$C$6:$F$82,TRUE(),TRUE()),1,2) -> 0.085086964 | C92: =INDEX(LINEST($B$6:$B$82,$C$6:$F$82,TRUE(),TRUE()),2,2) -> 0.030209072 | D92: =B92/C92 -> 2.816603 | E92: =TDIST(ABS(D92),$H$88,2) -> 0.0062588178
A93: EMBI (t-6) | B93: =INDEX(LINEST($B$6:$B$82,$C$6:$F$82,TRUE(),TRUE()),1,1) -> 2.4977378e-05 | C93: =INDEX(LINEST($B$6:$B$82,$C$6:$F$82,TRUE(),TRUE()),2,1) -> 6.8944462e-06 | D93: =B93/C93 -> 3.6228259 | E93: =TDIST(ABS(D93),$H$88,2) -> 0.00053937701
A95: B. BONDAD DE AJUSTE
A96: n (observaciones) | B96: =COUNT($B$6:$B$82) -> 77
A97: k (parametros) | B97: 5
A98: R2 | B98: =INDEX(LINEST($B$6:$B$82,$C$6:$F$82,TRUE(),TRUE()),3,1) -> 0.66165713
A99: R2 ajustado | B99: =1-(1-B98)*(B96-1)/(B96-B97) -> 0.64286031
A100: SSR | B100: =INDEX(LINEST($B$6:$B$82,$C$6:$F$82,TRUE(),TRUE()),5,2) -> 0.095000423
A101: log-verosimilitud | B101: =-B96/2*(LN(2*PI())+LN(B100/B96)+1) -> 148.60239
A102: AIC | B102: =-2*B101+2*B97 -> -287.20478
A103: BIC | B103: =-2*B101+LN(B96)*B97 -> -275.48575
A105: Durbin-Watson | B105: =SUMXMY2(H7:H82,H6:H81)/SUMSQ(H6:H82) -> 0.63378658
A107: C. TEST F: H0 = beta_EMBI(t) + beta_EMBI(t-6) = 0
A108: Si no se rechaza, los dos terminos en nivel son de hecho UNA diferencia: EMBI(t)-EMBI(t-6).
A109: SSR irrestricto | B109: =B100 -> 0.095000423
A110: SSR restringido | B110: =INDEX(LINEST($B$6:$B$82,$L$6:$N$82,TRUE(),TRUE()),5,2) -> 0.095528375
A111: q (restricciones) | B111: 1
A112: gl residuales | B112: =$H$88 -> 72
A113: F | B113: =((B110-B109)/B111)/(B109/B112) -> 0.40013046
...

Sheet Modelo_Nuevo
A1: MODELO PROPUESTO — PBI ~ PBI BR(t) + D4lnEMBI(t-2) + M1R(t)
A2: EMBI bajo el mismo filtro D4log(.) que la dependiente y colapsado a un solo rezago. Minimo BIC entre 1.782 combinaciones (subconjuntos de hasta 2 rezagos de EMBI x rezagos 0-8 de PBI BR y M1R).
A5: Periodo | B5: y = PBI | C5: PBI BR (t) | D5: D4lnEMBI (t-2) | E5: M1R (t) | F5: const=1 | G5: residuo e | H5: e^2 | I5: h_0 | J5: h_1 | K5: h_2 | L5: h_3
A6: =Datos!A13 -> 2007Q1 | B6: =Datos!E13 -> 0.083589411 | C6: =Datos!C13 -> 0.052 | D6: =Datos!H11 -> -0.19907832 | E6: =Datos!D13 -> 0.10364673 | F6: 1 | G6: =B6-($B$89+$B$90*C6+$B$91*D6+$B$92*E6) -> 0.012813284 | H6: =G6^2 -> 0.00016418024 | I6: =F6*$G6 -> 0.012813284 | J6: =C6*$G6 -> 0.00066629075 | K6: =D6*$G6 -> -0.0025508469 | L6: =E6*$G6 -> 0.001328055
A7: =Datos!A14 -> 2007Q2 | B7: =Datos!E14 -> 0.098593874 | C7: =Datos!C14 -> 0.0654 | D7: =Datos!H12 -> -0.40749439 | E7: =Datos!D14 -> 0.10878117 | F7: 1 | G7: =B7-($B$89+$B$90*C7+$B$91*D7+$B$92*E7) -> 0.0030092172 | H7: =G7^2 -> 9.0553884e-06 | I7: =F7*$G7 -> 0.0030092172 | J7: =C7*$G7 -> 0.00019680281 | K7: =D7*$G7 -> -0.0012262391 | L7: =E7*$G7 -> 0.00032734616
A8: =Datos!A15 -> 2007Q3 | B8: =Datos!E15 -> 0.084277977 | C8: =Datos!C15 -> 0.0587 | D8: =Datos!H13 -> -0.62896681 | E8: =Datos!D15 -> 0.095031538 | F8: 1 | G8: =B8-($B$89+$B$90*C8+$B$91*D8+$B$92*E8) -> -0.013750171 | H8: =G8^2 -> 0.00018906721 | I8: =F8*$G8 -> -0.013750171 | J8: =C8*$G8 -> -0.00080713505 | K8: =D8*$G8 -> 0.0086484013 | L8: =E8*$G8 -> -0.0013066999
A9: =Datos!A16 -> 2007Q4 | B9: =Datos!E16 -> 0.092673486 | C9: =Datos!C16 -> 0.0664 | D9: =Datos!H14 -> -0.27606314 | E9: =Datos!D16 -> 0.03479478 | F9: 1 | G9: =B9-($B$89+$B$90*C9+$B$91*D9+$B$92*E9) -> 0.0089992853 | H9: =G9^2 -> 8.0987136e-05 | I9: =F9*$G9 -> 0.0089992853 | J9: =C9*$G9 -> 0.00059755254 | K9: =D9*$G9 -> -0.0024843709 | L9: =E9*$G9 -> 0.00031312815
A10: =Datos!A17 -> 2008Q1 | B10: =Datos!E17 -> 0.069123146 | C10: =Datos!C17 -> 0.0616 | D10: =Datos!H15 -> 0.20245337 | E10: =Datos!D17 -> 0.0060995986 | F10: 1 | G10: =B10-($B$89+$B$90*C10+$B$91*D10+$B$92*E10) -> 0.016368149 | H10: =G10^2 -> 0.00026791631 | I10: =F10*$G10 -> 0.016368149 | J10: =C10*$G10 -> 0.001008278 | K10: =D10*$G10 -> 0.0033137871 | L10: =E10*$G10 -> 9.9839141e-05
A11: =Datos!A18 -> 2008Q2 | B11: =Datos!E18 -> 0.054526855 | C11: =Datos!C18 -> 0.0634 | D11: =Datos!H16 -> 0.31730851 | E11: =Datos!D18 -> -0.032825593 | F11: 1 | G11: =B11-($B$89+$B$90*C11+$B$91*D11+$B$92*E11) -> 0.0089101538 | H11: =G11^2 -> 7.939084e-05 | I11: =F11*$G11 -> 0.0089101538 | J11: =C11*$G11 -> 0.00056490375 | K11: =D11*$G11 -> 0.0028272676 | L11: =E11*$G11 -> -0.00029248108
A12: =Datos!A19 -> 2008Q3 | B12: =Datos!E19 -> 0.060060161 | C12: =Datos!C19 -> 0.0698 | D12: =Datos!H17 -> 0.83000136 | E12: =Datos!D19 -> -0.01260622 | F12: 1 | G12: =B12-($B$89+$B$90*C12+$B$91*D12+$B$92*E12) -> 0.030795704 | H12: =G12^2 -> 0.00094837538 | I12: =F12*$G12 -> 0.030795704 | J12: =C12*$G12 -> 0.0021495401 | K12: =D12*$G12 -> 0.025560476 | L12: =E12*$G12 -> -0.00038821741
A13: =Datos!A20 -> 2008Q4 | B13: =Datos!E20 -> -0.019789909 | C13: =Datos!C20 -> 0.0102 | D13: =Datos!H18 -> 0.72951743 | E13: =Datos!D20 -> 0.0082101847 | F13: 1 | G13: =B13-($B$89+$B$90*C13+$B$91*D13+$B$92*E13) -> 0.0074280557 | H13: =G13^2 -> 5.5176012e-05 | I13: =F13*$G13 -> 0.0074280557 | J13: =C13*$G13 -> 7.5766169e-05 | K13: =D13*$G13 -> 0.0054188961 | L13: =E13*$G13 -> 6.0985709e-05
A14: =Datos!A21 -> 2009Q1 | B14: =Datos!E21 -> -0.061887551 | C14: =Datos!C21 -> -0.0242 | D14: =Datos!H19 -> 0.51795036 | E14: =Datos!D21 -> -0.029228652 | F14: 1 | G14: =B14-($B$89+$B$90*C14+$B$91*D14+$B$92*E14) -> -0.0051421654 | H14: =G14^2 -> 2.6441865e-05 | I14: =F14*$G14 -> -0.0051421654 | J14: =C14*$G14 -> 0.0001244404 | K14: =D14*$G14 -> -0.0026633864 | L14: =E14*$G14 -> 0.00015029856
A15: =Datos!A22 -> 2009Q2 | B15: =Datos!E22 -> -0.11274547 | C15: =Datos!C22 -> -0.022 | D15: =Datos!H20 -> 1.4782059 | E15: =Datos!D22 -> -0.073032733 | F15: 1 | G15: =B15-($B$89+$B$90*C15+$B$91*D15+$B$92*E15) -> -0.0077297713 | H15: =G15^2 -> 5.9749364e-05 | I15: =F15*$G15 -> -0.0077297713 | J15: =C15*$G15 -> 0.00017005497 | K15: =D15*$G15 -> -0.011426194 | L15: =E15*$G15 -> 0.00056452632
A16: =Datos!A23 -> 2009Q3 | B16: =Datos!E23 -> -0.0565118 | C16: =Datos!C23 -> -0.0116 | D16: =Datos!H21 -> 1.2599804 | E16: =Datos!D23 -> -0.04586153 | F16: 1 | G16: =B16-($B$89+$B$90*C16+$B$91*D16+$B$92*E16) -> 0.024441216 | H16: =G16^2 -> 0.00059737303 | I16: =F16*$G16 -> 0.024441216 | J16: =C16*$G16 -> -0.0002835181 | K16: =D16*$G16 -> 0.030795453 | L16: =E16*$G16 -> -0.0011209116
A17: =Datos!A24 -> 2009Q4 | B17: =Datos!E24 -> 0.0028199823 | C17: =Datos!C24 -> 0.0533 | D17: =Datos!H22 -> 0.9612717 | E17: =Datos!D24 -> -0.051628665 | F17: 1 | G17: =B17-($B$89+$B$90*C17+$B$91*D17+$B$92*E17) -> 0.00091276122 | H17: =G17^2 -> 8.3313304e-07 | I17: =F17*$G17 -> 0.00091276122 | J17: =C17*$G17 -> 4.8650173e-05 | K17: =D17*$G17 -> 0.00087741153 | L17: =E17*$G17 -> -4.7124643e-05
... A82: =Datos!A89 -> 2026Q1 | B82: =Datos!E89 -> 0.024694045 | C82: =Datos!C89 -> 0.0182 | D82: =Datos!H87 -> -0.53880137 | E82: =Datos!D89 -> -0.030260826 | F82: 1 | G82: =B82-($B$89+$B$90*C82+$B$91*D82+$B$92*E82) -> -0.014848045 | H82: =G82^2 -> 0.00022046444 | I82: =F82*$G82 -> -0.014848045 | J82: =C82*$G82 -> -0.00027023442 | K82: =D82*$G82 -> 0.008000147 | L82: =E82*$G82 -> 0.00044931411
A87: A. ESTIMACION OLS (LINEST devuelve los coeficientes en orden inverso; se extraen con INDEX)
A88: Regresor | B88: Coef. | C88: Error est. | D88: t | E88: p-valor | G88: gl resid. | H88: =INDEX(LINEST($B$6:$B$82,$C$6:$E$82,TRUE(),TRUE()),4,2) -> 73
A89: const | B89: =INDEX(LINEST($B$6:$B$82,$C$6:$E$82,TRUE(),TRUE()),1,4) -> -0.0032819381 | C89: =INDEX(LINEST($B$6:$B$82,$C$6:$E$82,TRUE(),TRUE()),2,4) -> 0.0042980763 | D89: =B89/C89 -> -0.76358304 | E89: =TDIST(ABS(D89),$H$88,2) -> 0.44757662
A90: PBI BR (t) | B90: =INDEX(LINEST($B$6:$B$82,$C$6:$E$82,TRUE(),TRUE()),1,3) -> 1.0607549 | C90: =INDEX(LINEST($B$6:$B$82,$C$6:$E$82,TRUE(),TRUE()),2,3) -> 0.10786529 | D90: =B90/C90 -> 9.8340708 | E90: =TDIST(ABS(D90),$H$88,2) -> 5.1725252e-15
A91: D4lnEMBI (t-2) | B91: =INDEX(LINEST($B$6:$B$82,$C$6:$E$82,TRUE(),TRUE()),1,2) -> -0.048642682 | C91: =INDEX(LINEST($B$6:$B$82,$C$6:$E$82,TRUE(),TRUE()),2,2) -> 0.0070023294 | D91: =B91/C91 -> -6.9466429 | E91: =TDIST(ABS(D91),$H$88,2) -> 1.3080866e-09
A92: M1R (t) | B92: =INDEX(LINEST($B$6:$B$82,$C$6:$E$82,TRUE(),TRUE()),1,1) -> 0.088908816 | C92: =INDEX(LINEST($B$6:$B$82,$C$6:$E$82,TRUE(),TRUE()),2,1) -> 0.026248324 | D92: =B92/C92 -> 3.3872187 | E92: =TDIST(ABS(D92),$H$88,2) -> 0.0011404826
A94: B. BONDAD DE AJUSTE
A95: n (observaciones) | B95: =COUNT($B$6:$B$82) -> 77
A96: k (parametros) | B96: 4
A97: R2 | B97: =INDEX(LINEST($B$6:$B$82,$C$6:$E$82,TRUE(),TRUE()),3,1) -> 0.73307957
A98: R2 ajustado | B98: =1-(1-B97)*(B95-1)/(B95-B96) -> 0.72211024
A99: SSR | B99: =INDEX(LINEST($B$6:$B$82,$C$6:$E$82,TRUE(),TRUE()),5,2) -> 0.074946323
A100: log-verosimilitud | B100: =-B95/2*(LN(2*PI())+LN(B99/B95)+1) -> 157.73109
A101: AIC | B101: =-2*B100+2*B96 -> -307.46218
A102: BIC | B102: =-2*B100+LN(B95)*B96 -> -298.08696
A104: Durbin-Watson | B104: =SUMXMY2(G7:G82,G6:G81)/SUMSQ(G6:G82) -> 0.75726826
A106: C. ERRORES ESTANDAR HAC (Newey-West, nucleo de Bartlett, L=4)
A107: V = (X'X)^-1 S (X'X)^-1 , S = G0 + SUM_l w_l (G_l + G_l') , w_l = 1 - l/5. Obligatorio: el filtro interanual induce una MA(3) mecanica en los residuos.
A108: X'X
B109: =SUMPRODUCT($F$6:$F$82,$F$6:$F$82) -> 77 | C109: =SUMPRODUCT($F$6:$F$82,$C$6:$C$82) -> 1.5676 | D109: =SUMPRODUCT($F$6:$F$82,$D$6:$D$82) -> 2.7827346 | E109: =SUMPRODUCT($F$6:$F$82,$E$6:$E$82) -> -0.72884975
B110: =SUMPRODUCT($C$6:$C$82,$F$6:$F$82) -> 1.5676 | C110: =SUMPRODUCT($C$6:$C$82,$C$6:$C$82) -> 0.12665778 | D110: =SUMPRODUCT($C$6:$C$82,$D$6:$D$82) -> -0.3092527 | E110: =SUMPRODUCT($C$6:$C$82,$E$6:$E$82) -> -0.04026195
B111: =SUMPRODUCT($D$6:$D$82,$F$6:$F$82) -> 2.7827346 | C111: =SUMPRODUCT($D$6:$D$82,$C$6:$C$82) -> -0.3092527 | D111: =SUMPRODUCT($D$6:$D$82,$D$6:$D$82) -> 22.497807 | E111: =SUMPRODUCT($D$6:$D$82,$E$6:$E$82) -> -0.1895482
B112: =SUMPRODUCT($E$6:$E$82,$F$6:$F$82) -> -0.72884975 | C112: =SUMPRODUCT($E$6:$E$82,$C$6:$C$82) -> -0.04026195 | D112: =SUMPRODUCT($E$6:$E$82,$D$6:$D$82) -> -0.1895482 | E112: =SUMPRODUCT($E$6:$E$82,$E$6:$E$82) -> 1.5071079
A113: (X'X)^-1 = A
...

Sheet Modelo_COVID
A1: MODELO PROPUESTO + DUMMIES IMPULSO COVID (2020Q2 y 2021Q2)
A2: Ojo: en este modelo el COVID pesa MUCHO menos que en los anteriores, porque el PBI de Brasil se derrumbo al mismo tiempo y absorbe buena parte del shock. Ver la hoja Resumen.
A5: Periodo | B5: y = PBI | C5: PBI BR (t) | D5: D4lnEMBI (t-2) | E5: M1R (t) | F5: D_2020Q2 | G5: D_2021Q2 | H5: const=1 | I5: residuo e | J5: e^2 | K5: h_0 | L5: h_1 | M5: h_2 | N5: h_3 | O5: h_4 | P5: h_5
A6: =Datos!A13 -> 2007Q1 | B6: =Datos!E13 -> 0.083589411 | C6: =Datos!C13 -> 0.052 | D6: =Datos!H11 -> -0.19907832 | E6: =Datos!D13 -> 0.10364673 | F6: =IF($A6="2020Q2",1,0) -> 0 | G6: =IF($A6="2021Q2",1,0) -> 0 | H6: 1 | I6: =B6-($B$89+$B$90*C6+$B$91*D6+$B$92*E6+$B$93*F6+$B$94*G6) -> 0.016271598 | J6: =I6^2 -> 0.00026476491 | K6: =H6*$I6 -> 0.016271598 | L6: =C6*$I6 -> 0.00084612311 | M6: =D6*$I6 -> -0.0032393224 | N6: =E6*$I6 -> 0.0016864979 | O6: =F6*$I6 -> 0 | P6: =G6*$I6 -> 0
A7: =Datos!A14 -> 2007Q2 | B7: =Datos!E14 -> 0.098593874 | C7: =Datos!C14 -> 0.0654 | D7: =Datos!H12 -> -0.40749439 | E7: =Datos!D14 -> 0.10878117 | F7: =IF($A7="2020Q2",1,0) -> 0 | G7: =IF($A7="2021Q2",1,0) -> 0 | H7: 1 | I7: =B7-($B$89+$B$90*C7+$B$91*D7+$B$92*E7+$B$93*F7+$B$94*G7) -> 0.0091348941 | J7: =I7^2 -> 8.3446289e-05 | K7: =H7*$I7 -> 0.0091348941 | L7: =C7*$I7 -> 0.00059742207 | M7: =D7*$I7 -> -0.0037224181 | N7: =E7*$I7 -> 0.00099370443 | O7: =F7*$I7 -> 0 | P7: =G7*$I7 -> 0
A8: =Datos!A15 -> 2007Q3 | B8: =Datos!E15 -> 0.084277977 | C8: =Datos!C15 -> 0.0587 | D8: =Datos!H13 -> -0.62896681 | E8: =Datos!D15 -> 0.095031538 | F8: =IF($A8="2020Q2",1,0) -> 0 | G8: =IF($A8="2021Q2",1,0) -> 0 | H8: 1 | I8: =B8-($B$89+$B$90*C8+$B$91*D8+$B$92*E8+$B$93*F8+$B$94*G8) -> -0.0078073408 | J8: =I8^2 -> 6.0954571e-05 | K8: =H8*$I8 -> -0.0078073408 | L8: =C8*$I8 -> -0.00045829091 | M8: =D8*$I8 -> 0.0049105583 | N8: =E8*$I8 -> -0.0007419436 | O8: =F8*$I8 -> 0 | P8: =G8*$I8 -> 0
A9: =Datos!A16 -> 2007Q4 | B9: =Datos!E16 -> 0.092673486 | C9: =Datos!C16 -> 0.0664 | D9: =Datos!H14 -> -0.27606314 | E9: =Datos!D16 -> 0.03479478 | F9: =IF($A9="2020Q2",1,0) -> 0 | G9: =IF($A9="2021Q2",1,0) -> 0 | H9: 1 | I9: =B9-($B$89+$B$90*C9+$B$91*D9+$B$92*E9+$B$93*F9+$B$94*G9) -> 0.016368468 | J9: =I9^2 -> 0.00026792673 | K9: =H9*$I9 -> 0.016368468 | L9: =C9*$I9 -> 0.0010868662 | M9: =D9*$I9 -> -0.0045187305 | N9: =E9*$I9 -> 0.00056953723 | O9: =F9*$I9 -> 0 | P9: =G9*$I9 -> 0
A10: =Datos!A17 -> 2008Q1 | B10: =Datos!E17 -> 0.069123146 | C10: =Datos!C17 -> 0.0616 | D10: =Datos!H15 -> 0.20245337 | E10: =Datos!D17 -> 0.0060995986 | F10: =IF($A10="2020Q2",1,0) -> 0 | G10: =IF($A10="2021Q2",1,0) -> 0 | H10: 1 | I10: =B10-($B$89+$B$90*C10+$B$91*D10+$B$92*E10+$B$93*F10+$B$94*G10) -> 0.022156664 | J10: =I10^2 -> 0.00049091774 | K10: =H10*$I10 -> 0.022156664 | L10: =C10*$I10 -> 0.0013648505 | M10: =D10*$I10 -> 0.0044856913 | N10: =E10*$I10 -> 0.00013514675 | O10: =F10*$I10 -> 0 | P10: =G10*$I10 -> 0
A11: =Datos!A18 -> 2008Q2 | B11: =Datos!E18 -> 0.054526855 | C11: =Datos!C18 -> 0.0634 | D11: =Datos!H16 -> 0.31730851 | E11: =Datos!D18 -> -0.032825593 | F11: =IF($A11="2020Q2",1,0) -> 0 | G11: =IF($A11="2021Q2",1,0) -> 0 | H11: 1 | I11: =B11-($B$89+$B$90*C11+$B$91*D11+$B$92*E11+$B$93*F11+$B$94*G11) -> 0.015428854 | J11: =I11^2 -> 0.00023804953 | K11: =H11*$I11 -> 0.015428854 | L11: =C11*$I11 -> 0.00097818933 | M11: =D11*$I11 -> 0.0048957066 | N11: =E11*$I11 -> -0.00050646127 | O11: =F11*$I11 -> 0 | P11: =G11*$I11 -> 0
A12: =Datos!A19 -> 2008Q3 | B12: =Datos!E19 -> 0.060060161 | C12: =Datos!C19 -> 0.0698 | D12: =Datos!H17 -> 0.83000136 | E12: =Datos!D19 -> -0.01260622 | F12: =IF($A12="2020Q2",1,0) -> 0 | G12: =IF($A12="2021Q2",1,0) -> 0 | H12: 1 | I12: =B12-($B$89+$B$90*C12+$B$91*D12+$B$92*E12+$B$93*F12+$B$94*G12) -> 0.036489039 | J12: =I12^2 -> 0.0013314499 | K12: =H12*$I12 -> 0.036489039 | L12: =C12*$I12 -> 0.0025469349 | M12: =D12*$I12 -> 0.030285952 | N12: =E12*$I12 -> -0.00045998884 | O12: =F12*$I12 -> 0 | P12: =G12*$I12 -> 0
A13: =Datos!A20 -> 2008Q4 | B13: =Datos!E20 -> -0.019789909 | C13: =Datos!C20 -> 0.0102 | D13: =Datos!H18 -> 0.72951743 | E13: =Datos!D20 -> 0.0082101847 | F13: =IF($A13="2020Q2",1,0) -> 0 | G13: =IF($A13="2021Q2",1,0) -> 0 | H13: 1 | I13: =B13-($B$89+$B$90*C13+$B$91*D13+$B$92*E13+$B$93*F13+$B$94*G13) -> 0.0033339982 | J13: =I13^2 -> 1.1115544e-05 | K13: =H13*$I13 -> 0.0033339982 | L13: =C13*$I13 -> 3.4006782e-05 | M13: =D13*$I13 -> 0.0024322098 | N13: =E13*$I13 -> 2.7372741e-05 | O13: =F13*$I13 -> 0 | P13: =G13*$I13 -> 0
A14: =Datos!A21 -> 2009Q1 | B14: =Datos!E21 -> -0.061887551 | C14: =Datos!C21 -> -0.0242 | D14: =Datos!H19 -> 0.51795036 | E14: =Datos!D21 -> -0.029228652 | F14: =IF($A14="2020Q2",1,0) -> 0 | G14: =IF($A14="2021Q2",1,0) -> 0 | H14: 1 | I14: =B14-($B$89+$B$90*C14+$B$91*D14+$B$92*E14+$B$93*F14+$B$94*G14) -> -0.013472671 | J14: =I14^2 -> 0.00018151287 | K14: =H14*$I14 -> -0.013472671 | L14: =C14*$I14 -> 0.00032603864 | M14: =D14*$I14 -> -0.0069781749 | N14: =E14*$I14 -> 0.00039378802 | O14: =F14*$I14 -> 0 | P14: =G14*$I14 -> 0
A15: =Datos!A22 -> 2009Q2 | B15: =Datos!E22 -> -0.11274547 | C15: =Datos!C22 -> -0.022 | D15: =Datos!H20 -> 1.4782059 | E15: =Datos!D22 -> -0.073032733 | F15: =IF($A15="2020Q2",1,0) -> 0 | G15: =IF($A15="2021Q2",1,0) -> 0 | H15: 1 | I15: =B15-($B$89+$B$90*C15+$B$91*D15+$B$92*E15+$B$93*F15+$B$94*G15) -> -0.017584893 | J15: =I15^2 -> 0.00030922848 | K15: =H15*$I15 -> -0.017584893 | L15: =C15*$I15 -> 0.00038686765 | M15: =D15*$I15 -> -0.025994094 | N15: =E15*$I15 -> 0.0012842728 | O15: =F15*$I15 -> 0 | P15: =G15*$I15 -> 0
A16: =Datos!A23 -> 2009Q3 | B16: =Datos!E23 -> -0.0565118 | C16: =Datos!C23 -> -0.0116 | D16: =Datos!H21 -> 1.2599804 | E16: =Datos!D23 -> -0.04586153 | F16: =IF($A16="2020Q2",1,0) -> 0 | G16: =IF($A16="2021Q2",1,0) -> 0 | H16: 1 | I16: =B16-($B$89+$B$90*C16+$B$91*D16+$B$92*E16+$B$93*F16+$B$94*G16) -> 0.016361073 | J16: =I16^2 -> 0.0002676847 | K16: =H16*$I16 -> 0.016361073 | L16: =C16*$I16 -> -0.00018978844 | M16: =D16*$I16 -> 0.020614631 | N16: =E16*$I16 -> -0.00075034383 | O16: =F16*$I16 -> 0 | P16: =G16*$I16 -> 0
A17: =Datos!A24 -> 2009Q4 | B17: =Datos!E24 -> 0.0028199823 | C17: =Datos!C24 -> 0.0533 | D17: =Datos!H22 -> 0.9612717 | E17: =Datos!D24 -> -0.051628665 | F17: =IF($A17="2020Q2",1,0) -> 0 | G17: =IF($A17="2021Q2",1,0) -> 0 | H17: 1 | I17: =B17-($B$89+$B$90*C17+$B$91*D17+$B$92*E17+$B$93*F17+$B$94*G17) -> 0.0043237988 | J17: =I17^2 -> 1.8695236e-05 | K17: =H17*$I17 -> 0.0043237988 | L17: =C17*$I17 -> 0.00023045847 | M17: =D17*$I17 -> 0.0041563454 | N17: =E17*$I17 -> -0.00022323196 | O17: =F17*$I17 -> 0 | P17: =G17*$I17 -> 0
... A82: =Datos!A89 -> 2026Q1 | B82: =Datos!E89 -> 0.024694045 | C82: =Datos!C89 -> 0.0182 | D82: =Datos!H87 -> -0.53880137 | E82: =Datos!D89 -> -0.030260826 | F82: =IF($A82="2020Q2",1,0) -> 0 | G82: =IF($A82="2021Q2",1,0) -> 0 | H82: 1 | I82: =B82-($B$89+$B$90*C82+$B$91*D82+$B$92*E82+$B$93*F82+$B$94*G82) -> -0.01326305 | J82: =I82^2 -> 0.00017590849 | K82: =H82*$I82 -> -0.01326305 | L82: =C82*$I82 -> -0.00024138751 | M82: =D82*$I82 -> 0.0071461494 | N82: =E82*$I82 -> 0.00040135084 | O82: =F82*$I82 -> 0 | P82: =G82*$I82 -> 0
A87: A. ESTIMACION OLS (LINEST devuelve los coeficientes en orden inverso; se extraen con INDEX)
A88: Regresor | B88: Coef. | C88: Error est. | D88: t | E88: p-valor | G88: gl resid. | H88: =INDEX(LINEST($B$6:$B$82,$C$6:$G$82,TRUE(),TRUE()),4,2) -> 71
A89: const | B89: =INDEX(LINEST($B$6:$B$82,$C$6:$G$82,TRUE(),TRUE()),1,6) -> 0.00021985685 | C89: =INDEX(LINEST($B$6:$B$82,$C$6:$G$82,TRUE(),TRUE()),2,6) -> 0.0043627735 | D89: =B89/C89 -> 0.050393827 | E89: =TDIST(ABS(D89),$H$88,2) -> 0.95995006
A90: PBI BR (t) | B90: =INDEX(LINEST($B$6:$B$82,$C$6:$G$82,TRUE(),TRUE()),1,5) -> 0.8985969 | C90: =INDEX(LINEST($B$6:$B$82,$C$6:$G$82,TRUE(),TRUE()),2,5) -> 0.11887318 | D90: =B90/C90 -> 7.5592902 | E90: =TDIST(ABS(D90),$H$88,2) -> 1.0953615e-10
A91: D4lnEMBI (t-2) | B91: =INDEX(LINEST($B$6:$B$82,$C$6:$G$82,TRUE(),TRUE()),1,4) -> -0.045785174 | C91: =INDEX(LINEST($B$6:$B$82,$C$6:$G$82,TRUE(),TRUE()),2,4) -> 0.0068436804 | D91: =B91/C91 -> -6.690139 | E91: =TDIST(ABS(D91),$H$88,2) -> 4.322675e-09
A92: M1R (t) | B92: =INDEX(LINEST($B$6:$B$82,$C$6:$G$82,TRUE(),TRUE()),1,3) -> 0.10860046 | C92: =INDEX(LINEST($B$6:$B$82,$C$6:$G$82,TRUE(),TRUE()),2,3) -> 0.026368917 | D92: =B92/C92 -> 4.1185027 | E92: =TDIST(ABS(D92),$H$88,2) -> 0.00010168244
A93: D_2020Q2 | B93: =INDEX(LINEST($B$6:$B$82,$C$6:$G$82,TRUE(),TRUE()),1,2) -> -0.079176941 | C93: =INDEX(LINEST($B$6:$B$82,$C$6:$G$82,TRUE(),TRUE()),2,2) -> 0.035981606 | D93: =B93/C93 -> -2.2004838 | E93: =TDIST(ABS(D93),$H$88,2) -> 0.031026984
A94: D_2021Q2 | B94: =INDEX(LINEST($B$6:$B$82,$C$6:$G$82,TRUE(),TRUE()),1,1) -> 0.070138162 | C94: =INDEX(LINEST($B$6:$B$82,$C$6:$G$82,TRUE(),TRUE()),2,1) -> 0.033622803 | D94: =B94/C94 -> 2.0860296 | E94: =TDIST(ABS(D94),$H$88,2) -> 0.040569906
A96: B. BONDAD DE AJUSTE
A97: n (observaciones) | B97: =COUNT($B$6:$B$82) -> 77
A98: k (parametros) | B98: 6
A99: R2 | B99: =INDEX(LINEST($B$6:$B$82,$C$6:$G$82,TRUE(),TRUE()),3,1) -> 0.75960653
A100: R2 ajustado | B100: =1-(1-B99)*(B97-1)/(B97-B98) -> 0.74267741
A101: SSR | B101: =INDEX(LINEST($B$6:$B$82,$C$6:$G$82,TRUE(),TRUE()),5,2) -> 0.067498042
A102: log-verosimilitud | B102: =-B97/2*(LN(2*PI())+LN(B101/B97)+1) -> 161.76102
A103: AIC | B103: =-2*B102+2*B98 -> -311.52205
A104: BIC | B104: =-2*B102+LN(B97)*B98 -> -297.45922
A106: Durbin-Watson | B106: =SUMXMY2(I7:I82,I6:I81)/SUMSQ(I6:I82) -> 0.90246402
A108: C. ERRORES ESTANDAR HAC (Newey-West, nucleo de Bartlett, L=4)
A109: V = (X'X)^-1 S (X'X)^-1 , S = G0 + SUM_l w_l (G_l + G_l') , w_l = 1 - l/5. Obligatorio: el filtro interanual induce una MA(3) mecanica en los residuos.
A110: X'X
B111: =SUMPRODUCT($H$6:$H$82,$H$6:$H$82) -> 77 | C111: =SUMPRODUCT($H$6:$H$82,$C$6:$C$82) -> 1.5676 | D111: =SUMPRODUCT($H$6:$H$82,$D$6:$D$82) -> 2.7827346 | E111: =SUMPRODUCT($H$6:$H$82,$E$6:$E$82) -> -0.72884975 | F111: =SUMPRODUCT($H$6:$H$82,$F$6:$F$82) -> 1 | G111: =SUMPRODUCT($H$6:$H$82,$G$6:$G$82) -> 1
B112: =SUMPRODUCT($C$6:$C$82,$H$6:$H$82) -> 1.5676 | C112: =SUMPRODUCT($C$6:$C$82,$C$6:$C$82) -> 0.12665778 | D112: =SUMPRODUCT($C$6:$C$82,$D$6:$D$82) -> -0.3092527 | E112: =SUMPRODUCT($C$6:$C$82,$E$6:$E$82) -> -0.04026195 | F112: =SUMPRODUCT($C$6:$C$82,$F$6:$F$82) -> -0.1014 | G112: =SUMPRODUCT($C$6:$C$82,$G$6:$G$82) -> 0.124
B113: =SUMPRODUCT($D$6:$D$82,$H$6:$H$82) -> 2.7827346 | C113: =SUMPRODUCT($D$6:$D$82,$C$6:$C$82) -> -0.3092527 | D113: =SUMPRODUCT($D$6:$D$82,$D$6:$D$82) -> 22.497807 | E113: =SUMPRODUCT($D$6:$D$82,$E$6:$E$82) -> -0.1895482 | F113: =SUMPRODUCT($D$6:$D$82,$F$6:$F$82) -> 1.1351546 | G113: =SUMPRODUCT($D$6:$D$82,$G$6:$G$82) -> -0.43584616
...

Sheet Diagnosticos
A1: DIAGNOSTICOS DE RESIDUOS
A4: A. AUTOCORRELACION DE LOS RESIDUOS
A5: Rezago | B5: Base | C5: Nuevo | D5: Nuevo + dummies
A6: 1 | B6: =SUMPRODUCT(Modelo_Base!$H$7:$H$82,Modelo_Base!$H$6:$H$81)/SUMSQ(Modelo_Base!$H$6:$H$82) -> 0.68103219 | C6: =SUMPRODUCT(Modelo_Nuevo!$G$7:$G$82,Modelo_Nuevo!$G$6:$G$81)/SUMSQ(Modelo_Nuevo!$G$6:$G$82) -> 0.61879974 | D6: =SUMPRODUCT(Modelo_COVID!$I$7:$I$82,Modelo_COVID!$I$6:$I$81)/SUMSQ(Modelo_COVID!$I$6:$I$82) -> 0.54550365 | F6: Los rezagos 1-3 positivos y decrecientes son la MA(3) que induce el filtro interanual de la dependiente, no mala especificacion. Por eso se reportan errores HAC y el n efectivo es ~n/4.
A7: 2 | B7: =SUMPRODUCT(Modelo_Base!$H$8:$H$82,Modelo_Base!$H$6:$H$80)/SUMSQ(Modelo_Base!$H$6:$H$82) -> 0.35043244 | C7: =SUMPRODUCT(Modelo_Nuevo!$G$8:$G$82,Modelo_Nuevo!$G$6:$G$80)/SUMSQ(Modelo_Nuevo!$G$6:$G$82) -> 0.30778832 | D7: =SUMPRODUCT(Modelo_COVID!$I$8:$I$82,Modelo_COVID!$I$6:$I$80)/SUMSQ(Modelo_COVID!$I$6:$I$82) -> 0.28542285
A8: 3 | B8: =SUMPRODUCT(Modelo_Base!$H$9:$H$82,Modelo_Base!$H$6:$H$79)/SUMSQ(Modelo_Base!$H$6:$H$82) -> 0.1261096 | C8: =SUMPRODUCT(Modelo_Nuevo!$G$9:$G$82,Modelo_Nuevo!$G$6:$G$79)/SUMSQ(Modelo_Nuevo!$G$6:$G$82) -> 0.1246917 | D8: =SUMPRODUCT(Modelo_COVID!$I$9:$I$82,Modelo_COVID!$I$6:$I$79)/SUMSQ(Modelo_COVID!$I$6:$I$82) -> 0.11490957
A9: 4 | B9: =SUMPRODUCT(Modelo_Base!$H$10:$H$82,Modelo_Base!$H$6:$H$78)/SUMSQ(Modelo_Base!$H$6:$H$82) -> -0.07540356 | C9: =SUMPRODUCT(Modelo_Nuevo!$G$10:$G$82,Modelo_Nuevo!$G$6:$G$78)/SUMSQ(Modelo_Nuevo!$G$6:$G$82) -> -0.12958304 | D9: =SUMPRODUCT(Modelo_COVID!$I$10:$I$82,Modelo_COVID!$I$6:$I$78)/SUMSQ(Modelo_COVID!$I$6:$I$82) -> -0.16041653
A10: 5 | B10: =SUMPRODUCT(Modelo_Base!$H$11:$H$82,Modelo_Base!$H$6:$H$77)/SUMSQ(Modelo_Base!$H$6:$H$82) -> -0.06200181 | C10: =SUMPRODUCT(Modelo_Nuevo!$G$11:$G$82,Modelo_Nuevo!$G$6:$G$77)/SUMSQ(Modelo_Nuevo!$G$6:$G$82) -> -0.063935545 | D10: =SUMPRODUCT(Modelo_COVID!$I$11:$I$82,Modelo_COVID!$I$6:$I$77)/SUMSQ(Modelo_COVID!$I$6:$I$82) -> -0.09468359
A11: 6 | B11: =SUMPRODUCT(Modelo_Base!$H$12:$H$82,Modelo_Base!$H$6:$H$76)/SUMSQ(Modelo_Base!$H$6:$H$82) -> -0.063216752 | C11: =SUMPRODUCT(Modelo_Nuevo!$G$12:$G$82,Modelo_Nuevo!$G$6:$G$76)/SUMSQ(Modelo_Nuevo!$G$6:$G$82) -> 0.022089418 | D11: =SUMPRODUCT(Modelo_COVID!$I$12:$I$82,Modelo_COVID!$I$6:$I$76)/SUMSQ(Modelo_COVID!$I$6:$I$82) -> -0.032257177
A12: 7 | B12: =SUMPRODUCT(Modelo_Base!$H$13:$H$82,Modelo_Base!$H$6:$H$75)/SUMSQ(Modelo_Base!$H$6:$H$82) -> -0.10202165 | C12: =SUMPRODUCT(Modelo_Nuevo!$G$13:$G$82,Modelo_Nuevo!$G$6:$G$75)/SUMSQ(Modelo_Nuevo!$G$6:$G$82) -> 0.019502021 | D12: =SUMPRODUCT(Modelo_COVID!$I$13:$I$82,Modelo_COVID!$I$6:$I$75)/SUMSQ(Modelo_COVID!$I$6:$I$82) -> 0.0021539343
A13: 8 | B13: =SUMPRODUCT(Modelo_Base!$H$14:$H$82,Modelo_Base!$H$6:$H$74)/SUMSQ(Modelo_Base!$H$6:$H$82) -> -0.15539666 | C13: =SUMPRODUCT(Modelo_Nuevo!$G$14:$G$82,Modelo_Nuevo!$G$6:$G$74)/SUMSQ(Modelo_Nuevo!$G$6:$G$82) -> -0.015808941 | D13: =SUMPRODUCT(Modelo_COVID!$I$14:$I$82,Modelo_COVID!$I$6:$I$74)/SUMSQ(Modelo_COVID!$I$6:$I$82) -> 0.010261494
A15: Durbin-Watson | B15: =Modelo_Base!B105 -> 0.63378658 | C15: =Modelo_Nuevo!B104 -> 0.75726826 | D15: =Modelo_COVID!B106 -> 0.90246402
A17: B. HETEROCEDASTICIDAD — Breusch-Pagan (LM = n x R2 de e^2 sobre X)
A18: Modelo | B18: R2 auxiliar | C18: LM | D18: gl | E18: p-valor
A19: Base | B19: =INDEX(LINEST(Modelo_Base!$I$6:$I$82,Modelo_Base!$C$6:$F$82,TRUE(),TRUE()),3,1) -> 0.19304858 | C19: =77*B19 -> 14.864741 | D19: 4 | E19: =CHIDIST(C19,D19) -> 0.0049901339
A20: Nuevo | B20: =INDEX(LINEST(Modelo_Nuevo!$H$6:$H$82,Modelo_Nuevo!$C$6:$E$82,TRUE(),TRUE()),3,1) -> 0.12757934 | C20: =77*B20 -> 9.823609 | D20: 3 | E20: =CHIDIST(C20,D20) -> 0.020126596
A21: Nuevo + dummies | B21: =INDEX(LINEST(Modelo_COVID!$J$6:$J$82,Modelo_COVID!$C$6:$G$82,TRUE(),TRUE()),3,1) -> 0.084357842 | C21: =77*B21 -> 6.4955539 | D21: 5 | E21: =CHIDIST(C21,D21) -> 0.2609386
A24: C. NORMALIDAD — Jarque-Bera
A25: Modelo | B25: Asimetria | C25: Curtosis exc. | D25: JB | E25: p-valor
A26: Base | B26: =SKEW(Modelo_Base!$H$6:$H$82) -> 0.2907736 | C26: =KURT(Modelo_Base!$H$6:$H$82) -> -0.54734623 | D26: =77/6*(B26^2+C26^2/4) -> 2.046227 | E26: =CHIDIST(D26,2) -> 0.35947397
A27: Nuevo | B27: =SKEW(Modelo_Nuevo!$G$6:$G$82) -> 0.2552992 | C27: =KURT(Modelo_Nuevo!$G$6:$G$82) -> -0.34031708 | D27: =77/6*(B27^2+C27^2/4) -> 1.2080223 | E27: =CHIDIST(D27,2) -> 0.54661468
A28: Nuevo + dummies | B28: =SKEW(Modelo_COVID!$I$6:$I$82) -> 0.2253004 | C28: =KURT(Modelo_COVID!$I$6:$I$82) -> -0.38495914 | D28: =77/6*(B28^2+C28^2/4) -> 1.1268777 | E28: =CHIDIST(D28,2) -> 0.56924813
