Workbook

Sheet Resumen
A1: COMPARACION DE MODELOS — PBI trimestral argentino
A2: Misma muestra 2006Q4-2026Q1 (n=78) en los cuatro modelos: sin eso, AIC y BIC no son comparables.
A4: Metrica | B4: BASE (niveles) | C4: NUEVO (i.a.) | D4: NUEVO + dummies COVID
A5: n | B5: =Modelo_Base!B99 -> 78 | C5: =Modelo_Nuevo!B98 -> 78 | D5: =Modelo_Nuevo!B173 -> 78
A6: k (parametros) | B6: =Modelo_Base!B100 -> 5 | C6: =Modelo_Nuevo!B99 -> 4 | D6: =Modelo_Nuevo!B174 -> 9
A7: R2 | B7: =Modelo_Base!B101 -> 0.44752378 | C7: =Modelo_Nuevo!B100 -> 0.53929008 | D7: =Modelo_Nuevo!B175 -> 0.65549367
A8: R2 ajustado | B8: =Modelo_Base!B102 -> 0.41725111 | C8: =Modelo_Nuevo!B101 -> 0.52061265 | D8: =Modelo_Nuevo!B176 -> 0.6155509
A9: SSR | B9: =Modelo_Base!B103 -> 0.15870843 | C9: =Modelo_Nuevo!B102 -> 0.13234696 | D9: =Modelo_Nuevo!B177 -> 0.098965453
A10: AIC | B10: =Modelo_Base!B105 -> -252.04243 | C10: =Modelo_Nuevo!B104 -> -268.21049 | D10: =Modelo_Nuevo!B179 -> -280.88166
A11: BIC | B11: =Modelo_Base!B106 -> -240.25888 | C11: =Modelo_Nuevo!B105 -> -258.78365 | D11: =Modelo_Nuevo!B180 -> -259.67129
A12: Durbin-Watson | B12: =Diagnosticos!B6 -> 0.83140737 | C12: =Diagnosticos!C6 -> 1.0801443 | D12: =Diagnosticos!D6 -> 0.90488717
A13: Breusch-Pagan p | B13: =Diagnosticos!E21 -> 7.2856501e-05 | C13: =Diagnosticos!E22 -> 0.29010568 | D13: =Diagnosticos!E23 -> 0.79551386
A15: Coeficientes del modelo nuevo (errores HAC, Newey-West L=4)
A16: Regresor | B16: Coef. | C16: se HAC | D16: t | E16: p
A17: =Modelo_Nuevo!A157 -> const | B17: =Modelo_Nuevo!B157 -> 0.014087706 | C17: =Modelo_Nuevo!C157 -> 0.0066625848 | D17: =Modelo_Nuevo!D157 -> 2.1144505 | E17: =Modelo_Nuevo!E157 -> 0.037845398
A18: =Modelo_Nuevo!A158 -> x1 D4lnITCRM(t) | B18: =Modelo_Nuevo!B158 -> -0.14720768 | C18: =Modelo_Nuevo!C158 -> 0.033526773 | D18: =Modelo_Nuevo!D158 -> -4.39075 | E18: =Modelo_Nuevo!E158 -> 3.6991539e-05
A19: =Modelo_Nuevo!A159 -> x2 D4lnEMBI(t-1) | B19: =Modelo_Nuevo!B159 -> -0.057342281 | C19: =Modelo_Nuevo!C159 -> 0.012447824 | D19: =Modelo_Nuevo!D159 -> -4.6066107 | E19: =Modelo_Nuevo!E159 -> 1.6681963e-05
A20: =Modelo_Nuevo!A160 -> x3 M3R(t-2) | B20: =Modelo_Nuevo!B160 -> 0.17964923 | C20: =Modelo_Nuevo!C160 -> 0.038922698 | D20: =Modelo_Nuevo!D160 -> 4.6155389 | E20: =Modelo_Nuevo!E160 -> 1.6135004e-05
A23: Restriccion implicita del modelo base
A24: H0: beta_EMBI(t) + beta_EMBI(t-5) = 0
A25: F | B25: =Modelo_Base!B114 -> 0.044999739
A26: p-valor | B26: =Modelo_Base!B115 -> 0.8325957
A27: No rechazar implica que los dos terminos de EMBI en nivel son, de hecho, la diferencia EMBI(t)-EMBI(t-5).
A30: COMO USAR ESTE ARCHIVO
A31: 1. Los unicos datos editables son las celdas azules de la hoja Datos (EMBI, ITCRM, M3R, GDP).
A32: 2. Todo lo demas son formulas: al agregar un trimestre nuevo, extender las filas y recalcular.
A33: 3. Las regresiones usan INDEX(LINEST(...)) para devolver escalares en vez de formulas matriciales.
A34: 4. AIC y BIC replican la convencion de statsmodels: -2logL + 2k y -2logL + ln(n)k.
A35: 5. Los errores HAC de la hoja Modelo_Nuevo son los que hay que citar: el filtro interanual
A36: induce una MA(3) y los errores OLS estan subestimados.

Sheet Datos
A1: DATOS Y TRANSFORMACIONES
A2: Trimestral 2005Q1-2026Q1. Azul = dato original (editable). Negro = formula.
A3: GDP y M3R ya vienen como variacion interanual (I(0)). ITCRM y EMBI vienen en NIVEL (I(1)): se les aplica el mismo filtro D4log(.) para balancear la regresion.
A4: Periodo | B4: EMBI (pb) | C4: ITCRM | D4: M3R (i.a.) | E4: GDP (i.a.) | G4: ln(EMBI) | H4: ln(ITCRM) | I4: D4 ln EMBI | J4: D4 ln ITCRM
A5: 2005Q1 | C5: 162.25658 | D5: 0.1262661 | E5: 0.072187868 | G5: =IF(ISNUMBER(B5),LN(B5),"") | H5: =LN(C5) -> 5.0891789
A6: 2005Q2 | C6: 159.96635 | D6: 0.16505259 | E6: 0.13077981 | G6: =IF(ISNUMBER(B6),LN(B6),"") | H6: =LN(C6) -> 5.0749635
A7: 2005Q3 | B7: 413.72934 | C7: 160.08002 | D7: 0.083135769 | E7: 0.069719779 | G7: =IF(ISNUMBER(B7),LN(B7),"") -> 6.025212 | H7: =LN(C7) -> 5.0756738
A8: 2005Q4 | B8: 423.41625 | C8: 163.86937 | D8: 0.066830714 | E8: 0.077828945 | G8: =IF(ISNUMBER(B8),LN(B8),"") -> 6.0483557 | H8: =LN(C8) -> 5.0990696
A9: 2006Q1 | B9: 394.41518 | C9: 166.81312 | D9: 0.024910905 | E9: 0.078495711 | G9: =IF(ISNUMBER(B9),LN(B9),"") -> 5.9774041 | H9: =LN(C9) -> 5.1168741 | I9: =IF(AND(ISNUMBER(G9),ISNUMBER(G5)),G9-G5,"") | J9: =H9-H5 -> 0.027695184
A10: 2006Q2 | B10: 353.71381 | C10: 166.01956 | D10: 0.048520637 | E10: 0.055715853 | G10: =IF(ISNUMBER(B10),LN(B10),"") -> 5.8684881 | H10: =LN(C10) -> 5.1121056 | I10: =IF(AND(ISNUMBER(G10),ISNUMBER(G6)),G10-G6,"") | J10: =H10-H6 -> 0.037142109
A11: 2006Q3 | B11: 339.04529 | C11: 165.95339 | D11: 0.06474531 | E11: 0.093804903 | G11: =IF(ISNUMBER(B11),LN(B11),"") -> 5.8261337 | H11: =LN(C11) -> 5.1117069 | I11: =IF(AND(ISNUMBER(G11),ISNUMBER(G7)),G11-G7,"") -> -0.19907832 | J11: =H11-H7 -> 0.036033111
A12: 2006Q4 | B12: 281.70526 | C12: 163.55654 | D12: 0.092447249 | E12: 0.096770404 | G12: =IF(ISNUMBER(B12),LN(B12),"") -> 5.6408613 | H12: =LN(C12) -> 5.0971587 | I12: =IF(AND(ISNUMBER(G12),ISNUMBER(G8)),G12-G8,"") -> -0.40749439 | J12: =H12-H8 -> -0.0019108998
A13: 2007Q1 | B13: 210.27944 | C13: 163.25891 | D13: 0.1266018 | E13: 0.083589411 | G13: =IF(ISNUMBER(B13),LN(B13),"") -> 5.3484373 | H13: =LN(C13) -> 5.0953374 | I13: =IF(AND(ISNUMBER(G13),ISNUMBER(G9)),G13-G9,"") -> -0.62896681 | J13: =H13-H9 -> -0.02153676
A14: 2007Q2 | B14: 268.38567 | C14: 161.94276 | D14: 0.11396594 | E14: 0.098593874 | G14: =IF(ISNUMBER(B14),LN(B14),"") -> 5.592425 | H14: =LN(C14) -> 5.0872429 | I14: =IF(AND(ISNUMBER(G14),ISNUMBER(G10)),G14-G10,"") -> -0.27606314 | J14: =H14-H10 -> -0.024862684
A15: 2007Q3 | B15: 415.12806 | C15: 157.56185 | D15: 0.089343321 | E15: 0.084277977 | G15: =IF(ISNUMBER(B15),LN(B15),"") -> 6.0285871 | H15: =LN(C15) -> 5.0598181 | I15: =IF(AND(ISNUMBER(G15),ISNUMBER(G11)),G15-G11,"") -> 0.20245337 | J15: =H15-H11 -> -0.051888871
A16: 2007Q4 | B16: 386.90139 | C16: 158.87912 | D16: 0.037973687 | E16: 0.092673486 | G16: =IF(ISNUMBER(B16),LN(B16),"") -> 5.9581698 | H16: =LN(C16) -> 5.0681437 | I16: =IF(AND(ISNUMBER(G16),ISNUMBER(G12)),G16-G12,"") -> 0.31730851 | J16: =H16-H12 -> -0.029015053
A17: 2008Q1 | B17: 482.23843 | C17: 159.28776 | D17: 0.0057682917 | E17: 0.069123146 | G17: =IF(ISNUMBER(B17),LN(B17),"") -> 6.1784387 | H17: =LN(C17) -> 5.0707124 | I17: =IF(AND(ISNUMBER(G17),ISNUMBER(G13)),G17-G13,"") -> 0.83000136 | J17: =H17-H13 -> -0.024624979
A18: 2008Q2 | B18: 556.6532 | C18: 152.76989 | D18: -0.041444326 | E18: 0.054526855 | G18: =IF(ISNUMBER(B18),LN(B18),"") -> 6.3219424 | H18: =LN(C18) -> 5.0289328 | I18: =IF(AND(ISNUMBER(G18),ISNUMBER(G14)),G18-G14,"") -> 0.72951743 | J18: =H18-H14 -> -0.058310111
A19: 2008Q3 | B19: 696.82717 | C19: 142.65201 | D19: -0.031056134 | E19: 0.060060161 | G19: =IF(ISNUMBER(B19),LN(B19),"") -> 6.5465374 | H19: =LN(C19) -> 4.9604081 | I19: =IF(AND(ISNUMBER(G19),ISNUMBER(G15)),G19-G15,"") -> 0.51795036 | J19: =H19-H15 -> -0.099409929
A20: 2008Q4 | B20: 1696.5902 | C20: 128.29866 | D20: -0.043350325 | E20: -0.019789909 | G20: =IF(ISNUMBER(B20),LN(B20),"") -> 7.4363758 | H20: =LN(C20) -> 4.8543608 | I20: =IF(AND(ISNUMBER(G20),ISNUMBER(G16)),G20-G16,"") -> 1.4782059 | J20: =H20-H16 -> -0.21378284
... A89: 2026Q1 | B89: 536.22222 | C89: 92.688617 | D89: 0.0053681849 | E89: 0.024694045 | G89: =IF(ISNUMBER(B89),LN(B89),"") -> 6.2845487 | H89: =LN(C89) -> 4.5292457 | I89: =IF(AND(ISNUMBER(G89),ISNUMBER(G85)),G89-G85,"") -> -0.24419616 | J89: =H89-H85 -> 0.14206562
B90: EMBI 2005Q1-Q2 estaba codificado como 0 en el origen: es un faltante, no un dato.

Sheet Modelo_Nuevo
A1: MODELO PROPUESTO — GDP(t) ~ D4lnITCRM(t) + D4lnEMBI(t-1) + M3R(t-2)
A2: Todas las variables bajo el mismo filtro D4log(.) que la dependiente. Rezagos elegidos por minimizacion de BIC sobre una grilla 0-8.
A5: Periodo | B5: y = GDP | C5: x1 D4lnITCRM(t) | D5: x2 D4lnEMBI(t-1) | E5: x3 M3R(t-2) | F5: D_2020Q2 | G5: D_2020Q3 | H5: D_2020Q4 | I5: D_2021Q1 | J5: D_2021Q2 | K5: const=1 | L5: residuo e | M5: h_const | N5: h_x1 | O5: h_x2 | P5: h_x3 | Q5: e^2 | R5: residuo e (dummies) | S5: e^2 (dummies)
A6: =Datos!A12 -> 2006Q4 | B6: =Datos!E12 -> 0.096770404 | C6: =Datos!J12 -> -0.0019108998 | D6: =Datos!I11 -> -0.19907832 | E6: =Datos!D10 -> 0.048520637 | F6: =IF($A6="2020Q2",1,0) -> 0 | G6: =IF($A6="2020Q3",1,0) -> 0 | H6: =IF($A6="2020Q4",1,0) -> 0 | I6: =IF($A6="2021Q1",1,0) -> 0 | J6: =IF($A6="2021Q2",1,0) -> 0 | K6: 1 | L6: =B6-($B$92+$B$93*C6+$B$94*D6+$B$95*E6) -> 0.062269099 | M6: =K6*$L6 -> 0.062269099 | N6: =C6*$L6 -> -0.00011899001 | O6: =D6*$L6 -> -0.012396427 | P6: =E6*$L6 -> 0.0030213363 | Q6: =L6^2 -> 0.0038774407 | R6: =B6-($B$164+$B$165*C6+$B$166*D6+$B$167*E6+$B$168*F6+$B$169*G6+$B$170*H6+$B$171*I6+$B$172*J6) -> 0.062904401 | S6: =R6^2 -> 0.0039569637
A7: =Datos!A13 -> 2007Q1 | B7: =Datos!E13 -> 0.083589411 | C7: =Datos!J13 -> -0.02153676 | D7: =Datos!I12 -> -0.40749439 | E7: =Datos!D11 -> 0.06474531 | F7: =IF($A7="2020Q2",1,0) -> 0 | G7: =IF($A7="2020Q3",1,0) -> 0 | H7: =IF($A7="2020Q4",1,0) -> 0 | I7: =IF($A7="2021Q1",1,0) -> 0 | J7: =IF($A7="2021Q2",1,0) -> 0 | K7: 1 | L7: =B7-($B$92+$B$93*C7+$B$94*D7+$B$95*E7) -> 0.031333226 | M7: =K7*$L7 -> 0.031333226 | N7: =C7*$L7 -> -0.00067481618 | O7: =D7*$L7 -> -0.012768114 | P7: =E7*$L7 -> 0.0020286795 | Q7: =L7^2 -> 0.00098177107 | R7: =B7-($B$164+$B$165*C7+$B$166*D7+$B$167*E7+$B$168*F7+$B$169*G7+$B$170*H7+$B$171*I7+$B$172*J7) -> 0.034398277 | S7: =R7^2 -> 0.0011832415
A8: =Datos!A14 -> 2007Q2 | B8: =Datos!E14 -> 0.098593874 | C8: =Datos!J14 -> -0.024862684 | D8: =Datos!I13 -> -0.62896681 | E8: =Datos!D12 -> 0.092447249 | F8: =IF($A8="2020Q2",1,0) -> 0 | G8: =IF($A8="2020Q3",1,0) -> 0 | H8: =IF($A8="2020Q4",1,0) -> 0 | I8: =IF($A8="2021Q1",1,0) -> 0 | J8: =IF($A8="2021Q2",1,0) -> 0 | K8: 1 | L8: =B8-($B$92+$B$93*C8+$B$94*D8+$B$95*E8) -> 0.028171721 | M8: =K8*$L8 -> 0.028171721 | N8: =C8*$L8 -> -0.00070042461 | O8: =D8*$L8 -> -0.017719078 | P8: =E8*$L8 -> 0.0026043981 | Q8: =L8^2 -> 0.00079364588 | R8: =B8-($B$164+$B$165*C8+$B$166*D8+$B$167*E8+$B$168*F8+$B$169*G8+$B$170*H8+$B$171*I8+$B$172*J8) -> 0.034071969 | S8: =R8^2 -> 0.0011608991
A9: =Datos!A15 -> 2007Q3 | B9: =Datos!E15 -> 0.084277977 | C9: =Datos!J15 -> -0.051888871 | D9: =Datos!I14 -> -0.27606314 | E9: =Datos!D13 -> 0.1266018 | F9: =IF($A9="2020Q2",1,0) -> 0 | G9: =IF($A9="2020Q3",1,0) -> 0 | H9: =IF($A9="2020Q4",1,0) -> 0 | I9: =IF($A9="2021Q1",1,0) -> 0 | J9: =IF($A9="2021Q2",1,0) -> 0 | K9: 1 | L9: =B9-($B$92+$B$93*C9+$B$94*D9+$B$95*E9) -> 0.023977826 | M9: =K9*$L9 -> 0.023977826 | N9: =C9*$L9 -> -0.0012441823 | O9: =D9*$L9 -> -0.0066193939 | P9: =E9*$L9 -> 0.0030356359 | Q9: =L9^2 -> 0.00057493614 | R9: =B9-($B$164+$B$165*C9+$B$166*D9+$B$167*E9+$B$168*F9+$B$169*G9+$B$170*H9+$B$171*I9+$B$172*J9) -> 0.026716341 | S9: =R9^2 -> 0.00071376285
A10: =Datos!A16 -> 2007Q4 | B10: =Datos!E16 -> 0.092673486 | C10: =Datos!J16 -> -0.029015053 | D10: =Datos!I15 -> 0.20245337 | E10: =Datos!D14 -> 0.11396594 | F10: =IF($A10="2020Q2",1,0) -> 0 | G10: =IF($A10="2020Q3",1,0) -> 0 | H10: =IF($A10="2020Q4",1,0) -> 0 | I10: =IF($A10="2021Q1",1,0) -> 0 | J10: =IF($A10="2021Q2",1,0) -> 0 | K10: 1 | L10: =B10-($B$92+$B$93*C10+$B$94*D10+$B$95*E10) -> 0.065449787 | M10: =K10*$L10 -> 0.065449787 | N10: =C10*$L10 -> -0.001899029 | O10: =D10*$L10 -> 0.01325053 | P10: =E10*$L10 -> 0.0074590465 | Q10: =L10^2 -> 0.0042836747 | R10: =B10-($B$164+$B$165*C10+$B$166*D10+$B$167*E10+$B$168*F10+$B$169*G10+$B$170*H10+$B$171*I10+$B$172*J10) -> 0.062996329 | S10: =R10^2 -> 0.0039685375
A11: =Datos!A17 -> 2008Q1 | B11: =Datos!E17 -> 0.069123146 | C11: =Datos!J17 -> -0.024624979 | D11: =Datos!I16 -> 0.31730851 | E11: =Datos!D15 -> 0.089343321 | F11: =IF($A11="2020Q2",1,0) -> 0 | G11: =IF($A11="2020Q3",1,0) -> 0 | H11: =IF($A11="2020Q4",1,0) -> 0 | I11: =IF($A11="2021Q1",1,0) -> 0 | J11: =IF($A11="2021Q2",1,0) -> 0 | K11: 1 | L11: =B11-($B$92+$B$93*C11+$B$94*D11+$B$95*E11) -> 0.053555189 | M11: =K11*$L11 -> 0.053555189 | N11: =C11*$L11 -> -0.0013187954 | O11: =D11*$L11 -> 0.016993517 | P11: =E11*$L11 -> 0.0047847984 | Q11: =L11^2 -> 0.0028681583 | R11: =B11-($B$164+$B$165*C11+$B$166*D11+$B$167*E11+$B$168*F11+$B$169*G11+$B$170*H11+$B$171*I11+$B$172*J11) -> 0.049448598 | S11: =R11^2 -> 0.0024451638
A12: =Datos!A18 -> 2008Q2 | B12: =Datos!E18 -> 0.054526855 | C12: =Datos!J18 -> -0.058310111 | D12: =Datos!I17 -> 0.83000136 | E12: =Datos!D16 -> 0.037973687 | F12: =IF($A12="2020Q2",1,0) -> 0 | G12: =IF($A12="2020Q3",1,0) -> 0 | H12: =IF($A12="2020Q4",1,0) -> 0 | I12: =IF($A12="2021Q1",1,0) -> 0 | J12: =IF($A12="2021Q2",1,0) -> 0 | K12: 1 | L12: =B12-($B$92+$B$93*C12+$B$94*D12+$B$95*E12) -> 0.072627681 | M12: =K12*$L12 -> 0.072627681 | N12: =C12*$L12 -> -0.0042349282 | O12: =D12*$L12 -> 0.060281074 | P12: =E12*$L12 -> 0.0027579408 | Q12: =L12^2 -> 0.00527478 | R12: =B12-($B$164+$B$165*C12+$B$166*D12+$B$167*E12+$B$168*F12+$B$169*G12+$B$170*H12+$B$171*I12+$B$172*J12) -> 0.062059641 | S12: =R12^2 -> 0.003851399
A13: =Datos!A19 -> 2008Q3 | B13: =Datos!E19 -> 0.060060161 | C13: =Datos!J19 -> -0.099409929 | D13: =Datos!I18 -> 0.72951743 | E13: =Datos!D17 -> 0.0057682917 | F13: =IF($A13="2020Q2",1,0) -> 0 | G13: =IF($A13="2020Q3",1,0) -> 0 | H13: =IF($A13="2020Q4",1,0) -> 0 | I13: =IF($A13="2021Q1",1,0) -> 0 | J13: =IF($A13="2021Q2",1,0) -> 0 | K13: 1 | L13: =B13-($B$92+$B$93*C13+$B$94*D13+$B$95*E13) -> 0.072134475 | M13: =K13*$L13 -> 0.072134475 | N13: =C13*$L13 -> -0.007170883 | O13: =D13*$L13 -> 0.052623357 | P13: =E13*$L13 -> 0.0004160927 | Q13: =L13^2 -> 0.0052033825 | R13: =B13-($B$164+$B$165*C13+$B$166*D13+$B$167*E13+$B$168*F13+$B$169*G13+$B$170*H13+$B$171*I13+$B$172*J13) -> 0.061885794 | S13: =R13^2 -> 0.0038298515
A14: =Datos!A20 -> 2008Q4 | B14: =Datos!E20 -> -0.019789909 | C14: =Datos!J20 -> -0.21378284 | D14: =Datos!I19 -> 0.51795036 | E14: =Datos!D18 -> -0.041444326 | F14: =IF($A14="2020Q2",1,0) -> 0 | G14: =IF($A14="2020Q3",1,0) -> 0 | H14: =IF($A14="2020Q4",1,0) -> 0 | I14: =IF($A14="2021Q1",1,0) -> 0 | J14: =IF($A14="2021Q2",1,0) -> 0 | K14: 1 | L14: =B14-($B$92+$B$93*C14+$B$94*D14+$B$95*E14) -> -0.028202193 | M14: =K14*$L14 -> -0.028202193 | N14: =C14*$L14 -> 0.0060291449 | O14: =D14*$L14 -> -0.014607336 | P14: =E14*$L14 -> 0.0011688209 | Q14: =L14^2 -> 0.00079536371 | R14: =B14-($B$164+$B$165*C14+$B$166*D14+$B$167*E14+$B$168*F14+$B$169*G14+$B$170*H14+$B$171*I14+$B$172*J14) -> -0.037485561 | S14: =R14^2 -> 0.0014051673
A15: =Datos!A21 -> 2009Q1 | B15: =Datos!E21 -> -0.061887551 | C15: =Datos!J21 -> -0.18189845 | D15: =Datos!I20 -> 1.4782059 | E15: =Datos!D19 -> -0.031056134 | F15: =IF($A15="2020Q2",1,0) -> 0 | G15: =IF($A15="2020Q3",1,0) -> 0 | H15: =IF($A15="2020Q4",1,0) -> 0 | I15: =IF($A15="2021Q1",1,0) -> 0 | J15: =IF($A15="2021Q2",1,0) -> 0 | K15: 1 | L15: =B15-($B$92+$B$93*C15+$B$94*D15+$B$95*E15) -> -0.012409195 | M15: =K15*$L15 -> -0.012409195 | N15: =C15*$L15 -> 0.0022572134 | O15: =D15*$L15 -> -0.018343346 | P15: =E15*$L15 -> 0.00038538163 | Q15: =L15^2 -> 0.00015398813 | R15: =B15-($B$164+$B$165*C15+$B$166*D15+$B$167*E15+$B$168*F15+$B$169*G15+$B$170*H15+$B$171*I15+$B$172*J15) -> -0.031489971 | S15: =R15^2 -> 0.00099161829
A16: =Datos!A22 -> 2009Q2 | B16: =Datos!E22 -> -0.11274547 | C16: =Datos!J22 -> -0.06846215 | D16: =Datos!I21 -> 1.2599804 | E16: =Datos!D20 -> -0.043350325 | F16: =IF($A16="2020Q2",1,0) -> 0 | G16: =IF($A16="2020Q3",1,0) -> 0 | H16: =IF($A16="2020Q4",1,0) -> 0 | I16: =IF($A16="2021Q1",1,0) -> 0 | J16: =IF($A16="2021Q2",1,0) -> 0 | K16: 1 | L16: =B16-($B$92+$B$93*C16+$B$94*D16+$B$95*E16) -> -0.056873328 | M16: =K16*$L16 -> -0.056873328 | N16: =C16*$L16 -> 0.0038936703 | O16: =D16*$L16 -> -0.071659279 | P16: =E16*$L16 -> 0.0024654772 | Q16: =L16^2 -> 0.0032345754 | R16: =B16-($B$164+$B$165*C16+$B$166*D16+$B$167*E16+$B$168*F16+$B$169*G16+$B$170*H16+$B$171*I16+$B$172*J16) -> -0.073515064 | S16: =R16^2 -> 0.0054044646
A17: =Datos!A23 -> 2009Q3 | B17: =Datos!E23 -> -0.0565118 | C17: =Datos!J23 -> 0.054680944 | D17: =Datos!I22 -> 0.9612717 | E17: =Datos!D21 -> -0.093991254 | F17: =IF($A17="2020Q2",1,0) -> 0 | G17: =IF($A17="2020Q3",1,0) -> 0 | H17: =IF($A17="2020Q4",1,0) -> 0 | I17: =IF($A17="2021Q1",1,0) -> 0 | J17: =IF($A17="2021Q2",1,0) -> 0 | K17: 1 | L17: =B17-($B$92+$B$93*C17+$B$94*D17+$B$95*E17) -> 0.0094569176 | M17: =K17*$L17 -> 0.0094569176 | N17: =C17*$L17 -> 0.00051711318 | O17: =D17*$L17 -> 0.0090906672 | P17: =E17*$L17 -> -0.00088886755 | Q17: =L17^2 -> 8.943329e-05 | R17: =B17-($B$164+$B$165*C17+$B$166*D17+$B$167*E17+$B$168*F17+$B$169*G17+$B$170*H17+$B$171*I17+$B$172*J17) -> -0.0045838578 | S17: =R17^2 -> 2.1011752e-05
... A83: =Datos!A89 -> 2026Q1 | B83: =Datos!E89 -> 0.024694045 | C83: =Datos!J89 -> 0.14206562 | D83: =Datos!I88 -> -0.20074313 | E83: =Datos!D87 -> 0.18005331 | F83: =IF($A83="2020Q2",1,0) -> 0 | G83: =IF($A83="2020Q3",1,0) -> 0 | H83: =IF($A83="2020Q4",1,0) -> 0 | I83: =IF($A83="2021Q1",1,0) -> 0 | J83: =IF($A83="2021Q2",1,0) -> 0 | K83: 1 | L83: =B83-($B$92+$B$93*C83+$B$94*D83+$B$95*E83) -> -0.012338018 | M83: =K83*$L83 -> -0.012338018 | N83: =C83*$L83 -> -0.0017528081 | O83: =D83*$L83 -> 0.0024767723 | P83: =E83*$L83 -> -0.0022215009 | Q83: =L83^2 -> 0.00015222668 | R83: =B83-($B$164+$B$165*C83+$B$166*D83+$B$167*E83+$B$168*F83+$B$169*G83+$B$170*H83+$B$171*I83+$B$172*J83) -> -0.0087532003 | S83: =R83^2 -> 7.6618515e-05
A90: A. ESTIMACION OLS (sin dummies)
A91: Regresor | B91: Coef. | C91: Error est. | D91: t | E91: p-valor | F91: =INDEX(LINEST($B$6:$B$83,$C$6:$E$83,TRUE(),TRUE()),4,2) -> 74
A92: const | B92: =INDEX(LINEST($B$6:$B$83,$C$6:$E$83,TRUE(),TRUE()),1,4) -> 0.014087706 | C92: =INDEX(LINEST($B$6:$B$83,$C$6:$E$83,TRUE(),TRUE()),2,4) -> 0.004917568 | D92: =B92/C92 -> 2.8647709 | E92: =TDIST(ABS(D92),$F$91,2) -> 0.0054282164
A93: x1 D4lnITCRM(t) | B93: =INDEX(LINEST($B$6:$B$83,$C$6:$E$83,TRUE(),TRUE()),1,3) -> -0.14720768 | C93: =INDEX(LINEST($B$6:$B$83,$C$6:$E$83,TRUE(),TRUE()),2,3) -> 0.035660499 | D93: =B93/C93 -> -4.128032 | E93: =TDIST(ABS(D93),$F$91,2) -> 9.4960173e-05
A94: x2 D4lnEMBI(t-1) | B94: =INDEX(LINEST($B$6:$B$83,$C$6:$E$83,TRUE(),TRUE()),1,2) -> -0.057342281 | C94: =INDEX(LINEST($B$6:$B$83,$C$6:$E$83,TRUE(),TRUE()),2,2) -> 0.0090344109 | D94: =B94/C94 -> -6.3470969 | E94: =TDIST(ABS(D94),$F$91,2) -> 1.578403e-08
A95: x3 M3R(t-2) | B95: =INDEX(LINEST($B$6:$B$83,$C$6:$E$83,TRUE(),TRUE()),1,1) -> 0.17964923 | C95: =INDEX(LINEST($B$6:$B$83,$C$6:$E$83,TRUE(),TRUE()),2,1) -> 0.038491378 | D95: =B95/C95 -> 4.6672588 | E95: =TDIST(ABS(D95),$F$91,2) -> 1.3293458e-05
A97: B. BONDAD DE AJUSTE
A98: n (observaciones) | B98: =COUNT($B$6:$B$83) -> 78
A99: k (parametros) | B99: 4
A100: R2 | B100: =INDEX(LINEST($B$6:$B$83,$C$6:$E$83,TRUE(),TRUE()),3,1) -> 0.53929008
A101: R2 ajustado | B101: =1-(1-B100)*(B98-1)/(B98-B99) -> 0.52061265
A102: SSR | B102: =INDEX(LINEST($B$6:$B$83,$C$6:$E$83,TRUE(),TRUE()),5,2) -> 0.13234696
A103: log-verosimilitud | B103: =-B98/2*(LN(2*PI())+LN(B102/B98)+1) -> 138.10524
A104: AIC | B104: =-2*B103+2*B99 -> -268.21049
A105: BIC | B105: =-2*B103+LN(B98)*B99 -> -258.78365
A107: C. ERRORES ESTANDAR HAC (Newey-West, Bartlett, L=4)
A108: Obligatorio: el filtro interanual induce una MA(3) mecanica en los residuos. Sandwich V = (X'X)^-1 S (X'X)^-1 con S = G0 + SUM w_l (G_l + G_l').
A110: X'X
B111: =SUMPRODUCT($K$6:$K$83,$K$6:$K$83) -> 78 | C111: =SUMPRODUCT($K$6:$K$83,$C$6:$C$83) -> -2.316177 | D111: =SUMPRODUCT($K$6:$K$83,$D$6:$D$83) -> 2.5819915 | E111: =SUMPRODUCT($K$6:$K$83,$E$6:$E$83) -> 0.0834787
B112: =SUMPRODUCT($C$6:$C$83,$K$6:$K$83) -> -2.316177 | C112: =SUMPRODUCT($C$6:$C$83,$C$6:$C$83) -> 1.4999404 | D112: =SUMPRODUCT($C$6:$C$83,$D$6:$D$83) -> 0.043202423 | E112: =SUMPRODUCT($C$6:$C$83,$E$6:$E$83) -> 0.1653893
B113: =SUMPRODUCT($D$6:$D$83,$K$6:$K$83) -> 2.5819915 | C113: =SUMPRODUCT($D$6:$D$83,$C$6:$C$83) -> 0.043202423 | D113: =SUMPRODUCT($D$6:$D$83,$D$6:$D$83) -> 22.538104 | E113: =SUMPRODUCT($D$6:$D$83,$E$6:$E$83) -> -0.79309673
B114: =SUMPRODUCT($E$6:$E$83,$K$6:$K$83) -> 0.0834787 | C114: =SUMPRODUCT($E$6:$E$83,$C$6:$C$83) -> 0.1653893 | D114: =SUMPRODUCT($E$6:$E$83,$D$6:$D$83) -> -0.79309673 | E114: =SUMPRODUCT($E$6:$E$83,$E$6:$E$83) -> 1.2561418
A115: (X'X)^-1 = A
B116: =INDEX(MINVERSE($B$111:$E$114),1,1) -> 0.013521302 | C116: =INDEX(MINVERSE($B$111:$E$114),1,2) -> 0.021463248 | D116: =INDEX(MINVERSE($B$111:$E$114),1,3) -> -0.0017603313 | E116: =INDEX(MINVERSE($B$111:$E$114),1,4) -> -0.0048359549
...

Sheet Modelo_Base
A1: MODELO BASE — GDP(t) ~ EMBI(t) + ITCRM(t-2) + EMBI(t-5) + M3R(t)
A2: EMBI e ITCRM entran en NIVEL: regresion no balanceada (I(1) contra I(0)).
A5: Periodo | B5: y = GDP | C5: EMBI(t) | D5: ITCRM(t-2) | E5: EMBI(t-5) | F5: M3R(t) | G5: residuo e | H5: e^2 | I5: EMBI(t)-EMBI(t-5) | K5: R: EMBI(t)-EMBI(t-5) | L5: R: ITCRM(t-2) | M5: R: M3R(t)
A6: =Datos!A12 -> 2006Q4 | B6: =Datos!E12 -> 0.096770404 | C6: =Datos!B12 -> 281.70526 | D6: =Datos!C10 -> 166.01956 | E6: =Datos!B7 -> 413.72934 | F6: =Datos!D12 -> 0.092447249 | G6: =B6-($B$92+$B$93*C6+$B$94*D6+$B$95*E6+$B$96*F6) -> 0.016864131 | H6: =G6^2 -> 0.00028439892 | I6: =C6-E6 -> -132.02409 | K6: =I6 -> -132.02409 | L6: =D6 -> 166.01956 | M6: =F6 -> 0.092447249
A7: =Datos!A13 -> 2007Q1 | B7: =Datos!E13 -> 0.083589411 | C7: =Datos!B13 -> 210.27944 | D7: =Datos!C11 -> 165.95339 | E7: =Datos!B8 -> 423.41625 | F7: =Datos!D13 -> 0.1266018 | G7: =B7-($B$92+$B$93*C7+$B$94*D7+$B$95*E7+$B$96*F7) -> -0.0034817816 | H7: =G7^2 -> 1.2122803e-05 | I7: =C7-E7 -> -213.13681 | K7: =I7 -> -213.13681 | L7: =D7 -> 165.95339 | M7: =F7 -> 0.1266018
A8: =Datos!A14 -> 2007Q2 | B8: =Datos!E14 -> 0.098593874 | C8: =Datos!B14 -> 268.38567 | D8: =Datos!C12 -> 163.55654 | E8: =Datos!B9 -> 394.41518 | F8: =Datos!D14 -> 0.11396594 | G8: =B8-($B$92+$B$93*C8+$B$94*D8+$B$95*E8+$B$96*F8) -> 0.019275497 | H8: =G8^2 -> 0.00037154479 | I8: =C8-E8 -> -126.02951 | K8: =I8 -> -126.02951 | L8: =D8 -> 163.55654 | M8: =F8 -> 0.11396594
A9: =Datos!A15 -> 2007Q3 | B9: =Datos!E15 -> 0.084277977 | C9: =Datos!B15 -> 415.12806 | D9: =Datos!C13 -> 163.25891 | E9: =Datos!B10 -> 353.71381 | F9: =Datos!D15 -> 0.089343321 | G9: =B9-($B$92+$B$93*C9+$B$94*D9+$B$95*E9+$B$96*F9) -> 0.016881327 | H9: =G9^2 -> 0.0002849792 | I9: =C9-E9 -> 61.414254 | K9: =I9 -> 61.414254 | L9: =D9 -> 163.25891 | M9: =F9 -> 0.089343321
A10: =Datos!A16 -> 2007Q4 | B10: =Datos!E16 -> 0.092673486 | C10: =Datos!B16 -> 386.90139 | D10: =Datos!C14 -> 161.94276 | E10: =Datos!B11 -> 339.04529 | F10: =Datos!D16 -> 0.037973687 | G10: =B10-($B$92+$B$93*C10+$B$94*D10+$B$95*E10+$B$96*F10) -> 0.030663087 | H10: =G10^2 -> 0.00094022493 | I10: =C10-E10 -> 47.856101 | K10: =I10 -> 47.856101 | L10: =D10 -> 161.94276 | M10: =F10 -> 0.037973687
A11: =Datos!A17 -> 2008Q1 | B11: =Datos!E17 -> 0.069123146 | C11: =Datos!B17 -> 482.23843 | D11: =Datos!C15 -> 157.56185 | E11: =Datos!B12 -> 281.70526 | F11: =Datos!D17 -> 0.0057682917 | G11: =B11-($B$92+$B$93*C11+$B$94*D11+$B$95*E11+$B$96*F11) -> 0.02182297 | H11: =G11^2 -> 0.00047624203 | I11: =C11-E11 -> 200.53317 | K11: =I11 -> 200.53317 | L11: =D11 -> 157.56185 | M11: =F11 -> 0.0057682917
A12: =Datos!A18 -> 2008Q2 | B12: =Datos!E18 -> 0.054526855 | C12: =Datos!B18 -> 556.6532 | D12: =Datos!C16 -> 158.87912 | E12: =Datos!B13 -> 210.27944 | F12: =Datos!D18 -> -0.041444326 | G12: =B12-($B$92+$B$93*C12+$B$94*D12+$B$95*E12+$B$96*F12) -> 0.017786848 | H12: =G12^2 -> 0.00031637195 | I12: =C12-E12 -> 346.37377 | K12: =I12 -> 346.37377 | L12: =D12 -> 158.87912 | M12: =F12 -> -0.041444326
A13: =Datos!A19 -> 2008Q3 | B13: =Datos!E19 -> 0.060060161 | C13: =Datos!B19 -> 696.82717 | D13: =Datos!C17 -> 159.28776 | E13: =Datos!B14 -> 268.38567 | F13: =Datos!D19 -> -0.031056134 | G13: =B13-($B$92+$B$93*C13+$B$94*D13+$B$95*E13+$B$96*F13) -> 0.025903168 | H13: =G13^2 -> 0.00067097412 | I13: =C13-E13 -> 428.44151 | K13: =I13 -> 428.44151 | L13: =D13 -> 159.28776 | M13: =F13 -> -0.031056134
A14: =Datos!A20 -> 2008Q4 | B14: =Datos!E20 -> -0.019789909 | C14: =Datos!B20 -> 1696.5902 | D14: =Datos!C18 -> 152.76989 | E14: =Datos!B15 -> 415.12806 | F14: =Datos!D20 -> -0.043350325 | G14: =B14-($B$92+$B$93*C14+$B$94*D14+$B$95*E14+$B$96*F14) -> -0.0049710301 | H14: =G14^2 -> 2.471114e-05 | I14: =C14-E14 -> 1281.4622 | K14: =I14 -> 1281.4622 | L14: =D14 -> 152.76989 | M14: =F14 -> -0.043350325
A15: =Datos!A21 -> 2009Q1 | B15: =Datos!E21 -> -0.061887551 | C15: =Datos!B21 -> 1700.0604 | D15: =Datos!C19 -> 142.65201 | E15: =Datos!B16 -> 386.90139 | F15: =Datos!D21 -> -0.093991254 | G15: =B15-($B$92+$B$93*C15+$B$94*D15+$B$95*E15+$B$96*F15) -> -0.031381972 | H15: =G15^2 -> 0.00098482817 | I15: =C15-E15 -> 1313.159 | K15: =I15 -> 1313.159 | L15: =D15 -> 142.65201 | M15: =F15 -> -0.093991254
A16: =Datos!A22 -> 2009Q2 | B16: =Datos!E22 -> -0.11274547 | C16: =Datos!B22 -> 1455.6592 | D16: =Datos!C20 -> 128.29866 | E16: =Datos!B17 -> 482.23843 | F16: =Datos!D22 -> -0.12102494 | G16: =B16-($B$92+$B$93*C16+$B$94*D16+$B$95*E16+$B$96*F16) -> -0.083462068 | H16: =G16^2 -> 0.0069659168 | I16: =C16-E16 -> 973.42076 | K16: =I16 -> 973.42076 | L16: =D16 -> 128.29866 | M16: =F16 -> -0.12102494
A17: =Datos!A23 -> 2009Q3 | B17: =Datos!E23 -> -0.0565118 | C17: =Datos!B23 -> 921.66961 | D17: =Datos!C21 -> 132.79598 | E17: =Datos!B18 -> 556.6532 | F17: =Datos!D23 -> -0.10212969 | G17: =B17-($B$92+$B$93*C17+$B$94*D17+$B$95*E17+$B$96*F17) -> -0.063338832 | H17: =G17^2 -> 0.0040118077 | I17: =C17-E17 -> 365.01641 | K17: =I17 -> 365.01641 | L17: =D17 -> 132.79598 | M17: =F17 -> -0.10212969
... A83: =Datos!A89 -> 2026Q1 | B83: =Datos!E89 -> 0.024694045 | C83: =Datos!B89 -> 536.22222 | D83: =Datos!C87 -> 95.3862 | E83: =Datos!B84 -> 920.4 | F83: =Datos!D89 -> 0.0053681849 | G83: =B83-($B$92+$B$93*C83+$B$94*D83+$B$95*E83+$B$96*F83) -> 0.0044987522 | H83: =G83^2 -> 2.0238772e-05 | I83: =C83-E83 -> -384.17778 | K83: =I83 -> -384.17778 | L83: =D83 -> 95.3862 | M83: =F83 -> 0.0053681849
A90: A. ESTIMACION OLS
A91: Regresor | B91: Coef. | C91: Error est. | D91: t | E91: p-valor | F91: =INDEX(LINEST($B$6:$B$83,$C$6:$F$83,TRUE(),TRUE()),4,2) -> 73
A92: const | B92: =INDEX(LINEST($B$6:$B$83,$C$6:$F$83,TRUE(),TRUE()),1,5) -> -0.089025409 | C92: =INDEX(LINEST($B$6:$B$83,$C$6:$F$83,TRUE(),TRUE()),2,5) -> 0.030346164 | D92: =B92/C92 -> -2.9336627 | E92: =TDIST(ABS(D92),$F$91,2) -> 0.0044739479
A93: EMBI(t) | B93: =INDEX(LINEST($B$6:$B$83,$C$6:$F$83,TRUE(),TRUE()),1,4) -> -4.9382446e-05 | C93: =INDEX(LINEST($B$6:$B$83,$C$6:$F$83,TRUE(),TRUE()),2,4) -> 9.2052546e-06 | D93: =B93/C93 -> -5.3645932 | E93: =TDIST(ABS(D93),$F$91,2) -> 9.1458604e-07
A94: ITCRM(t-2) | B94: =INDEX(LINEST($B$6:$B$83,$C$6:$F$83,TRUE(),TRUE()),1,3) -> 0.00092094807 | C94: =INDEX(LINEST($B$6:$B$83,$C$6:$F$83,TRUE(),TRUE()),2,3) -> 0.00023028734 | D94: =B94/C94 -> 3.999126 | E94: =TDIST(ABS(D94),$F$91,2) -> 0.00015064669
A95: EMBI(t-5) | B95: =INDEX(LINEST($B$6:$B$83,$C$6:$F$83,TRUE(),TRUE()),1,2) -> 5.1447117e-05 | C95: =INDEX(LINEST($B$6:$B$83,$C$6:$F$83,TRUE(),TRUE()),2,2) -> 9.22251e-06 | D95: =B95/C95 -> 5.578429 | E95: =TDIST(ABS(D95),$F$91,2) -> 3.8888742e-07
A96: M3R(t) | B96: =INDEX(LINEST($B$6:$B$83,$C$6:$F$83,TRUE(),TRUE()),1,1) -> 0.09370104 | C96: =INDEX(LINEST($B$6:$B$83,$C$6:$F$83,TRUE(),TRUE()),2,1) -> 0.042376222 | D96: =B96/C96 -> 2.2111702 | E96: =TDIST(ABS(D96),$F$91,2) -> 0.030156026
A98: B. BONDAD DE AJUSTE
A99: n (observaciones) | B99: =COUNT($B$6:$B$83) -> 78
A100: k (parametros) | B100: 5
A101: R2 | B101: =INDEX(LINEST($B$6:$B$83,$C$6:$F$83,TRUE(),TRUE()),3,1) -> 0.44752378
A102: R2 ajustado | B102: =1-(1-B101)*(B99-1)/(B99-B100) -> 0.41725111
A103: SSR | B103: =INDEX(LINEST($B$6:$B$83,$C$6:$F$83,TRUE(),TRUE()),5,2) -> 0.15870843
A104: log-verosimilitud | B104: =-B99/2*(LN(2*PI())+LN(B103/B99)+1) -> 131.02121
A105: AIC | B105: =-2*B104+2*B100 -> -252.04243
A106: BIC | B106: =-2*B104+LN(B99)*B100 -> -240.25888
A108: C. TEST F: H0 = beta_EMBI(t) + beta_EMBI(t-5) = 0
A109: Si no se rechaza, los dos terminos en nivel son de hecho UNA diferencia (EMBI(t)-EMBI(t-5)): el modelo gasta un grado de libertad de mas.
A110: SSR modelo sin restringir | B110: =B103 -> 0.15870843
A111: SSR modelo restringido | B111: =INDEX(LINEST($B$6:$B$83,$K$6:$M$83,TRUE(),TRUE()),5,2) -> 0.15880626
A112: q (restricciones) | B112: 1
A113: gl residuales | B113: =F91 -> 73
A114: F | B114: =((B111-B110)/B112)/(B110/B113) -> 0.044999739
A115: p-valor | B115: =FDIST(B114,B112,B113) -> 0.8325957

Sheet Diagnosticos
A1: DIAGNOSTICOS DE RESIDUOS
A2: Durbin-Watson, autocorrelacion muestral, Breusch-Pagan y Jarque-Bera.
A4: A. AUTOCORRELACION
A5: Durbin-Watson | B5: Modelo Base | C5: Modelo Nuevo | D5: Nuevo + dummies
B6: =SUMXMY2(Modelo_Base!G7:G83,Modelo_Base!G6:G82)/SUMSQ(Modelo_Base!G6:G83) -> 0.83140737 | C6: =SUMXMY2(Modelo_Nuevo!L7:L83,Modelo_Nuevo!L6:L82)/SUMSQ(Modelo_Nuevo!L6:L83) -> 1.0801443 | D6: =SUMXMY2(Modelo_Nuevo!R7:R83,Modelo_Nuevo!R6:R82)/SUMSQ(Modelo_Nuevo!R6:R83) -> 0.90488717
A8: Autocorrelacion muestral de los residuos
A9: Rezago | B9: Base | C9: Nuevo | E9: Los rezagos 1-3 grandes y el 4 negativo son la firma de la MA(3) que induce el filtro interanual, no evidencia de mala especificacion. Por eso se reportan errores HAC y el n efectivo es ~n/4.
A10: 1 | B10: =SUMPRODUCT(Modelo_Base!G7:G83,Modelo_Base!G6:G82)/SUMSQ(Modelo_Base!G6:G83) -> 0.58333657 | C10: =SUMPRODUCT(Modelo_Nuevo!L7:L83,Modelo_Nuevo!L6:L82)/SUMSQ(Modelo_Nuevo!L6:L83) -> 0.44470396
A11: 2 | B11: =SUMPRODUCT(Modelo_Base!G8:G83,Modelo_Base!G6:G81)/SUMSQ(Modelo_Base!G6:G83) -> 0.26676373 | C11: =SUMPRODUCT(Modelo_Nuevo!L8:L83,Modelo_Nuevo!L6:L81)/SUMSQ(Modelo_Nuevo!L6:L83) -> 0.32822879
A12: 3 | B12: =SUMPRODUCT(Modelo_Base!G9:G83,Modelo_Base!G6:G80)/SUMSQ(Modelo_Base!G6:G83) -> -0.030533375 | C12: =SUMPRODUCT(Modelo_Nuevo!L9:L83,Modelo_Nuevo!L6:L80)/SUMSQ(Modelo_Nuevo!L6:L83) -> 0.15875222
A13: 4 | B13: =SUMPRODUCT(Modelo_Base!G10:G83,Modelo_Base!G6:G79)/SUMSQ(Modelo_Base!G6:G83) -> -0.30153034 | C13: =SUMPRODUCT(Modelo_Nuevo!L10:L83,Modelo_Nuevo!L6:L79)/SUMSQ(Modelo_Nuevo!L6:L83) -> -0.21352499
A14: 5 | B14: =SUMPRODUCT(Modelo_Base!G11:G83,Modelo_Base!G6:G78)/SUMSQ(Modelo_Base!G6:G83) -> -0.19833704 | C14: =SUMPRODUCT(Modelo_Nuevo!L11:L83,Modelo_Nuevo!L6:L78)/SUMSQ(Modelo_Nuevo!L6:L83) -> -0.024001251
A15: 6 | B15: =SUMPRODUCT(Modelo_Base!G12:G83,Modelo_Base!G6:G77)/SUMSQ(Modelo_Base!G6:G83) -> -0.1973862 | C15: =SUMPRODUCT(Modelo_Nuevo!L12:L83,Modelo_Nuevo!L6:L77)/SUMSQ(Modelo_Nuevo!L6:L83) -> -0.066205419
A16: 7 | B16: =SUMPRODUCT(Modelo_Base!G13:G83,Modelo_Base!G6:G76)/SUMSQ(Modelo_Base!G6:G83) -> -0.15510588 | C16: =SUMPRODUCT(Modelo_Nuevo!L13:L83,Modelo_Nuevo!L6:L76)/SUMSQ(Modelo_Nuevo!L6:L83) -> 0.087436379
A17: 8 | B17: =SUMPRODUCT(Modelo_Base!G14:G83,Modelo_Base!G6:G75)/SUMSQ(Modelo_Base!G6:G83) -> -0.16398231 | C17: =SUMPRODUCT(Modelo_Nuevo!L14:L83,Modelo_Nuevo!L6:L75)/SUMSQ(Modelo_Nuevo!L6:L83) -> 0.098962499
A19: B. HETEROCEDASTICIDAD — Breusch-Pagan (LM = n x R2 de e^2 sobre X)
A20: Modelo | B20: R2 auxiliar | C20: LM | D20: gl | E20: p-valor
A21: Base | B21: =INDEX(LINEST(Modelo_Base!$H$6:$H$83,Modelo_Base!$C$6:$F$83,TRUE(),TRUE()),3,1) -> 0.31024617 | C21: =78*B21 -> 24.199201 | D21: 4 | E21: =CHIDIST(C21,D21) -> 7.2856501e-05
A22: Nuevo | B22: =INDEX(LINEST(Modelo_Nuevo!$Q$6:$Q$83,Modelo_Nuevo!$C$6:$E$83,TRUE(),TRUE()),3,1) -> 0.04803908 | C22: =78*B22 -> 3.7470483 | D22: 3 | E22: =CHIDIST(C22,D22) -> 0.29010568
A23: Nuevo + dummies | B23: =INDEX(LINEST(Modelo_Nuevo!$S$6:$S$83,Modelo_Nuevo!$C$6:$J$83,TRUE(),TRUE()),3,1) -> 0.059456431 | C23: =78*B23 -> 4.6376016 | D23: 8 | E23: =CHIDIST(C23,D23) -> 0.79551386
A26: C. NORMALIDAD — Jarque-Bera
A27: Modelo | B27: Asimetria | C27: Curtosis exc. | D27: JB | E27: p-valor
A28: Base | B28: =SKEW(Modelo_Base!$G$6:$G$83) -> -0.029780401 | C28: =KURT(Modelo_Base!$G$6:$G$83) -> 0.72579659 | D28: =78/6*(B28^2+C28^2/4) -> 1.7235666 | E28: =CHIDIST(D28,2) -> 0.42240814
A29: Nuevo | B29: =SKEW(Modelo_Nuevo!$L$6:$L$83) -> 0.011086507 | C29: =KURT(Modelo_Nuevo!$L$6:$L$83) -> -0.12333506 | D29: =78/6*(B29^2+C29^2/4) -> 0.051035335 | E29: =CHIDIST(D29,2) -> 0.97480516
