Workbook

Sheet Resumen
A1: MODELO DE PBI — 6 VARIABLES (EMBI, GPN, VITI, M3R)
A2: Muestra 2007Q2-2026Q1 (n=76) en los tres modelos.
A4: Metrica | B4: ACTUAL d(PBI) | C4: ACTUAL + dummies COVID | D4: REZAGOS BIC d(PBI) | E4: ADL PBI en nivel | F4: ADL + dummies COVID
A5: n | B5: =Modelo_Actual!B97 -> 76 | C5: =Modelo_COVID!B99 -> 76 | D5: =Rezagos_BIC!B97 -> 76 | E5: =Modelo_ADL!B98 -> 76 | F5: =ADL_COVID!B100 -> 76
A6: k (parametros) | B6: =Modelo_Actual!B98 -> 7 | C6: =Modelo_COVID!B100 -> 9 | D6: =Rezagos_BIC!B98 -> 7 | E6: =Modelo_ADL!B99 -> 8 | F6: =ADL_COVID!B101 -> 10
A7: R2 | B7: =Modelo_Actual!B99 -> 0.50022065 | C7: =Modelo_COVID!B101 -> 0.63678404 | D7: =Rezagos_BIC!B99 -> 0.53286398 | E7: =Modelo_ADL!B100 -> 0.74331494 | F7: =ADL_COVID!B102 -> 0.83631975
A8: R2 ajustado | B8: =Modelo_Actual!B100 -> 0.45676157 | C8: =Modelo_COVID!B102 -> 0.59341497 | D8: =Rezagos_BIC!B100 -> 0.49224346 | E8: =Modelo_ADL!B101 -> 0.71689147 | F8: =ADL_COVID!B103 -> 0.81399972
A9: SSR | B9: =Modelo_Actual!B101 -> 0.077263395 | C9: =Modelo_COVID!B103 -> 0.056151375 | D9: =Rezagos_BIC!B101 -> 0.072216898 | E9: =Modelo_ADL!B102 -> 0.070874291 | F9: =ADL_COVID!B104 -> 0.045194377
A10: AIC | B10: =Modelo_Actual!B103 -> -294.05774 | C10: =Modelo_COVID!B105 -> -314.31459 | D10: =Rezagos_BIC!B103 -> -299.19125 | E10: =Modelo_ADL!B104 -> -298.61749 | F10: =ADL_COVID!B106 -> -328.81255
A11: BIC | B11: =Modelo_Actual!B104 -> -277.7426 | C11: =Modelo_COVID!B106 -> -293.33799 | D11: =Rezagos_BIC!B104 -> -282.87612 | E11: =Modelo_ADL!B105 -> -279.97162 | F11: =ADL_COVID!B107 -> -305.50522
A12: Durbin-Watson | B12: =Modelo_Actual!B106 -> 2.1484731 | C12: =Modelo_COVID!B108 -> 1.9633109 | D12: =Rezagos_BIC!B106 -> 2.0279652 | E12: =Modelo_ADL!B107 -> 2.1160134 | F12: =ADL_COVID!B109 -> 1.9624859
A13: Autocorrel. residuos rezago 4 | B13: =Diagnosticos!B9 -> -0.46796055 | C13: =Diagnosticos!C9 -> -0.42131253 | D13: =Diagnosticos!E9 -> -0.36184538 | E13: =Diagnosticos!D9 -> -0.50257175 | F13: =Diagnosticos!F9 -> -0.45643969
A14: Breusch-Pagan p | B14: =Diagnosticos!E19 -> 0.043180836 | C14: =Diagnosticos!E20 -> 0.12373875 | D14: =Diagnosticos!E22 -> 0.019193558 | E14: =Diagnosticos!E21 -> 0.066492279 | F14: =Diagnosticos!E23 -> 0.054074223
A15: Test F de las dummies COVID (H0: ambas = 0) | B15: F / p -> | C15: =Modelo_COVID!B220 -> 12.595465 | D15: =Modelo_COVID!B221 -> 2.2722249e-05
A16: AIC, BIC y R2 de la columna ADL NO son comparables con las otras dos: la variable dependiente es distinta (PBI en nivel vs. su diferencia). Para compararlas se usa el test F de abajo.
A18: Contraste decisivo: conviene diferenciar el PBI?
A19: H0: el coeficiente de PBI(t-1) es igual a 1 (= diferenciar la dependiente) | B19: sin dummies | C19: con dummies
A20: F | B20: =Modelo_ADL!B115 -> 6.1299957 | C20: =ADL_COVID!B232 -> 16.001146
A21: p-valor | B21: =Modelo_ADL!B116 -> 0.0157859 | C21: =ADL_COVID!B233 -> 0.00016254492
A23: Coeficientes de la especificacion recomendada (ADL + dummies), errores HAC (Newey-West, L=4)
A24: Regresor | B24: Coef. | C24: se HAC | D24: t HAC | E24: p HAC
A25: =ADL_COVID!A214 -> const | B25: =ADL_COVID!B214 -> 0.0043873779 | C25: =ADL_COVID!C214 -> 0.002922833 | D25: =ADL_COVID!D214 -> 1.5010703 | E25: =ADL_COVID!E214 -> 0.13810658
A26: =ADL_COVID!A215 -> d(M3R) t | B26: =ADL_COVID!B215 -> 0.19773407 | C26: =ADL_COVID!C215 -> 0.051443948 | D26: =ADL_COVID!D215 -> 3.84368 | E26: =ADL_COVID!E215 -> 0.00027506184
A27: =ADL_COVID!A216 -> d(EMBI) t | B27: =ADL_COVID!B216 -> -2.7488042e-05 | C27: =ADL_COVID!C216 -> 1.2754228e-05 | D27: =ADL_COVID!D216 -> -2.1552102 | E27: =ADL_COVID!E216 -> 0.034797517
A28: =ADL_COVID!A217 -> d(EMBI) t-2 | B28: =ADL_COVID!B217 -> -5.0135604e-05 | C28: =ADL_COVID!C217 -> 1.363676e-05 | D28: =ADL_COVID!D217 -> -3.6765041 | E28: =ADL_COVID!E217 -> 0.00047655385
A29: =ADL_COVID!A218 -> d(EMBI) t-6 | B29: =ADL_COVID!B218 -> 2.2106438e-05 | C29: =ADL_COVID!C218 -> 1.5297515e-05 | D29: =ADL_COVID!D218 -> 1.4450999 | E29: =ADL_COVID!E218 -> 0.15316125
A30: =ADL_COVID!A219 -> d(GPN) t-6 | B30: =ADL_COVID!B219 -> -0.077211698 | C30: =ADL_COVID!C219 -> 0.019967803 | D30: =ADL_COVID!D219 -> -3.86681 | E30: =ADL_COVID!E219 -> 0.00025465941
A31: =ADL_COVID!A220 -> d(VITI) t-7 | B31: =ADL_COVID!B220 -> 0.11750335 | C31: =ADL_COVID!C220 -> 0.029579869 | D31: =ADL_COVID!D220 -> 3.9724093 | E31: =ADL_COVID!E220 -> 0.00017857236
A32: =ADL_COVID!A221 -> PBI t-1 | B32: =ADL_COVID!B221 -> 0.77322057 | C32: =ADL_COVID!C221 -> 0.056156988 | D32: =ADL_COVID!D221 -> 13.768911 | E32: =ADL_COVID!E221 -> 4.4626516e-21
A33: =ADL_COVID!A222 -> D_2020Q2 | B33: =ADL_COVID!B222 -> -0.1452701 | C33: =ADL_COVID!C222 -> 0.020382753 | D33: =ADL_COVID!D222 -> -7.1271089 | E33: =ADL_COVID!E222 -> 9.6215134e-10
A34: =ADL_COVID!A223 -> D_2021Q2 | B34: =ADL_COVID!B223 -> 0.14866773 | C34: =ADL_COVID!C223 -> 0.015901867 | D34: =ADL_COVID!D223 -> 9.349074 | E34: =ADL_COVID!E223 -> 1.0476197e-13
A37: COMO USAR ESTE ARCHIVO
A38: 1. Editable solo lo azul de la hoja Datos (EMBI, M3R, GPN, VITI, GDP). Todo lo demas es formula.
A39: 2. Para agregar un trimestre: extender las filas de Datos y de cada hoja de modelo, y recalcular.
A40: 3. Las regresiones usan INDEX(LINEST(...)) para devolver escalares, sin formulas matriciales.
A41: 4. AIC y BIC siguen la convencion de statsmodels: -2logL + 2k y -2logL + ln(n)k.
A42: 5. Cita los errores HAC, no los de LINEST: hay autocorrelacion residual en el rezago 4.

Sheet Datos
A1: DATOS Y PRIMERAS DIFERENCIAS
A2: Azul = dato original (editable). Negro = formula. Trimestral 2005Q1-2026Q1.
A3: EMBI 2005Q1-Q2 venia codificado como 0 en el origen: se trata como faltante. GDP, M3R, GPN y VITI ya vienen como variacion interanual; d(.) las diferencia una vez mas.
A4: Periodo | B4: EMBI (pb) | C4: M3R | D4: GPN | E4: VITI | F4: GDP | H4: d(EMBI) | I4: d(M3R) | J4: d(GPN) | K4: d(VITI) | L4: d(GDP)
A5: 2005Q1 | C5: 0.1262661 | D5: 0.19626135 | E5: -0.091076176 | F5: 0.072187868
A6: 2005Q2 | C6: 0.16505259 | D6: 0.24378613 | E6: -0.092873553 | F6: 0.13077981 | H6: =IF(AND(ISNUMBER(B6),ISNUMBER(B5)),B6-B5,"") | I6: =C6-C5 -> 0.038786492 | J6: =D6-D5 -> 0.047524776 | K6: =E6-E5 -> -0.0017973767 | L6: =F6-F5 -> 0.05859194
A7: 2005Q3 | B7: 413.72934 | C7: 0.083135769 | D7: 0.24758358 | E7: 0.022351191 | F7: 0.069719779 | H7: =IF(AND(ISNUMBER(B7),ISNUMBER(B6)),B7-B6,"") | I7: =C7-C6 -> -0.081916822 | J7: =D7-D6 -> 0.0037974481 | K7: =E7-E6 -> 0.11522474 | L7: =F7-F6 -> -0.061060029
A8: 2005Q4 | B8: 423.41625 | C8: 0.066830714 | D8: 0.18229946 | E8: 0.041704235 | F8: 0.077828945 | H8: =IF(AND(ISNUMBER(B8),ISNUMBER(B7)),B8-B7,"") -> 9.6869022 | I8: =C8-C7 -> -0.016305055 | J8: =D8-D7 -> -0.065284118 | K8: =E8-E7 -> 0.019353043 | L8: =F8-F7 -> 0.0081091663
A9: 2006Q1 | B9: 394.41518 | C9: 0.024910905 | D9: 0.28693314 | E9: 0.066973169 | F9: 0.078495711 | H9: =IF(AND(ISNUMBER(B9),ISNUMBER(B8)),B9-B8,"") -> -29.001068 | I9: =C9-C8 -> -0.041919809 | J9: =D9-D8 -> 0.10463368 | K9: =E9-E8 -> 0.025268935 | L9: =F9-F8 -> 0.0006667657
A10: 2006Q2 | B10: 353.71381 | C10: 0.048520637 | D10: 0.2540691 | E10: 0.067706744 | F10: 0.055715853 | H10: =IF(AND(ISNUMBER(B10),ISNUMBER(B9)),B10-B9,"") -> -40.701368 | I10: =C10-C9 -> 0.023609732 | J10: =D10-D9 -> -0.032864038 | K10: =E10-E9 -> 0.00073357525 | L10: =F10-F9 -> -0.022779858
A11: 2006Q3 | B11: 339.04529 | C11: 0.06474531 | D11: 0.28130623 | E11: 0.018443079 | F11: 0.093804903 | H11: =IF(AND(ISNUMBER(B11),ISNUMBER(B10)),B11-B10,"") -> -14.668524 | I11: =C11-C10 -> 0.016224674 | J11: =D11-D10 -> 0.027237131 | K11: =E11-E10 -> -0.049263666 | L11: =F11-F10 -> 0.03808905
A12: 2006Q4 | B12: 281.70526 | C12: 0.092447249 | D12: 0.30014681 | E12: 0.0287149 | F12: 0.096770404 | H12: =IF(AND(ISNUMBER(B12),ISNUMBER(B11)),B12-B11,"") -> -57.340028 | I12: =C12-C11 -> 0.027701939 | J12: =D12-D11 -> 0.018840582 | K12: =E12-E11 -> 0.010271822 | L12: =F12-F11 -> 0.002965501
A13: 2007Q1 | B13: 210.27944 | C13: 0.1266018 | D13: 0.3354463 | E13: 0.068186259 | F13: 0.083589411 | H13: =IF(AND(ISNUMBER(B13),ISNUMBER(B12)),B13-B12,"") -> -71.425823 | I13: =C13-C12 -> 0.034154549 | J13: =D13-D12 -> 0.03529949 | K13: =E13-E12 -> 0.039471358 | L13: =F13-F12 -> -0.013180992
A14: 2007Q2 | B14: 268.38567 | C14: 0.11396594 | D14: 0.34084552 | E14: 0.026535251 | F14: 0.098593874 | H14: =IF(AND(ISNUMBER(B14),ISNUMBER(B13)),B14-B13,"") -> 58.106231 | I14: =C14-C13 -> -0.012635858 | J14: =D14-D13 -> 0.0053992196 | K14: =E14-E13 -> -0.041651007 | L14: =F14-F13 -> 0.015004463
A15: 2007Q3 | B15: 415.12806 | C15: 0.089343321 | D15: 0.44092854 | E15: 0.0081467198 | F15: 0.084277977 | H15: =IF(AND(ISNUMBER(B15),ISNUMBER(B14)),B15-B14,"") -> 146.7424 | I15: =C15-C14 -> -0.024622619 | J15: =D15-D14 -> 0.10008301 | K15: =E15-E14 -> -0.018388531 | L15: =F15-F14 -> -0.014315897
A16: 2007Q4 | B16: 386.90139 | C16: 0.037973687 | D16: 0.36017815 | E16: 0.13455358 | F16: 0.092673486 | H16: =IF(AND(ISNUMBER(B16),ISNUMBER(B15)),B16-B15,"") -> -28.226676 | I16: =C16-C15 -> -0.051369633 | J16: =D16-D15 -> -0.08075039 | K16: =E16-E15 -> 0.12640686 | L16: =F16-F15 -> 0.0083955092
A17: 2008Q1 | B17: 482.23843 | C17: 0.0057682917 | D17: 0.34656181 | E17: 0.22926803 | F17: 0.069123146 | H17: =IF(AND(ISNUMBER(B17),ISNUMBER(B16)),B17-B16,"") -> 95.337039 | I17: =C17-C16 -> -0.032205396 | J17: =D17-D16 -> -0.013616332 | K17: =E17-E16 -> 0.094714456 | L17: =F17-F16 -> -0.023550341
A18: 2008Q2 | B18: 556.6532 | C18: -0.041444326 | D18: 0.39823908 | E18: 0.14032077 | F18: 0.054526855 | H18: =IF(AND(ISNUMBER(B18),ISNUMBER(B17)),B18-B17,"") -> 74.414777 | I18: =C18-C17 -> -0.047212617 | J18: =D18-D17 -> 0.051677263 | K18: =E18-E17 -> -0.088947266 | L18: =F18-F17 -> -0.014596291
... A89: 2026Q1 | B89: 536.22222 | C89: 0.0053681849 | D89: 0.35 | E89: 0 | F89: 0.024694045 | H89: =IF(AND(ISNUMBER(B89),ISNUMBER(B88)),B89-B88,"") -> -216.77778 | I89: =C89-C88 -> -0.099649603 | J89: =D89-D88 -> 0.086823623 | K89: =E89-E88 -> 0.010107087 | L89: =F89-F88 -> 0.0041135381

Sheet Modelo_Actual
A1: MODELO ACTUAL — d(PBI) ~ d(M3R) + d(EMBI) + d(EMBI t-2) + d(EMBI t-6) + d(GPN t-6) + d(VITI t-7)
A2: Especificacion tal cual la usas. Muestra 2007Q2-2026Q1 (n=76), la primera con todos los rezagos disponibles.
A5: Periodo | B5: y | C5: d(M3R) t | D5: d(EMBI) t | E5: d(EMBI) t-2 | F5: d(EMBI) t-6 | G5: d(GPN) t-6 | H5: d(VITI) t-7 | I5: const=1 | J5: residuo e | K5: e^2 | L5: h_0 | M5: h_1 | N5: h_2 | O5: h_3 | P5: h_4 | Q5: h_5 | R5: h_6
A6: =Datos!A14 -> 2007Q2 | B6: =Datos!L14 -> 0.015004463 | C6: =Datos!I14 -> -0.012635858 | D6: =Datos!H14 -> 58.106231 | E6: =Datos!H12 -> -57.340028 | F6: =Datos!H8 -> 9.6869022 | G6: =Datos!J8 -> -0.065284118 | H6: =Datos!K7 -> 0.11522474 | I6: 1 | J6: =B6-($B$88+$B$89*C6+$B$90*D6+$B$91*E6+$B$92*F6+$B$93*G6+$B$94*H6) -> -0.01435158 | K6: =J6^2 -> 0.00020596785 | L6: =I6*$J6 -> -0.01435158 | M6: =C6*$J6 -> 0.00018134453 | N6: =D6*$J6 -> -0.83391622 | O6: =E6*$J6 -> 0.82291999 | P6: =F6*$J6 -> -0.13902235 | Q6: =G6*$J6 -> 0.00093693024 | R6: =H6*$J6 -> -0.0016536571
A7: =Datos!A15 -> 2007Q3 | B7: =Datos!L15 -> -0.014315897 | C7: =Datos!I15 -> -0.024622619 | D7: =Datos!H15 -> 146.7424 | E7: =Datos!H13 -> -71.425823 | F7: =Datos!H9 -> -29.001068 | G7: =Datos!J9 -> 0.10463368 | H7: =Datos!K8 -> 0.019353043 | I7: 1 | J7: =B7-($B$88+$B$89*C7+$B$90*D7+$B$91*E7+$B$92*F7+$B$93*G7+$B$94*H7) -> 0.00090397528 | K7: =J7^2 -> 8.171713e-07 | L7: =I7*$J7 -> 0.00090397528 | M7: =C7*$J7 -> -2.2258239e-05 | N7: =D7*$J7 -> 0.1326515 | O7: =E7*$J7 -> -0.064567178 | P7: =F7*$J7 -> -0.026216249 | Q7: =G7*$J7 -> 9.4586258e-05 | R7: =H7*$J7 -> 1.7494673e-05
A8: =Datos!A16 -> 2007Q4 | B8: =Datos!L16 -> 0.0083955092 | C8: =Datos!I16 -> -0.051369633 | D8: =Datos!H16 -> -28.226676 | E8: =Datos!H14 -> 58.106231 | F8: =Datos!H10 -> -40.701368 | G8: =Datos!J10 -> -0.032864038 | H8: =Datos!K9 -> 0.025268935 | I8: 1 | J8: =B8-($B$88+$B$89*C8+$B$90*D8+$B$91*E8+$B$92*F8+$B$93*G8+$B$94*H8) -> 0.0065178475 | K8: =J8^2 -> 4.2482336e-05 | L8: =I8*$J8 -> 0.0065178475 | M8: =C8*$J8 -> -0.00033481944 | N8: =D8*$J8 -> -0.18397717 | O8: =E8*$J8 -> 0.37872755 | P8: =F8*$J8 -> -0.26528531 | Q8: =G8*$J8 -> -0.00021420278 | R8: =H8*$J8 -> 0.00016469906
A9: =Datos!A17 -> 2008Q1 | B9: =Datos!L17 -> -0.023550341 | C9: =Datos!I17 -> -0.032205396 | D9: =Datos!H17 -> 95.337039 | E9: =Datos!H15 -> 146.7424 | F9: =Datos!H11 -> -14.668524 | G9: =Datos!J11 -> 0.027237131 | H9: =Datos!K10 -> 0.00073357525 | I9: 1 | J9: =B9-($B$88+$B$89*C9+$B$90*D9+$B$91*E9+$B$92*F9+$B$93*G9+$B$94*H9) -> -0.0033027563 | K9: =J9^2 -> 1.0908199e-05 | L9: =I9*$J9 -> -0.0033027563 | M9: =C9*$J9 -> 0.00010636657 | N9: =D9*$J9 -> -0.31487501 | O9: =E9*$J9 -> -0.48465438 | P9: =F9*$J9 -> 0.048446559 | Q9: =G9*$J9 -> -8.9957608e-05 | R9: =H9*$J9 -> -2.4228203e-06
A10: =Datos!A18 -> 2008Q2 | B10: =Datos!L18 -> -0.014596291 | C10: =Datos!I18 -> -0.047212617 | D10: =Datos!H18 -> 74.414777 | E10: =Datos!H16 -> -28.226676 | F10: =Datos!H12 -> -57.340028 | G10: =Datos!J12 -> 0.018840582 | H10: =Datos!K11 -> -0.049263666 | I10: 1 | J10: =B10-($B$88+$B$89*C10+$B$90*D10+$B$91*E10+$B$92*F10+$B$93*G10+$B$94*H10) -> 0.0048824658 | K10: =J10^2 -> 2.3838472e-05 | L10: =I10*$J10 -> 0.0048824658 | M10: =C10*$J10 -> -0.00023051399 | N10: =D10*$J10 -> 0.3633276 | O10: =E10*$J10 -> -0.13781578 | P10: =F10*$J10 -> -0.27996072 | Q10: =G10*$J10 -> 9.1988495e-05 | R10: =H10*$J10 -> -0.00024052816
A11: =Datos!A19 -> 2008Q3 | B11: =Datos!L19 -> 0.0055333067 | C11: =Datos!I19 -> 0.010388192 | D11: =Datos!H19 -> 140.17397 | E11: =Datos!H17 -> 95.337039 | F11: =Datos!H13 -> -71.425823 | G11: =Datos!J13 -> 0.03529949 | H11: =Datos!K12 -> 0.010271822 | I11: 1 | J11: =B11-($B$88+$B$89*C11+$B$90*D11+$B$91*E11+$B$92*F11+$B$93*G11+$B$94*H11) -> 0.022744447 | K11: =J11^2 -> 0.00051730986 | L11: =I11*$J11 -> 0.022744447 | M11: =C11*$J11 -> 0.00023627368 | N11: =D11*$J11 -> 3.1881794 | O11: =E11*$J11 -> 2.1683882 | P11: =F11*$J11 -> -1.6245408 | Q11: =G11*$J11 -> 0.00080286738 | R11: =H11*$J11 -> 0.0002336269
A12: =Datos!A20 -> 2008Q4 | B12: =Datos!L20 -> -0.07985007 | C12: =Datos!I20 -> -0.012294191 | D12: =Datos!H20 -> 999.76307 | E12: =Datos!H18 -> 74.414777 | F12: =Datos!H14 -> 58.106231 | G12: =Datos!J14 -> 0.0053992196 | H12: =Datos!K13 -> 0.039471358 | I12: 1 | J12: =B12-($B$88+$B$89*C12+$B$90*D12+$B$91*E12+$B$92*F12+$B$93*G12+$B$94*H12) -> -0.020166994 | K12: =J12^2 -> 0.00040670766 | L12: =I12*$J12 -> -0.020166994 | M12: =C12*$J12 -> 0.00024793687 | N12: =D12*$J12 -> -20.162216 | O12: =E12*$J12 -> -1.5007224 | P12: =F12*$J12 -> -1.171828 | Q12: =G12*$J12 -> -0.00010888603 | R12: =H12*$J12 -> -0.00079601865
A13: =Datos!A21 -> 2009Q1 | B13: =Datos!L21 -> -0.042097643 | C13: =Datos!I21 -> -0.05064093 | D13: =Datos!H21 -> 3.4701679 | E13: =Datos!H19 -> 140.17397 | F13: =Datos!H15 -> 146.7424 | G13: =Datos!J15 -> 0.10008301 | H13: =Datos!K14 -> -0.041651007 | I13: 1 | J13: =B13-($B$88+$B$89*C13+$B$90*D13+$B$91*E13+$B$92*F13+$B$93*G13+$B$94*H13) -> -0.015997317 | K13: =J13^2 -> 0.00025591414 | L13: =I13*$J13 -> -0.015997317 | M13: =C13*$J13 -> 0.00081011899 | N13: =D13*$J13 -> -0.055513375 | O13: =E13*$J13 -> -2.2424074 | P13: =F13*$J13 -> -2.3474846 | Q13: =G13*$J13 -> -0.0016010597 | R13: =H13*$J13 -> 0.00066630436
A14: =Datos!A22 -> 2009Q2 | B14: =Datos!L22 -> -0.05085792 | C14: =Datos!I22 -> -0.027033683 | D14: =Datos!H22 -> -244.40122 | E14: =Datos!H20 -> 999.76307 | F14: =Datos!H16 -> -28.226676 | G14: =Datos!J16 -> -0.08075039 | H14: =Datos!K15 -> -0.018388531 | I14: 1 | J14: =B14-($B$88+$B$89*C14+$B$90*D14+$B$91*E14+$B$92*F14+$B$93*G14+$B$94*H14) -> -0.0085854664 | K14: =J14^2 -> 7.3710233e-05 | L14: =I14*$J14 -> -0.0085854664 | M14: =C14*$J14 -> 0.00023209678 | N14: =D14*$J14 -> 2.0982985 | O14: =E14*$J14 -> -8.5834322 | P14: =F14*$J14 -> 0.24233918 | Q14: =G14*$J14 -> 0.00069327976 | R14: =H14*$J14 -> 0.00015787412
A15: =Datos!A23 -> 2009Q3 | B15: =Datos!L23 -> 0.056233672 | C15: =Datos!I23 -> 0.01889525 | D15: =Datos!H23 -> -533.98958 | E15: =Datos!H21 -> 3.4701679 | F15: =Datos!H17 -> 95.337039 | G15: =Datos!J17 -> -0.013616332 | H15: =Datos!K16 -> 0.12640686 | I15: 1 | J15: =B15-($B$88+$B$89*C15+$B$90*D15+$B$91*E15+$B$92*F15+$B$93*G15+$B$94*H15) -> -0.0095721105 | K15: =J15^2 -> 9.1625299e-05 | L15: =I15*$J15 -> -0.0095721105 | M15: =C15*$J15 -> -0.00018086742 | N15: =D15*$J15 -> 5.1114073 | O15: =E15*$J15 -> -0.033216831 | P15: =F15*$J15 -> -0.91257667 | Q15: =G15*$J15 -> 0.00013033703 | R15: =H15*$J15 -> -0.0012099804
A16: =Datos!A24 -> 2009Q4 | B16: =Datos!L24 -> 0.059331782 | C16: =Datos!I24 -> 0.020266082 | D16: =Datos!H24 -> -203.74584 | E16: =Datos!H22 -> -244.40122 | F16: =Datos!H18 -> 74.414777 | G16: =Datos!J18 -> 0.051677263 | H16: =Datos!K17 -> 0.094714456 | I16: 1 | J16: =B16-($B$88+$B$89*C16+$B$90*D16+$B$91*E16+$B$92*F16+$B$93*G16+$B$94*H16) -> 0.013454586 | K16: =J16^2 -> 0.00018102588 | L16: =I16*$J16 -> 0.013454586 | M16: =C16*$J16 -> 0.00027267173 | N16: =D16*$J16 -> -2.7413158 | O16: =E16*$J16 -> -3.2883172 | P16: =F16*$J16 -> 1.00122 | Q16: =G16*$J16 -> 0.00069529617 | R16: =H16*$J16 -> 0.0012743438
A17: =Datos!A25 -> 2010Q1 | B17: =Datos!L25 -> 0.054312709 | C17: =Datos!I25 -> 0.036485145 | D17: =Datos!H25 -> 15.441636 | E17: =Datos!H23 -> -533.98958 | F17: =Datos!H19 -> 140.17397 | G17: =Datos!J19 -> -0.092266092 | H17: =Datos!K18 -> -0.088947266 | I17: 1 | J17: =B17-($B$88+$B$89*C17+$B$90*D17+$B$91*E17+$B$92*F17+$B$93*G17+$B$94*H17) -> 0.019053047 | K17: =J17^2 -> 0.00036301861 | L17: =I17*$J17 -> 0.019053047 | M17: =C17*$J17 -> 0.00069515319 | N17: =D17*$J17 -> 0.29421022 | O17: =E17*$J17 -> -10.174129 | P17: =F17*$J17 -> 2.6707413 | Q17: =G17*$J17 -> -0.0017579502 | R17: =H17*$J17 -> -0.0016947165
... A81: =Datos!A89 -> 2026Q1 | B81: =Datos!L89 -> 0.0041135381 | C81: =Datos!I89 -> -0.099649603 | D81: =Datos!H89 -> -216.77778 | E81: =Datos!H87 -> 142.30769 | F81: =Datos!H83 -> 140.77357 | G81: =Datos!J83 -> -0.11430199 | H81: =Datos!K82 -> 0.0075734887 | I81: 1 | J81: =B81-($B$88+$B$89*C81+$B$90*D81+$B$91*E81+$B$92*F81+$B$93*G81+$B$94*H81) -> -0.012647556 | K81: =J81^2 -> 0.00015996068 | L81: =I81*$J81 -> -0.012647556 | M81: =C81*$J81 -> 0.001260324 | N81: =D81*$J81 -> 2.7417092 | O81: =E81*$J81 -> -1.7998446 | P81: =F81*$J81 -> -1.7804417 | Q81: =G81*$J81 -> 0.0014456409 | R81: =H81*$J81 -> -9.5786125e-05
A86: A. ESTIMACION OLS (LINEST devuelve los coeficientes en orden inverso; se extraen con INDEX)
A87: Regresor | B87: Coef. | C87: Error est. | D87: t | E87: p-valor | G87: gl residuales | H87: =INDEX(LINEST($B$6:$B$81,$C$6:$H$81,TRUE(),TRUE()),4,2) -> 69
A88: const | B88: =INDEX(LINEST($B$6:$B$81,$C$6:$H$81,TRUE(),TRUE()),1,7) -> 0.0013190503 | C88: =INDEX(LINEST($B$6:$B$81,$C$6:$H$81,TRUE(),TRUE()),2,7) -> 0.0038807022 | D88: =B88/C88 -> 0.33989989 | E88: =TDIST(ABS(D88),$H$87,2) -> 0.73496444
A89: d(M3R) t | B89: =INDEX(LINEST($B$6:$B$81,$C$6:$H$81,TRUE(),TRUE()),1,6) -> 0.091517054 | C89: =INDEX(LINEST($B$6:$B$81,$C$6:$H$81,TRUE(),TRUE()),2,6) -> 0.0513891 | D89: =B89/C89 -> 1.7808651 | E89: =TDIST(ABS(D89),$H$87,2) -> 0.079336081
A90: d(EMBI) t | B90: =INDEX(LINEST($B$6:$B$81,$C$6:$H$81,TRUE(),TRUE()),1,5) -> -6.4190805e-05 | C90: =INDEX(LINEST($B$6:$B$81,$C$6:$H$81,TRUE(),TRUE()),2,5) -> 1.3290071e-05 | D90: =B90/C90 -> -4.8299823 | E90: =TDIST(ABS(D90),$H$87,2) -> 7.9302611e-06
A91: d(EMBI) t-2 | B91: =INDEX(LINEST($B$6:$B$81,$C$6:$H$81,TRUE(),TRUE()),1,4) -> -6.1513158e-05 | C91: =INDEX(LINEST($B$6:$B$81,$C$6:$H$81,TRUE(),TRUE()),2,4) -> 1.4020588e-05 | D91: =B91/C91 -> -4.387345 | E91: =TDIST(ABS(D91),$H$87,2) -> 4.0290863e-05
A92: d(EMBI) t-6 | B92: =INDEX(LINEST($B$6:$B$81,$C$6:$H$81,TRUE(),TRUE()),1,3) -> 3.56561e-05 | C92: =INDEX(LINEST($B$6:$B$81,$C$6:$H$81,TRUE(),TRUE()),2,3) -> 1.4290254e-05 | D92: =B92/C92 -> 2.4951342 | E92: =TDIST(ABS(D92),$H$87,2) -> 0.014987528
A93: d(GPN) t-6 | B93: =INDEX(LINEST($B$6:$B$81,$C$6:$H$81,TRUE(),TRUE()),1,2) -> -0.11336554 | C93: =INDEX(LINEST($B$6:$B$81,$C$6:$H$81,TRUE(),TRUE()),2,2) -> 0.032193393 | D93: =B93/C93 -> -3.5213917 | E93: =TDIST(ABS(D93),$H$87,2) -> 0.00076572832
A94: d(VITI) t-7 | B94: =INDEX(LINEST($B$6:$B$81,$C$6:$H$81,TRUE(),TRUE()),1,1) -> 0.18789143 | C94: =INDEX(LINEST($B$6:$B$81,$C$6:$H$81,TRUE(),TRUE()),2,1) -> 0.059715505 | D94: =B94/C94 -> 3.1464429 | E94: =TDIST(ABS(D94),$H$87,2) -> 0.0024397968
A96: B. BONDAD DE AJUSTE
A97: n (observaciones) | B97: =COUNT($B$6:$B$81) -> 76
A98: k (parametros) | B98: 7
A99: R2 | B99: =INDEX(LINEST($B$6:$B$81,$C$6:$H$81,TRUE(),TRUE()),3,1) -> 0.50022065
A100: R2 ajustado | B100: =1-(1-B99)*(B97-1)/(B97-B98) -> 0.45676157
A101: SSR | B101: =INDEX(LINEST($B$6:$B$81,$C$6:$H$81,TRUE(),TRUE()),5,2) -> 0.077263395
A102: log-verosimilitud | B102: =-B97/2*(LN(2*PI())+LN(B101/B97)+1) -> 154.02887
A103: AIC | B103: =-2*B102+2*B98 -> -294.05774
A104: BIC | B104: =-2*B102+LN(B97)*B98 -> -277.7426
A106: Durbin-Watson | B106: =SUMXMY2(J7:J81,J6:J80)/SUMSQ(J6:J81) -> 2.1484731
A108: C. ERRORES ESTANDAR HAC (Newey-West, nucleo de Bartlett, L=4)
A109: V = (X'X)^-1 S (X'X)^-1 , S = G0 + SUM_l w_l (G_l + G_l') , w_l = 1 - l/5
A110: X'X
B111: =SUMPRODUCT($I$6:$I$81,$I$6:$I$81) -> 76 | C111: =SUMPRODUCT($I$6:$I$81,$C$6:$C$81) -> -0.12123361 | D111: =SUMPRODUCT($I$6:$I$81,$D$6:$D$81) -> 325.94279 | E111: =SUMPRODUCT($I$6:$I$81,$E$6:$E$81) -> 527.10856 | F111: =SUMPRODUCT($I$6:$I$81,$F$6:$F$81) -> 1070.8161 | G111: =SUMPRODUCT($I$6:$I$81,$G$6:$G$81) -> 1.2903792 | H111: =SUMPRODUCT($I$6:$I$81,$H$6:$H$81) -> 0.071327431
B112: =SUMPRODUCT($C$6:$C$81,$I$6:$I$81) -> -0.12123361 | C112: =SUMPRODUCT($C$6:$C$81,$C$6:$C$81) -> 0.49396366 | D112: =SUMPRODUCT($C$6:$C$81,$D$6:$D$81) -> -213.84407 | E112: =SUMPRODUCT($C$6:$C$81,$E$6:$E$81) -> 536.0929 | F112: =SUMPRODUCT($C$6:$C$81,$F$6:$F$81) -> -258.35727 | G112: =SUMPRODUCT($C$6:$C$81,$G$6:$G$81) -> 0.07043989 | H112: =SUMPRODUCT($C$6:$C$81,$H$6:$H$81) -> -0.03686038
...

Sheet Modelo_COVID
A1: MODELO ACTUAL + DUMMIES IMPULSO COVID (2020Q2 y 2021Q2)
A2: Los dos trimestres atipicos en d(PBI): el derrumbe (2020Q2) y el rebote por efecto base (2021Q2). Una dummy impulso es equivalente a excluir esa observacion, pero conserva n y no rompe los rezagos.
A5: Periodo | B5: y | C5: d(M3R) t | D5: d(EMBI) t | E5: d(EMBI) t-2 | F5: d(EMBI) t-6 | G5: d(GPN) t-6 | H5: d(VITI) t-7 | I5: D_2020Q2 | J5: D_2021Q2 | K5: const=1 | L5: residuo e | M5: e^2 | N5: h_0 | O5: h_1 | P5: h_2 | Q5: h_3 | R5: h_4 | S5: h_5 | T5: h_6 | U5: h_7 | V5: h_8
A6: =Datos!A14 -> 2007Q2 | B6: =Datos!L14 -> 0.015004463 | C6: =Datos!I14 -> -0.012635858 | D6: =Datos!H14 -> 58.106231 | E6: =Datos!H12 -> -57.340028 | F6: =Datos!H8 -> 9.6869022 | G6: =Datos!J8 -> -0.065284118 | H6: =Datos!K7 -> 0.11522474 | I6: =IF($A6="2020Q2",1,0) -> 0 | J6: =IF($A6="2021Q2",1,0) -> 0 | K6: 1 | L6: =B6-($B$88+$B$89*C6+$B$90*D6+$B$91*E6+$B$92*F6+$B$93*G6+$B$94*H6+$B$95*I6+$B$96*J6) -> -0.0051546413 | M6: =L6^2 -> 2.6570327e-05 | N6: =K6*$L6 -> -0.0051546413 | O6: =C6*$L6 -> 6.5133317e-05 | P6: =D6*$L6 -> -0.29951678 | Q6: =E6*$L6 -> 0.29556728 | R6: =F6*$L6 -> -0.049932506 | S6: =G6*$L6 -> 0.00033651621 | T6: =H6*$L6 -> -0.00059394223 | U6: =I6*$L6 -> 0 | V6: =J6*$L6 -> 0
A7: =Datos!A15 -> 2007Q3 | B7: =Datos!L15 -> -0.014315897 | C7: =Datos!I15 -> -0.024622619 | D7: =Datos!H15 -> 146.7424 | E7: =Datos!H13 -> -71.425823 | F7: =Datos!H9 -> -29.001068 | G7: =Datos!J9 -> 0.10463368 | H7: =Datos!K8 -> 0.019353043 | I7: =IF($A7="2020Q2",1,0) -> 0 | J7: =IF($A7="2021Q2",1,0) -> 0 | K7: 1 | L7: =B7-($B$88+$B$89*C7+$B$90*D7+$B$91*E7+$B$92*F7+$B$93*G7+$B$94*H7+$B$95*I7+$B$96*J7) -> 0.0017709551 | M7: =L7^2 -> 3.1362818e-06 | N7: =K7*$L7 -> 0.0017709551 | O7: =C7*$L7 -> -4.3605551e-05 | P7: =D7*$L7 -> 0.25987419 | Q7: =E7*$L7 -> -0.12649192 | R7: =F7*$L7 -> -0.051359589 | S7: =G7*$L7 -> 0.00018530154 | T7: =H7*$L7 -> 3.427337e-05 | U7: =I7*$L7 -> 0 | V7: =J7*$L7 -> 0
A8: =Datos!A16 -> 2007Q4 | B8: =Datos!L16 -> 0.0083955092 | C8: =Datos!I16 -> -0.051369633 | D8: =Datos!H16 -> -28.226676 | E8: =Datos!H14 -> 58.106231 | F8: =Datos!H10 -> -40.701368 | G8: =Datos!J10 -> -0.032864038 | H8: =Datos!K9 -> 0.025268935 | I8: =IF($A8="2020Q2",1,0) -> 0 | J8: =IF($A8="2021Q2",1,0) -> 0 | K8: 1 | L8: =B8-($B$88+$B$89*C8+$B$90*D8+$B$91*E8+$B$92*F8+$B$93*G8+$B$94*H8+$B$95*I8+$B$96*J8) -> 0.014327905 | M8: =L8^2 -> 0.00020528887 | N8: =K8*$L8 -> 0.014327905 | O8: =C8*$L8 -> -0.00073601924 | P8: =D8*$L8 -> -0.40442915 | Q8: =E8*$L8 -> 0.83254058 | R8: =F8*$L8 -> -0.58316534 | S8: =G8*$L8 -> -0.00047087282 | T8: =H8*$L8 -> 0.0003620509 | U8: =I8*$L8 -> 0 | V8: =J8*$L8 -> 0
A9: =Datos!A17 -> 2008Q1 | B9: =Datos!L17 -> -0.023550341 | C9: =Datos!I17 -> -0.032205396 | D9: =Datos!H17 -> 95.337039 | E9: =Datos!H15 -> 146.7424 | F9: =Datos!H11 -> -14.668524 | G9: =Datos!J11 -> 0.027237131 | H9: =Datos!K10 -> 0.00073357525 | I9: =IF($A9="2020Q2",1,0) -> 0 | J9: =IF($A9="2021Q2",1,0) -> 0 | K9: 1 | L9: =B9-($B$88+$B$89*C9+$B$90*D9+$B$91*E9+$B$92*F9+$B$93*G9+$B$94*H9+$B$95*I9+$B$96*J9) -> -0.0032156216 | M9: =L9^2 -> 1.0340222e-05 | N9: =K9*$L9 -> -0.0032156216 | O9: =C9*$L9 -> 0.00010356037 | P9: =D9*$L9 -> -0.30656784 | Q9: =E9*$L9 -> -0.47186802 | R9: =F9*$L9 -> 0.047168422 | S9: =G9*$L9 -> -8.7584309e-05 | T9: =H9*$L9 -> -2.3589004e-06 | U9: =I9*$L9 -> 0 | V9: =J9*$L9 -> 0
A10: =Datos!A18 -> 2008Q2 | B10: =Datos!L18 -> -0.014596291 | C10: =Datos!I18 -> -0.047212617 | D10: =Datos!H18 -> 74.414777 | E10: =Datos!H16 -> -28.226676 | F10: =Datos!H12 -> -57.340028 | G10: =Datos!J12 -> 0.018840582 | H10: =Datos!K11 -> -0.049263666 | I10: =IF($A10="2020Q2",1,0) -> 0 | J10: =IF($A10="2021Q2",1,0) -> 0 | K10: 1 | L10: =B10-($B$88+$B$89*C10+$B$90*D10+$B$91*E10+$B$92*F10+$B$93*G10+$B$94*H10+$B$95*I10+$B$96*J10) -> 0.006588092 | M10: =L10^2 -> 4.3402956e-05 | N10: =K10*$L10 -> 0.006588092 | O10: =C10*$L10 -> -0.00031104107 | P10: =D10*$L10 -> 0.49025139 | Q10: =E10*$L10 -> -0.18595994 | R10: =F10*$L10 -> -0.37776138 | S10: =G10*$L10 -> 0.00012412348 | T10: =H10*$L10 -> -0.00032455356 | U10: =I10*$L10 -> 0 | V10: =J10*$L10 -> 0
A11: =Datos!A19 -> 2008Q3 | B11: =Datos!L19 -> 0.0055333067 | C11: =Datos!I19 -> 0.010388192 | D11: =Datos!H19 -> 140.17397 | E11: =Datos!H17 -> 95.337039 | F11: =Datos!H13 -> -71.425823 | G11: =Datos!J13 -> 0.03529949 | H11: =Datos!K12 -> 0.010271822 | I11: =IF($A11="2020Q2",1,0) -> 0 | J11: =IF($A11="2021Q2",1,0) -> 0 | K11: 1 | L11: =B11-($B$88+$B$89*C11+$B$90*D11+$B$91*E11+$B$92*F11+$B$93*G11+$B$94*H11+$B$95*I11+$B$96*J11) -> 0.017894963 | M11: =L11^2 -> 0.00032022971 | N11: =K11*$L11 -> 0.017894963 | O11: =C11*$L11 -> 0.00018589631 | P11: =D11*$L11 -> 2.508408 | Q11: =E11*$L11 -> 1.7060528 | R11: =F11*$L11 -> -1.2781625 | S11: =G11*$L11 -> 0.00063168308 | T11: =H11*$L11 -> 0.00018381387 | U11: =I11*$L11 -> 0 | V11: =J11*$L11 -> 0
A12: =Datos!A20 -> 2008Q4 | B12: =Datos!L20 -> -0.07985007 | C12: =Datos!I20 -> -0.012294191 | D12: =Datos!H20 -> 999.76307 | E12: =Datos!H18 -> 74.414777 | F12: =Datos!H14 -> 58.106231 | G12: =Datos!J14 -> 0.0053992196 | H12: =Datos!K13 -> 0.039471358 | I12: =IF($A12="2020Q2",1,0) -> 0 | J12: =IF($A12="2021Q2",1,0) -> 0 | K12: 1 | L12: =B12-($B$88+$B$89*C12+$B$90*D12+$B$91*E12+$B$92*F12+$B$93*G12+$B$94*H12+$B$95*I12+$B$96*J12) -> -0.033709729 | M12: =L12^2 -> 0.0011363458 | N12: =K12*$L12 -> -0.033709729 | O12: =C12*$L12 -> 0.00041443384 | P12: =D12*$L12 -> -33.701742 | Q12: =E12*$L12 -> -2.508502 | R12: =F12*$L12 -> -1.9587453 | S12: =G12*$L12 -> -0.00018200623 | T12: =H12*$L12 -> -0.0013305688 | U12: =I12*$L12 -> 0 | V12: =J12*$L12 -> 0
A13: =Datos!A21 -> 2009Q1 | B13: =Datos!L21 -> -0.042097643 | C13: =Datos!I21 -> -0.05064093 | D13: =Datos!H21 -> 3.4701679 | E13: =Datos!H19 -> 140.17397 | F13: =Datos!H15 -> 146.7424 | G13: =Datos!J15 -> 0.10008301 | H13: =Datos!K14 -> -0.041651007 | I13: =IF($A13="2020Q2",1,0) -> 0 | J13: =IF($A13="2021Q2",1,0) -> 0 | K13: 1 | L13: =B13-($B$88+$B$89*C13+$B$90*D13+$B$91*E13+$B$92*F13+$B$93*G13+$B$94*H13+$B$95*I13+$B$96*J13) -> -0.014785026 | M13: =L13^2 -> 0.000218597 | N13: =K13*$L13 -> -0.014785026 | O13: =C13*$L13 -> 0.00074872748 | P13: =D13*$L13 -> -0.051306524 | Q13: =E13*$L13 -> -2.0724758 | R13: =F13*$L13 -> -2.1695902 | S13: =G13*$L13 -> -0.00147973 | T13: =H13*$L13 -> 0.00061581124 | U13: =I13*$L13 -> 0 | V13: =J13*$L13 -> 0
A14: =Datos!A22 -> 2009Q2 | B14: =Datos!L22 -> -0.05085792 | C14: =Datos!I22 -> -0.027033683 | D14: =Datos!H22 -> -244.40122 | E14: =Datos!H20 -> 999.76307 | F14: =Datos!H16 -> -28.226676 | G14: =Datos!J16 -> -0.08075039 | H14: =Datos!K15 -> -0.018388531 | I14: =IF($A14="2020Q2",1,0) -> 0 | J14: =IF($A14="2021Q2",1,0) -> 0 | K14: 1 | L14: =B14-($B$88+$B$89*C14+$B$90*D14+$B$91*E14+$B$92*F14+$B$93*G14+$B$94*H14+$B$95*I14+$B$96*J14) -> -0.014113379 | M14: =L14^2 -> 0.00019918748 | N14: =K14*$L14 -> -0.014113379 | O14: =C14*$L14 -> 0.00038153662 | P14: =D14*$L14 -> 3.4493271 | Q14: =E14*$L14 -> -14.110035 | R14: =F14*$L14 -> 0.39837379 | S14: =G14*$L14 -> 0.0011396609 | T14: =H14*$L14 -> 0.00025952432 | U14: =I14*$L14 -> 0 | V14: =J14*$L14 -> 0
A15: =Datos!A23 -> 2009Q3 | B15: =Datos!L23 -> 0.056233672 | C15: =Datos!I23 -> 0.01889525 | D15: =Datos!H23 -> -533.98958 | E15: =Datos!H21 -> 3.4701679 | F15: =Datos!H17 -> 95.337039 | G15: =Datos!J17 -> -0.013616332 | H15: =Datos!K16 -> 0.12640686 | I15: =IF($A15="2020Q2",1,0) -> 0 | J15: =IF($A15="2021Q2",1,0) -> 0 | K15: 1 | L15: =B15-($B$88+$B$89*C15+$B$90*D15+$B$91*E15+$B$92*F15+$B$93*G15+$B$94*H15+$B$95*I15+$B$96*J15) -> 0.0053306373 | M15: =L15^2 -> 2.8415694e-05 | N15: =K15*$L15 -> 0.0053306373 | O15: =C15*$L15 -> 0.00010072373 | P15: =D15*$L15 -> -2.8465048 | Q15: =E15*$L15 -> 0.018498207 | R15: =F15*$L15 -> 0.50820718 | S15: =G15*$L15 -> -7.2583728e-05 | T15: =H15*$L15 -> 0.00067382911 | U15: =I15*$L15 -> 0 | V15: =J15*$L15 -> 0
A16: =Datos!A24 -> 2009Q4 | B16: =Datos!L24 -> 0.059331782 | C16: =Datos!I24 -> 0.020266082 | D16: =Datos!H24 -> -203.74584 | E16: =Datos!H22 -> -244.40122 | F16: =Datos!H18 -> 74.414777 | G16: =Datos!J18 -> 0.051677263 | H16: =Datos!K17 -> 0.094714456 | I16: =IF($A16="2020Q2",1,0) -> 0 | J16: =IF($A16="2021Q2",1,0) -> 0 | K16: 1 | L16: =B16-($B$88+$B$89*C16+$B$90*D16+$B$91*E16+$B$92*F16+$B$93*G16+$B$94*H16+$B$95*I16+$B$96*J16) -> 0.022994695 | M16: =L16^2 -> 0.00052875599 | N16: =K16*$L16 -> 0.022994695 | O16: =C16*$L16 -> 0.00046601236 | P16: =D16*$L16 -> -4.6850733 | Q16: =E16*$L16 -> -5.6199314 | R16: =F16*$L16 -> 1.7111451 | S16: =G16*$L16 -> 0.0011883029 | T16: =H16*$L16 -> 0.00217793 | U16: =I16*$L16 -> 0 | V16: =J16*$L16 -> 0
A17: =Datos!A25 -> 2010Q1 | B17: =Datos!L25 -> 0.054312709 | C17: =Datos!I25 -> 0.036485145 | D17: =Datos!H25 -> 15.441636 | E17: =Datos!H23 -> -533.98958 | F17: =Datos!H19 -> 140.17397 | G17: =Datos!J19 -> -0.092266092 | H17: =Datos!K18 -> -0.088947266 | I17: =IF($A17="2020Q2",1,0) -> 0 | J17: =IF($A17="2021Q2",1,0) -> 0 | K17: 1 | L17: =B17-($B$88+$B$89*C17+$B$90*D17+$B$91*E17+$B$92*F17+$B$93*G17+$B$94*H17+$B$95*I17+$B$96*J17) -> 0.01981932 | M17: =L17^2 -> 0.00039280544 | N17: =K17*$L17 -> 0.01981932 | O17: =C17*$L17 -> 0.00072311075 | P17: =D17*$L17 -> 0.30604272 | Q17: =E17*$L17 -> -10.58331 | R17: =F17*$L17 -> 2.7781527 | S17: =G17*$L17 -> -0.0018286512 | T17: =H17*$L17 -> -0.0017628743 | U17: =I17*$L17 -> 0 | V17: =J17*$L17 -> 0
... A81: =Datos!A89 -> 2026Q1 | B81: =Datos!L89 -> 0.0041135381 | C81: =Datos!I89 -> -0.099649603 | D81: =Datos!H89 -> -216.77778 | E81: =Datos!H87 -> 142.30769 | F81: =Datos!H83 -> 140.77357 | G81: =Datos!J83 -> -0.11430199 | H81: =Datos!K82 -> 0.0075734887 | I81: =IF($A81="2020Q2",1,0) -> 0 | J81: =IF($A81="2021Q2",1,0) -> 0 | K81: 1 | L81: =B81-($B$88+$B$89*C81+$B$90*D81+$B$91*E81+$B$92*F81+$B$93*G81+$B$94*H81+$B$95*I81+$B$96*J81) -> 0.0042947547 | M81: =L81^2 -> 1.8444918e-05 | N81: =K81*$L81 -> 0.0042947547 | O81: =C81*$L81 -> -0.00042797059 | P81: =D81*$L81 -> -0.93100737 | Q81: =E81*$L81 -> 0.61117662 | R81: =F81*$L81 -> 0.60458796 | S81: =G81*$L81 -> -0.00049089901 | T81: =H81*$L81 -> 3.2526276e-05 | U81: =I81*$L81 -> 0 | V81: =J81*$L81 -> 0
A86: A. ESTIMACION OLS (LINEST devuelve los coeficientes en orden inverso; se extraen con INDEX)
A87: Regresor | B87: Coef. | C87: Error est. | D87: t | E87: p-valor | G87: gl residuales | H87: =INDEX(LINEST($B$6:$B$81,$C$6:$J$81,TRUE(),TRUE()),4,2) -> 67
A88: const | B88: =INDEX(LINEST($B$6:$B$81,$C$6:$J$81,TRUE(),TRUE()),1,9) -> 0.00085191829 | C88: =INDEX(LINEST($B$6:$B$81,$C$6:$J$81,TRUE(),TRUE()),2,9) -> 0.0034077949 | D88: =B88/C88 -> 0.24999107 | E88: =TDIST(ABS(D88),$H$87,2) -> 0.80335919
A89: d(M3R) t | B89: =INDEX(LINEST($B$6:$B$81,$C$6:$J$81,TRUE(),TRUE()),1,8) -> 0.20710893 | C89: =INDEX(LINEST($B$6:$B$81,$C$6:$J$81,TRUE(),TRUE()),2,8) -> 0.050768569 | D89: =B89/C89 -> 4.0794715 | E89: =TDIST(ABS(D89),$H$87,2) -> 0.00012237236
A90: d(EMBI) t | B90: =INDEX(LINEST($B$6:$B$81,$C$6:$J$81,TRUE(),TRUE()),1,7) -> -4.7363666e-05 | C90: =INDEX(LINEST($B$6:$B$81,$C$6:$J$81,TRUE(),TRUE()),2,7) -> 1.2532984e-05 | D90: =B90/C90 -> -3.7791214 | E90: =TDIST(ABS(D90),$H$87,2) -> 0.00033718249
A91: d(EMBI) t-2 | B91: =INDEX(LINEST($B$6:$B$81,$C$6:$J$81,TRUE(),TRUE()),1,6) -> -4.8035176e-05 | C91: =INDEX(LINEST($B$6:$B$81,$C$6:$J$81,TRUE(),TRUE()),2,6) -> 1.243989e-05 | D91: =B91/C91 -> -3.8613828 | E91: =TDIST(ABS(D91),$H$87,2) -> 0.000256497
A92: d(EMBI) t-6 | B92: =INDEX(LINEST($B$6:$B$81,$C$6:$J$81,TRUE(),TRUE()),1,5) -> 2.9831095e-05 | C92: =INDEX(LINEST($B$6:$B$81,$C$6:$J$81,TRUE(),TRUE()),2,5) -> 1.2714561e-05 | D92: =B92/C92 -> 2.3462152 | E92: =TDIST(ABS(D92),$H$87,2) -> 0.02193177
A93: d(GPN) t-6 | B93: =INDEX(LINEST($B$6:$B$81,$C$6:$J$81,TRUE(),TRUE()),1,4) -> -0.095919949 | C93: =INDEX(LINEST($B$6:$B$81,$C$6:$J$81,TRUE(),TRUE()),2,4) -> 0.028195864 | D93: =B93/C93 -> -3.4019156 | E93: =TDIST(ABS(D93),$H$87,2) -> 0.0011325945
A94: d(VITI) t-7 | B94: =INDEX(LINEST($B$6:$B$81,$C$6:$J$81,TRUE(),TRUE()),1,3) -> 0.13339973 | C94: =INDEX(LINEST($B$6:$B$81,$C$6:$J$81,TRUE(),TRUE()),2,3) -> 0.052804644 | D94: =B94/C94 -> 2.5262879 | E94: =TDIST(ABS(D94),$H$87,2) -> 0.013896795
A95: D_2020Q2 | B95: =INDEX(LINEST($B$6:$B$81,$C$6:$J$81,TRUE(),TRUE()),1,2) -> -0.11740911 | C95: =INDEX(LINEST($B$6:$B$81,$C$6:$J$81,TRUE(),TRUE()),2,2) -> 0.035430033 | D95: =B95/C95 -> -3.31383 | E95: =TDIST(ABS(D95),$H$87,2) -> 0.0014871074
A96: D_2021Q2 | B96: =INDEX(LINEST($B$6:$B$81,$C$6:$J$81,TRUE(),TRUE()),1,1) -> 0.14194854 | C96: =INDEX(LINEST($B$6:$B$81,$C$6:$J$81,TRUE(),TRUE()),2,1) -> 0.033068079 | D96: =B96/C96 -> 4.2926153 | E96: =TDIST(ABS(D96),$H$87,2) -> 5.8209248e-05
A98: B. BONDAD DE AJUSTE
A99: n (observaciones) | B99: =COUNT($B$6:$B$81) -> 76
A100: k (parametros) | B100: 9
A101: R2 | B101: =INDEX(LINEST($B$6:$B$81,$C$6:$J$81,TRUE(),TRUE()),3,1) -> 0.63678404
A102: R2 ajustado | B102: =1-(1-B101)*(B99-1)/(B99-B100) -> 0.59341497
A103: SSR | B103: =INDEX(LINEST($B$6:$B$81,$C$6:$J$81,TRUE(),TRUE()),5,2) -> 0.056151375
A104: log-verosimilitud | B104: =-B99/2*(LN(2*PI())+LN(B103/B99)+1) -> 166.15729
A105: AIC | B105: =-2*B104+2*B100 -> -314.31459
A106: BIC | B106: =-2*B104+LN(B99)*B100 -> -293.33799
A108: Durbin-Watson | B108: =SUMXMY2(L7:L81,L6:L80)/SUMSQ(L6:L81) -> 1.9633109
A110: C. ERRORES ESTANDAR HAC (Newey-West, nucleo de Bartlett, L=4)
A111: V = (X'X)^-1 S (X'X)^-1 , S = G0 + SUM_l w_l (G_l + G_l') , w_l = 1 - l/5
A112: X'X
...

Sheet Modelo_ADL
A1: ALTERNATIVA ADL — PBI ~ (mismos regresores) + PBI(t-1)
A2: Diferenciar el PBI equivale a imponer coeficiente 1 sobre PBI(t-1). Aca se lo deja libre y se contrasta la restriccion.
A5: Periodo | B5: y | C5: d(M3R) t | D5: d(EMBI) t | E5: d(EMBI) t-2 | F5: d(EMBI) t-6 | G5: d(GPN) t-6 | H5: d(VITI) t-7 | I5: PBI t-1 | J5: const=1 | K5: residuo e | L5: e^2
A6: =Datos!A14 -> 2007Q2 | B6: =Datos!F14 -> 0.098593874 | C6: =Datos!I14 -> -0.012635858 | D6: =Datos!H14 -> 58.106231 | E6: =Datos!H12 -> -57.340028 | F6: =Datos!H8 -> 9.6869022 | G6: =Datos!J8 -> -0.065284118 | H6: =Datos!K7 -> 0.11522474 | I6: =Datos!F13 -> 0.083589411 | J6: 1 | K6: =B6-($B$88+$B$89*C6+$B$90*D6+$B$91*E6+$B$92*F6+$B$93*G6+$B$94*H6+$B$95*I6) -> -0.002042138 | L6: =K6^2 -> 4.1703276e-06
A7: =Datos!A15 -> 2007Q3 | B7: =Datos!F15 -> 0.084277977 | C7: =Datos!I15 -> -0.024622619 | D7: =Datos!H15 -> 146.7424 | E7: =Datos!H13 -> -71.425823 | F7: =Datos!H9 -> -29.001068 | G7: =Datos!J9 -> 0.10463368 | H7: =Datos!K8 -> 0.019353043 | I7: =Datos!F14 -> 0.098593874 | J7: 1 | K7: =B7-($B$88+$B$89*C7+$B$90*D7+$B$91*E7+$B$92*F7+$B$93*G7+$B$94*H7+$B$95*I7) -> 0.011212535 | L7: =K7^2 -> 0.00012572094
A8: =Datos!A16 -> 2007Q4 | B8: =Datos!F16 -> 0.092673486 | C8: =Datos!I16 -> -0.051369633 | D8: =Datos!H16 -> -28.226676 | E8: =Datos!H14 -> 58.106231 | F8: =Datos!H10 -> -40.701368 | G8: =Datos!J10 -> -0.032864038 | H8: =Datos!K9 -> 0.025268935 | I8: =Datos!F15 -> 0.084277977 | J8: 1 | K8: =B8-($B$88+$B$89*C8+$B$90*D8+$B$91*E8+$B$92*F8+$B$93*G8+$B$94*H8+$B$95*I8) -> 0.018162762 | L8: =K8^2 -> 0.00032988594
A9: =Datos!A17 -> 2008Q1 | B9: =Datos!F17 -> 0.069123146 | C9: =Datos!I17 -> -0.032205396 | D9: =Datos!H17 -> 95.337039 | E9: =Datos!H15 -> 146.7424 | F9: =Datos!H11 -> -14.668524 | G9: =Datos!J11 -> 0.027237131 | H9: =Datos!K10 -> 0.00073357525 | I9: =Datos!F16 -> 0.092673486 | J9: 1 | K9: =B9-($B$88+$B$89*C9+$B$90*D9+$B$91*E9+$B$92*F9+$B$93*G9+$B$94*H9+$B$95*I9) -> 0.008127214 | L9: =K9^2 -> 6.6051608e-05
A10: =Datos!A18 -> 2008Q2 | B10: =Datos!F18 -> 0.054526855 | C10: =Datos!I18 -> -0.047212617 | D10: =Datos!H18 -> 74.414777 | E10: =Datos!H16 -> -28.226676 | F10: =Datos!H12 -> -57.340028 | G10: =Datos!J12 -> 0.018840582 | H10: =Datos!K11 -> -0.049263666 | I10: =Datos!F17 -> 0.069123146 | J10: 1 | K10: =B10-($B$88+$B$89*C10+$B$90*D10+$B$91*E10+$B$92*F10+$B$93*G10+$B$94*H10+$B$95*I10) -> 0.011258671 | L10: =K10^2 -> 0.00012675768
A11: =Datos!A19 -> 2008Q3 | B11: =Datos!F19 -> 0.060060161 | C11: =Datos!I19 -> 0.010388192 | D11: =Datos!H19 -> 140.17397 | E11: =Datos!H17 -> 95.337039 | F11: =Datos!H13 -> -71.425823 | G11: =Datos!J13 -> 0.03529949 | H11: =Datos!K12 -> 0.010271822 | I11: =Datos!F18 -> 0.054526855 | J11: 1 | K11: =B11-($B$88+$B$89*C11+$B$90*D11+$B$91*E11+$B$92*F11+$B$93*G11+$B$94*H11+$B$95*I11) -> 0.027486938 | L11: =K11^2 -> 0.00075553175
A12: =Datos!A20 -> 2008Q4 | B12: =Datos!F20 -> -0.019789909 | C12: =Datos!I20 -> -0.012294191 | D12: =Datos!H20 -> 999.76307 | E12: =Datos!H18 -> 74.414777 | F12: =Datos!H14 -> 58.106231 | G12: =Datos!J14 -> 0.0053992196 | H12: =Datos!K13 -> 0.039471358 | I12: =Datos!F19 -> 0.060060161 | J12: 1 | K12: =B12-($B$88+$B$89*C12+$B$90*D12+$B$91*E12+$B$92*F12+$B$93*G12+$B$94*H12+$B$95*I12) -> -0.023806129 | L12: =K12^2 -> 0.0005667318
A13: =Datos!A21 -> 2009Q1 | B13: =Datos!F21 -> -0.061887551 | C13: =Datos!I21 -> -0.05064093 | D13: =Datos!H21 -> 3.4701679 | E13: =Datos!H19 -> 140.17397 | F13: =Datos!H15 -> 146.7424 | G13: =Datos!J15 -> 0.10008301 | H13: =Datos!K14 -> -0.041651007 | I13: =Datos!F20 -> -0.019789909 | J13: 1 | K13: =B13-($B$88+$B$89*C13+$B$90*D13+$B$91*E13+$B$92*F13+$B$93*G13+$B$94*H13+$B$95*I13) -> -0.02313803 | L13: =K13^2 -> 0.00053536845
A14: =Datos!A22 -> 2009Q2 | B14: =Datos!F22 -> -0.11274547 | C14: =Datos!I22 -> -0.027033683 | D14: =Datos!H22 -> -244.40122 | E14: =Datos!H20 -> 999.76307 | F14: =Datos!H16 -> -28.226676 | G14: =Datos!J16 -> -0.08075039 | H14: =Datos!K15 -> -0.018388531 | I14: =Datos!F21 -> -0.061887551 | J14: 1 | K14: =B14-($B$88+$B$89*C14+$B$90*D14+$B$91*E14+$B$92*F14+$B$93*G14+$B$94*H14+$B$95*I14) -> -0.015375574 | L14: =K14^2 -> 0.00023640828
A15: =Datos!A23 -> 2009Q3 | B15: =Datos!F23 -> -0.0565118 | C15: =Datos!I23 -> 0.01889525 | D15: =Datos!H23 -> -533.98958 | E15: =Datos!H21 -> 3.4701679 | F15: =Datos!H17 -> 95.337039 | G15: =Datos!J17 -> -0.013616332 | H15: =Datos!K16 -> 0.12640686 | I15: =Datos!F22 -> -0.11274547 | J15: 1 | K15: =B15-($B$88+$B$89*C15+$B$90*D15+$B$91*E15+$B$92*F15+$B$93*G15+$B$94*H15+$B$95*I15) -> -0.022697377 | L15: =K15^2 -> 0.00051517093
A16: =Datos!A24 -> 2009Q4 | B16: =Datos!F24 -> 0.0028199823 | C16: =Datos!I24 -> 0.020266082 | D16: =Datos!H24 -> -203.74584 | E16: =Datos!H22 -> -244.40122 | F16: =Datos!H18 -> 74.414777 | G16: =Datos!J18 -> 0.051677263 | H16: =Datos!K17 -> 0.094714456 | I16: =Datos!F23 -> -0.0565118 | J16: 1 | K16: =B16-($B$88+$B$89*C16+$B$90*D16+$B$91*E16+$B$92*F16+$B$93*G16+$B$94*H16+$B$95*I16) -> 0.0039719301 | L16: =K16^2 -> 1.5776229e-05
A17: =Datos!A25 -> 2010Q1 | B17: =Datos!F25 -> 0.057132691 | C17: =Datos!I25 -> 0.036485145 | D17: =Datos!H25 -> 15.441636 | E17: =Datos!H23 -> -533.98958 | F17: =Datos!H19 -> 140.17397 | G17: =Datos!J19 -> -0.092266092 | H17: =Datos!K18 -> -0.088947266 | I17: =Datos!F24 -> 0.0028199823 | J17: 1 | K17: =B17-($B$88+$B$89*C17+$B$90*D17+$B$91*E17+$B$92*F17+$B$93*G17+$B$94*H17+$B$95*I17) -> 0.0176042 | L17: =K17^2 -> 0.00030990787
... A81: =Datos!A89 -> 2026Q1 | B81: =Datos!F89 -> 0.024694045 | C81: =Datos!I89 -> -0.099649603 | D81: =Datos!H89 -> -216.77778 | E81: =Datos!H87 -> 142.30769 | F81: =Datos!H83 -> 140.77357 | G81: =Datos!J83 -> -0.11430199 | H81: =Datos!K82 -> 0.0075734887 | I81: =Datos!F88 -> 0.020580507 | J81: 1 | K81: =B81-($B$88+$B$89*C81+$B$90*D81+$B$91*E81+$B$92*F81+$B$93*G81+$B$94*H81+$B$95*I81) -> -0.0081158934 | L81: =K81^2 -> 6.5867726e-05
A86: A. ESTIMACION OLS (LINEST devuelve los coeficientes en orden inverso; se extraen con INDEX)
A87: Regresor | B87: Coef. | C87: Error est. | D87: t | E87: p-valor | G87: gl residuales | H87: =INDEX(LINEST($B$6:$B$81,$C$6:$I$81,TRUE(),TRUE()),4,2) -> 68
A88: const | B88: =INDEX(LINEST($B$6:$B$81,$C$6:$I$81,TRUE(),TRUE()),1,8) -> 0.003760784 | C88: =INDEX(LINEST($B$6:$B$81,$C$6:$I$81,TRUE(),TRUE()),2,8) -> 0.0038717273 | D88: =B88/C88 -> 0.97134528 | E88: =TDIST(ABS(D88),$H$87,2) -> 0.33481891
A89: d(M3R) t | B89: =INDEX(LINEST($B$6:$B$81,$C$6:$I$81,TRUE(),TRUE()),1,7) -> 0.071321551 | C89: =INDEX(LINEST($B$6:$B$81,$C$6:$I$81,TRUE(),TRUE()),2,7) -> 0.050245609 | D89: =B89/C89 -> 1.4194584 | E89: =TDIST(ABS(D89),$H$87,2) -> 0.16033347
A90: d(EMBI) t | B90: =INDEX(LINEST($B$6:$B$81,$C$6:$I$81,TRUE(),TRUE()),1,6) -> -5.2292435e-05 | C90: =INDEX(LINEST($B$6:$B$81,$C$6:$I$81,TRUE(),TRUE()),2,6) -> 1.3692984e-05 | D90: =B90/C90 -> -3.8189218 | E90: =TDIST(ABS(D90),$H$87,2) -> 0.00029249195
A91: d(EMBI) t-2 | B91: =INDEX(LINEST($B$6:$B$81,$C$6:$I$81,TRUE(),TRUE()),1,5) -> -6.4481987e-05 | C91: =INDEX(LINEST($B$6:$B$81,$C$6:$I$81,TRUE(),TRUE()),2,5) -> 1.3579804e-05 | D91: =B91/C91 -> -4.7483739 | E91: =TDIST(ABS(D91),$H$87,2) -> 1.097708e-05
A92: d(EMBI) t-6 | B92: =INDEX(LINEST($B$6:$B$81,$C$6:$I$81,TRUE(),TRUE()),1,4) -> 2.9270449e-05 | C92: =INDEX(LINEST($B$6:$B$81,$C$6:$I$81,TRUE(),TRUE()),2,4) -> 1.4026095e-05 | D92: =B92/C92 -> 2.0868566 | E92: =TDIST(ABS(D92),$H$87,2) -> 0.040652648
A93: d(GPN) t-6 | B93: =INDEX(LINEST($B$6:$B$81,$C$6:$I$81,TRUE(),TRUE()),1,3) -> -0.09978693 | C93: =INDEX(LINEST($B$6:$B$81,$C$6:$I$81,TRUE(),TRUE()),2,3) -> 0.031539974 | D93: =B93/C93 -> -3.1638241 | E93: =TDIST(ABS(D93),$H$87,2) -> 0.0023286384
A94: d(VITI) t-7 | B94: =INDEX(LINEST($B$6:$B$81,$C$6:$I$81,TRUE(),TRUE()),1,2) -> 0.18114638 | C94: =INDEX(LINEST($B$6:$B$81,$C$6:$I$81,TRUE(),TRUE()),2,2) -> 0.057676603 | D94: =B94/C94 -> 3.1407255 | E94: =TDIST(ABS(D94),$H$87,2) -> 0.0024947615
A95: PBI t-1 | B95: =INDEX(LINEST($B$6:$B$81,$C$6:$I$81,TRUE(),TRUE()),1,1) -> 0.83081058 | C95: =INDEX(LINEST($B$6:$B$81,$C$6:$I$81,TRUE(),TRUE()),2,1) -> 0.068334985 | D95: =B95/C95 -> 12.15791 | E95: =TDIST(ABS(D95),$H$87,2) -> 1.0233023e-18
A97: B. BONDAD DE AJUSTE
A98: n (observaciones) | B98: =COUNT($B$6:$B$81) -> 76
A99: k (parametros) | B99: 8
A100: R2 | B100: =INDEX(LINEST($B$6:$B$81,$C$6:$I$81,TRUE(),TRUE()),3,1) -> 0.74331494
A101: R2 ajustado | B101: =1-(1-B100)*(B98-1)/(B98-B99) -> 0.71689147
A102: SSR | B102: =INDEX(LINEST($B$6:$B$81,$C$6:$I$81,TRUE(),TRUE()),5,2) -> 0.070874291
A103: log-verosimilitud | B103: =-B98/2*(LN(2*PI())+LN(B102/B98)+1) -> 157.30874
A104: AIC | B104: =-2*B103+2*B99 -> -298.61749
A105: BIC | B105: =-2*B103+LN(B98)*B99 -> -279.97162
A107: Durbin-Watson | B107: =SUMXMY2(K7:K81,K6:K80)/SUMSQ(K6:K81) -> 2.1160134
A109: C. TEST F: H0 = coeficiente de PBI(t-1) igual a 1
A110: Si se rechaza, diferenciar la variable dependiente impone una restriccion que los datos no avalan.
A111: SSR irrestricto (este modelo) | B111: =B102 -> 0.070874291
A112: SSR restringido (Modelo_Actual) | B112: =Modelo_Actual!B101 -> 0.077263395
...

Sheet ADL_COVID
A1: ADL + DUMMIES COVID — PBI ~ (6 regresores) + PBI(t-1) + D_2020Q2 + D_2021Q2
A2: Combina las dos correcciones: no diferencia la dependiente (deja PBI(t-1) libre) y neutraliza los dos trimestres atipicos. Es la especificacion con menor BIC de todas las probadas.
A5: Periodo | B5: y | C5: d(M3R) t | D5: d(EMBI) t | E5: d(EMBI) t-2 | F5: d(EMBI) t-6 | G5: d(GPN) t-6 | H5: d(VITI) t-7 | I5: PBI t-1 | J5: D_2020Q2 | K5: D_2021Q2 | L5: const=1 | M5: residuo e | N5: e^2 | O5: h_0 | P5: h_1 | Q5: h_2 | R5: h_3 | S5: h_4 | T5: h_5 | U5: h_6 | V5: h_7 | W5: h_8 | X5: h_9
A6: =Datos!A14 -> 2007Q2 | B6: =Datos!F14 -> 0.098593874 | C6: =Datos!I14 -> -0.012635858 | D6: =Datos!H14 -> 58.106231 | E6: =Datos!H12 -> -57.340028 | F6: =Datos!H8 -> 9.6869022 | G6: =Datos!J8 -> -0.065284118 | H6: =Datos!K7 -> 0.11522474 | I6: =Datos!F13 -> 0.083589411 | J6: =IF($A6="2020Q2",1,0) -> 0 | K6: =IF($A6="2021Q2",1,0) -> 0 | L6: 1 | M6: =B6-($B$88+$B$89*C6+$B$90*D6+$B$91*E6+$B$92*F6+$B$93*G6+$B$94*H6+$B$95*I6+$B$96*J6+$B$97*K6) -> 0.012000299 | N6: =M6^2 -> 0.00014400718 | O6: =L6*$M6 -> 0.012000299 | P6: =C6*$M6 -> -0.00015163408 | Q6: =D6*$M6 -> 0.69729217 | R6: =E6*$M6 -> -0.68809749 | S6: =F6*$M6 -> 0.11624573 | T6: =G6*$M6 -> -0.00078342896 | U6: =H6*$M6 -> 0.0013827314 | V6: =I6*$M6 -> 0.001003098 | W6: =J6*$M6 -> 0 | X6: =K6*$M6 -> 0
A7: =Datos!A15 -> 2007Q3 | B7: =Datos!F15 -> 0.084277977 | C7: =Datos!I15 -> -0.024622619 | D7: =Datos!H15 -> 146.7424 | E7: =Datos!H13 -> -71.425823 | F7: =Datos!H9 -> -29.001068 | G7: =Datos!J9 -> 0.10463368 | H7: =Datos!K8 -> 0.019353043 | I7: =Datos!F14 -> 0.098593874 | J7: =IF($A7="2020Q2",1,0) -> 0 | K7: =IF($A7="2021Q2",1,0) -> 0 | L7: 1 | M7: =B7-($B$88+$B$89*C7+$B$90*D7+$B$91*E7+$B$92*F7+$B$93*G7+$B$94*H7+$B$95*I7+$B$96*J7+$B$97*K7) -> 0.01542321 | N7: =M7^2 -> 0.00023787541 | O7: =L7*$M7 -> 0.01542321 | P7: =C7*$M7 -> -0.00037975982 | Q7: =D7*$M7 -> 2.2632388 | R7: =E7*$M7 -> -1.1016155 | S7: =F7*$M7 -> -0.44728957 | T7: =G7*$M7 -> 0.0016137872 | U7: =H7*$M7 -> 0.00029848605 | V7: =I7*$M7 -> 0.001520634 | W7: =J7*$M7 -> 0 | X7: =K7*$M7 -> 0
A8: =Datos!A16 -> 2007Q4 | B8: =Datos!F16 -> 0.092673486 | C8: =Datos!I16 -> -0.051369633 | D8: =Datos!H16 -> -28.226676 | E8: =Datos!H14 -> 58.106231 | F8: =Datos!H10 -> -40.701368 | G8: =Datos!J10 -> -0.032864038 | H8: =Datos!K9 -> 0.025268935 | I8: =Datos!F15 -> 0.084277977 | J8: =IF($A8="2020Q2",1,0) -> 0 | K8: =IF($A8="2021Q2",1,0) -> 0 | L8: 1 | M8: =B8-($B$88+$B$89*C8+$B$90*D8+$B$91*E8+$B$92*F8+$B$93*G8+$B$94*H8+$B$95*I8+$B$96*J8+$B$97*K8) -> 0.030808554 | N8: =M8^2 -> 0.00094916703 | O8: =L8*$M8 -> 0.030808554 | P8: =C8*$M8 -> -0.0015826242 | Q8: =D8*$M8 -> -0.8696231 | R8: =E8*$M8 -> 1.790169 | S8: =F8*$M8 -> -1.2539503 | T8: =G8*$M8 -> -0.0010124935 | U8: =H8*$M8 -> 0.00077849935 | V8: =I8*$M8 -> 0.0025964826 | W8: =J8*$M8 -> 0 | X8: =K8*$M8 -> 0
A9: =Datos!A17 -> 2008Q1 | B9: =Datos!F17 -> 0.069123146 | C9: =Datos!I17 -> -0.032205396 | D9: =Datos!H17 -> 95.337039 | E9: =Datos!H15 -> 146.7424 | F9: =Datos!H11 -> -14.668524 | G9: =Datos!J11 -> 0.027237131 | H9: =Datos!K10 -> 0.00073357525 | I9: =Datos!F16 -> 0.092673486 | J9: =IF($A9="2020Q2",1,0) -> 0 | K9: =IF($A9="2021Q2",1,0) -> 0 | L9: 1 | M9: =B9-($B$88+$B$89*C9+$B$90*D9+$B$91*E9+$B$92*F9+$B$93*G9+$B$94*H9+$B$95*I9+$B$96*J9+$B$97*K9) -> 0.01176557 | N9: =M9^2 -> 0.00013842863 | O9: =L9*$M9 -> 0.01176557 | P9: =C9*$M9 -> -0.00037891483 | Q9: =D9*$M9 -> 1.1216946 | R9: =E9*$M9 -> 1.7265079 | S9: =F9*$M9 -> -0.17258354 | T9: =G9*$M9 -> 0.00032046037 | U9: =H9*$M9 -> 8.6309308e-06 | V9: =I9*$M9 -> 0.0010903564 | W9: =J9*$M9 -> 0 | X9: =K9*$M9 -> 0
A10: =Datos!A18 -> 2008Q2 | B10: =Datos!F18 -> 0.054526855 | C10: =Datos!I18 -> -0.047212617 | D10: =Datos!H18 -> 74.414777 | E10: =Datos!H16 -> -28.226676 | F10: =Datos!H12 -> -57.340028 | G10: =Datos!J12 -> 0.018840582 | H10: =Datos!K11 -> -0.049263666 | I10: =Datos!F17 -> 0.069123146 | J10: =IF($A10="2020Q2",1,0) -> 0 | K10: =IF($A10="2021Q2",1,0) -> 0 | L10: 1 | M10: =B10-($B$88+$B$89*C10+$B$90*D10+$B$91*E10+$B$92*F10+$B$93*G10+$B$94*H10+$B$95*I10+$B$96*J10+$B$97*K10) -> 0.01516888 | N10: =M10^2 -> 0.00023009491 | O10: =L10*$M10 -> 0.01516888 | P10: =C10*$M10 -> -0.00071616251 | Q10: =D10*$M10 -> 1.1287888 | R10: =E10*$M10 -> -0.42816706 | S10: =F10*$M10 -> -0.86978398 | T10: =G10*$M10 -> 0.00028579051 | U10: =H10*$M10 -> -0.00074727461 | V10: =I10*$M10 -> 0.0010485207 | W10: =J10*$M10 -> 0 | X10: =K10*$M10 -> 0
A11: =Datos!A19 -> 2008Q3 | B11: =Datos!F19 -> 0.060060161 | C11: =Datos!I19 -> 0.010388192 | D11: =Datos!H19 -> 140.17397 | E11: =Datos!H17 -> 95.337039 | F11: =Datos!H13 -> -71.425823 | G11: =Datos!J13 -> 0.03529949 | H11: =Datos!K12 -> 0.010271822 | I11: =Datos!F18 -> 0.054526855 | J11: =IF($A11="2020Q2",1,0) -> 0 | K11: =IF($A11="2021Q2",1,0) -> 0 | L11: 1 | M11: =B11-($B$88+$B$89*C11+$B$90*D11+$B$91*E11+$B$92*F11+$B$93*G11+$B$94*H11+$B$95*I11+$B$96*J11+$B$97*K11) -> 0.023187817 | N11: =M11^2 -> 0.00053767486 | O11: =L11*$M11 -> 0.023187817 | P11: =C11*$M11 -> 0.00024087949 | Q11: =D11*$M11 -> 3.2503283 | R11: =E11*$M11 -> 2.2106578 | S11: =F11*$M11 -> -1.6562089 | T11: =G11*$M11 -> 0.00081851813 | U11: =H11*$M11 -> 0.00023818112 | V11: =I11*$M11 -> 0.0012643587 | W11: =J11*$M11 -> 0 | X11: =K11*$M11 -> 0
A12: =Datos!A20 -> 2008Q4 | B12: =Datos!F20 -> -0.019789909 | C12: =Datos!I20 -> -0.012294191 | D12: =Datos!H20 -> 999.76307 | E12: =Datos!H18 -> 74.414777 | F12: =Datos!H14 -> 58.106231 | G12: =Datos!J14 -> 0.0053992196 | H12: =Datos!K13 -> 0.039471358 | I12: =Datos!F19 -> 0.060060161 | J12: =IF($A12="2020Q2",1,0) -> 0 | K12: =IF($A12="2021Q2",1,0) -> 0 | L12: 1 | M12: =B12-($B$88+$B$89*C12+$B$90*D12+$B$91*E12+$B$92*F12+$B$93*G12+$B$94*H12+$B$95*I12+$B$96*J12+$B$97*K12) -> -0.042479355 | N12: =M12^2 -> 0.0018044956 | O12: =L12*$M12 -> -0.042479355 | P12: =C12*$M12 -> 0.00052224929 | Q12: =D12*$M12 -> -42.469291 | R12: =E12*$M12 -> -3.1610917 | S12: =F12*$M12 -> -2.4683152 | T12: =G12*$M12 -> -0.00022935537 | U12: =H12*$M12 -> -0.0016767178 | V12: =I12*$M12 -> -0.0025513169 | W12: =J12*$M12 -> 0 | X12: =K12*$M12 -> 0
A13: =Datos!A21 -> 2009Q1 | B13: =Datos!F21 -> -0.061887551 | C13: =Datos!I21 -> -0.05064093 | D13: =Datos!H21 -> 3.4701679 | E13: =Datos!H19 -> 140.17397 | F13: =Datos!H15 -> 146.7424 | G13: =Datos!J15 -> 0.10008301 | H13: =Datos!K14 -> -0.041651007 | I13: =Datos!F20 -> -0.019789909 | J13: =IF($A13="2020Q2",1,0) -> 0 | K13: =IF($A13="2021Q2",1,0) -> 0 | L13: 1 | M13: =B13-($B$88+$B$89*C13+$B$90*D13+$B$91*E13+$B$92*F13+$B$93*G13+$B$94*H13+$B$95*I13+$B$96*J13+$B$97*K13) -> -0.024458672 | N13: =M13^2 -> 0.00059822664 | O13: =L13*$M13 -> -0.024458672 | P13: =C13*$M13 -> 0.0012386099 | Q13: =D13*$M13 -> -0.084875699 | R13: =E13*$M13 -> -3.4284691 | S13: =F13*$M13 -> -3.5891242 | T13: =G13*$M13 -> -0.0024478976 | U13: =H13*$M13 -> 0.0010187283 | V13: =I13*$M13 -> 0.00048403489 | W13: =J13*$M13 -> 0 | X13: =K13*$M13 -> 0
A14: =Datos!A22 -> 2009Q2 | B14: =Datos!F22 -> -0.11274547 | C14: =Datos!I22 -> -0.027033683 | D14: =Datos!H22 -> -244.40122 | E14: =Datos!H20 -> 999.76307 | F14: =Datos!H16 -> -28.226676 | G14: =Datos!J16 -> -0.08075039 | H14: =Datos!K15 -> -0.018388531 | I14: =Datos!F21 -> -0.061887551 | J14: =IF($A14="2020Q2",1,0) -> 0 | K14: =IF($A14="2021Q2",1,0) -> 0 | L14: 1 | M14: =B14-($B$88+$B$89*C14+$B$90*D14+$B$91*E14+$B$92*F14+$B$93*G14+$B$94*H14+$B$95*I14+$B$96*J14+$B$97*K14) -> -0.023979196 | N14: =M14^2 -> 0.00057500186 | O14: =L14*$M14 -> -0.023979196 | P14: =C14*$M14 -> 0.00064824599 | Q14: =D14*$M14 -> 5.8605448 | R14: =E14*$M14 -> -23.973515 | S14: =F14*$M14 -> 0.67685302 | T14: =G14*$M14 -> 0.0019363295 | U14: =H14*$M14 -> 0.00044094221 | V14: =I14*$M14 -> 0.0014840138 | W14: =J14*$M14 -> 0 | X14: =K14*$M14 -> 0
A15: =Datos!A23 -> 2009Q3 | B15: =Datos!F23 -> -0.0565118 | C15: =Datos!I23 -> 0.01889525 | D15: =Datos!H23 -> -533.98958 | E15: =Datos!H21 -> 3.4701679 | F15: =Datos!H17 -> 95.337039 | G15: =Datos!J17 -> -0.013616332 | H15: =Datos!K16 -> 0.12640686 | I15: =Datos!F22 -> -0.11274547 | J15: =IF($A15="2020Q2",1,0) -> 0 | K15: =IF($A15="2021Q2",1,0) -> 0 | L15: 1 | M15: =B15-($B$88+$B$89*C15+$B$90*D15+$B$91*E15+$B$92*F15+$B$93*G15+$B$94*H15+$B$95*I15+$B$96*J15+$B$97*K15) -> -0.009974775 | N15: =M15^2 -> 9.9496137e-05 | O15: =L15*$M15 -> -0.009974775 | P15: =C15*$M15 -> -0.00018847587 | Q15: =D15*$M15 -> 5.3264259 | R15: =E15*$M15 -> -0.034614144 | S15: =F15*$M15 -> -0.95096552 | T15: =G15*$M15 -> 0.00013581985 | U15: =H15*$M15 -> -0.00126088 | V15: =I15*$M15 -> 0.0011246107 | W15: =J15*$M15 -> 0 | X15: =K15*$M15 -> 0
A16: =Datos!A24 -> 2009Q4 | B16: =Datos!F24 -> 0.0028199823 | C16: =Datos!I24 -> 0.020266082 | D16: =Datos!H24 -> -203.74584 | E16: =Datos!H22 -> -244.40122 | F16: =Datos!H18 -> 74.414777 | G16: =Datos!J18 -> 0.051677263 | H16: =Datos!K17 -> 0.094714456 | I16: =Datos!F23 -> -0.0565118 | J16: =IF($A16="2020Q2",1,0) -> 0 | K16: =IF($A16="2021Q2",1,0) -> 0 | L16: 1 | M16: =B16-($B$88+$B$89*C16+$B$90*D16+$B$91*E16+$B$92*F16+$B$93*G16+$B$94*H16+$B$95*I16+$B$96*J16+$B$97*K16) -> 0.011483396 | N16: =M16^2 -> 0.00013186839 | O16: =L16*$M16 -> 0.011483396 | P16: =C16*$M16 -> 0.00023272345 | Q16: =D16*$M16 -> -2.3396942 | R16: =E16*$M16 -> -2.8065561 | S16: =F16*$M16 -> 0.85453438 | T16: =G16*$M16 -> 0.0005934305 | U16: =H16*$M16 -> 0.0010876436 | V16: =I16*$M16 -> -0.0006489474 | W16: =J16*$M16 -> 0 | X16: =K16*$M16 -> 0
A17: =Datos!A25 -> 2010Q1 | B17: =Datos!F25 -> 0.057132691 | C17: =Datos!I25 -> 0.036485145 | D17: =Datos!H25 -> 15.441636 | E17: =Datos!H23 -> -533.98958 | F17: =Datos!H19 -> 140.17397 | G17: =Datos!J19 -> -0.092266092 | H17: =Datos!K18 -> -0.088947266 | I17: =Datos!F24 -> 0.0028199823 | J17: =IF($A17="2020Q2",1,0) -> 0 | K17: =IF($A17="2021Q2",1,0) -> 0 | L17: 1 | M17: =B17-($B$88+$B$89*C17+$B$90*D17+$B$91*E17+$B$92*F17+$B$93*G17+$B$94*H17+$B$95*I17+$B$96*J17+$B$97*K17) -> 0.017231892 | N17: =M17^2 -> 0.00029693808 | O17: =L17*$M17 -> 0.017231892 | P17: =C17*$M17 -> 0.00062870805 | Q17: =D17*$M17 -> 0.26608859 | R17: =E17*$M17 -> -9.2016505 | S17: =F17*$M17 -> 2.4154626 | T17: =G17*$M17 -> -0.0015899193 | U17: =H17*$M17 -> -0.0015327296 | V17: =I17*$M17 -> 4.8593628e-05 | W17: =J17*$M17 -> 0 | X17: =K17*$M17 -> 0
... A81: =Datos!A89 -> 2026Q1 | B81: =Datos!F89 -> 0.024694045 | C81: =Datos!I89 -> -0.099649603 | D81: =Datos!H89 -> -216.77778 | E81: =Datos!H87 -> 142.30769 | F81: =Datos!H83 -> 140.77357 | G81: =Datos!J83 -> -0.11430199 | H81: =Datos!K82 -> 0.0075734887 | I81: =Datos!F88 -> 0.020580507 | J81: =IF($A81="2020Q2",1,0) -> 0 | K81: =IF($A81="2021Q2",1,0) -> 0 | L81: 1 | M81: =B81-($B$88+$B$89*C81+$B$90*D81+$B$91*E81+$B$92*F81+$B$93*G81+$B$94*H81+$B$95*I81+$B$96*J81+$B$97*K81) -> 0.01244604 | N81: =M81^2 -> 0.0001549039 | O81: =L81*$M81 -> 0.01244604 | P81: =C81*$M81 -> -0.0012402429 | Q81: =D81*$M81 -> -2.6980248 | R81: =E81*$M81 -> 1.7711672 | S81: =F81*$M81 -> 1.7520735 | T81: =G81*$M81 -> -0.0014226071 | U81: =H81*$M81 -> 9.4259941e-05 | V81: =I81*$M81 -> 0.00025614581 | W81: =J81*$M81 -> 0 | X81: =K81*$M81 -> 0
A86: A. ESTIMACION OLS (LINEST devuelve los coeficientes en orden inverso; se extraen con INDEX)
A87: Regresor | B87: Coef. | C87: Error est. | D87: t | E87: p-valor | G87: gl residuales | H87: =INDEX(LINEST($B$6:$B$81,$C$6:$K$81,TRUE(),TRUE()),4,2) -> 66
A88: const | B88: =INDEX(LINEST($B$6:$B$81,$C$6:$K$81,TRUE(),TRUE()),1,10) -> 0.0043873779 | C88: =INDEX(LINEST($B$6:$B$81,$C$6:$K$81,TRUE(),TRUE()),2,10) -> 0.0032046456 | D88: =B88/C88 -> 1.3690681 | E88: =TDIST(ABS(D88),$H$87,2) -> 0.1756193
A89: d(M3R) t | B89: =INDEX(LINEST($B$6:$B$81,$C$6:$K$81,TRUE(),TRUE()),1,9) -> 0.19773407 | C89: =INDEX(LINEST($B$6:$B$81,$C$6:$K$81,TRUE(),TRUE()),2,9) -> 0.045950261 | D89: =B89/C89 -> 4.3032198 | E89: =TDIST(ABS(D89),$H$87,2) -> 5.6946678e-05
A90: d(EMBI) t | B90: =INDEX(LINEST($B$6:$B$81,$C$6:$K$81,TRUE(),TRUE()),1,8) -> -2.7488042e-05 | C90: =INDEX(LINEST($B$6:$B$81,$C$6:$K$81,TRUE(),TRUE()),2,8) -> 1.237048e-05 | D90: =B90/C90 -> -2.2220674 | E90: =TDIST(ABS(D90),$H$87,2) -> 0.029711729
A91: d(EMBI) t-2 | B91: =INDEX(LINEST($B$6:$B$81,$C$6:$K$81,TRUE(),TRUE()),1,7) -> -5.0135604e-05 | C91: =INDEX(LINEST($B$6:$B$81,$C$6:$K$81,TRUE(),TRUE()),2,7) -> 1.1256852e-05 | D91: =B91/C91 -> -4.4537854 | E91: =TDIST(ABS(D91),$H$87,2) -> 3.336379e-05
A92: d(EMBI) t-6 | B92: =INDEX(LINEST($B$6:$B$81,$C$6:$K$81,TRUE(),TRUE()),1,6) -> 2.2106438e-05 | C92: =INDEX(LINEST($B$6:$B$81,$C$6:$K$81,TRUE(),TRUE()),2,6) -> 1.1653985e-05 | D92: =B92/C92 -> 1.8968994 | E92: =TDIST(ABS(D92),$H$87,2) -> 0.062218281
A93: d(GPN) t-6 | B93: =INDEX(LINEST($B$6:$B$81,$C$6:$K$81,TRUE(),TRUE()),1,5) -> -0.077211698 | C93: =INDEX(LINEST($B$6:$B$81,$C$6:$K$81,TRUE(),TRUE()),2,5) -> 0.025912216 | D93: =B93/C93 -> -2.9797412 | E93: =TDIST(ABS(D93),$H$87,2) -> 0.0040347552
A94: d(VITI) t-7 | B94: =INDEX(LINEST($B$6:$B$81,$C$6:$K$81,TRUE(),TRUE()),1,4) -> 0.11750335 | C94: =INDEX(LINEST($B$6:$B$81,$C$6:$K$81,TRUE(),TRUE()),2,4) -> 0.047896038 | D94: =B94/C94 -> 2.4532999 | E94: =TDIST(ABS(D94),$H$87,2) -> 0.016804084
A95: PBI t-1 | B95: =INDEX(LINEST($B$6:$B$81,$C$6:$K$81,TRUE(),TRUE()),1,3) -> 0.77322057 | C95: =INDEX(LINEST($B$6:$B$81,$C$6:$K$81,TRUE(),TRUE()),2,3) -> 0.056692827 | D95: =B95/C95 -> 13.638772 | E95: =TDIST(ABS(D95),$H$87,2) -> 7.1127822e-21
A96: D_2020Q2 | B96: =INDEX(LINEST($B$6:$B$81,$C$6:$K$81,TRUE(),TRUE()),1,2) -> -0.1452701 | C96: =INDEX(LINEST($B$6:$B$81,$C$6:$K$81,TRUE(),TRUE()),2,2) -> 0.032774356 | D96: =B96/C96 -> -4.4324318 | E96: =TDIST(ABS(D96),$H$87,2) -> 3.6010657e-05
A97: D_2021Q2 | B97: =INDEX(LINEST($B$6:$B$81,$C$6:$K$81,TRUE(),TRUE()),1,1) -> 0.14866773 | C97: =INDEX(LINEST($B$6:$B$81,$C$6:$K$81,TRUE(),TRUE()),2,1) -> 0.029937882 | D97: =B97/C97 -> 4.9658735 | E97: =TDIST(ABS(D97),$H$87,2) -> 5.1024096e-06
A99: B. BONDAD DE AJUSTE
A100: n (observaciones) | B100: =COUNT($B$6:$B$81) -> 76
A101: k (parametros) | B101: 10
A102: R2 | B102: =INDEX(LINEST($B$6:$B$81,$C$6:$K$81,TRUE(),TRUE()),3,1) -> 0.83631975
A103: R2 ajustado | B103: =1-(1-B102)*(B100-1)/(B100-B101) -> 0.81399972
A104: SSR | B104: =INDEX(LINEST($B$6:$B$81,$C$6:$K$81,TRUE(),TRUE()),5,2) -> 0.045194377
A105: log-verosimilitud | B105: =-B100/2*(LN(2*PI())+LN(B104/B100)+1) -> 174.40628
A106: AIC | B106: =-2*B105+2*B101 -> -328.81255
A107: BIC | B107: =-2*B105+LN(B100)*B101 -> -305.50522
A109: Durbin-Watson | B109: =SUMXMY2(M7:M81,M6:M80)/SUMSQ(M6:M81) -> 1.9624859
A111: C. ERRORES ESTANDAR HAC (Newey-West, nucleo de Bartlett, L=4)
A112: V = (X'X)^-1 S (X'X)^-1 , S = G0 + SUM_l w_l (G_l + G_l') , w_l = 1 - l/5
...

Sheet Rezagos_BIC
A1: REZAGOS OPTIMOS POR BIC — d(M3R t-5), d(EMBI t / t-2 / t-6), d(GPN t-6), d(VITI t-1)
A2: Minimo BIC entre 94.041 combinaciones (subconjuntos de hasta 3 rezagos de EMBI x rezagos 0-8 del resto) sujeto a que todos los p sean menores a 0,05. OJO: d(M3R) t-5 sale con signo NEGATIVO.
A5: Periodo | B5: y | C5: d(M3R) t-5 | D5: d(EMBI) t | E5: d(EMBI) t-2 | F5: d(EMBI) t-6 | G5: d(GPN) t-6 | H5: d(VITI) t-1 | I5: const=1 | J5: residuo e | K5: e^2
A6: =Datos!A14 -> 2007Q2 | B6: =Datos!L14 -> 0.015004463 | C6: =Datos!I9 -> -0.041919809 | D6: =Datos!H14 -> 58.106231 | E6: =Datos!H12 -> -57.340028 | F6: =Datos!H8 -> 9.6869022 | G6: =Datos!J8 -> -0.065284118 | H6: =Datos!K13 -> 0.039471358 | I6: 1 | J6: =B6-($B$88+$B$89*C6+$B$90*D6+$B$91*E6+$B$92*F6+$B$93*G6+$B$94*H6) -> -0.0053546091 | K6: =J6^2 -> 2.8671839e-05
