Workbook

Sheet Resumen
A1: MODELO DE PBI — PBI BR, M3R, M1R, RPRIM, EMBI
A2: Muestra comun 2007Q3-2026Q1 (n=75) en los cuatro modelos.
A4: Metrica | B4: BASE (sin AR) | C4: BASE + PBI(t-1) | D4: OPTIMO | E4: OPTIMO + dummies COVID
A5: n | B5: =Modelo_Base!B97 -> 75 | C5: =Modelo_ADL!B98 -> 75 | D5: =Modelo_Optimo!B95 -> 75 | E5: =Modelo_COVID!B97 -> 75
A6: k (parametros) | B6: =Modelo_Base!B98 -> 8 | C6: =Modelo_ADL!B99 -> 9 | D6: =Modelo_Optimo!B96 -> 6 | E6: =Modelo_COVID!B98 -> 8
A7: R2 | B7: =Modelo_Base!B99 -> 0.27884352 | C7: =Modelo_ADL!B100 -> 0.81904415 | D7: =Modelo_Optimo!B97 -> 0.81088071 | E7: =Modelo_COVID!B99 -> 0.85020979
A8: R2 ajustado | B8: =Modelo_Base!B100 -> 0.20349882 | C8: =Modelo_ADL!B101 -> 0.7971101 | D8: =Modelo_Optimo!B98 -> 0.79717642 | E8: =Modelo_COVID!B100 -> 0.83456007
A9: SSR | B9: =Modelo_Base!B101 -> 0.19399275 | C9: =Modelo_ADL!B102 -> 0.048677542 | D9: =Modelo_Optimo!B99 -> 0.050873524 | E9: =Modelo_COVID!B101 -> 0.040293912
A10: AIC | B10: =Modelo_Base!B103 -> -217.96591 | C10: =Modelo_ADL!B104 -> -319.66114 | D10: =Modelo_Optimo!B101 -> -322.35178 | E10: =Modelo_COVID!B103 -> -335.83745
A11: BIC | B11: =Modelo_Base!B104 -> -199.42601 | C11: =Modelo_ADL!B105 -> -298.80375 | D11: =Modelo_Optimo!B102 -> -308.44685 | E11: =Modelo_COVID!B104 -> -317.29754
A12: Durbin-Watson | B12: =Modelo_Base!B106 -> 0.68276096 | C12: =Modelo_ADL!B107 -> 2.1218404 | D12: =Modelo_Optimo!B104 -> 2.1976834 | E12: =Modelo_COVID!B106 -> 2.1890832
A13: Autocorrel. residuos rezago 1 | B13: =Diagnosticos!B6 -> 0.64608499 | C13: =Diagnosticos!C6 -> -0.066466256 | D13: =Diagnosticos!D6 -> -0.10777179 | E13: =Diagnosticos!E6 -> -0.11113202
A14: Breusch-Pagan p | B14: =Diagnosticos!E19 -> 0.10076524 | C14: =Diagnosticos!E20 -> 0.35359342 | D14: =Diagnosticos!E21 -> 0.59898732 | E14: =Diagnosticos!E22 -> 0.8620686
A16: Los dos rezagos largos de EMBI de tu especificacion
A17: H0: beta_EMBI(t-6) + beta_EMBI(t-7) = 0
A18: F | B18: =Modelo_Base!B114 -> 0.0025477332 | C18: Ninguno de los dos es significativo por separado y se cancelan entre si: no aportan.
A19: p-valor | B19: =Modelo_Base!B115 -> 0.95989399
A21: Test F de las dummies COVID (H0: ambas = 0)
A22: F | B22: =Modelo_COVID!B209 -> 8.7957955
A23: p-valor | B23: =Modelo_COVID!B210 -> 0.00040555047
A25: Test F: conviene diferenciar la dependiente? (H0: coef PBI(t-1) = 1)
A26: F | B26: =Modelo_COVID!B218 -> 6.831233
A27: p-valor | B27: =Modelo_COVID!B219 -> 0.011051551
A29: Coeficientes de la especificacion recomendada, errores HAC (Newey-West, L=4)
A30: Regresor | B30: Coef. | C30: se HAC | D30: t HAC | E30: p HAC
A31: =Modelo_COVID!A193 -> const | B31: =Modelo_COVID!B193 -> 0.0020966365 | C31: =Modelo_COVID!C193 -> 0.0023564939 | D31: =Modelo_COVID!D193 -> 0.88972712 | E31: =Modelo_COVID!E193 -> 0.376796
A32: =Modelo_COVID!A194 -> PBI t-1 | B32: =Modelo_COVID!B194 -> 0.84724037 | C32: =Modelo_COVID!C194 -> 0.045468192 | D32: =Modelo_COVID!D194 -> 18.633694 | E32: =Modelo_COVID!E194 -> 3.3177696e-28
A33: =Modelo_COVID!A195 -> d(PBI BR) t | B33: =Modelo_COVID!B195 -> 0.6270259 | C33: =Modelo_COVID!C195 -> 0.17209088 | D33: =Modelo_COVID!D195 -> 3.6435742 | E33: =Modelo_COVID!E195 -> 0.00052544139
A34: =Modelo_COVID!A196 -> d(EMBI) t-2 | B34: =Modelo_COVID!B196 -> -4.61925e-05 | C34: =Modelo_COVID!C196 -> 6.9381226e-06 | D34: =Modelo_COVID!D196 -> -6.6577809 | E34: =Modelo_COVID!E196 -> 6.1760313e-09
A35: =Modelo_COVID!A197 -> d(RPRIM) t-2 | B35: =Modelo_COVID!B197 -> -1.6032226 | C35: =Modelo_COVID!C197 -> 0.44094685 | D35: =Modelo_COVID!D197 -> -3.6358636 | E35: =Modelo_COVID!E197 -> 0.00053872386
A36: =Modelo_COVID!A198 -> d(M1R) t | B36: =Modelo_COVID!B198 -> 0.24286594 | C36: =Modelo_COVID!C198 -> 0.039430886 | D36: =Modelo_COVID!D198 -> 6.1592819 | E36: =Modelo_COVID!E198 -> 4.6789392e-08
A37: =Modelo_COVID!A199 -> D_2020Q2 | B37: =Modelo_COVID!B199 -> -0.11967415 | C37: =Modelo_COVID!C199 -> 0.024377872 | D37: =Modelo_COVID!D199 -> -4.9091303 | E37: =Modelo_COVID!E199 -> 6.1616427e-06
A38: =Modelo_COVID!A200 -> D_2021Q2 | B38: =Modelo_COVID!B200 -> 0.11370194 | C38: =Modelo_COVID!C200 -> 0.021874488 | D38: =Modelo_COVID!D200 -> 5.1979245 | E38: =Modelo_COVID!E200 -> 2.0629728e-06
A40: COMO USAR ESTE ARCHIVO
A41: 1. Editable solo lo azul de la hoja Datos. Todo lo demas es formula.
A42: 2. Para agregar un trimestre: extender las filas de Datos y de cada hoja de modelo, y recalcular.
A43: 3. Las regresiones usan INDEX(LINEST(...)) para devolver escalares, sin formulas matriciales.
A44: 4. AIC y BIC siguen la convencion de statsmodels: -2logL + 2k y -2logL + ln(n)k.
A45: 5. Cita los errores HAC, no los de LINEST.

Sheet Datos
A1: DATOS Y TRANSFORMACIONES
A2: Azul = dato original (editable). Negro = formula. Trimestral 2005Q1-2026Q1.
A3: PBI, PBI de Brasil, M3R y M1R ya vienen como variacion interanual (I(0)). EMBI y RPRIM son I(1) y requieren diferencia. d(.) es la primera diferencia de cada serie.
A4: Periodo | B4: EMBI (pb) | C4: PBI BR | D4: M3R | E4: M1R | F4: RPRIM | G4: PBI (dep.) | I4: d(EMBI) | J4: d(PBI BR) | K4: d(M3R) | L4: d(M1R) | M4: d(RPRIM) | N4: PBI (t-1)
A5: 2005Q1 | C5: 0.0419 | D5: 0.1262661 | E5: 0.16600162 | F5: 0.034908139 | G5: 0.072187868
A6: 2005Q2 | C6: 0.0447 | D6: 0.16505259 | E6: 0.17034803 | F6: 0.032382121 | G6: 0.13077981 | I6: =IF(AND(ISNUMBER(B6),ISNUMBER(B5)),B6-B5,"") | J6: =C6-C5 -> 0.0028 | K6: =D6-D5 -> 0.038786492 | L6: =E6-E5 -> 0.0043464128 | M6: =F6-F5 -> -0.0025260179 | N6: =G5 -> 0.072187868
A7: 2005Q3 | B7: 413.72934 | C7: 0.0211 | D7: 0.083135769 | E7: 0.095469669 | F7: 0.031469465 | G7: 0.069719779 | I7: =IF(AND(ISNUMBER(B7),ISNUMBER(B6)),B7-B6,"") | J7: =C7-C6 -> -0.0236 | K7: =D7-D6 -> -0.081916822 | L7: =E7-E6 -> -0.074878365 | M7: =F7-F6 -> -0.00091265601 | N7: =G6 -> 0.13077981
A8: 2005Q4 | B8: 423.41625 | C8: 0.0215 | D8: 0.066830714 | E8: 0.10753949 | F8: 0.033622607 | G8: 0.077828945 | I8: =IF(AND(ISNUMBER(B8),ISNUMBER(B7)),B8-B7,"") -> 9.6869022 | J8: =C8-C7 -> 0.0004 | K8: =D8-D7 -> -0.016305055 | L8: =E8-E7 -> 0.012069817 | M8: =F8-F7 -> 0.0021531419 | N8: =G7 -> 0.069719779
A9: 2006Q1 | B9: 394.41518 | C9: 0.0428 | D9: 0.024910905 | E9: 0.065572691 | F9: 0.032958003 | G9: 0.078495711 | I9: =IF(AND(ISNUMBER(B9),ISNUMBER(B8)),B9-B8,"") -> -29.001068 | J9: =C9-C8 -> 0.0213 | K9: =D9-D8 -> -0.041919809 | L9: =E9-E8 -> -0.041966795 | M9: =F9-F8 -> -0.00066460466 | N9: =G8 -> 0.077828945
A10: 2006Q2 | B10: 353.71381 | C10: 0.0228 | D10: 0.048520637 | E10: 0.074826081 | F10: 0.031862289 | G10: 0.055715853 | I10: =IF(AND(ISNUMBER(B10),ISNUMBER(B9)),B10-B9,"") -> -40.701368 | J10: =C10-C9 -> -0.02 | K10: =D10-D9 -> 0.023609732 | L10: =E10-E9 -> 0.0092533896 | M10: =F10-F9 -> -0.0010957136 | N10: =G9 -> 0.078495711
A11: 2006Q3 | B11: 339.04529 | C11: 0.0449 | D11: 0.06474531 | E11: 0.0729218 | F11: 0.031968251 | G11: 0.093804903 | I11: =IF(AND(ISNUMBER(B11),ISNUMBER(B10)),B11-B10,"") -> -14.668524 | J11: =C11-C10 -> 0.0221 | K11: =D11-D10 -> 0.016224674 | L11: =E11-E10 -> -0.0019042811 | M11: =F11-F10 -> 0.00010596207 | N11: =G10 -> 0.055715853
A12: 2006Q4 | B12: 281.70526 | C12: 0.048 | D12: 0.092447249 | E12: 0.082156516 | F12: 0.032215474 | G12: 0.096770404 | I12: =IF(AND(ISNUMBER(B12),ISNUMBER(B11)),B12-B11,"") -> -57.340028 | J12: =C12-C11 -> 0.0031 | K12: =D12-D11 -> 0.027701939 | L12: =E12-E11 -> 0.0092347162 | M12: =F12-F11 -> 0.00024722299 | N12: =G11 -> 0.093804903
A13: 2007Q1 | B13: 210.27944 | C13: 0.052 | D13: 0.1266018 | E13: 0.10364673 | F13: 0.031042814 | G13: 0.083589411 | I13: =IF(AND(ISNUMBER(B13),ISNUMBER(B12)),B13-B12,"") -> -71.425823 | J13: =C13-C12 -> 0.004 | K13: =D13-D12 -> 0.034154549 | L13: =E13-E12 -> 0.021490214 | M13: =F13-F12 -> -0.0011726597 | N13: =G12 -> 0.096770404
A14: 2007Q2 | B14: 268.38567 | C14: 0.0654 | D14: 0.11396594 | E14: 0.10878117 | F14: 0.031321511 | G14: 0.098593874 | I14: =IF(AND(ISNUMBER(B14),ISNUMBER(B13)),B14-B13,"") -> 58.106231 | J14: =C14-C13 -> 0.0134 | K14: =D14-D13 -> -0.012635858 | L14: =E14-E13 -> 0.0051344367 | M14: =F14-F13 -> 0.00027869619 | N14: =G13 -> 0.083589411
A15: 2007Q3 | B15: 415.12806 | C15: 0.0587 | D15: 0.089343321 | E15: 0.095031538 | F15: 0.031924431 | G15: 0.084277977 | I15: =IF(AND(ISNUMBER(B15),ISNUMBER(B14)),B15-B14,"") -> 146.7424 | J15: =C15-C14 -> -0.0067 | K15: =D15-D14 -> -0.024622619 | L15: =E15-E14 -> -0.013749629 | M15: =F15-F14 -> 0.00060292067 | N15: =G14 -> 0.098593874
A16: 2007Q4 | B16: 386.90139 | C16: 0.0664 | D16: 0.037973687 | E16: 0.03479478 | F16: 0.028543076 | G16: 0.092673486 | I16: =IF(AND(ISNUMBER(B16),ISNUMBER(B15)),B16-B15,"") -> -28.226676 | J16: =C16-C15 -> 0.0077 | K16: =D16-D15 -> -0.051369633 | L16: =E16-E15 -> -0.060236757 | M16: =F16-F15 -> -0.0033813551 | N16: =G15 -> 0.084277977
A17: 2008Q1 | B17: 482.23843 | C17: 0.0616 | D17: 0.0057682917 | E17: 0.0060995986 | F17: 0.025607989 | G17: 0.069123146 | I17: =IF(AND(ISNUMBER(B17),ISNUMBER(B16)),B17-B16,"") -> 95.337039 | J17: =C17-C16 -> -0.0048 | K17: =D17-D16 -> -0.032205396 | L17: =E17-E16 -> -0.028695182 | M17: =F17-F16 -> -0.0029350876 | N17: =G16 -> 0.092673486
A18: 2008Q2 | B18: 556.6532 | C18: 0.0634 | D18: -0.041444326 | E18: -0.032825593 | F18: 0.023277094 | G18: 0.054526855 | I18: =IF(AND(ISNUMBER(B18),ISNUMBER(B17)),B18-B17,"") -> 74.414777 | J18: =C18-C17 -> 0.0018 | K18: =D18-D17 -> -0.047212617 | L18: =E18-E17 -> -0.038925191 | M18: =F18-F17 -> -0.0023308948 | N18: =G17 -> 0.069123146
... A89: 2026Q1 | B89: 536.22222 | C89: 0.0182 | D89: 0.0053681849 | E89: -0.030260826 | F89: 0.012 | G89: 0.024694045 | I89: =IF(AND(ISNUMBER(B89),ISNUMBER(B88)),B89-B88,"") -> -216.77778 | J89: =C89-C88 -> 0 | K89: =D89-D88 -> -0.099649603 | L89: =E89-E88 -> -0.10243736 | M89: =F89-F88 -> 0.0023432509 | N89: =G88 -> 0.020580507
B91: EMBI 2005Q1-Q2 venia codificado como 0 en el origen: es un faltante, no un dato.

Sheet Modelo_Base
A1: MODELO BASE — PBI ~ d(PBI BR) + d(M3R) + d(RPRIM t-1) + d(EMBI t-2) + d(M1R t-3) + d(EMBI t-6) + d(EMBI t-7)
A2: Especificacion tal cual la usas: dependiente en NIVEL (variacion i.a.) contra regresores todos DIFERENCIADOS. Muestra comun 2007Q3-2026Q1 (n=75).
A5: Periodo | B5: y = PBI | C5: d(PBI BR) t | D5: d(M3R) t | E5: d(RPRIM) t-1 | F5: d(EMBI) t-2 | G5: d(M1R) t-3 | H5: d(EMBI) t-6 | I5: d(EMBI) t-7 | J5: const=1 | K5: residuo e | L5: e^2 | P5: R: d(PBI BR) | Q5: R: d(M3R) | R5: R: d(RPRIM t-1) | S5: R: d(EMBI t-2) | T5: R: d(M1R t-3) | U5: R: d(EMBI t-6)-d(EMBI t-7)
A6: =Datos!A15 -> 2007Q3 | B6: =Datos!G15 -> 0.084277977 | C6: =Datos!J15 -> -0.0067 | D6: =Datos!K15 -> -0.024622619 | E6: =Datos!M14 -> 0.00027869619 | F6: =Datos!I13 -> -71.425823 | G6: =Datos!L12 -> 0.0092347162 | H6: =Datos!I9 -> -29.001068 | I6: =Datos!I8 -> 9.6869022 | J6: 1 | K6: =B6-($B$87+$B$88*C6+$B$89*D6+$B$90*E6+$B$91*F6+$B$92*G6+$B$93*H6+$B$94*I6) -> 0.065145279 | L6: =K6^2 -> 0.0042439074 | P6: =C6 -> -0.0067 | Q6: =D6 -> -0.024622619 | R6: =E6 -> 0.00027869619 | S6: =F6 -> -71.425823 | T6: =G6 -> 0.0092347162 | U6: =H6-I6 -> -38.687971
A7: =Datos!A16 -> 2007Q4 | B7: =Datos!G16 -> 0.092673486 | C7: =Datos!J16 -> 0.0077 | D7: =Datos!K16 -> -0.051369633 | E7: =Datos!M15 -> 0.00060292067 | F7: =Datos!I14 -> 58.106231 | G7: =Datos!L13 -> 0.021490214 | H7: =Datos!I10 -> -40.701368 | I7: =Datos!I9 -> -29.001068 | J7: 1 | K7: =B7-($B$87+$B$88*C7+$B$89*D7+$B$90*E7+$B$91*F7+$B$92*G7+$B$93*H7+$B$94*I7) -> 0.074282602 | L7: =K7^2 -> 0.0055179049 | P7: =C7 -> 0.0077 | Q7: =D7 -> -0.051369633 | R7: =E7 -> 0.00060292067 | S7: =F7 -> 58.106231 | T7: =G7 -> 0.021490214 | U7: =H7-I7 -> -11.700299
A8: =Datos!A17 -> 2008Q1 | B8: =Datos!G17 -> 0.069123146 | C8: =Datos!J17 -> -0.0048 | D8: =Datos!K17 -> -0.032205396 | E8: =Datos!M16 -> -0.0033813551 | F8: =Datos!I15 -> 146.7424 | G8: =Datos!L14 -> 0.0051344367 | H8: =Datos!I11 -> -14.668524 | I8: =Datos!I10 -> -40.701368 | J8: 1 | K8: =B8-($B$87+$B$88*C8+$B$89*D8+$B$90*E8+$B$91*F8+$B$92*G8+$B$93*H8+$B$94*I8) -> 0.075854467 | L8: =K8^2 -> 0.0057539001 | P8: =C8 -> -0.0048 | Q8: =D8 -> -0.032205396 | R8: =E8 -> -0.0033813551 | S8: =F8 -> 146.7424 | T8: =G8 -> 0.0051344367 | U8: =H8-I8 -> 26.032844
A9: =Datos!A18 -> 2008Q2 | B9: =Datos!G18 -> 0.054526855 | C9: =Datos!J18 -> 0.0018 | D9: =Datos!K18 -> -0.047212617 | E9: =Datos!M17 -> -0.0029350876 | F9: =Datos!I16 -> -28.226676 | G9: =Datos!L15 -> -0.013749629 | H9: =Datos!I12 -> -57.340028 | I9: =Datos!I11 -> -14.668524 | J9: 1 | K9: =B9-($B$87+$B$88*C9+$B$89*D9+$B$90*E9+$B$91*F9+$B$92*G9+$B$93*H9+$B$94*I9) -> 0.046940531 | L9: =K9^2 -> 0.0022034134 | P9: =C9 -> 0.0018 | Q9: =D9 -> -0.047212617 | R9: =E9 -> -0.0029350876 | S9: =F9 -> -28.226676 | T9: =G9 -> -0.013749629 | U9: =H9-I9 -> -42.671504
A10: =Datos!A19 -> 2008Q3 | B10: =Datos!G19 -> 0.060060161 | C10: =Datos!J19 -> 0.0064 | D10: =Datos!K19 -> 0.010388192 | E10: =Datos!M18 -> -0.0023308948 | F10: =Datos!I17 -> 95.337039 | G10: =Datos!L16 -> -0.060236757 | H10: =Datos!I13 -> -71.425823 | I10: =Datos!I12 -> -57.340028 | J10: 1 | K10: =B10-($B$87+$B$88*C10+$B$89*D10+$B$90*E10+$B$91*F10+$B$92*G10+$B$93*H10+$B$94*I10) -> 0.061907093 | L10: =K10^2 -> 0.0038324882 | P10: =C10 -> 0.0064 | Q10: =D10 -> 0.010388192 | R10: =E10 -> -0.0023308948 | S10: =F10 -> 95.337039 | T10: =G10 -> -0.060236757 | U10: =H10-I10 -> -14.085795
A11: =Datos!A20 -> 2008Q4 | B11: =Datos!G20 -> -0.019789909 | C11: =Datos!J20 -> -0.0596 | D11: =Datos!K20 -> -0.012294191 | E11: =Datos!M19 -> -4.1934295e-05 | F11: =Datos!I18 -> 74.414777 | G11: =Datos!L17 -> -0.028695182 | H11: =Datos!I14 -> 58.106231 | I11: =Datos!I13 -> -71.425823 | J11: 1 | K11: =B11-($B$87+$B$88*C11+$B$89*D11+$B$90*E11+$B$91*F11+$B$92*G11+$B$93*H11+$B$94*I11) -> -0.0018375044 | L11: =K11^2 -> 3.3764224e-06 | P11: =C11 -> -0.0596 | Q11: =D11 -> -0.012294191 | R11: =E11 -> -4.1934295e-05 | S11: =F11 -> 74.414777 | T11: =G11 -> -0.028695182 | U11: =H11-I11 -> 129.53205
A12: =Datos!A21 -> 2009Q1 | B12: =Datos!G21 -> -0.061887551 | C12: =Datos!J21 -> -0.0344 | D12: =Datos!K21 -> -0.05064093 | E12: =Datos!M20 -> -0.0027010372 | F12: =Datos!I19 -> 140.17397 | G12: =Datos!L18 -> -0.038925191 | H12: =Datos!I15 -> 146.7424 | I12: =Datos!I14 -> 58.106231 | J12: 1 | K12: =B12-($B$87+$B$88*C12+$B$89*D12+$B$90*E12+$B$91*F12+$B$92*G12+$B$93*H12+$B$94*I12) -> -0.041105603 | L12: =K12^2 -> 0.0016896706 | P12: =C12 -> -0.0344 | Q12: =D12 -> -0.05064093 | R12: =E12 -> -0.0027010372 | S12: =F12 -> 140.17397 | T12: =G12 -> -0.038925191 | U12: =H12-I12 -> 88.636166
A13: =Datos!A22 -> 2009Q2 | B13: =Datos!G22 -> -0.11274547 | C13: =Datos!J22 -> 0.0022 | D13: =Datos!K22 -> -0.027033683 | E13: =Datos!M21 -> -0.003479831 | F13: =Datos!I20 -> 999.76307 | G13: =Datos!L19 -> 0.020219373 | H13: =Datos!I16 -> -28.226676 | I13: =Datos!I15 -> 146.7424 | J13: 1 | K13: =B13-($B$87+$B$88*C13+$B$89*D13+$B$90*E13+$B$91*F13+$B$92*G13+$B$93*H13+$B$94*I13) -> -0.054391402 | L13: =K13^2 -> 0.0029584246 | P13: =C13 -> 0.0022 | Q13: =D13 -> -0.027033683 | R13: =E13 -> -0.003479831 | S13: =F13 -> 999.76307 | T13: =G13 -> 0.020219373 | U13: =H13-I13 -> -174.96907
A14: =Datos!A23 -> 2009Q3 | B14: =Datos!G23 -> -0.0565118 | C14: =Datos!J23 -> 0.0104 | D14: =Datos!K23 -> 0.01889525 | E14: =Datos!M22 -> -0.0080313345 | F14: =Datos!I21 -> 3.4701679 | G14: =Datos!L20 -> 0.020816404 | H14: =Datos!I17 -> 95.337039 | I14: =Datos!I16 -> -28.226676 | J14: 1 | K14: =B14-($B$87+$B$88*C14+$B$89*D14+$B$90*E14+$B$91*F14+$B$92*G14+$B$93*H14+$B$94*I14) -> -0.052238661 | L14: =K14^2 -> 0.0027288777 | P14: =C14 -> 0.0104 | Q14: =D14 -> 0.01889525 | R14: =E14 -> -0.0080313345 | S14: =F14 -> 3.4701679 | T14: =G14 -> 0.020816404 | U14: =H14-I14 -> 123.56372
A15: =Datos!A24 -> 2009Q4 | B15: =Datos!G24 -> 0.0028199823 | C15: =Datos!J24 -> 0.0649 | D15: =Datos!K24 -> 0.020266082 | E15: =Datos!M23 -> -0.0083302112 | F15: =Datos!I22 -> -244.40122 | G15: =Datos!L21 -> -0.037438837 | H15: =Datos!I18 -> 74.414777 | I15: =Datos!I17 -> 95.337039 | J15: 1 | K15: =B15-($B$87+$B$88*C15+$B$89*D15+$B$90*E15+$B$91*F15+$B$92*G15+$B$93*H15+$B$94*I15) -> -0.025963499 | L15: =K15^2 -> 0.00067410329 | P15: =C15 -> 0.0649 | Q15: =D15 -> 0.020266082 | R15: =E15 -> -0.0083302112 | S15: =F15 -> -244.40122 | T15: =G15 -> -0.037438837 | U15: =H15-I15 -> -20.922262
A16: =Datos!A25 -> 2010Q1 | B16: =Datos!G25 -> 0.057132691 | C16: =Datos!J25 -> 0.0388 | D16: =Datos!K25 -> 0.036485145 | E16: =Datos!M24 -> -0.0073833969 | F16: =Datos!I23 -> -533.98958 | G16: =Datos!L22 -> -0.043804081 | H16: =Datos!I19 -> 140.17397 | I16: =Datos!I18 -> 74.414777 | J16: 1 | K16: =B16-($B$87+$B$88*C16+$B$89*D16+$B$90*E16+$B$91*F16+$B$92*G16+$B$93*H16+$B$94*I16) -> 0.017873257 | L16: =K16^2 -> 0.00031945332 | P16: =C16 -> 0.0388 | Q16: =D16 -> 0.036485145 | R16: =E16 -> -0.0073833969 | S16: =F16 -> -533.98958 | T16: =G16 -> -0.043804081 | U16: =H16-I16 -> 65.759192
A17: =Datos!A26 -> 2010Q2 | B17: =Datos!G26 -> 0.162442 | C17: =Datos!J26 -> -0.0069 | D17: =Datos!K26 -> 0.11549915 | E17: =Datos!M25 -> -0.0027481508 | F17: =Datos!I24 -> -203.74584 | G17: =Datos!L23 -> 0.027171203 | H17: =Datos!I20 -> 999.76307 | I17: =Datos!I19 -> 140.17397 | J17: 1 | K17: =B17-($B$87+$B$88*C17+$B$89*D17+$B$90*E17+$B$91*F17+$B$92*G17+$B$93*H17+$B$94*I17) -> 0.14689821 | L17: =K17^2 -> 0.021579085 | P17: =C17 -> -0.0069 | Q17: =D17 -> 0.11549915 | R17: =E17 -> -0.0027481508 | S17: =F17 -> -203.74584 | T17: =G17 -> 0.027171203 | U17: =H17-I17 -> 859.5891
... A80: =Datos!A89 -> 2026Q1 | B80: =Datos!G89 -> 0.024694045 | C80: =Datos!J89 -> 0 | D80: =Datos!K89 -> -0.099649603 | E80: =Datos!M88 -> -0.0016763505 | F80: =Datos!I87 -> 142.30769 | G80: =Datos!L86 -> 0.028594651 | H80: =Datos!I83 -> 140.77357 | I80: =Datos!I82 -> -411.7502 | J80: 1 | K80: =B80-($B$87+$B$88*C80+$B$89*D80+$B$90*E80+$B$91*F80+$B$92*G80+$B$93*H80+$B$94*I80) -> 0.024885922 | L80: =K80^2 -> 0.00061930911 | P80: =C80 -> 0 | Q80: =D80 -> -0.099649603 | R80: =E80 -> -0.0016763505 | S80: =F80 -> 142.30769 | T80: =G80 -> 0.028594651 | U80: =H80-I80 -> 552.52377
A85: A. ESTIMACION OLS (LINEST devuelve los coeficientes en orden inverso; se extraen con INDEX)
A86: Regresor | B86: Coef. | C86: Error est. | D86: t | E86: p-valor | G86: gl resid. | H86: =INDEX(LINEST($B$6:$B$80,$C$6:$I$80,TRUE(),TRUE()),4,2) -> 67
A87: const | B87: =INDEX(LINEST($B$6:$B$80,$C$6:$I$80,TRUE(),TRUE()),1,8) -> 0.01506005 | C87: =INDEX(LINEST($B$6:$B$80,$C$6:$I$80,TRUE(),TRUE()),2,8) -> 0.0062490826 | D87: =B87/C87 -> 2.4099617 | E87: =TDIST(ABS(D87),$H$86,2) -> 0.01870672
A88: d(PBI BR) t | B88: =INDEX(LINEST($B$6:$B$80,$C$6:$I$80,TRUE(),TRUE()),1,7) -> 0.40755943 | C88: =INDEX(LINEST($B$6:$B$80,$C$6:$I$80,TRUE(),TRUE()),2,7) -> 0.25870585 | D88: =B88/C88 -> 1.5753777 | E88: =TDIST(ABS(D88),$H$86,2) -> 0.11987978
A89: d(M3R) t | B89: =INDEX(LINEST($B$6:$B$80,$C$6:$I$80,TRUE(),TRUE()),1,6) -> -0.0015620714 | C89: =INDEX(LINEST($B$6:$B$80,$C$6:$I$80,TRUE(),TRUE()),2,6) -> 0.083726046 | D89: =B89/C89 -> -0.018656935 | E89: =TDIST(ABS(D89),$H$86,2) -> 0.98517023
A90: d(RPRIM) t-1 | B90: =INDEX(LINEST($B$6:$B$80,$C$6:$I$80,TRUE(),TRUE()),1,5) -> 3.0711585 | C90: =INDEX(LINEST($B$6:$B$80,$C$6:$I$80,TRUE(),TRUE()),2,5) -> 1.0000887 | D90: =B90/C90 -> 3.0708861 | E90: =TDIST(ABS(D90),$H$86,2) -> 0.0030821914
A91: d(EMBI) t-2 | B91: =INDEX(LINEST($B$6:$B$80,$C$6:$I$80,TRUE(),TRUE()),1,4) -> -6.6838372e-05 | C91: =INDEX(LINEST($B$6:$B$80,$C$6:$I$80,TRUE(),TRUE()),2,4) -> 2.3044531e-05 | D91: =B91/C91 -> -2.9004006 | E91: =TDIST(ABS(D91),$H$86,2) -> 0.0050364669
A92: d(M1R) t-3 | B92: =INDEX(LINEST($B$6:$B$80,$C$6:$I$80,TRUE(),TRUE()),1,3) -> 0.098902675 | C92: =INDEX(LINEST($B$6:$B$80,$C$6:$I$80,TRUE(),TRUE()),2,3) -> 0.081919875 | D92: =B92/C92 -> 1.2073099 | E92: =TDIST(ABS(D92),$H$86,2) -> 0.23155776
A93: d(EMBI) t-6 | B93: =INDEX(LINEST($B$6:$B$80,$C$6:$I$80,TRUE(),TRUE()),1,2) -> -5.3511464e-06 | C93: =INDEX(LINEST($B$6:$B$80,$C$6:$I$80,TRUE(),TRUE()),2,2) -> 2.2692433e-05 | D93: =B93/C93 -> -0.23581193 | E93: =TDIST(ABS(D93),$H$86,2) -> 0.81429796
A94: d(EMBI) t-7 | B94: =INDEX(LINEST($B$6:$B$80,$C$6:$I$80,TRUE(),TRUE()),1,1) -> 6.8546932e-06 | C94: =INDEX(LINEST($B$6:$B$80,$C$6:$I$80,TRUE(),TRUE()),2,1) -> 2.2906679e-05 | D94: =B94/C94 -> 0.2992443 | E94: =TDIST(ABS(D94),$H$86,2) -> 0.76567995
A96: B. BONDAD DE AJUSTE
A97: n (observaciones) | B97: =COUNT($B$6:$B$80) -> 75
A98: k (parametros) | B98: 8
A99: R2 | B99: =INDEX(LINEST($B$6:$B$80,$C$6:$I$80,TRUE(),TRUE()),3,1) -> 0.27884352
A100: R2 ajustado | B100: =1-(1-B99)*(B97-1)/(B97-B98) -> 0.20349882
A101: SSR | B101: =INDEX(LINEST($B$6:$B$80,$C$6:$I$80,TRUE(),TRUE()),5,2) -> 0.19399275
A102: log-verosimilitud | B102: =-B97/2*(LN(2*PI())+LN(B101/B97)+1) -> 116.98296
A103: AIC | B103: =-2*B102+2*B98 -> -217.96591
A104: BIC | B104: =-2*B102+LN(B97)*B98 -> -199.42601
A106: Durbin-Watson | B106: =SUMXMY2(K7:K80,K6:K79)/SUMSQ(K6:K80) -> 0.68276096
A108: C. TEST F: H0 = beta_EMBI(t-6) + beta_EMBI(t-7) = 0
A109: Los dos rezagos largos de EMBI son individualmente no significativos y practicamente se cancelan entre si.
A110: SSR irrestricto | B110: =B101 -> 0.19399275
A111: SSR restringido | B111: =INDEX(LINEST($B$6:$B$80,$P$6:$U$80,TRUE(),TRUE()),5,2) -> 0.19400013
...

Sheet Modelo_ADL
A1: MODELO BASE + PBI(t-1)
A2: La dependiente es persistente y todos los regresores estan diferenciados: sin termino autorregresivo el modelo no puede explicar esa persistencia. Aca se agrega PBI(t-1).
A5: Periodo | B5: y = PBI | C5: PBI t-1 | D5: d(PBI BR) t | E5: d(M3R) t | F5: d(RPRIM) t-1 | G5: d(EMBI) t-2 | H5: d(M1R) t-3 | I5: d(EMBI) t-6 | J5: d(EMBI) t-7 | K5: const=1 | L5: residuo e | M5: e^2
A6: =Datos!A15 -> 2007Q3 | B6: =Datos!G15 -> 0.084277977 | C6: =Datos!N15 -> 0.098593874 | D6: =Datos!J15 -> -0.0067 | E6: =Datos!K15 -> -0.024622619 | F6: =Datos!M14 -> 0.00027869619 | G6: =Datos!I13 -> -71.425823 | H6: =Datos!L12 -> 0.0092347162 | I6: =Datos!I9 -> -29.001068 | J6: =Datos!I8 -> 9.6869022 | K6: 1 | L6: =B6-($B$87+$B$88*C6+$B$89*D6+$B$90*E6+$B$91*F6+$B$92*G6+$B$93*H6+$B$94*I6+$B$95*J6) -> 0.0033317169 | M6: =L6^2 -> 1.1100337e-05
A7: =Datos!A16 -> 2007Q4 | B7: =Datos!G16 -> 0.092673486 | C7: =Datos!N16 -> 0.084277977 | D7: =Datos!J16 -> 0.0077 | E7: =Datos!K16 -> -0.051369633 | F7: =Datos!M15 -> 0.00060292067 | G7: =Datos!I14 -> 58.106231 | H7: =Datos!L13 -> 0.021490214 | I7: =Datos!I10 -> -40.701368 | J7: =Datos!I9 -> -29.001068 | K7: 1 | L7: =B7-($B$87+$B$88*C7+$B$89*D7+$B$90*E7+$B$91*F7+$B$92*G7+$B$93*H7+$B$94*I7+$B$95*J7) -> 0.017400436 | M7: =L7^2 -> 0.00030277516
A8: =Datos!A17 -> 2008Q1 | B8: =Datos!G17 -> 0.069123146 | C8: =Datos!N17 -> 0.092673486 | D8: =Datos!J17 -> -0.0048 | E8: =Datos!K17 -> -0.032205396 | F8: =Datos!M16 -> -0.0033813551 | G8: =Datos!I15 -> 146.7424 | H8: =Datos!L14 -> 0.0051344367 | I8: =Datos!I11 -> -14.668524 | J8: =Datos!I10 -> -40.701368 | K8: 1 | L8: =B8-($B$87+$B$88*C8+$B$89*D8+$B$90*E8+$B$91*F8+$B$92*G8+$B$93*H8+$B$94*I8+$B$95*J8) -> 0.0034453253 | M8: =L8^2 -> 1.1870266e-05
A9: =Datos!A18 -> 2008Q2 | B9: =Datos!G18 -> 0.054526855 | C9: =Datos!N18 -> 0.069123146 | D9: =Datos!J18 -> 0.0018 | E9: =Datos!K18 -> -0.047212617 | F9: =Datos!M17 -> -0.0029350876 | G9: =Datos!I16 -> -28.226676 | H9: =Datos!L15 -> -0.013749629 | I9: =Datos!I12 -> -57.340028 | J9: =Datos!I11 -> -14.668524 | K9: 1 | L9: =B9-($B$87+$B$88*C9+$B$89*D9+$B$90*E9+$B$91*F9+$B$92*G9+$B$93*H9+$B$94*I9+$B$95*J9) -> -0.00022497213 | M9: =L9^2 -> 5.0612461e-08
A10: =Datos!A19 -> 2008Q3 | B10: =Datos!G19 -> 0.060060161 | C10: =Datos!N19 -> 0.054526855 | D10: =Datos!J19 -> 0.0064 | E10: =Datos!K19 -> 0.010388192 | F10: =Datos!M18 -> -0.0023308948 | G10: =Datos!I17 -> 95.337039 | H10: =Datos!L16 -> -0.060236757 | I10: =Datos!I13 -> -71.425823 | J10: =Datos!I12 -> -57.340028 | K10: 1 | L10: =B10-($B$87+$B$88*C10+$B$89*D10+$B$90*E10+$B$91*F10+$B$92*G10+$B$93*H10+$B$94*I10+$B$95*J10) -> 0.012164894 | M10: =L10^2 -> 0.00014798464
A11: =Datos!A20 -> 2008Q4 | B11: =Datos!G20 -> -0.019789909 | C11: =Datos!N20 -> 0.060060161 | D11: =Datos!J20 -> -0.0596 | E11: =Datos!K20 -> -0.012294191 | F11: =Datos!M19 -> -4.1934295e-05 | G11: =Datos!I18 -> 74.414777 | H11: =Datos!L17 -> -0.028695182 | I11: =Datos!I14 -> 58.106231 | J11: =Datos!I13 -> -71.425823 | K11: 1 | L11: =B11-($B$87+$B$88*C11+$B$89*D11+$B$90*E11+$B$91*F11+$B$92*G11+$B$93*H11+$B$94*I11+$B$95*J11) -> -0.001654518 | M11: =L11^2 -> 2.7374297e-06
A12: =Datos!A21 -> 2009Q1 | B12: =Datos!G21 -> -0.061887551 | C12: =Datos!N21 -> -0.019789909 | D12: =Datos!J21 -> -0.0344 | E12: =Datos!K21 -> -0.05064093 | F12: =Datos!M20 -> -0.0027010372 | G12: =Datos!I19 -> 140.17397 | H12: =Datos!L18 -> -0.038925191 | I12: =Datos!I15 -> 146.7424 | J12: =Datos!I14 -> 58.106231 | K12: 1 | L12: =B12-($B$87+$B$88*C12+$B$89*D12+$B$90*E12+$B$91*F12+$B$92*G12+$B$93*H12+$B$94*I12+$B$95*J12) -> 0.0075511702 | M12: =L12^2 -> 5.7020171e-05
A13: =Datos!A22 -> 2009Q2 | B13: =Datos!G22 -> -0.11274547 | C13: =Datos!N22 -> -0.061887551 | D13: =Datos!J22 -> 0.0022 | E13: =Datos!K22 -> -0.027033683 | F13: =Datos!M21 -> -0.003479831 | G13: =Datos!I20 -> 999.76307 | H13: =Datos!L19 -> 0.020219373 | I13: =Datos!I16 -> -28.226676 | J13: =Datos!I15 -> 146.7424 | K13: 1 | L13: =B13-($B$87+$B$88*C13+$B$89*D13+$B$90*E13+$B$91*F13+$B$92*G13+$B$93*H13+$B$94*I13+$B$95*J13) -> -0.014193613 | M13: =L13^2 -> 0.00020145866
A14: =Datos!A23 -> 2009Q3 | B14: =Datos!G23 -> -0.0565118 | C14: =Datos!N23 -> -0.11274547 | D14: =Datos!J23 -> 0.0104 | E14: =Datos!K23 -> 0.01889525 | F14: =Datos!M22 -> -0.0080313345 | G14: =Datos!I21 -> 3.4701679 | H14: =Datos!L20 -> 0.020816404 | I14: =Datos!I17 -> 95.337039 | J14: =Datos!I16 -> -28.226676 | K14: 1 | L14: =B14-($B$87+$B$88*C14+$B$89*D14+$B$90*E14+$B$91*F14+$B$92*G14+$B$93*H14+$B$94*I14+$B$95*J14) -> 0.028246522 | M14: =L14^2 -> 0.00079786601
A15: =Datos!A24 -> 2009Q4 | B15: =Datos!G24 -> 0.0028199823 | C15: =Datos!N24 -> -0.0565118 | D15: =Datos!J24 -> 0.0649 | E15: =Datos!K24 -> 0.020266082 | F15: =Datos!M23 -> -0.0083302112 | G15: =Datos!I22 -> -244.40122 | H15: =Datos!L21 -> -0.037438837 | I15: =Datos!I18 -> 74.414777 | J15: =Datos!I17 -> 95.337039 | K15: 1 | L15: =B15-($B$87+$B$88*C15+$B$89*D15+$B$90*E15+$B$91*F15+$B$92*G15+$B$93*H15+$B$94*I15+$B$95*J15) -> -0.030693125 | M15: =L15^2 -> 0.00094206795
A16: =Datos!A25 -> 2010Q1 | B16: =Datos!G25 -> 0.057132691 | C16: =Datos!N25 -> 0.0028199823 | D16: =Datos!J25 -> 0.0388 | E16: =Datos!K25 -> 0.036485145 | F16: =Datos!M24 -> -0.0073833969 | G16: =Datos!I23 -> -533.98958 | H16: =Datos!L22 -> -0.043804081 | I16: =Datos!I19 -> 140.17397 | J16: =Datos!I18 -> 74.414777 | K16: 1 | L16: =B16-($B$87+$B$88*C16+$B$89*D16+$B$90*E16+$B$91*F16+$B$92*G16+$B$93*H16+$B$94*I16+$B$95*J16) -> -0.016405897 | M16: =L16^2 -> 0.00026915345
A17: =Datos!A26 -> 2010Q2 | B17: =Datos!G26 -> 0.162442 | C17: =Datos!N26 -> 0.057132691 | D17: =Datos!J26 -> -0.0069 | E17: =Datos!K26 -> 0.11549915 | F17: =Datos!M25 -> -0.0027481508 | G17: =Datos!I24 -> -203.74584 | H17: =Datos!L23 -> 0.027171203 | I17: =Datos!I20 -> 999.76307 | J17: =Datos!I19 -> 140.17397 | K17: 1 | L17: =B17-($B$87+$B$88*C17+$B$89*D17+$B$90*E17+$B$91*F17+$B$92*G17+$B$93*H17+$B$94*I17+$B$95*J17) -> 0.062476937 | M17: =L17^2 -> 0.0039033677
... A80: =Datos!A89 -> 2026Q1 | B80: =Datos!G89 -> 0.024694045 | C80: =Datos!N89 -> 0.020580507 | D80: =Datos!J89 -> 0 | E80: =Datos!K89 -> -0.099649603 | F80: =Datos!M88 -> -0.0016763505 | G80: =Datos!I87 -> 142.30769 | H80: =Datos!L86 -> 0.028594651 | I80: =Datos!I83 -> 140.77357 | J80: =Datos!I82 -> -411.7502 | K80: 1 | L80: =B80-($B$87+$B$88*C80+$B$89*D80+$B$90*E80+$B$91*F80+$B$92*G80+$B$93*H80+$B$94*I80+$B$95*J80) -> 0.022996473 | M80: =L80^2 -> 0.00052883777
A85: A. ESTIMACION OLS (LINEST devuelve los coeficientes en orden inverso; se extraen con INDEX)
A86: Regresor | B86: Coef. | C86: Error est. | D86: t | E86: p-valor | G86: gl resid. | H86: =INDEX(LINEST($B$6:$B$80,$C$6:$J$80,TRUE(),TRUE()),4,2) -> 66
A87: const | B87: =INDEX(LINEST($B$6:$B$80,$C$6:$J$80,TRUE(),TRUE()),1,9) -> 0.0013736963 | C87: =INDEX(LINEST($B$6:$B$80,$C$6:$J$80,TRUE(),TRUE()),2,9) -> 0.0033012183 | D87: =B87/C87 -> 0.41611799 | E87: =TDIST(ABS(D87),$H$86,2) -> 0.6786737
A88: PBI t-1 | B88: =INDEX(LINEST($B$6:$B$80,$C$6:$J$80,TRUE(),TRUE()),1,8) -> 0.8950021 | C88: =INDEX(LINEST($B$6:$B$80,$C$6:$J$80,TRUE(),TRUE()),2,8) -> 0.063761844 | D88: =B88/C88 -> 14.036641 | E88: =TDIST(ABS(D88),$H$86,2) -> 1.7221424e-21
A89: d(PBI BR) t | B89: =INDEX(LINEST($B$6:$B$80,$C$6:$J$80,TRUE(),TRUE()),1,7) -> 1.1344449 | C89: =INDEX(LINEST($B$6:$B$80,$C$6:$J$80,TRUE(),TRUE()),2,7) -> 0.14046418 | D89: =B89/C89 -> 8.0764003 | E89: =TDIST(ABS(D89),$H$86,2) -> 1.9325152e-11
A90: d(M3R) t | B90: =INDEX(LINEST($B$6:$B$80,$C$6:$J$80,TRUE(),TRUE()),1,6) -> 0.16436936 | C90: =INDEX(LINEST($B$6:$B$80,$C$6:$J$80,TRUE(),TRUE()),2,6) -> 0.043879249 | D90: =B90/C90 -> 3.7459475 | E90: =TDIST(ABS(D90),$H$86,2) -> 0.00037989583
A91: d(RPRIM) t-1 | B91: =INDEX(LINEST($B$6:$B$80,$C$6:$J$80,TRUE(),TRUE()),1,5) -> 0.48933317 | C91: =INDEX(LINEST($B$6:$B$80,$C$6:$J$80,TRUE(),TRUE()),2,5) -> 0.53721838 | D91: =B91/C91 -> 0.91086453 | E91: =TDIST(ABS(D91),$H$86,2) -> 0.36568155
A92: d(EMBI) t-2 | B92: =INDEX(LINEST($B$6:$B$80,$C$6:$J$80,TRUE(),TRUE()),1,4) -> -4.1758214e-05 | C92: =INDEX(LINEST($B$6:$B$80,$C$6:$J$80,TRUE(),TRUE()),2,4) -> 1.1767119e-05 | D92: =B92/C92 -> -3.5487202 | E92: =TDIST(ABS(D92),$H$86,2) -> 0.00071876847
A93: d(M1R) t-3 | B93: =INDEX(LINEST($B$6:$B$80,$C$6:$J$80,TRUE(),TRUE()),1,3) -> 0.067989512 | C93: =INDEX(LINEST($B$6:$B$80,$C$6:$J$80,TRUE(),TRUE()),2,3) -> 0.041403926 | D93: =B93/C93 -> 1.642103 | E93: =TDIST(ABS(D93),$H$86,2) -> 0.10532545
A94: d(EMBI) t-6 | B94: =INDEX(LINEST($B$6:$B$80,$C$6:$J$80,TRUE(),TRUE()),1,2) -> 2.7055881e-05 | C94: =INDEX(LINEST($B$6:$B$80,$C$6:$J$80,TRUE(),TRUE()),2,2) -> 1.1683355e-05 | D94: =B94/C94 -> 2.3157629 | E94: =TDIST(ABS(D94),$H$86,2) -> 0.023687702
A95: d(EMBI) t-7 | B95: =INDEX(LINEST($B$6:$B$80,$C$6:$J$80,TRUE(),TRUE()),1,1) -> 1.7157495e-06 | C95: =INDEX(LINEST($B$6:$B$80,$C$6:$J$80,TRUE(),TRUE()),2,1) -> 1.1566895e-05 | D95: =B95/C95 -> 0.14833276 | E95: =TDIST(ABS(D95),$H$86,2) -> 0.88253243
A97: B. BONDAD DE AJUSTE
A98: n (observaciones) | B98: =COUNT($B$6:$B$80) -> 75
A99: k (parametros) | B99: 9
A100: R2 | B100: =INDEX(LINEST($B$6:$B$80,$C$6:$J$80,TRUE(),TRUE()),3,1) -> 0.81904415
A101: R2 ajustado | B101: =1-(1-B100)*(B98-1)/(B98-B99) -> 0.7971101
A102: SSR | B102: =INDEX(LINEST($B$6:$B$80,$C$6:$J$80,TRUE(),TRUE()),5,2) -> 0.048677542
A103: log-verosimilitud | B103: =-B98/2*(LN(2*PI())+LN(B102/B98)+1) -> 168.83057
A104: AIC | B104: =-2*B103+2*B99 -> -319.66114
A105: BIC | B105: =-2*B103+LN(B98)*B99 -> -298.80375
A107: Durbin-Watson | B107: =SUMXMY2(L7:L80,L6:L79)/SUMSQ(L6:L80) -> 2.1218404

Sheet Modelo_Optimo
A1: MODELO OPTIMO — PBI ~ PBI(t-1) + d(PBI BR t) + d(EMBI t-2) + d(RPRIM t-2) + d(M1R t)
A2: Minimo BIC. Se buscaron 295.245 combinaciones de rezagos y despues se permitio excluir variables. d(M3R) sale (redundante con d(M1R)) y los rezagos 6 y 7 de EMBI colapsan a uno solo en t-2.
A5: Periodo | B5: y = PBI | C5: PBI t-1 | D5: d(PBI BR) t | E5: d(EMBI) t-2 | F5: d(RPRIM) t-2 | G5: d(M1R) t | H5: const=1 | I5: residuo e | J5: e^2 | K5: h_0 | L5: h_1 | M5: h_2 | N5: h_3 | O5: h_4 | P5: h_5
A6: =Datos!A15 -> 2007Q3 | B6: =Datos!G15 -> 0.084277977 | C6: =Datos!N15 -> 0.098593874 | D6: =Datos!J15 -> -0.0067 | E6: =Datos!I13 -> -71.425823 | F6: =Datos!M13 -> -0.0011726597 | G6: =Datos!L15 -> -0.013749629 | H6: 1 | I6: =B6-($B$87+$B$88*C6+$B$89*D6+$B$90*E6+$B$91*F6+$B$92*G6) -> -0.003963256 | J6: =I6^2 -> 1.5707398e-05 | K6: =H6*$I6 -> -0.003963256 | L6: =C6*$I6 -> -0.00039075276 | M6: =D6*$I6 -> 2.6553815e-05 | N6: =E6*$I6 -> 0.28307882 | O6: =F6*$I6 -> 4.6475506e-06 | P6: =G6*$I6 -> 5.44933e-05
A7: =Datos!A16 -> 2007Q4 | B7: =Datos!G16 -> 0.092673486 | C7: =Datos!N16 -> 0.084277977 | D7: =Datos!J16 -> 0.0077 | E7: =Datos!I14 -> 58.106231 | F7: =Datos!M14 -> 0.00027869619 | G7: =Datos!L16 -> -0.060236757 | H7: 1 | I7: =B7-($B$87+$B$88*C7+$B$89*D7+$B$90*E7+$B$91*F7+$B$92*G7) -> 0.018899806 | J7: =I7^2 -> 0.00035720267 | K7: =H7*$I7 -> 0.018899806 | L7: =C7*$I7 -> 0.0015928374 | M7: =D7*$I7 -> 0.00014552851 | N7: =E7*$I7 -> 1.0981965 | O7: =F7*$I7 -> 5.267304e-06 | P7: =G7*$I7 -> -0.001138463
A8: =Datos!A17 -> 2008Q1 | B8: =Datos!G17 -> 0.069123146 | C8: =Datos!N17 -> 0.092673486 | D8: =Datos!J17 -> -0.0048 | E8: =Datos!I15 -> 146.7424 | F8: =Datos!M15 -> 0.00060292067 | G8: =Datos!L17 -> -0.028695182 | H8: 1 | I8: =B8-($B$87+$B$88*C8+$B$89*D8+$B$90*E8+$B$91*F8+$B$92*G8) -> 0.00045057481 | J8: =I8^2 -> 2.0301766e-07 | K8: =H8*$I8 -> 0.00045057481 | L8: =C8*$I8 -> 4.1756339e-05 | M8: =D8*$I8 -> -2.1627591e-06 | N8: =E8*$I8 -> 0.066118428 | O8: =F8*$I8 -> 2.7166087e-07 | P8: =G8*$I8 -> -1.2929326e-05
A9: =Datos!A18 -> 2008Q2 | B9: =Datos!G18 -> 0.054526855 | C9: =Datos!N18 -> 0.069123146 | D9: =Datos!J18 -> 0.0018 | E9: =Datos!I16 -> -28.226676 | F9: =Datos!M16 -> -0.0033813551 | G9: =Datos!L18 -> -0.038925191 | H9: 1 | I9: =B9-($B$87+$B$88*C9+$B$89*D9+$B$90*E9+$B$91*F9+$B$92*G9) -> -0.011852151 | J9: =I9^2 -> 0.00014047347 | K9: =H9*$I9 -> -0.011852151 | L9: =C9*$I9 -> -0.00081925793 | M9: =D9*$I9 -> -2.1333871e-05 | N9: =E9*$I9 -> 0.33454682 | O9: =F9*$I9 -> 4.0076329e-05 | P9: =G9*$I9 -> 0.00046134723
A10: =Datos!A19 -> 2008Q3 | B10: =Datos!G19 -> 0.060060161 | C10: =Datos!N19 -> 0.054526855 | D10: =Datos!J19 -> 0.0064 | E10: =Datos!I17 -> 95.337039 | F10: =Datos!M17 -> -0.0029350876 | G10: =Datos!L19 -> 0.020219373 | H10: 1 | I10: =B10-($B$87+$B$88*C10+$B$89*D10+$B$90*E10+$B$91*F10+$B$92*G10) -> -0.001398694 | J10: =I10^2 -> 1.956345e-06 | K10: =H10*$I10 -> -0.001398694 | L10: =C10*$I10 -> -7.6266386e-05 | M10: =D10*$I10 -> -8.9516418e-06 | N10: =E10*$I10 -> -0.13334735 | O10: =F10*$I10 -> 4.1052895e-06 | P10: =G10*$I10 -> -2.8280716e-05
A11: =Datos!A20 -> 2008Q4 | B11: =Datos!G20 -> -0.019789909 | C11: =Datos!N20 -> 0.060060161 | D11: =Datos!J20 -> -0.0596 | E11: =Datos!I18 -> 74.414777 | F11: =Datos!M18 -> -0.0023308948 | G11: =Datos!L20 -> 0.020816404 | H11: 1 | I11: =B11-($B$87+$B$88*C11+$B$89*D11+$B$90*E11+$B$91*F11+$B$92*G11) -> -0.01501151 | J11: =I11^2 -> 0.00022534542 | K11: =H11*$I11 -> -0.01501151 | L11: =C11*$I11 -> -0.00090159368 | M11: =D11*$I11 -> 0.00089468597 | N11: =E11*$I11 -> -1.1170781 | O11: =F11*$I11 -> 3.499025e-05 | P11: =G11*$I11 -> -0.00031248565
A12: =Datos!A21 -> 2009Q1 | B12: =Datos!G21 -> -0.061887551 | C12: =Datos!N21 -> -0.019789909 | D12: =Datos!J21 -> -0.0344 | E12: =Datos!I19 -> 140.17397 | F12: =Datos!M19 -> -4.1934295e-05 | G12: =Datos!L21 -> -0.037438837 | H12: 1 | I12: =B12-($B$87+$B$88*C12+$B$89*D12+$B$90*E12+$B$91*F12+$B$92*G12) -> 0.0065497969 | J12: =I12^2 -> 4.289984e-05 | K12: =H12*$I12 -> 0.0065497969 | L12: =C12*$I12 -> -0.00012961988 | M12: =D12*$I12 -> -0.00022531301 | N12: =E12*$I12 -> 0.91811103 | O12: =F12*$I12 -> -2.7466112e-07 | P12: =G12*$I12 -> -0.00024521678
A13: =Datos!A22 -> 2009Q2 | B13: =Datos!G22 -> -0.11274547 | C13: =Datos!N22 -> -0.061887551 | D13: =Datos!J22 -> 0.0022 | E13: =Datos!I20 -> 999.76307 | F13: =Datos!M20 -> -0.0027010372 | G13: =Datos!L22 -> -0.043804081 | H13: 1 | I13: =B13-($B$87+$B$88*C13+$B$89*D13+$B$90*E13+$B$91*F13+$B$92*G13) -> -0.0037642027 | J13: =I13^2 -> 1.4169222e-05 | K13: =H13*$I13 -> -0.0037642027 | L13: =C13*$I13 -> 0.00023295729 | M13: =D13*$I13 -> -8.2812459e-06 | N13: =E13*$I13 -> -3.7633109 | O13: =F13*$I13 -> 1.0167252e-05 | P13: =G13*$I13 -> 0.00016488744
A14: =Datos!A23 -> 2009Q3 | B14: =Datos!G23 -> -0.0565118 | C14: =Datos!N23 -> -0.11274547 | D14: =Datos!J23 -> 0.0104 | E14: =Datos!I21 -> 3.4701679 | F14: =Datos!M21 -> -0.003479831 | G14: =Datos!L23 -> 0.027171203 | H14: 1 | I14: =B14-($B$87+$B$88*C14+$B$89*D14+$B$90*E14+$B$91*F14+$B$92*G14) -> 0.026599794 | J14: =I14^2 -> 0.00070754903 | K14: =H14*$I14 -> 0.026599794 | L14: =C14*$I14 -> -0.0029990063 | M14: =D14*$I14 -> 0.00027663785 | N14: =E14*$I14 -> 0.09230575 | O14: =F14*$I14 -> -9.2562786e-05 | P14: =G14*$I14 -> 0.00072274839
A15: =Datos!A24 -> 2009Q4 | B15: =Datos!G24 -> 0.0028199823 | C15: =Datos!N24 -> -0.0565118 | D15: =Datos!J24 -> 0.0649 | E15: =Datos!I22 -> -244.40122 | F15: =Datos!M22 -> -0.0080313345 | G15: =Datos!L24 -> -0.0057671342 | H15: 1 | I15: =B15-($B$87+$B$88*C15+$B$89*D15+$B$90*E15+$B$91*F15+$B$92*G15) -> -0.038455583 | J15: =I15^2 -> 0.0014788319 | K15: =H15*$I15 -> -0.038455583 | L15: =C15*$I15 -> 0.0021731942 | M15: =D15*$I15 -> -0.0024957673 | N15: =E15*$I15 -> 9.3985914 | O15: =F15*$I15 -> 0.00030884965 | P15: =G15*$I15 -> 0.00022177851
A16: =Datos!A25 -> 2010Q1 | B16: =Datos!G25 -> 0.057132691 | C16: =Datos!N25 -> 0.0028199823 | D16: =Datos!J25 -> 0.0388 | E16: =Datos!I23 -> -533.98958 | F16: =Datos!M23 -> -0.0083302112 | G16: =Datos!L25 -> 0.031541814 | H16: 1 | I16: =B16-($B$87+$B$88*C16+$B$89*D16+$B$90*E16+$B$91*F16+$B$92*G16) -> -0.032691592 | J16: =I16^2 -> 0.0010687402 | K16: =H16*$I16 -> -0.032691592 | L16: =C16*$I16 -> -9.218971e-05 | M16: =D16*$I16 -> -0.0012684338 | N16: =E16*$I16 -> 17.45697 | O16: =F16*$I16 -> 0.00027232787 | P16: =G16*$I16 -> -0.0010311521
A17: =Datos!A26 -> 2010Q2 | B17: =Datos!G26 -> 0.162442 | C17: =Datos!N26 -> 0.057132691 | D17: =Datos!J26 -> -0.0069 | E17: =Datos!I24 -> -203.74584 | F17: =Datos!M24 -> -0.0073833969 | G17: =Datos!L26 -> 0.093573973 | H17: 1 | I17: =B17-($B$87+$B$88*C17+$B$89*D17+$B$90*E17+$B$91*F17+$B$92*G17) -> 0.078779933 | J17: =I17^2 -> 0.0062062778 | K17: =H17*$I17 -> 0.078779933 | L17: =C17*$I17 -> 0.0045009095 | M17: =D17*$I17 -> -0.00054358153 | N17: =E17*$I17 -> -16.051083 | O17: =F17*$I17 -> -0.00058166351 | P17: =G17*$I17 -> 0.0073717513
... A80: =Datos!A89 -> 2026Q1 | B80: =Datos!G89 -> 0.024694045 | C80: =Datos!N89 -> 0.020580507 | D80: =Datos!J89 -> 0 | E80: =Datos!I87 -> 142.30769 | F80: =Datos!M87 -> -3.8653015e-05 | G80: =Datos!L89 -> -0.10243736 | H80: 1 | I80: =B80-($B$87+$B$88*C80+$B$89*D80+$B$90*E80+$B$91*F80+$B$92*G80) -> 0.029881463 | J80: =I80^2 -> 0.00089290182 | K80: =H80*$I80 -> 0.029881463 | L80: =C80*$I80 -> 0.00061497566 | M80: =D80*$I80 -> 0 | N80: =E80*$I80 -> 4.252362 | O80: =F80*$I80 -> -1.1550086e-06 | P80: =G80*$I80 -> -0.0030609782
A85: A. ESTIMACION OLS (LINEST devuelve los coeficientes en orden inverso; se extraen con INDEX)
A86: Regresor | B86: Coef. | C86: Error est. | D86: t | E86: p-valor | G86: gl resid. | H86: =INDEX(LINEST($B$6:$B$80,$C$6:$G$80,TRUE(),TRUE()),4,2) -> 69
A87: const | B87: =INDEX(LINEST($B$6:$B$80,$C$6:$G$80,TRUE(),TRUE()),1,6) -> 0.0010778578 | C87: =INDEX(LINEST($B$6:$B$80,$C$6:$G$80,TRUE(),TRUE()),2,6) -> 0.0032614901 | D87: =B87/C87 -> 0.33048016 | E87: =TDIST(ABS(D87),$H$86,2) -> 0.74203858
A88: PBI t-1 | B88: =INDEX(LINEST($B$6:$B$80,$C$6:$G$80,TRUE(),TRUE()),1,5) -> 0.9299384 | C88: =INDEX(LINEST($B$6:$B$80,$C$6:$G$80,TRUE(),TRUE()),2,5) -> 0.060856974 | D88: =B88/C88 -> 15.28072 | E88: =TDIST(ABS(D88),$H$86,2) -> 7.7735458e-24
A89: d(PBI BR) t | B89: =INDEX(LINEST($B$6:$B$80,$C$6:$G$80,TRUE(),TRUE()),1,4) -> 1.0869134 | C89: =INDEX(LINEST($B$6:$B$80,$C$6:$G$80,TRUE(),TRUE()),2,4) -> 0.14589513 | D89: =B89/C89 -> 7.4499637 | E89: =TDIST(ABS(D89),$H$86,2) -> 2.0220189e-10
A90: d(EMBI) t-2 | B90: =INDEX(LINEST($B$6:$B$80,$C$6:$G$80,TRUE(),TRUE()),1,3) -> -5.0756623e-05 | C90: =INDEX(LINEST($B$6:$B$80,$C$6:$G$80,TRUE(),TRUE()),2,3) -> 1.1451232e-05 | D90: =B90/C90 -> -4.4324158 | E90: =TDIST(ABS(D90),$H$86,2) -> 3.4258396e-05
A91: d(RPRIM) t-2 | B91: =INDEX(LINEST($B$6:$B$80,$C$6:$G$80,TRUE(),TRUE()),1,2) -> -1.3485975 | C91: =INDEX(LINEST($B$6:$B$80,$C$6:$G$80,TRUE(),TRUE()),2,2) -> 0.5297361 | D91: =B91/C91 -> -2.5457911 | E91: =TDIST(ABS(D91),$H$86,2) -> 0.013140483
A92: d(M1R) t | B92: =INDEX(LINEST($B$6:$B$80,$C$6:$G$80,TRUE(),TRUE()),1,1) -> 0.1779912 | C92: =INDEX(LINEST($B$6:$B$80,$C$6:$G$80,TRUE(),TRUE()),2,1) -> 0.046076905 | D92: =B92/C92 -> 3.8629157 | E92: =TDIST(ABS(D92),$H$86,2) -> 0.00024987737
A94: B. BONDAD DE AJUSTE
A95: n (observaciones) | B95: =COUNT($B$6:$B$80) -> 75
A96: k (parametros) | B96: 6
A97: R2 | B97: =INDEX(LINEST($B$6:$B$80,$C$6:$G$80,TRUE(),TRUE()),3,1) -> 0.81088071
A98: R2 ajustado | B98: =1-(1-B97)*(B95-1)/(B95-B96) -> 0.79717642
A99: SSR | B99: =INDEX(LINEST($B$6:$B$80,$C$6:$G$80,TRUE(),TRUE()),5,2) -> 0.050873524
A100: log-verosimilitud | B100: =-B95/2*(LN(2*PI())+LN(B99/B95)+1) -> 167.17589
A101: AIC | B101: =-2*B100+2*B96 -> -322.35178
A102: BIC | B102: =-2*B100+LN(B95)*B96 -> -308.44685
A104: Durbin-Watson | B104: =SUMXMY2(I7:I80,I6:I79)/SUMSQ(I6:I80) -> 2.1976834
A106: C. ERRORES ESTANDAR HAC (Newey-West, nucleo de Bartlett, L=4)
A107: V = (X'X)^-1 S (X'X)^-1 , S = G0 + SUM_l w_l (G_l + G_l') , w_l = 1 - l/5. Obligatorio: el filtro interanual induce una MA(3) mecanica en los residuos.
A108: X'X
B109: =SUMPRODUCT($H$6:$H$80,$H$6:$H$80) -> 75 | C109: =SUMPRODUCT($H$6:$H$80,$C$6:$C$80) -> 1.1016858 | D109: =SUMPRODUCT($H$6:$H$80,$D$6:$D$80) -> -0.0472 | E109: =SUMPRODUCT($H$6:$H$80,$E$6:$E$80) -> 584.44859 | F109: =SUMPRODUCT($H$6:$H$80,$F$6:$F$80) -> -0.020882375 | G109: =SUMPRODUCT($H$6:$H$80,$G$6:$G$80) -> -0.13904199
B110: =SUMPRODUCT($C$6:$C$80,$H$6:$H$80) -> 1.1016858 | C110: =SUMPRODUCT($C$6:$C$80,$C$6:$C$80) -> 0.29219785 | D110: =SUMPRODUCT($C$6:$C$80,$D$6:$D$80) -> -0.043140041 | E110: =SUMPRODUCT($C$6:$C$80,$E$6:$E$80) -> -121.05992 | F110: =SUMPRODUCT($C$6:$C$80,$F$6:$F$80) -> 0.0083877578 | G110: =SUMPRODUCT($C$6:$C$80,$G$6:$G$80) -> -0.058554814
B111: =SUMPRODUCT($D$6:$D$80,$H$6:$H$80) -> -0.0472 | C111: =SUMPRODUCT($D$6:$D$80,$C$6:$C$80) -> -0.043140041 | D111: =SUMPRODUCT($D$6:$D$80,$D$6:$D$80) -> 0.05390014 | E111: =SUMPRODUCT($D$6:$D$80,$E$6:$E$80) -> -147.77577 | F111: =SUMPRODUCT($D$6:$D$80,$F$6:$F$80) -> -0.0047386937 | G111: =SUMPRODUCT($D$6:$D$80,$G$6:$G$80) -> -0.061634318
...

Sheet Modelo_COVID
A1: MODELO OPTIMO + DUMMIES IMPULSO COVID (2020Q2 y 2021Q2)
A2: Especificacion recomendada. El test F de las dos dummies y el de la restriccion sobre PBI(t-1) estan abajo.
A5: Periodo | B5: y = PBI | C5: PBI t-1 | D5: d(PBI BR) t | E5: d(EMBI) t-2 | F5: d(RPRIM) t-2 | G5: d(M1R) t | H5: D_2020Q2 | I5: D_2021Q2 | J5: const=1 | K5: residuo e | L5: e^2 | M5: h_0 | N5: h_1 | O5: h_2 | P5: h_3 | Q5: h_4 | R5: h_5 | S5: h_6 | T5: h_7 | W5: aux: PBI - PBI(t-1)
A6: =Datos!A15 -> 2007Q3 | B6: =Datos!G15 -> 0.084277977 | C6: =Datos!N15 -> 0.098593874 | D6: =Datos!J15 -> -0.0067 | E6: =Datos!I13 -> -71.425823 | F6: =Datos!M13 -> -0.0011726597 | G6: =Datos!L15 -> -0.013749629 | H6: =IF($A6="2020Q2",1,0) -> 0 | I6: =IF($A6="2021Q2",1,0) -> 0 | J6: 1 | K6: =B6-($B$87+$B$88*C6+$B$89*D6+$B$90*E6+$B$91*F6+$B$92*G6+$B$93*H6+$B$94*I6) -> 0.0010096486 | L6: =K6^2 -> 1.0193903e-06 | M6: =J6*$K6 -> 0.0010096486 | N6: =C6*$K6 -> 9.9545165e-05 | O6: =D6*$K6 -> -6.7646455e-06 | P6: =E6*$K6 -> -0.07211498 | Q6: =F6*$K6 -> -1.1839742e-06 | R6: =G6*$K6 -> -1.3882294e-05 | S6: =H6*$K6 -> 0 | T6: =I6*$K6 -> 0 | W6: =B6-C6 -> -0.014315897
A7: =Datos!A16 -> 2007Q4 | B7: =Datos!G16 -> 0.092673486 | C7: =Datos!N16 -> 0.084277977 | D7: =Datos!J16 -> 0.0077 | E7: =Datos!I14 -> 58.106231 | F7: =Datos!M14 -> 0.00027869619 | G7: =Datos!L16 -> -0.060236757 | H7: =IF($A7="2020Q2",1,0) -> 0 | I7: =IF($A7="2021Q2",1,0) -> 0 | J7: 1 | K7: =B7-($B$87+$B$88*C7+$B$89*D7+$B$90*E7+$B$91*F7+$B$92*G7+$B$93*H7+$B$94*I7) -> 0.032105387 | L7: =K7^2 -> 0.0010307559 | M7: =J7*$K7 -> 0.032105387 | N7: =C7*$K7 -> 0.002705777 | O7: =D7*$K7 -> 0.00024721148 | P7: =E7*$K7 -> 1.865523 | Q7: =F7*$K7 -> 8.947649e-06 | R7: =G7*$K7 -> -0.0019339244 | S7: =H7*$K7 -> 0 | T7: =I7*$K7 -> 0 | W7: =B7-C7 -> 0.0083955092
A8: =Datos!A17 -> 2008Q1 | B8: =Datos!G17 -> 0.069123146 | C8: =Datos!N17 -> 0.092673486 | D8: =Datos!J17 -> -0.0048 | E8: =Datos!I15 -> 146.7424 | F8: =Datos!M15 -> 0.00060292067 | G8: =Datos!L17 -> -0.028695182 | H8: =IF($A8="2020Q2",1,0) -> 0 | I8: =IF($A8="2021Q2",1,0) -> 0 | J8: 1 | K8: =B8-($B$87+$B$88*C8+$B$89*D8+$B$90*E8+$B$91*F8+$B$92*G8+$B$93*H8+$B$94*I8) -> 0.0062336112 | L8: =K8^2 -> 3.8857908e-05 | M8: =J8*$K8 -> 0.0062336112 | N8: =C8*$K8 -> 0.00057769048 | O8: =D8*$K8 -> -2.9921334e-05 | P8: =E8*$K8 -> 0.91473504 | Q8: =F8*$K8 -> 3.758373e-06 | R8: =G8*$K8 -> -0.0001788746 | S8: =H8*$K8 -> 0 | T8: =I8*$K8 -> 0 | W8: =B8-C8 -> -0.023550341
A9: =Datos!A18 -> 2008Q2 | B9: =Datos!G18 -> 0.054526855 | C9: =Datos!N18 -> 0.069123146 | D9: =Datos!J18 -> 0.0018 | E9: =Datos!I16 -> -28.226676 | F9: =Datos!M16 -> -0.0033813551 | G9: =Datos!L18 -> -0.038925191 | H9: =IF($A9="2020Q2",1,0) -> 0 | I9: =IF($A9="2021Q2",1,0) -> 0 | J9: 1 | K9: =B9-($B$87+$B$88*C9+$B$89*D9+$B$90*E9+$B$91*F9+$B$92*G9+$B$93*H9+$B$94*I9) -> -0.0045336705 | L9: =K9^2 -> 2.0554168e-05 | M9: =J9*$K9 -> -0.0045336705 | N9: =C9*$K9 -> -0.00031338157 | O9: =D9*$K9 -> -8.1606069e-06 | P9: =E9*$K9 -> 0.12797045 | Q9: =F9*$K9 -> 1.532995e-05 | R9: =G9*$K9 -> 0.00017647399 | S9: =H9*$K9 -> 0 | T9: =I9*$K9 -> 0 | W9: =B9-C9 -> -0.014596291
A10: =Datos!A19 -> 2008Q3 | B10: =Datos!G19 -> 0.060060161 | C10: =Datos!N19 -> 0.054526855 | D10: =Datos!J19 -> 0.0064 | E10: =Datos!I17 -> 95.337039 | F10: =Datos!M17 -> -0.0029350876 | G10: =Datos!L19 -> 0.020219373 | H10: =IF($A10="2020Q2",1,0) -> 0 | I10: =IF($A10="2021Q2",1,0) -> 0 | J10: 1 | K10: =B10-($B$87+$B$88*C10+$B$89*D10+$B$90*E10+$B$91*F10+$B$92*G10+$B$93*H10+$B$94*I10) -> 0.0025408667 | L10: =K10^2 -> 6.4560038e-06 | M10: =J10*$K10 -> 0.0025408667 | N10: =C10*$K10 -> 0.00013854547 | O10: =D10*$K10 -> 1.6261547e-05 | P10: =E10*$K10 -> 0.24223871 | Q10: =F10*$K10 -> -7.4576664e-06 | R10: =G10*$K10 -> 5.1374732e-05 | S10: =H10*$K10 -> 0 | T10: =I10*$K10 -> 0 | W10: =B10-C10 -> 0.0055333067
A11: =Datos!A20 -> 2008Q4 | B11: =Datos!G20 -> -0.019789909 | C11: =Datos!N20 -> 0.060060161 | D11: =Datos!J20 -> -0.0596 | E11: =Datos!I18 -> 74.414777 | F11: =Datos!M18 -> -0.0023308948 | G11: =Datos!L20 -> 0.020816404 | H11: =IF($A11="2020Q2",1,0) -> 0 | I11: =IF($A11="2021Q2",1,0) -> 0 | J11: 1 | K11: =B11-($B$87+$B$88*C11+$B$89*D11+$B$90*E11+$B$91*F11+$B$92*G11+$B$93*H11+$B$94*I11) -> -0.040756329 | L11: =K11^2 -> 0.0016610784 | M11: =J11*$K11 -> -0.040756329 | N11: =C11*$K11 -> -0.0024478317 | O11: =D11*$K11 -> 0.0024290772 | P11: =E11*$K11 -> -3.0328732 | Q11: =F11*$K11 -> 9.4998718e-05 | R11: =G11*$K11 -> -0.00084840024 | S11: =H11*$K11 -> 0 | T11: =I11*$K11 -> 0 | W11: =B11-C11 -> -0.07985007
A12: =Datos!A21 -> 2009Q1 | B12: =Datos!G21 -> -0.061887551 | C12: =Datos!N21 -> -0.019789909 | D12: =Datos!J21 -> -0.0344 | E12: =Datos!I19 -> 140.17397 | F12: =Datos!M19 -> -4.1934295e-05 | G12: =Datos!L21 -> -0.037438837 | H12: =IF($A12="2020Q2",1,0) -> 0 | I12: =IF($A12="2021Q2",1,0) -> 0 | J12: 1 | K12: =B12-($B$87+$B$88*C12+$B$89*D12+$B$90*E12+$B$91*F12+$B$92*G12+$B$93*H12+$B$94*I12) -> -0.010147313 | L12: =K12^2 -> 0.00010296795 | M12: =J12*$K12 -> -0.010147313 | N12: =C12*$K12 -> 0.00020081439 | O12: =D12*$K12 -> 0.00034906755 | P12: =E12*$K12 -> -1.4223891 | Q12: =F12*$K12 -> 4.255204e-07 | R12: =G12*$K12 -> 0.00037990358 | S12: =H12*$K12 -> 0 | T12: =I12*$K12 -> 0 | W12: =B12-C12 -> -0.042097643
A13: =Datos!A22 -> 2009Q2 | B13: =Datos!G22 -> -0.11274547 | C13: =Datos!N22 -> -0.061887551 | D13: =Datos!J22 -> 0.0022 | E13: =Datos!I20 -> 999.76307 | F13: =Datos!M20 -> -0.0027010372 | G13: =Datos!L22 -> -0.043804081 | H13: =IF($A13="2020Q2",1,0) -> 0 | I13: =IF($A13="2021Q2",1,0) -> 0 | J13: 1 | K13: =B13-($B$87+$B$88*C13+$B$89*D13+$B$90*E13+$B$91*F13+$B$92*G13+$B$93*H13+$B$94*I13) -> -0.011298222 | L13: =K13^2 -> 0.00012764981 | M13: =J13*$K13 -> -0.011298222 | N13: =C13*$K13 -> 0.00069921927 | O13: =D13*$K13 -> -2.4856087e-05 | P13: =E13*$K13 -> -11.295545 | Q13: =F13*$K13 -> 3.0516917e-05 | R13: =G13*$K13 -> 0.00049490821 | S13: =H13*$K13 -> 0 | T13: =I13*$K13 -> 0 | W13: =B13-C13 -> -0.05085792
A14: =Datos!A23 -> 2009Q3 | B14: =Datos!G23 -> -0.0565118 | C14: =Datos!N23 -> -0.11274547 | D14: =Datos!J23 -> 0.0104 | E14: =Datos!I21 -> 3.4701679 | F14: =Datos!M21 -> -0.003479831 | G14: =Datos!L23 -> 0.027171203 | H14: =IF($A14="2020Q2",1,0) -> 0 | I14: =IF($A14="2021Q2",1,0) -> 0 | J14: 1 | K14: =B14-($B$87+$B$88*C14+$B$89*D14+$B$90*E14+$B$91*F14+$B$92*G14+$B$93*H14+$B$94*I14) -> 0.018375402 | L14: =K14^2 -> 0.0003376554 | M14: =J14*$K14 -> 0.018375402 | N14: =C14*$K14 -> -0.0020717434 | O14: =D14*$K14 -> 0.00019110418 | P14: =E14*$K14 -> 0.06376573 | Q14: =F14*$K14 -> -6.3943293e-05 | R14: =G14*$K14 -> 0.00049928177 | S14: =H14*$K14 -> 0 | T14: =I14*$K14 -> 0 | W14: =B14-C14 -> 0.056233672
A15: =Datos!A24 -> 2009Q4 | B15: =Datos!G24 -> 0.0028199823 | C15: =Datos!N24 -> -0.0565118 | D15: =Datos!J24 -> 0.0649 | E15: =Datos!I22 -> -244.40122 | F15: =Datos!M22 -> -0.0080313345 | G15: =Datos!L24 -> -0.0057671342 | H15: =IF($A15="2020Q2",1,0) -> 0 | I15: =IF($A15="2021Q2",1,0) -> 0 | J15: 1 | K15: =B15-($B$87+$B$88*C15+$B$89*D15+$B$90*E15+$B$91*F15+$B$92*G15+$B$93*H15+$B$94*I15) -> -0.014856437 | L15: =K15^2 -> 0.00022071372 | M15: =J15*$K15 -> -0.014856437 | N15: =C15*$K15 -> 0.000839564 | O15: =D15*$K15 -> -0.00096418277 | P15: =E15*$K15 -> 3.6309313 | Q15: =F15*$K15 -> 0.00011931702 | R15: =G15*$K15 -> 8.5679067e-05 | S15: =H15*$K15 -> 0 | T15: =I15*$K15 -> 0 | W15: =B15-C15 -> 0.059331782
A16: =Datos!A25 -> 2010Q1 | B16: =Datos!G25 -> 0.057132691 | C16: =Datos!N25 -> 0.0028199823 | D16: =Datos!J25 -> 0.0388 | E16: =Datos!I23 -> -533.98958 | F16: =Datos!M23 -> -0.0083302112 | G16: =Datos!L25 -> 0.031541814 | H16: =IF($A16="2020Q2",1,0) -> 0 | I16: =IF($A16="2021Q2",1,0) -> 0 | J16: 1 | K16: =B16-($B$87+$B$88*C16+$B$89*D16+$B$90*E16+$B$91*F16+$B$92*G16+$B$93*H16+$B$94*I16) -> -0.017363683 | L16: =K16^2 -> 0.00030149747 | M16: =J16*$K16 -> -0.017363683 | N16: =C16*$K16 -> -4.8965277e-05 | O16: =D16*$K16 -> -0.00067371088 | P16: =E16*$K16 -> 9.2720256 | Q16: =F16*$K16 -> 0.00014464314 | R16: =G16*$K16 -> -0.00054768205 | S16: =H16*$K16 -> 0 | T16: =I16*$K16 -> 0 | W16: =B16-C16 -> 0.054312709
A17: =Datos!A26 -> 2010Q2 | B17: =Datos!G26 -> 0.162442 | C17: =Datos!N26 -> 0.057132691 | D17: =Datos!J26 -> -0.0069 | E17: =Datos!I24 -> -203.74584 | F17: =Datos!M24 -> -0.0073833969 | G17: =Datos!L26 -> 0.093573973 | H17: =IF($A17="2020Q2",1,0) -> 0 | I17: =IF($A17="2021Q2",1,0) -> 0 | J17: 1 | K17: =B17-($B$87+$B$88*C17+$B$89*D17+$B$90*E17+$B$91*F17+$B$92*G17+$B$93*H17+$B$94*I17) -> 0.072292025 | L17: =K17^2 -> 0.0052261369 | M17: =J17*$K17 -> 0.072292025 | N17: =C17*$K17 -> 0.0041302379 | O17: =D17*$K17 -> -0.00049881497 | P17: =E17*$K17 -> -14.729199 | Q17: =F17*$K17 -> -0.00053376071 | R17: =G17*$K17 -> 0.006764652 | S17: =H17*$K17 -> 0 | T17: =I17*$K17 -> 0 | W17: =B17-C17 -> 0.1053093
... A80: =Datos!A89 -> 2026Q1 | B80: =Datos!G89 -> 0.024694045 | C80: =Datos!N89 -> 0.020580507 | D80: =Datos!J89 -> 0 | E80: =Datos!I87 -> 142.30769 | F80: =Datos!M87 -> -3.8653015e-05 | G80: =Datos!L89 -> -0.10243736 | H80: =IF($A80="2020Q2",1,0) -> 0 | I80: =IF($A80="2021Q2",1,0) -> 0 | J80: 1 | K80: =B80-($B$87+$B$88*C80+$B$89*D80+$B$90*E80+$B$91*F80+$B$92*G80+$B$93*H80+$B$94*I80) -> 0.036550897 | L80: =K80^2 -> 0.0013359681 | M80: =J80*$K80 -> 0.036550897 | N80: =C80*$K80 -> 0.000752236 | O80: =D80*$K80 -> 0 | P80: =E80*$K80 -> 5.2014738 | Q80: =F80*$K80 -> -1.4128024e-06 | R80: =G80*$K80 -> -0.0037441774 | S80: =H80*$K80 -> 0 | T80: =I80*$K80 -> 0 | W80: =B80-C80 -> 0.0041135381
A85: A. ESTIMACION OLS (LINEST devuelve los coeficientes en orden inverso; se extraen con INDEX)
A86: Regresor | B86: Coef. | C86: Error est. | D86: t | E86: p-valor | G86: gl resid. | H86: =INDEX(LINEST($B$6:$B$80,$C$6:$I$80,TRUE(),TRUE()),4,2) -> 67
A87: const | B87: =INDEX(LINEST($B$6:$B$80,$C$6:$I$80,TRUE(),TRUE()),1,8) -> 0.0020966365 | C87: =INDEX(LINEST($B$6:$B$80,$C$6:$I$80,TRUE(),TRUE()),2,8) -> 0.0029980334 | D87: =B87/C87 -> 0.69933727 | E87: =TDIST(ABS(D87),$H$86,2) -> 0.48676213
A88: PBI t-1 | B88: =INDEX(LINEST($B$6:$B$80,$C$6:$I$80,TRUE(),TRUE()),1,7) -> 0.84724037 | C88: =INDEX(LINEST($B$6:$B$80,$C$6:$I$80,TRUE(),TRUE()),2,7) -> 0.058446572 | D88: =B88/C88 -> 14.495981 | E88: =TDIST(ABS(D88),$H$86,2) -> 2.4480487e-22
A89: d(PBI BR) t | B89: =INDEX(LINEST($B$6:$B$80,$C$6:$I$80,TRUE(),TRUE()),1,6) -> 0.6270259 | C89: =INDEX(LINEST($B$6:$B$80,$C$6:$I$80,TRUE(),TRUE()),2,6) -> 0.17144508 | D89: =B89/C89 -> 3.657299 | E89: =TDIST(ABS(D89),$H$86,2) -> 0.00050256715
A90: d(EMBI) t-2 | B90: =INDEX(LINEST($B$6:$B$80,$C$6:$I$80,TRUE(),TRUE()),1,5) -> -4.61925e-05 | C90: =INDEX(LINEST($B$6:$B$80,$C$6:$I$80,TRUE(),TRUE()),2,5) -> 1.0403373e-05 | D90: =B90/C90 -> -4.4401467 | E90: =TDIST(ABS(D90),$H$86,2) -> 3.4435492e-05
A91: d(RPRIM) t-2 | B91: =INDEX(LINEST($B$6:$B$80,$C$6:$I$80,TRUE(),TRUE()),1,4) -> -1.6032226 | C91: =INDEX(LINEST($B$6:$B$80,$C$6:$I$80,TRUE(),TRUE()),2,4) -> 0.48303051 | D91: =B91/C91 -> -3.3190918 | E91: =TDIST(ABS(D91),$H$86,2) -> 0.0014632845
A92: d(M1R) t | B92: =INDEX(LINEST($B$6:$B$80,$C$6:$I$80,TRUE(),TRUE()),1,3) -> 0.24286594 | C92: =INDEX(LINEST($B$6:$B$80,$C$6:$I$80,TRUE(),TRUE()),2,3) -> 0.044411609 | D92: =B92/C92 -> 5.4685239 | E92: =TDIST(ABS(D92),$H$86,2) -> 7.2509746e-07
A93: D_2020Q2 | B93: =INDEX(LINEST($B$6:$B$80,$C$6:$I$80,TRUE(),TRUE()),1,2) -> -0.11967415 | C93: =INDEX(LINEST($B$6:$B$80,$C$6:$I$80,TRUE(),TRUE()),2,2) -> 0.033531697 | D93: =B93/C93 -> -3.5689857 | E93: =TDIST(ABS(D93),$H$86,2) -> 0.00066813114
A94: D_2021Q2 | B94: =INDEX(LINEST($B$6:$B$80,$C$6:$I$80,TRUE(),TRUE()),1,1) -> 0.11370194 | C94: =INDEX(LINEST($B$6:$B$80,$C$6:$I$80,TRUE(),TRUE()),2,1) -> 0.032366031 | D94: =B94/C94 -> 3.5130021 | E94: =TDIST(ABS(D94),$H$86,2) -> 0.00079867407
A96: B. BONDAD DE AJUSTE
A97: n (observaciones) | B97: =COUNT($B$6:$B$80) -> 75
A98: k (parametros) | B98: 8
A99: R2 | B99: =INDEX(LINEST($B$6:$B$80,$C$6:$I$80,TRUE(),TRUE()),3,1) -> 0.85020979
A100: R2 ajustado | B100: =1-(1-B99)*(B97-1)/(B97-B98) -> 0.83456007
A101: SSR | B101: =INDEX(LINEST($B$6:$B$80,$C$6:$I$80,TRUE(),TRUE()),5,2) -> 0.040293912
A102: log-verosimilitud | B102: =-B97/2*(LN(2*PI())+LN(B101/B97)+1) -> 175.91872
A103: AIC | B103: =-2*B102+2*B98 -> -335.83745
A104: BIC | B104: =-2*B102+LN(B97)*B98 -> -317.29754
A106: Durbin-Watson | B106: =SUMXMY2(K7:K80,K6:K79)/SUMSQ(K6:K80) -> 2.1890832
A108: C. ERRORES ESTANDAR HAC (Newey-West, nucleo de Bartlett, L=4)
A109: V = (X'X)^-1 S (X'X)^-1 , S = G0 + SUM_l w_l (G_l + G_l') , w_l = 1 - l/5. Obligatorio: el filtro interanual induce una MA(3) mecanica en los residuos.
A110: X'X
B111: =SUMPRODUCT($J$6:$J$80,$J$6:$J$80) -> 75 | C111: =SUMPRODUCT($J$6:$J$80,$C$6:$C$80) -> 1.1016858 | D111: =SUMPRODUCT($J$6:$J$80,$D$6:$D$80) -> -0.0472 | E111: =SUMPRODUCT($J$6:$J$80,$E$6:$E$80) -> 584.44859 | F111: =SUMPRODUCT($J$6:$J$80,$F$6:$F$80) -> -0.020882375 | G111: =SUMPRODUCT($J$6:$J$80,$G$6:$G$80) -> -0.13904199 | H111: =SUMPRODUCT($J$6:$J$80,$H$6:$H$80) -> 1 | I111: =SUMPRODUCT($J$6:$J$80,$I$6:$I$80) -> 1
...

Sheet Diagnosticos
A1: DIAGNOSTICOS DE RESIDUOS
A4: A. AUTOCORRELACION DE LOS RESIDUOS
A5: Rezago | B5: Base | C5: Base + PBI(t-1) | D5: Optimo | E5: Optimo + dummies
A6: 1 | B6: =SUMPRODUCT(Modelo_Base!$K$7:$K$80,Modelo_Base!$K$6:$K$79)/SUMSQ(Modelo_Base!$K$6:$K$80) -> 0.64608499 | C6: =SUMPRODUCT(Modelo_ADL!$L$7:$L$80,Modelo_ADL!$L$6:$L$79)/SUMSQ(Modelo_ADL!$L$6:$L$80) -> -0.066466256 | D6: =SUMPRODUCT(Modelo_Optimo!$I$7:$I$80,Modelo_Optimo!$I$6:$I$79)/SUMSQ(Modelo_Optimo!$I$6:$I$80) -> -0.10777179 | E6: =SUMPRODUCT(Modelo_COVID!$K$7:$K$80,Modelo_COVID!$K$6:$K$79)/SUMSQ(Modelo_COVID!$K$6:$K$80) -> -0.11113202 | G6: En el modelo base el rezago 1 es enorme (0,65): eso es la persistencia del PBI que ningun regresor diferenciado puede capturar. Al agregar PBI(t-1) desaparece, pero queda un residuo negativo en el rezago 4 que es la MA que arrastra el filtro interanual de la dependiente. Por eso: errores HAC.
A7: 2 | B7: =SUMPRODUCT(Modelo_Base!$K$8:$K$80,Modelo_Base!$K$6:$K$78)/SUMSQ(Modelo_Base!$K$6:$K$80) -> 0.39515923 | C7: =SUMPRODUCT(Modelo_ADL!$L$8:$L$80,Modelo_ADL!$L$6:$L$78)/SUMSQ(Modelo_ADL!$L$6:$L$80) -> -0.084627899 | D7: =SUMPRODUCT(Modelo_Optimo!$I$8:$I$80,Modelo_Optimo!$I$6:$I$78)/SUMSQ(Modelo_Optimo!$I$6:$I$80) -> -0.097024515 | E7: =SUMPRODUCT(Modelo_COVID!$K$8:$K$80,Modelo_COVID!$K$6:$K$78)/SUMSQ(Modelo_COVID!$K$6:$K$80) -> -0.026167283
A8: 3 | B8: =SUMPRODUCT(Modelo_Base!$K$9:$K$80,Modelo_Base!$K$6:$K$77)/SUMSQ(Modelo_Base!$K$6:$K$80) -> 0.15643395 | C8: =SUMPRODUCT(Modelo_ADL!$L$9:$L$80,Modelo_ADL!$L$6:$L$77)/SUMSQ(Modelo_ADL!$L$6:$L$80) -> 0.0753007 | D8: =SUMPRODUCT(Modelo_Optimo!$I$9:$I$80,Modelo_Optimo!$I$6:$I$77)/SUMSQ(Modelo_Optimo!$I$6:$I$80) -> 0.022768293 | E8: =SUMPRODUCT(Modelo_COVID!$K$9:$K$80,Modelo_COVID!$K$6:$K$77)/SUMSQ(Modelo_COVID!$K$6:$K$80) -> -0.038406025
A9: 4 | B9: =SUMPRODUCT(Modelo_Base!$K$10:$K$80,Modelo_Base!$K$6:$K$76)/SUMSQ(Modelo_Base!$K$6:$K$80) -> -0.065950029 | C9: =SUMPRODUCT(Modelo_ADL!$L$10:$L$80,Modelo_ADL!$L$6:$L$76)/SUMSQ(Modelo_ADL!$L$6:$L$80) -> -0.35061465 | D9: =SUMPRODUCT(Modelo_Optimo!$I$10:$I$80,Modelo_Optimo!$I$6:$I$76)/SUMSQ(Modelo_Optimo!$I$6:$I$80) -> -0.32607641 | E9: =SUMPRODUCT(Modelo_COVID!$K$10:$K$80,Modelo_COVID!$K$6:$K$76)/SUMSQ(Modelo_COVID!$K$6:$K$80) -> -0.29263056
A10: 5 | B10: =SUMPRODUCT(Modelo_Base!$K$11:$K$80,Modelo_Base!$K$6:$K$75)/SUMSQ(Modelo_Base!$K$6:$K$80) -> -0.12508945 | C10: =SUMPRODUCT(Modelo_ADL!$L$11:$L$80,Modelo_ADL!$L$6:$L$75)/SUMSQ(Modelo_ADL!$L$6:$L$80) -> -0.021992998 | D10: =SUMPRODUCT(Modelo_Optimo!$I$11:$I$80,Modelo_Optimo!$I$6:$I$75)/SUMSQ(Modelo_Optimo!$I$6:$I$80) -> 0.099623937 | E10: =SUMPRODUCT(Modelo_COVID!$K$11:$K$80,Modelo_COVID!$K$6:$K$75)/SUMSQ(Modelo_COVID!$K$6:$K$80) -> 0.15513168
A11: 6 | B11: =SUMPRODUCT(Modelo_Base!$K$12:$K$80,Modelo_Base!$K$6:$K$74)/SUMSQ(Modelo_Base!$K$6:$K$80) -> -0.17181406 | C11: =SUMPRODUCT(Modelo_ADL!$L$12:$L$80,Modelo_ADL!$L$6:$L$74)/SUMSQ(Modelo_ADL!$L$6:$L$80) -> 0.09907794 | D11: =SUMPRODUCT(Modelo_Optimo!$I$12:$I$80,Modelo_Optimo!$I$6:$I$74)/SUMSQ(Modelo_Optimo!$I$6:$I$80) -> -0.090361961 | E11: =SUMPRODUCT(Modelo_COVID!$K$12:$K$80,Modelo_COVID!$K$6:$K$74)/SUMSQ(Modelo_COVID!$K$6:$K$80) -> -0.15044201
A12: 7 | B12: =SUMPRODUCT(Modelo_Base!$K$13:$K$80,Modelo_Base!$K$6:$K$73)/SUMSQ(Modelo_Base!$K$6:$K$80) -> -0.12345774 | C12: =SUMPRODUCT(Modelo_ADL!$L$13:$L$80,Modelo_ADL!$L$6:$L$73)/SUMSQ(Modelo_ADL!$L$6:$L$80) -> 0.046954474 | D12: =SUMPRODUCT(Modelo_Optimo!$I$13:$I$80,Modelo_Optimo!$I$6:$I$73)/SUMSQ(Modelo_Optimo!$I$6:$I$80) -> 0.0079270041 | E12: =SUMPRODUCT(Modelo_COVID!$K$13:$K$80,Modelo_COVID!$K$6:$K$73)/SUMSQ(Modelo_COVID!$K$6:$K$80) -> 0.089244171
A13: 8 | B13: =SUMPRODUCT(Modelo_Base!$K$14:$K$80,Modelo_Base!$K$6:$K$72)/SUMSQ(Modelo_Base!$K$6:$K$80) -> -0.12622621 | C13: =SUMPRODUCT(Modelo_ADL!$L$14:$L$80,Modelo_ADL!$L$6:$L$72)/SUMSQ(Modelo_ADL!$L$6:$L$80) -> -0.079154854 | D13: =SUMPRODUCT(Modelo_Optimo!$I$14:$I$80,Modelo_Optimo!$I$6:$I$72)/SUMSQ(Modelo_Optimo!$I$6:$I$80) -> 0.010570896 | E13: =SUMPRODUCT(Modelo_COVID!$K$14:$K$80,Modelo_COVID!$K$6:$K$72)/SUMSQ(Modelo_COVID!$K$6:$K$80) -> -0.071224389
A15: Durbin-Watson | B15: =Modelo_Base!B106 -> 0.68276096 | C15: =Modelo_ADL!B107 -> 2.1218404 | D15: =Modelo_Optimo!B104 -> 2.1976834 | E15: =Modelo_COVID!B106 -> 2.1890832
A17: B. HETEROCEDASTICIDAD — Breusch-Pagan (LM = n x R2 de e^2 sobre X)
A18: Modelo | B18: R2 auxiliar | C18: LM | D18: gl | E18: p-valor
A19: Base | B19: =INDEX(LINEST(Modelo_Base!$L$6:$L$80,Modelo_Base!$C$6:$I$80,TRUE(),TRUE()),3,1) -> 0.15991641 | C19: =75*B19 -> 11.99373 | D19: 7 | E19: =CHIDIST(C19,D19) -> 0.10076524
A20: Base + PBI(t-1) | B20: =INDEX(LINEST(Modelo_ADL!$M$6:$M$80,Modelo_ADL!$C$6:$J$80,TRUE(),TRUE()),3,1) -> 0.11823383 | C20: =75*B20 -> 8.867537 | D20: 8 | E20: =CHIDIST(C20,D20) -> 0.35359342
A21: Optimo | B21: =INDEX(LINEST(Modelo_Optimo!$J$6:$J$80,Modelo_Optimo!$C$6:$G$80,TRUE(),TRUE()),3,1) -> 0.048830384 | C21: =75*B21 -> 3.6622788 | D21: 5 | E21: =CHIDIST(C21,D21) -> 0.59898732
